[2022-06-07 06:16:57,385] {taskinstance.py:1159} INFO - Dependencies all met for <TaskInstance: hands_on_test.spark_data_quality_check scheduled__2022-06-06T00:00:00+00:00 [queued]>
[2022-06-07 06:16:57,400] {taskinstance.py:1159} INFO - Dependencies all met for <TaskInstance: hands_on_test.spark_data_quality_check scheduled__2022-06-06T00:00:00+00:00 [queued]>
[2022-06-07 06:16:57,401] {taskinstance.py:1356} INFO - 
--------------------------------------------------------------------------------
[2022-06-07 06:16:57,402] {taskinstance.py:1357} INFO - Starting attempt 1 of 2
[2022-06-07 06:16:57,403] {taskinstance.py:1358} INFO - 
--------------------------------------------------------------------------------
[2022-06-07 06:16:57,421] {taskinstance.py:1377} INFO - Executing <Task(BashOperator): spark_data_quality_check> on 2022-06-06 00:00:00+00:00
[2022-06-07 06:16:57,427] {standard_task_runner.py:52} INFO - Started process 6438 to run task
[2022-06-07 06:16:57,432] {standard_task_runner.py:79} INFO - Running: ['***', 'tasks', 'run', 'hands_on_test', 'spark_data_quality_check', 'scheduled__2022-06-06T00:00:00+00:00', '--job-id', '44', '--raw', '--subdir', 'DAGS_FOLDER/dag.py', '--cfg-path', '/tmp/tmp0z52lkw6', '--error-file', '/tmp/tmp_vwpdtwi']
[2022-06-07 06:16:57,436] {standard_task_runner.py:80} INFO - Job 44: Subtask spark_data_quality_check
[2022-06-07 06:16:57,543] {task_command.py:369} INFO - Running <TaskInstance: hands_on_test.spark_data_quality_check scheduled__2022-06-06T00:00:00+00:00 [running]> on host a4a1e1d603db
[2022-06-07 06:16:57,645] {taskinstance.py:1571} INFO - Exporting the following env vars:
AIRFLOW_CTX_DAG_OWNER=pathairs
AIRFLOW_CTX_DAG_ID=hands_on_test
AIRFLOW_CTX_TASK_ID=spark_data_quality_check
AIRFLOW_CTX_EXECUTION_DATE=2022-06-06T00:00:00+00:00
AIRFLOW_CTX_TRY_NUMBER=1
AIRFLOW_CTX_DAG_RUN_ID=scheduled__2022-06-06T00:00:00+00:00
[2022-06-07 06:16:57,647] {subprocess.py:62} INFO - Tmp dir root location: 
 /tmp
[2022-06-07 06:16:57,649] {subprocess.py:74} INFO - Running command: ['bash', '-c', 'docker exec spark-master /spark/bin/spark-submit --master local[*] --name spark_data_quality_check /home/script/dq_check.py ']
[2022-06-07 06:16:57,661] {subprocess.py:85} INFO - Output:
[2022-06-07 06:17:00,061] {subprocess.py:92} INFO - 22/06/07 06:17:00 WARN NativeCodeLoader: Unable to load native-hadoop library for your platform... using builtin-java classes where applicable
[2022-06-07 06:17:00,917] {subprocess.py:92} INFO - Using Spark's default log4j profile: org/apache/spark/log4j-defaults.properties
[2022-06-07 06:17:00,932] {subprocess.py:92} INFO - 22/06/07 06:17:00 INFO SparkContext: Running Spark version 3.1.1
[2022-06-07 06:17:00,989] {subprocess.py:92} INFO - 22/06/07 06:17:00 INFO ResourceUtils: ==============================================================
[2022-06-07 06:17:00,990] {subprocess.py:92} INFO - 22/06/07 06:17:00 INFO ResourceUtils: No custom resources configured for spark.driver.
[2022-06-07 06:17:00,992] {subprocess.py:92} INFO - 22/06/07 06:17:00 INFO ResourceUtils: ==============================================================
[2022-06-07 06:17:00,994] {subprocess.py:92} INFO - 22/06/07 06:17:00 INFO SparkContext: Submitted application: spark_data_quality_check
[2022-06-07 06:17:01,030] {subprocess.py:92} INFO - 22/06/07 06:17:01 INFO ResourceProfile: Default ResourceProfile created, executor resources: Map(cores -> name: cores, amount: 1, script: , vendor: , memory -> name: memory, amount: 1024, script: , vendor: , offHeap -> name: offHeap, amount: 0, script: , vendor: ), task resources: Map(cpus -> name: cpus, amount: 1.0)
[2022-06-07 06:17:01,052] {subprocess.py:92} INFO - 22/06/07 06:17:01 INFO ResourceProfile: Limiting resource is cpu
[2022-06-07 06:17:01,054] {subprocess.py:92} INFO - 22/06/07 06:17:01 INFO ResourceProfileManager: Added ResourceProfile id: 0
[2022-06-07 06:17:01,129] {subprocess.py:92} INFO - 22/06/07 06:17:01 INFO SecurityManager: Changing view acls to: root
[2022-06-07 06:17:01,130] {subprocess.py:92} INFO - 22/06/07 06:17:01 INFO SecurityManager: Changing modify acls to: root
[2022-06-07 06:17:01,131] {subprocess.py:92} INFO - 22/06/07 06:17:01 INFO SecurityManager: Changing view acls groups to:
[2022-06-07 06:17:01,132] {subprocess.py:92} INFO - 22/06/07 06:17:01 INFO SecurityManager: Changing modify acls groups to:
[2022-06-07 06:17:01,133] {subprocess.py:92} INFO - 22/06/07 06:17:01 INFO SecurityManager: SecurityManager: authentication disabled; ui acls disabled; users  with view permissions: Set(root); groups with view permissions: Set(); users  with modify permissions: Set(root); groups with modify permissions: Set()
[2022-06-07 06:17:01,409] {subprocess.py:92} INFO - 22/06/07 06:17:01 INFO Utils: Successfully started service 'sparkDriver' on port 45933.
[2022-06-07 06:17:01,451] {subprocess.py:92} INFO - 22/06/07 06:17:01 INFO SparkEnv: Registering MapOutputTracker
[2022-06-07 06:17:01,523] {subprocess.py:92} INFO - 22/06/07 06:17:01 INFO SparkEnv: Registering BlockManagerMaster
[2022-06-07 06:17:01,552] {subprocess.py:92} INFO - 22/06/07 06:17:01 INFO BlockManagerMasterEndpoint: Using org.apache.spark.storage.DefaultTopologyMapper for getting topology information
[2022-06-07 06:17:01,555] {subprocess.py:92} INFO - 22/06/07 06:17:01 INFO BlockManagerMasterEndpoint: BlockManagerMasterEndpoint up
[2022-06-07 06:17:01,563] {subprocess.py:92} INFO - 22/06/07 06:17:01 INFO SparkEnv: Registering BlockManagerMasterHeartbeat
[2022-06-07 06:17:01,586] {subprocess.py:92} INFO - 22/06/07 06:17:01 INFO DiskBlockManager: Created local directory at /tmp/blockmgr-48191c3e-1514-4a75-8c1f-4abd463c6d59
[2022-06-07 06:17:01,622] {subprocess.py:92} INFO - 22/06/07 06:17:01 INFO MemoryStore: MemoryStore started with capacity 366.3 MiB
[2022-06-07 06:17:01,650] {subprocess.py:92} INFO - 22/06/07 06:17:01 INFO SparkEnv: Registering OutputCommitCoordinator
[2022-06-07 06:17:01,977] {subprocess.py:92} INFO - 22/06/07 06:17:01 INFO Utils: Successfully started service 'SparkUI' on port 4040.
[2022-06-07 06:17:02,068] {subprocess.py:92} INFO - 22/06/07 06:17:02 INFO SparkUI: Bound SparkUI to 0.0.0.0, and started at http://d952e2b2ede8:4040
[2022-06-07 06:17:02,348] {subprocess.py:92} INFO - 22/06/07 06:17:02 INFO Executor: Starting executor ID driver on host d952e2b2ede8
[2022-06-07 06:17:02,397] {subprocess.py:92} INFO - 22/06/07 06:17:02 INFO Utils: Successfully started service 'org.apache.spark.network.netty.NettyBlockTransferService' on port 38899.
[2022-06-07 06:17:02,399] {subprocess.py:92} INFO - 22/06/07 06:17:02 INFO NettyBlockTransferService: Server created on d952e2b2ede8:38899
[2022-06-07 06:17:02,400] {subprocess.py:92} INFO - 22/06/07 06:17:02 INFO BlockManager: Using org.apache.spark.storage.RandomBlockReplicationPolicy for block replication policy
[2022-06-07 06:17:02,409] {subprocess.py:92} INFO - 22/06/07 06:17:02 INFO BlockManagerMaster: Registering BlockManager BlockManagerId(driver, d952e2b2ede8, 38899, None)
[2022-06-07 06:17:02,415] {subprocess.py:92} INFO - 22/06/07 06:17:02 INFO BlockManagerMasterEndpoint: Registering block manager d952e2b2ede8:38899 with 366.3 MiB RAM, BlockManagerId(driver, d952e2b2ede8, 38899, None)
[2022-06-07 06:17:02,420] {subprocess.py:92} INFO - 22/06/07 06:17:02 INFO BlockManagerMaster: Registered BlockManager BlockManagerId(driver, d952e2b2ede8, 38899, None)
[2022-06-07 06:17:02,422] {subprocess.py:92} INFO - 22/06/07 06:17:02 INFO BlockManager: Initialized BlockManager: BlockManagerId(driver, d952e2b2ede8, 38899, None)
[2022-06-07 06:17:03,084] {subprocess.py:92} INFO - 22/06/07 06:17:03 INFO SharedState: Setting hive.metastore.warehouse.dir ('null') to the value of spark.sql.warehouse.dir ('file:/spark-warehouse').
[2022-06-07 06:17:03,085] {subprocess.py:92} INFO - 22/06/07 06:17:03 INFO SharedState: Warehouse path is 'file:/spark-warehouse'.
[2022-06-07 06:17:04,840] {subprocess.py:92} INFO - 22/06/07 06:17:04 INFO HadoopFSUtils: Listing leaf files and directories in parallel under 180 paths. The first several paths are: hdfs://hive-namenode:8020/user/spark/transformed_order_detail/dt=20190101, hdfs://hive-namenode:8020/user/spark/transformed_order_detail/dt=20190102, hdfs://hive-namenode:8020/user/spark/transformed_order_detail/dt=20190103, hdfs://hive-namenode:8020/user/spark/transformed_order_detail/dt=20190104, hdfs://hive-namenode:8020/user/spark/transformed_order_detail/dt=20190105, hdfs://hive-namenode:8020/user/spark/transformed_order_detail/dt=20190106, hdfs://hive-namenode:8020/user/spark/transformed_order_detail/dt=20190107, hdfs://hive-namenode:8020/user/spark/transformed_order_detail/dt=20190108, hdfs://hive-namenode:8020/user/spark/transformed_order_detail/dt=20190109, hdfs://hive-namenode:8020/user/spark/transformed_order_detail/dt=20190110.
[2022-06-07 06:17:05,457] {subprocess.py:92} INFO - 22/06/07 06:17:05 INFO SparkContext: Starting job: parquet at NativeMethodAccessorImpl.java:0
[2022-06-07 06:17:05,484] {subprocess.py:92} INFO - 22/06/07 06:17:05 INFO DAGScheduler: Got job 0 (parquet at NativeMethodAccessorImpl.java:0) with 180 output partitions
[2022-06-07 06:17:05,485] {subprocess.py:92} INFO - 22/06/07 06:17:05 INFO DAGScheduler: Final stage: ResultStage 0 (parquet at NativeMethodAccessorImpl.java:0)
[2022-06-07 06:17:05,486] {subprocess.py:92} INFO - 22/06/07 06:17:05 INFO DAGScheduler: Parents of final stage: List()
[2022-06-07 06:17:05,487] {subprocess.py:92} INFO - 22/06/07 06:17:05 INFO DAGScheduler: Missing parents: List()
[2022-06-07 06:17:05,500] {subprocess.py:92} INFO - 22/06/07 06:17:05 INFO DAGScheduler: Submitting ResultStage 0 (MapPartitionsRDD[2] at parquet at NativeMethodAccessorImpl.java:0), which has no missing parents
[2022-06-07 06:17:05,678] {subprocess.py:92} INFO - 22/06/07 06:17:05 INFO MemoryStore: Block broadcast_0 stored as values in memory (estimated size 83.6 KiB, free 366.2 MiB)
[2022-06-07 06:17:05,723] {subprocess.py:92} INFO - 22/06/07 06:17:05 INFO MemoryStore: Block broadcast_0_piece0 stored as bytes in memory (estimated size 29.5 KiB, free 366.2 MiB)
[2022-06-07 06:17:05,728] {subprocess.py:92} INFO - 22/06/07 06:17:05 INFO BlockManagerInfo: Added broadcast_0_piece0 in memory on d952e2b2ede8:38899 (size: 29.5 KiB, free: 366.3 MiB)
[2022-06-07 06:17:05,735] {subprocess.py:92} INFO - 22/06/07 06:17:05 INFO SparkContext: Created broadcast 0 from broadcast at DAGScheduler.scala:1383
[2022-06-07 06:17:05,757] {subprocess.py:92} INFO - 22/06/07 06:17:05 INFO DAGScheduler: Submitting 180 missing tasks from ResultStage 0 (MapPartitionsRDD[2] at parquet at NativeMethodAccessorImpl.java:0) (first 15 tasks are for partitions Vector(0, 1, 2, 3, 4, 5, 6, 7, 8, 9, 10, 11, 12, 13, 14))
[2022-06-07 06:17:05,759] {subprocess.py:92} INFO - 22/06/07 06:17:05 INFO TaskSchedulerImpl: Adding task set 0.0 with 180 tasks resource profile 0
[2022-06-07 06:17:05,873] {subprocess.py:92} INFO - 22/06/07 06:17:05 INFO TaskSetManager: Starting task 0.0 in stage 0.0 (TID 0) (d952e2b2ede8, executor driver, partition 0, PROCESS_LOCAL, 4553 bytes) taskResourceAssignments Map()
[2022-06-07 06:17:05,878] {subprocess.py:92} INFO - 22/06/07 06:17:05 INFO TaskSetManager: Starting task 1.0 in stage 0.0 (TID 1) (d952e2b2ede8, executor driver, partition 1, PROCESS_LOCAL, 4553 bytes) taskResourceAssignments Map()
[2022-06-07 06:17:05,892] {subprocess.py:92} INFO - 22/06/07 06:17:05 INFO TaskSetManager: Starting task 2.0 in stage 0.0 (TID 2) (d952e2b2ede8, executor driver, partition 2, PROCESS_LOCAL, 4553 bytes) taskResourceAssignments Map()
[2022-06-07 06:17:05,896] {subprocess.py:92} INFO - 22/06/07 06:17:05 INFO TaskSetManager: Starting task 3.0 in stage 0.0 (TID 3) (d952e2b2ede8, executor driver, partition 3, PROCESS_LOCAL, 4553 bytes) taskResourceAssignments Map()
[2022-06-07 06:17:05,942] {subprocess.py:92} INFO - 22/06/07 06:17:05 INFO Executor: Running task 0.0 in stage 0.0 (TID 0)
[2022-06-07 06:17:05,943] {subprocess.py:92} INFO - 22/06/07 06:17:05 INFO Executor: Running task 2.0 in stage 0.0 (TID 2)
[2022-06-07 06:17:05,944] {subprocess.py:92} INFO - 22/06/07 06:17:05 INFO Executor: Running task 3.0 in stage 0.0 (TID 3)
[2022-06-07 06:17:05,946] {subprocess.py:92} INFO - 22/06/07 06:17:05 INFO Executor: Running task 1.0 in stage 0.0 (TID 1)
[2022-06-07 06:17:06,784] {subprocess.py:92} INFO - 22/06/07 06:17:06 INFO Executor: Finished task 2.0 in stage 0.0 (TID 2). 2646 bytes result sent to driver
[2022-06-07 06:17:06,785] {subprocess.py:92} INFO - 22/06/07 06:17:06 INFO Executor: Finished task 1.0 in stage 0.0 (TID 1). 2689 bytes result sent to driver
[2022-06-07 06:17:06,786] {subprocess.py:92} INFO - 22/06/07 06:17:06 INFO Executor: Finished task 3.0 in stage 0.0 (TID 3). 2689 bytes result sent to driver
[2022-06-07 06:17:06,792] {subprocess.py:92} INFO - 22/06/07 06:17:06 INFO Executor: Finished task 0.0 in stage 0.0 (TID 0). 2689 bytes result sent to driver
[2022-06-07 06:17:06,793] {subprocess.py:92} INFO - 22/06/07 06:17:06 INFO TaskSetManager: Starting task 4.0 in stage 0.0 (TID 4) (d952e2b2ede8, executor driver, partition 4, PROCESS_LOCAL, 4553 bytes) taskResourceAssignments Map()
[2022-06-07 06:17:06,795] {subprocess.py:92} INFO - 22/06/07 06:17:06 INFO Executor: Running task 4.0 in stage 0.0 (TID 4)
[2022-06-07 06:17:06,799] {subprocess.py:92} INFO - 22/06/07 06:17:06 INFO TaskSetManager: Starting task 5.0 in stage 0.0 (TID 5) (d952e2b2ede8, executor driver, partition 5, PROCESS_LOCAL, 4553 bytes) taskResourceAssignments Map()
[2022-06-07 06:17:06,800] {subprocess.py:92} INFO - 22/06/07 06:17:06 INFO Executor: Running task 5.0 in stage 0.0 (TID 5)
[2022-06-07 06:17:06,810] {subprocess.py:92} INFO - 22/06/07 06:17:06 INFO TaskSetManager: Finished task 3.0 in stage 0.0 (TID 3) in 907 ms on d952e2b2ede8 (executor driver) (1/180)
[2022-06-07 06:17:06,816] {subprocess.py:92} INFO - 22/06/07 06:17:06 INFO TaskSetManager: Starting task 6.0 in stage 0.0 (TID 6) (d952e2b2ede8, executor driver, partition 6, PROCESS_LOCAL, 4553 bytes) taskResourceAssignments Map()
[2022-06-07 06:17:06,817] {subprocess.py:92} INFO - 22/06/07 06:17:06 INFO Executor: Running task 6.0 in stage 0.0 (TID 6)
[2022-06-07 06:17:06,825] {subprocess.py:92} INFO - 22/06/07 06:17:06 INFO TaskSetManager: Starting task 7.0 in stage 0.0 (TID 7) (d952e2b2ede8, executor driver, partition 7, PROCESS_LOCAL, 4553 bytes) taskResourceAssignments Map()
[2022-06-07 06:17:06,826] {subprocess.py:92} INFO - 22/06/07 06:17:06 INFO Executor: Running task 7.0 in stage 0.0 (TID 7)
[2022-06-07 06:17:06,841] {subprocess.py:92} INFO - 22/06/07 06:17:06 INFO Executor: Finished task 5.0 in stage 0.0 (TID 5). 2646 bytes result sent to driver
[2022-06-07 06:17:06,845] {subprocess.py:92} INFO - 22/06/07 06:17:06 INFO TaskSetManager: Starting task 8.0 in stage 0.0 (TID 8) (d952e2b2ede8, executor driver, partition 8, PROCESS_LOCAL, 4553 bytes) taskResourceAssignments Map()
[2022-06-07 06:17:06,846] {subprocess.py:92} INFO - 22/06/07 06:17:06 INFO Executor: Running task 8.0 in stage 0.0 (TID 8)
[2022-06-07 06:17:06,847] {subprocess.py:92} INFO - 22/06/07 06:17:06 INFO Executor: Finished task 6.0 in stage 0.0 (TID 6). 2646 bytes result sent to driver
[2022-06-07 06:17:06,848] {subprocess.py:92} INFO - 22/06/07 06:17:06 INFO TaskSetManager: Finished task 1.0 in stage 0.0 (TID 1) in 967 ms on d952e2b2ede8 (executor driver) (2/180)
[2022-06-07 06:17:06,848] {subprocess.py:92} INFO - 22/06/07 06:17:06 INFO TaskSetManager: Finished task 5.0 in stage 0.0 (TID 5) in 47 ms on d952e2b2ede8 (executor driver) (3/180)
[2022-06-07 06:17:06,854] {subprocess.py:92} INFO - 22/06/07 06:17:06 INFO Executor: Finished task 4.0 in stage 0.0 (TID 4). 2646 bytes result sent to driver
[2022-06-07 06:17:06,855] {subprocess.py:92} INFO - 22/06/07 06:17:06 INFO TaskSetManager: Finished task 2.0 in stage 0.0 (TID 2) in 976 ms on d952e2b2ede8 (executor driver) (4/180)
[2022-06-07 06:17:06,858] {subprocess.py:92} INFO - 22/06/07 06:17:06 INFO TaskSetManager: Starting task 9.0 in stage 0.0 (TID 9) (d952e2b2ede8, executor driver, partition 9, PROCESS_LOCAL, 4553 bytes) taskResourceAssignments Map()
[2022-06-07 06:17:06,860] {subprocess.py:92} INFO - 22/06/07 06:17:06 INFO TaskSetManager: Starting task 10.0 in stage 0.0 (TID 10) (d952e2b2ede8, executor driver, partition 10, PROCESS_LOCAL, 4553 bytes) taskResourceAssignments Map()
[2022-06-07 06:17:06,861] {subprocess.py:92} INFO - 22/06/07 06:17:06 INFO Executor: Running task 9.0 in stage 0.0 (TID 9)
[2022-06-07 06:17:06,862] {subprocess.py:92} INFO - 22/06/07 06:17:06 INFO TaskSetManager: Finished task 6.0 in stage 0.0 (TID 6) in 45 ms on d952e2b2ede8 (executor driver) (5/180)
[2022-06-07 06:17:06,863] {subprocess.py:92} INFO - 22/06/07 06:17:06 INFO Executor: Running task 10.0 in stage 0.0 (TID 10)
[2022-06-07 06:17:06,864] {subprocess.py:92} INFO - 22/06/07 06:17:06 INFO TaskSetManager: Finished task 4.0 in stage 0.0 (TID 4) in 71 ms on d952e2b2ede8 (executor driver) (6/180)
[2022-06-07 06:17:06,902] {subprocess.py:92} INFO - 22/06/07 06:17:06 INFO TaskSetManager: Finished task 0.0 in stage 0.0 (TID 0) in 1042 ms on d952e2b2ede8 (executor driver) (7/180)
[2022-06-07 06:17:06,931] {subprocess.py:92} INFO - 22/06/07 06:17:06 INFO Executor: Finished task 10.0 in stage 0.0 (TID 10). 2689 bytes result sent to driver
[2022-06-07 06:17:06,933] {subprocess.py:92} INFO - 22/06/07 06:17:06 INFO TaskSetManager: Starting task 11.0 in stage 0.0 (TID 11) (d952e2b2ede8, executor driver, partition 11, PROCESS_LOCAL, 4553 bytes) taskResourceAssignments Map()
[2022-06-07 06:17:06,936] {subprocess.py:92} INFO - 22/06/07 06:17:06 INFO TaskSetManager: Finished task 10.0 in stage 0.0 (TID 10) in 76 ms on d952e2b2ede8 (executor driver) (8/180)
[2022-06-07 06:17:06,943] {subprocess.py:92} INFO - 22/06/07 06:17:06 INFO Executor: Finished task 9.0 in stage 0.0 (TID 9). 2689 bytes result sent to driver
[2022-06-07 06:17:06,945] {subprocess.py:92} INFO - 22/06/07 06:17:06 INFO TaskSetManager: Starting task 12.0 in stage 0.0 (TID 12) (d952e2b2ede8, executor driver, partition 12, PROCESS_LOCAL, 4553 bytes) taskResourceAssignments Map()
[2022-06-07 06:17:06,947] {subprocess.py:92} INFO - 22/06/07 06:17:06 INFO Executor: Running task 12.0 in stage 0.0 (TID 12)
[2022-06-07 06:17:06,948] {subprocess.py:92} INFO - 22/06/07 06:17:06 INFO TaskSetManager: Finished task 9.0 in stage 0.0 (TID 9) in 90 ms on d952e2b2ede8 (executor driver) (9/180)
[2022-06-07 06:17:06,954] {subprocess.py:92} INFO - 22/06/07 06:17:06 INFO Executor: Running task 11.0 in stage 0.0 (TID 11)
[2022-06-07 06:17:06,960] {subprocess.py:92} INFO - 22/06/07 06:17:06 INFO Executor: Finished task 7.0 in stage 0.0 (TID 7). 2689 bytes result sent to driver
[2022-06-07 06:17:06,962] {subprocess.py:92} INFO - 22/06/07 06:17:06 INFO TaskSetManager: Starting task 13.0 in stage 0.0 (TID 13) (d952e2b2ede8, executor driver, partition 13, PROCESS_LOCAL, 4553 bytes) taskResourceAssignments Map()
[2022-06-07 06:17:06,972] {subprocess.py:92} INFO - 22/06/07 06:17:06 INFO Executor: Running task 13.0 in stage 0.0 (TID 13)
[2022-06-07 06:17:06,985] {subprocess.py:92} INFO - 22/06/07 06:17:06 INFO TaskSetManager: Finished task 7.0 in stage 0.0 (TID 7) in 149 ms on d952e2b2ede8 (executor driver) (10/180)
[2022-06-07 06:17:06,999] {subprocess.py:92} INFO - 22/06/07 06:17:06 INFO Executor: Finished task 8.0 in stage 0.0 (TID 8). 2689 bytes result sent to driver
[2022-06-07 06:17:07,001] {subprocess.py:92} INFO - 22/06/07 06:17:07 INFO TaskSetManager: Starting task 14.0 in stage 0.0 (TID 14) (d952e2b2ede8, executor driver, partition 14, PROCESS_LOCAL, 4553 bytes) taskResourceAssignments Map()
[2022-06-07 06:17:07,006] {subprocess.py:92} INFO - 22/06/07 06:17:07 INFO Executor: Finished task 12.0 in stage 0.0 (TID 12). 2646 bytes result sent to driver
[2022-06-07 06:17:07,015] {subprocess.py:92} INFO - 22/06/07 06:17:07 INFO TaskSetManager: Starting task 15.0 in stage 0.0 (TID 15) (d952e2b2ede8, executor driver, partition 15, PROCESS_LOCAL, 4553 bytes) taskResourceAssignments Map()
[2022-06-07 06:17:07,016] {subprocess.py:92} INFO - 22/06/07 06:17:07 INFO TaskSetManager: Finished task 8.0 in stage 0.0 (TID 8) in 174 ms on d952e2b2ede8 (executor driver) (11/180)
[2022-06-07 06:17:07,017] {subprocess.py:92} INFO - 22/06/07 06:17:07 INFO Executor: Running task 15.0 in stage 0.0 (TID 15)
[2022-06-07 06:17:07,019] {subprocess.py:92} INFO - 22/06/07 06:17:07 INFO TaskSetManager: Finished task 12.0 in stage 0.0 (TID 12) in 74 ms on d952e2b2ede8 (executor driver) (12/180)
[2022-06-07 06:17:07,021] {subprocess.py:92} INFO - 22/06/07 06:17:07 INFO Executor: Running task 14.0 in stage 0.0 (TID 14)
[2022-06-07 06:17:07,026] {subprocess.py:92} INFO - 22/06/07 06:17:07 INFO Executor: Finished task 11.0 in stage 0.0 (TID 11). 2646 bytes result sent to driver
[2022-06-07 06:17:07,028] {subprocess.py:92} INFO - 22/06/07 06:17:07 INFO TaskSetManager: Starting task 16.0 in stage 0.0 (TID 16) (d952e2b2ede8, executor driver, partition 16, PROCESS_LOCAL, 4553 bytes) taskResourceAssignments Map()
[2022-06-07 06:17:07,029] {subprocess.py:92} INFO - 22/06/07 06:17:07 INFO Executor: Finished task 13.0 in stage 0.0 (TID 13). 2646 bytes result sent to driver
[2022-06-07 06:17:07,032] {subprocess.py:92} INFO - 22/06/07 06:17:07 INFO Executor: Running task 16.0 in stage 0.0 (TID 16)
[2022-06-07 06:17:07,035] {subprocess.py:92} INFO - 22/06/07 06:17:07 INFO TaskSetManager: Finished task 11.0 in stage 0.0 (TID 11) in 102 ms on d952e2b2ede8 (executor driver) (13/180)
[2022-06-07 06:17:07,043] {subprocess.py:92} INFO - 22/06/07 06:17:07 INFO TaskSetManager: Starting task 17.0 in stage 0.0 (TID 17) (d952e2b2ede8, executor driver, partition 17, PROCESS_LOCAL, 4553 bytes) taskResourceAssignments Map()
[2022-06-07 06:17:07,044] {subprocess.py:92} INFO - 22/06/07 06:17:07 INFO TaskSetManager: Finished task 13.0 in stage 0.0 (TID 13) in 82 ms on d952e2b2ede8 (executor driver) (14/180)
[2022-06-07 06:17:07,047] {subprocess.py:92} INFO - 22/06/07 06:17:07 INFO Executor: Running task 17.0 in stage 0.0 (TID 17)
[2022-06-07 06:17:07,084] {subprocess.py:92} INFO - 22/06/07 06:17:07 INFO Executor: Finished task 15.0 in stage 0.0 (TID 15). 2646 bytes result sent to driver
[2022-06-07 06:17:07,087] {subprocess.py:92} INFO - 22/06/07 06:17:07 INFO TaskSetManager: Starting task 18.0 in stage 0.0 (TID 18) (d952e2b2ede8, executor driver, partition 18, PROCESS_LOCAL, 4553 bytes) taskResourceAssignments Map()
[2022-06-07 06:17:07,089] {subprocess.py:92} INFO - 22/06/07 06:17:07 INFO TaskSetManager: Finished task 15.0 in stage 0.0 (TID 15) in 76 ms on d952e2b2ede8 (executor driver) (15/180)
[2022-06-07 06:17:07,094] {subprocess.py:92} INFO - 22/06/07 06:17:07 INFO Executor: Finished task 17.0 in stage 0.0 (TID 17). 2646 bytes result sent to driver
[2022-06-07 06:17:07,095] {subprocess.py:92} INFO - 22/06/07 06:17:07 INFO Executor: Running task 18.0 in stage 0.0 (TID 18)
[2022-06-07 06:17:07,098] {subprocess.py:92} INFO - 22/06/07 06:17:07 INFO TaskSetManager: Starting task 19.0 in stage 0.0 (TID 19) (d952e2b2ede8, executor driver, partition 19, PROCESS_LOCAL, 4553 bytes) taskResourceAssignments Map()
[2022-06-07 06:17:07,099] {subprocess.py:92} INFO - 22/06/07 06:17:07 INFO Executor: Finished task 14.0 in stage 0.0 (TID 14). 2646 bytes result sent to driver
[2022-06-07 06:17:07,100] {subprocess.py:92} INFO - 22/06/07 06:17:07 INFO Executor: Running task 19.0 in stage 0.0 (TID 19)
[2022-06-07 06:17:07,102] {subprocess.py:92} INFO - 22/06/07 06:17:07 INFO TaskSetManager: Starting task 20.0 in stage 0.0 (TID 20) (d952e2b2ede8, executor driver, partition 20, PROCESS_LOCAL, 4553 bytes) taskResourceAssignments Map()
[2022-06-07 06:17:07,103] {subprocess.py:92} INFO - 22/06/07 06:17:07 INFO TaskSetManager: Finished task 14.0 in stage 0.0 (TID 14) in 102 ms on d952e2b2ede8 (executor driver) (16/180)
[2022-06-07 06:17:07,104] {subprocess.py:92} INFO - 22/06/07 06:17:07 INFO Executor: Running task 20.0 in stage 0.0 (TID 20)
[2022-06-07 06:17:07,106] {subprocess.py:92} INFO - 22/06/07 06:17:07 INFO TaskSetManager: Finished task 17.0 in stage 0.0 (TID 17) in 62 ms on d952e2b2ede8 (executor driver) (17/180)
[2022-06-07 06:17:07,109] {subprocess.py:92} INFO - 22/06/07 06:17:07 INFO Executor: Finished task 16.0 in stage 0.0 (TID 16). 2689 bytes result sent to driver
[2022-06-07 06:17:07,115] {subprocess.py:92} INFO - 22/06/07 06:17:07 INFO TaskSetManager: Starting task 21.0 in stage 0.0 (TID 21) (d952e2b2ede8, executor driver, partition 21, PROCESS_LOCAL, 4553 bytes) taskResourceAssignments Map()
[2022-06-07 06:17:07,117] {subprocess.py:92} INFO - 22/06/07 06:17:07 INFO TaskSetManager: Finished task 16.0 in stage 0.0 (TID 16) in 90 ms on d952e2b2ede8 (executor driver) (18/180)
[2022-06-07 06:17:07,119] {subprocess.py:92} INFO - 22/06/07 06:17:07 INFO Executor: Running task 21.0 in stage 0.0 (TID 21)
[2022-06-07 06:17:07,126] {subprocess.py:92} INFO - 22/06/07 06:17:07 INFO Executor: Finished task 19.0 in stage 0.0 (TID 19). 2646 bytes result sent to driver
[2022-06-07 06:17:07,128] {subprocess.py:92} INFO - 22/06/07 06:17:07 INFO TaskSetManager: Starting task 22.0 in stage 0.0 (TID 22) (d952e2b2ede8, executor driver, partition 22, PROCESS_LOCAL, 4553 bytes) taskResourceAssignments Map()
[2022-06-07 06:17:07,129] {subprocess.py:92} INFO - 22/06/07 06:17:07 INFO Executor: Running task 22.0 in stage 0.0 (TID 22)
[2022-06-07 06:17:07,130] {subprocess.py:92} INFO - 22/06/07 06:17:07 INFO TaskSetManager: Finished task 19.0 in stage 0.0 (TID 19) in 31 ms on d952e2b2ede8 (executor driver) (19/180)
[2022-06-07 06:17:07,139] {subprocess.py:92} INFO - 22/06/07 06:17:07 INFO Executor: Finished task 20.0 in stage 0.0 (TID 20). 2646 bytes result sent to driver
[2022-06-07 06:17:07,144] {subprocess.py:92} INFO - 22/06/07 06:17:07 INFO TaskSetManager: Starting task 23.0 in stage 0.0 (TID 23) (d952e2b2ede8, executor driver, partition 23, PROCESS_LOCAL, 4553 bytes) taskResourceAssignments Map()
[2022-06-07 06:17:07,145] {subprocess.py:92} INFO - 22/06/07 06:17:07 INFO TaskSetManager: Finished task 20.0 in stage 0.0 (TID 20) in 43 ms on d952e2b2ede8 (executor driver) (20/180)
[2022-06-07 06:17:07,145] {subprocess.py:92} INFO - 22/06/07 06:17:07 INFO Executor: Running task 23.0 in stage 0.0 (TID 23)
[2022-06-07 06:17:07,160] {subprocess.py:92} INFO - 22/06/07 06:17:07 INFO Executor: Finished task 22.0 in stage 0.0 (TID 22). 2646 bytes result sent to driver
[2022-06-07 06:17:07,161] {subprocess.py:92} INFO - 22/06/07 06:17:07 INFO TaskSetManager: Starting task 24.0 in stage 0.0 (TID 24) (d952e2b2ede8, executor driver, partition 24, PROCESS_LOCAL, 4553 bytes) taskResourceAssignments Map()
[2022-06-07 06:17:07,162] {subprocess.py:92} INFO - 22/06/07 06:17:07 INFO TaskSetManager: Finished task 22.0 in stage 0.0 (TID 22) in 35 ms on d952e2b2ede8 (executor driver) (21/180)
[2022-06-07 06:17:07,164] {subprocess.py:92} INFO - 22/06/07 06:17:07 INFO Executor: Finished task 18.0 in stage 0.0 (TID 18). 2646 bytes result sent to driver
[2022-06-07 06:17:07,168] {subprocess.py:92} INFO - 22/06/07 06:17:07 INFO Executor: Running task 24.0 in stage 0.0 (TID 24)
[2022-06-07 06:17:07,173] {subprocess.py:92} INFO - 22/06/07 06:17:07 INFO Executor: Finished task 23.0 in stage 0.0 (TID 23). 2689 bytes result sent to driver
[2022-06-07 06:17:07,180] {subprocess.py:92} INFO - 22/06/07 06:17:07 INFO TaskSetManager: Starting task 25.0 in stage 0.0 (TID 25) (d952e2b2ede8, executor driver, partition 25, PROCESS_LOCAL, 4553 bytes) taskResourceAssignments Map()
[2022-06-07 06:17:07,181] {subprocess.py:92} INFO - 22/06/07 06:17:07 INFO Executor: Running task 25.0 in stage 0.0 (TID 25)
[2022-06-07 06:17:07,183] {subprocess.py:92} INFO - 22/06/07 06:17:07 INFO TaskSetManager: Starting task 26.0 in stage 0.0 (TID 26) (d952e2b2ede8, executor driver, partition 26, PROCESS_LOCAL, 4553 bytes) taskResourceAssignments Map()
[2022-06-07 06:17:07,184] {subprocess.py:92} INFO - 22/06/07 06:17:07 INFO TaskSetManager: Finished task 23.0 in stage 0.0 (TID 23) in 40 ms on d952e2b2ede8 (executor driver) (22/180)
[2022-06-07 06:17:07,185] {subprocess.py:92} INFO - 22/06/07 06:17:07 INFO TaskSetManager: Finished task 18.0 in stage 0.0 (TID 18) in 98 ms on d952e2b2ede8 (executor driver) (23/180)
[2022-06-07 06:17:07,190] {subprocess.py:92} INFO - 22/06/07 06:17:07 INFO Executor: Running task 26.0 in stage 0.0 (TID 26)
[2022-06-07 06:17:07,194] {subprocess.py:92} INFO - 22/06/07 06:17:07 INFO Executor: Finished task 21.0 in stage 0.0 (TID 21). 2646 bytes result sent to driver
[2022-06-07 06:17:07,211] {subprocess.py:92} INFO - 22/06/07 06:17:07 INFO Executor: Finished task 25.0 in stage 0.0 (TID 25). 2646 bytes result sent to driver
[2022-06-07 06:17:07,215] {subprocess.py:92} INFO - 22/06/07 06:17:07 INFO TaskSetManager: Starting task 27.0 in stage 0.0 (TID 27) (d952e2b2ede8, executor driver, partition 27, PROCESS_LOCAL, 4553 bytes) taskResourceAssignments Map()
[2022-06-07 06:17:07,219] {subprocess.py:92} INFO - 22/06/07 06:17:07 INFO Executor: Running task 27.0 in stage 0.0 (TID 27)
[2022-06-07 06:17:07,221] {subprocess.py:92} INFO - 22/06/07 06:17:07 INFO TaskSetManager: Starting task 28.0 in stage 0.0 (TID 28) (d952e2b2ede8, executor driver, partition 28, PROCESS_LOCAL, 4553 bytes) taskResourceAssignments Map()
[2022-06-07 06:17:07,224] {subprocess.py:92} INFO - 22/06/07 06:17:07 INFO Executor: Running task 28.0 in stage 0.0 (TID 28)
[2022-06-07 06:17:07,226] {subprocess.py:92} INFO - 22/06/07 06:17:07 INFO TaskSetManager: Finished task 25.0 in stage 0.0 (TID 25) in 47 ms on d952e2b2ede8 (executor driver) (24/180)
[2022-06-07 06:17:07,228] {subprocess.py:92} INFO - 22/06/07 06:17:07 INFO TaskSetManager: Finished task 21.0 in stage 0.0 (TID 21) in 114 ms on d952e2b2ede8 (executor driver) (25/180)
[2022-06-07 06:17:07,245] {subprocess.py:92} INFO - 22/06/07 06:17:07 INFO Executor: Finished task 28.0 in stage 0.0 (TID 28). 2646 bytes result sent to driver
[2022-06-07 06:17:07,253] {subprocess.py:92} INFO - 22/06/07 06:17:07 INFO TaskSetManager: Starting task 29.0 in stage 0.0 (TID 29) (d952e2b2ede8, executor driver, partition 29, PROCESS_LOCAL, 4553 bytes) taskResourceAssignments Map()
[2022-06-07 06:17:07,254] {subprocess.py:92} INFO - 22/06/07 06:17:07 INFO Executor: Running task 29.0 in stage 0.0 (TID 29)
[2022-06-07 06:17:07,255] {subprocess.py:92} INFO - 22/06/07 06:17:07 INFO TaskSetManager: Finished task 28.0 in stage 0.0 (TID 28) in 33 ms on d952e2b2ede8 (executor driver) (26/180)
[2022-06-07 06:17:07,257] {subprocess.py:92} INFO - 22/06/07 06:17:07 INFO Executor: Finished task 24.0 in stage 0.0 (TID 24). 2646 bytes result sent to driver
[2022-06-07 06:17:07,263] {subprocess.py:92} INFO - 22/06/07 06:17:07 INFO Executor: Finished task 27.0 in stage 0.0 (TID 27). 2646 bytes result sent to driver
[2022-06-07 06:17:07,265] {subprocess.py:92} INFO - 22/06/07 06:17:07 INFO TaskSetManager: Starting task 30.0 in stage 0.0 (TID 30) (d952e2b2ede8, executor driver, partition 30, PROCESS_LOCAL, 4553 bytes) taskResourceAssignments Map()
[2022-06-07 06:17:07,267] {subprocess.py:92} INFO - 22/06/07 06:17:07 INFO TaskSetManager: Starting task 31.0 in stage 0.0 (TID 31) (d952e2b2ede8, executor driver, partition 31, PROCESS_LOCAL, 4553 bytes) taskResourceAssignments Map()
[2022-06-07 06:17:07,270] {subprocess.py:92} INFO - 22/06/07 06:17:07 INFO TaskSetManager: Finished task 27.0 in stage 0.0 (TID 27) in 55 ms on d952e2b2ede8 (executor driver) (27/180)
[2022-06-07 06:17:07,271] {subprocess.py:92} INFO - 22/06/07 06:17:07 INFO TaskSetManager: Finished task 24.0 in stage 0.0 (TID 24) in 110 ms on d952e2b2ede8 (executor driver) (28/180)
[2022-06-07 06:17:07,274] {subprocess.py:92} INFO - 22/06/07 06:17:07 INFO Executor: Running task 31.0 in stage 0.0 (TID 31)
[2022-06-07 06:17:07,280] {subprocess.py:92} INFO - 22/06/07 06:17:07 INFO Executor: Running task 30.0 in stage 0.0 (TID 30)
[2022-06-07 06:17:07,283] {subprocess.py:92} INFO - 22/06/07 06:17:07 INFO Executor: Finished task 26.0 in stage 0.0 (TID 26). 2646 bytes result sent to driver
[2022-06-07 06:17:07,285] {subprocess.py:92} INFO - 22/06/07 06:17:07 INFO Executor: Finished task 29.0 in stage 0.0 (TID 29). 2646 bytes result sent to driver
[2022-06-07 06:17:07,288] {subprocess.py:92} INFO - 22/06/07 06:17:07 INFO TaskSetManager: Starting task 32.0 in stage 0.0 (TID 32) (d952e2b2ede8, executor driver, partition 32, PROCESS_LOCAL, 4553 bytes) taskResourceAssignments Map()
[2022-06-07 06:17:07,291] {subprocess.py:92} INFO - 22/06/07 06:17:07 INFO Executor: Running task 32.0 in stage 0.0 (TID 32)
[2022-06-07 06:17:07,292] {subprocess.py:92} INFO - 22/06/07 06:17:07 INFO TaskSetManager: Finished task 26.0 in stage 0.0 (TID 26) in 108 ms on d952e2b2ede8 (executor driver) (29/180)
[2022-06-07 06:17:07,295] {subprocess.py:92} INFO - 22/06/07 06:17:07 INFO TaskSetManager: Starting task 33.0 in stage 0.0 (TID 33) (d952e2b2ede8, executor driver, partition 33, PROCESS_LOCAL, 4553 bytes) taskResourceAssignments Map()
[2022-06-07 06:17:07,297] {subprocess.py:92} INFO - 22/06/07 06:17:07 INFO Executor: Running task 33.0 in stage 0.0 (TID 33)
[2022-06-07 06:17:07,298] {subprocess.py:92} INFO - 22/06/07 06:17:07 INFO TaskSetManager: Finished task 29.0 in stage 0.0 (TID 29) in 51 ms on d952e2b2ede8 (executor driver) (30/180)
[2022-06-07 06:17:07,339] {subprocess.py:92} INFO - 22/06/07 06:17:07 INFO Executor: Finished task 32.0 in stage 0.0 (TID 32). 2646 bytes result sent to driver
[2022-06-07 06:17:07,340] {subprocess.py:92} INFO - 22/06/07 06:17:07 INFO Executor: Finished task 31.0 in stage 0.0 (TID 31). 2646 bytes result sent to driver
[2022-06-07 06:17:07,342] {subprocess.py:92} INFO - 22/06/07 06:17:07 INFO TaskSetManager: Starting task 34.0 in stage 0.0 (TID 34) (d952e2b2ede8, executor driver, partition 34, PROCESS_LOCAL, 4553 bytes) taskResourceAssignments Map()
[2022-06-07 06:17:07,344] {subprocess.py:92} INFO - 22/06/07 06:17:07 INFO TaskSetManager: Finished task 32.0 in stage 0.0 (TID 32) in 58 ms on d952e2b2ede8 (executor driver) (31/180)
[2022-06-07 06:17:07,347] {subprocess.py:92} INFO - 22/06/07 06:17:07 INFO Executor: Running task 34.0 in stage 0.0 (TID 34)
[2022-06-07 06:17:07,349] {subprocess.py:92} INFO - 22/06/07 06:17:07 INFO TaskSetManager: Starting task 35.0 in stage 0.0 (TID 35) (d952e2b2ede8, executor driver, partition 35, PROCESS_LOCAL, 4553 bytes) taskResourceAssignments Map()
[2022-06-07 06:17:07,350] {subprocess.py:92} INFO - 22/06/07 06:17:07 INFO TaskSetManager: Finished task 31.0 in stage 0.0 (TID 31) in 84 ms on d952e2b2ede8 (executor driver) (32/180)
[2022-06-07 06:17:07,351] {subprocess.py:92} INFO - 22/06/07 06:17:07 INFO Executor: Running task 35.0 in stage 0.0 (TID 35)
[2022-06-07 06:17:07,355] {subprocess.py:92} INFO - 22/06/07 06:17:07 INFO Executor: Finished task 30.0 in stage 0.0 (TID 30). 2646 bytes result sent to driver
[2022-06-07 06:17:07,358] {subprocess.py:92} INFO - 22/06/07 06:17:07 INFO TaskSetManager: Starting task 36.0 in stage 0.0 (TID 36) (d952e2b2ede8, executor driver, partition 36, PROCESS_LOCAL, 4553 bytes) taskResourceAssignments Map()
[2022-06-07 06:17:07,361] {subprocess.py:92} INFO - 22/06/07 06:17:07 INFO TaskSetManager: Finished task 30.0 in stage 0.0 (TID 30) in 94 ms on d952e2b2ede8 (executor driver) (33/180)
[2022-06-07 06:17:07,361] {subprocess.py:92} INFO - 22/06/07 06:17:07 INFO Executor: Running task 36.0 in stage 0.0 (TID 36)
[2022-06-07 06:17:07,366] {subprocess.py:92} INFO - 22/06/07 06:17:07 INFO Executor: Finished task 33.0 in stage 0.0 (TID 33). 2689 bytes result sent to driver
[2022-06-07 06:17:07,367] {subprocess.py:92} INFO - 22/06/07 06:17:07 INFO TaskSetManager: Starting task 37.0 in stage 0.0 (TID 37) (d952e2b2ede8, executor driver, partition 37, PROCESS_LOCAL, 4553 bytes) taskResourceAssignments Map()
[2022-06-07 06:17:07,368] {subprocess.py:92} INFO - 22/06/07 06:17:07 INFO Executor: Running task 37.0 in stage 0.0 (TID 37)
[2022-06-07 06:17:07,370] {subprocess.py:92} INFO - 22/06/07 06:17:07 INFO TaskSetManager: Finished task 33.0 in stage 0.0 (TID 33) in 74 ms on d952e2b2ede8 (executor driver) (34/180)
[2022-06-07 06:17:07,391] {subprocess.py:92} INFO - 22/06/07 06:17:07 INFO Executor: Finished task 35.0 in stage 0.0 (TID 35). 2646 bytes result sent to driver
[2022-06-07 06:17:07,393] {subprocess.py:92} INFO - 22/06/07 06:17:07 INFO Executor: Finished task 37.0 in stage 0.0 (TID 37). 2646 bytes result sent to driver
[2022-06-07 06:17:07,394] {subprocess.py:92} INFO - 22/06/07 06:17:07 INFO Executor: Finished task 34.0 in stage 0.0 (TID 34). 2646 bytes result sent to driver
[2022-06-07 06:17:07,397] {subprocess.py:92} INFO - 22/06/07 06:17:07 INFO Executor: Finished task 36.0 in stage 0.0 (TID 36). 2646 bytes result sent to driver
[2022-06-07 06:17:07,399] {subprocess.py:92} INFO - 22/06/07 06:17:07 INFO TaskSetManager: Starting task 38.0 in stage 0.0 (TID 38) (d952e2b2ede8, executor driver, partition 38, PROCESS_LOCAL, 4553 bytes) taskResourceAssignments Map()
[2022-06-07 06:17:07,401] {subprocess.py:92} INFO - 22/06/07 06:17:07 INFO Executor: Running task 38.0 in stage 0.0 (TID 38)
[2022-06-07 06:17:07,401] {subprocess.py:92} INFO - 22/06/07 06:17:07 INFO TaskSetManager: Starting task 39.0 in stage 0.0 (TID 39) (d952e2b2ede8, executor driver, partition 39, PROCESS_LOCAL, 4553 bytes) taskResourceAssignments Map()
[2022-06-07 06:17:07,403] {subprocess.py:92} INFO - 22/06/07 06:17:07 INFO TaskSetManager: Starting task 40.0 in stage 0.0 (TID 40) (d952e2b2ede8, executor driver, partition 40, PROCESS_LOCAL, 4553 bytes) taskResourceAssignments Map()
[2022-06-07 06:17:07,404] {subprocess.py:92} INFO - 22/06/07 06:17:07 INFO Executor: Running task 40.0 in stage 0.0 (TID 40)
[2022-06-07 06:17:07,405] {subprocess.py:92} INFO - 22/06/07 06:17:07 INFO TaskSetManager: Finished task 35.0 in stage 0.0 (TID 35) in 58 ms on d952e2b2ede8 (executor driver) (35/180)
[2022-06-07 06:17:07,407] {subprocess.py:92} INFO - 22/06/07 06:17:07 INFO TaskSetManager: Finished task 37.0 in stage 0.0 (TID 37) in 40 ms on d952e2b2ede8 (executor driver) (36/180)
[2022-06-07 06:17:07,407] {subprocess.py:92} INFO - 22/06/07 06:17:07 INFO TaskSetManager: Finished task 34.0 in stage 0.0 (TID 34) in 66 ms on d952e2b2ede8 (executor driver) (37/180)
[2022-06-07 06:17:07,411] {subprocess.py:92} INFO - 22/06/07 06:17:07 INFO Executor: Running task 39.0 in stage 0.0 (TID 39)
[2022-06-07 06:17:07,415] {subprocess.py:92} INFO - 22/06/07 06:17:07 INFO TaskSetManager: Starting task 41.0 in stage 0.0 (TID 41) (d952e2b2ede8, executor driver, partition 41, PROCESS_LOCAL, 4553 bytes) taskResourceAssignments Map()
[2022-06-07 06:17:07,415] {subprocess.py:92} INFO - 22/06/07 06:17:07 INFO Executor: Running task 41.0 in stage 0.0 (TID 41)
[2022-06-07 06:17:07,417] {subprocess.py:92} INFO - 22/06/07 06:17:07 INFO TaskSetManager: Finished task 36.0 in stage 0.0 (TID 36) in 58 ms on d952e2b2ede8 (executor driver) (38/180)
[2022-06-07 06:17:07,436] {subprocess.py:92} INFO - 22/06/07 06:17:07 INFO Executor: Finished task 41.0 in stage 0.0 (TID 41). 2646 bytes result sent to driver
[2022-06-07 06:17:07,438] {subprocess.py:92} INFO - 22/06/07 06:17:07 INFO TaskSetManager: Starting task 42.0 in stage 0.0 (TID 42) (d952e2b2ede8, executor driver, partition 42, PROCESS_LOCAL, 4553 bytes) taskResourceAssignments Map()
[2022-06-07 06:17:07,439] {subprocess.py:92} INFO - 22/06/07 06:17:07 INFO Executor: Running task 42.0 in stage 0.0 (TID 42)
[2022-06-07 06:17:07,440] {subprocess.py:92} INFO - 22/06/07 06:17:07 INFO Executor: Finished task 40.0 in stage 0.0 (TID 40). 2646 bytes result sent to driver
[2022-06-07 06:17:07,447] {subprocess.py:92} INFO - 22/06/07 06:17:07 INFO TaskSetManager: Starting task 43.0 in stage 0.0 (TID 43) (d952e2b2ede8, executor driver, partition 43, PROCESS_LOCAL, 4553 bytes) taskResourceAssignments Map()
[2022-06-07 06:17:07,448] {subprocess.py:92} INFO - 22/06/07 06:17:07 INFO TaskSetManager: Finished task 40.0 in stage 0.0 (TID 40) in 46 ms on d952e2b2ede8 (executor driver) (39/180)
[2022-06-07 06:17:07,449] {subprocess.py:92} INFO - 22/06/07 06:17:07 INFO Executor: Running task 43.0 in stage 0.0 (TID 43)
[2022-06-07 06:17:07,450] {subprocess.py:92} INFO - 22/06/07 06:17:07 INFO Executor: Finished task 39.0 in stage 0.0 (TID 39). 2646 bytes result sent to driver
[2022-06-07 06:17:07,453] {subprocess.py:92} INFO - 22/06/07 06:17:07 INFO TaskSetManager: Starting task 44.0 in stage 0.0 (TID 44) (d952e2b2ede8, executor driver, partition 44, PROCESS_LOCAL, 4553 bytes) taskResourceAssignments Map()
[2022-06-07 06:17:07,460] {subprocess.py:92} INFO - 22/06/07 06:17:07 INFO Executor: Finished task 38.0 in stage 0.0 (TID 38). 2646 bytes result sent to driver
[2022-06-07 06:17:07,462] {subprocess.py:92} INFO - 22/06/07 06:17:07 INFO Executor: Running task 44.0 in stage 0.0 (TID 44)
[2022-06-07 06:17:07,464] {subprocess.py:92} INFO - 22/06/07 06:17:07 INFO TaskSetManager: Starting task 45.0 in stage 0.0 (TID 45) (d952e2b2ede8, executor driver, partition 45, PROCESS_LOCAL, 4553 bytes) taskResourceAssignments Map()
[2022-06-07 06:17:07,466] {subprocess.py:92} INFO - 22/06/07 06:17:07 INFO TaskSetManager: Finished task 41.0 in stage 0.0 (TID 41) in 53 ms on d952e2b2ede8 (executor driver) (40/180)
[2022-06-07 06:17:07,467] {subprocess.py:92} INFO - 22/06/07 06:17:07 INFO TaskSetManager: Finished task 38.0 in stage 0.0 (TID 38) in 68 ms on d952e2b2ede8 (executor driver) (41/180)
[2022-06-07 06:17:07,468] {subprocess.py:92} INFO - 22/06/07 06:17:07 INFO TaskSetManager: Finished task 39.0 in stage 0.0 (TID 39) in 67 ms on d952e2b2ede8 (executor driver) (42/180)
[2022-06-07 06:17:07,472] {subprocess.py:92} INFO - 22/06/07 06:17:07 INFO Executor: Running task 45.0 in stage 0.0 (TID 45)
[2022-06-07 06:17:07,477] {subprocess.py:92} INFO - 22/06/07 06:17:07 INFO Executor: Finished task 43.0 in stage 0.0 (TID 43). 2646 bytes result sent to driver
[2022-06-07 06:17:07,480] {subprocess.py:92} INFO - 22/06/07 06:17:07 INFO TaskSetManager: Starting task 46.0 in stage 0.0 (TID 46) (d952e2b2ede8, executor driver, partition 46, PROCESS_LOCAL, 4553 bytes) taskResourceAssignments Map()
[2022-06-07 06:17:07,483] {subprocess.py:92} INFO - 22/06/07 06:17:07 INFO TaskSetManager: Finished task 43.0 in stage 0.0 (TID 43) in 35 ms on d952e2b2ede8 (executor driver) (43/180)
[2022-06-07 06:17:07,484] {subprocess.py:92} INFO - 22/06/07 06:17:07 INFO Executor: Running task 46.0 in stage 0.0 (TID 46)
[2022-06-07 06:17:07,501] {subprocess.py:92} INFO - 22/06/07 06:17:07 INFO Executor: Finished task 44.0 in stage 0.0 (TID 44). 2646 bytes result sent to driver
[2022-06-07 06:17:07,504] {subprocess.py:92} INFO - 22/06/07 06:17:07 INFO TaskSetManager: Starting task 47.0 in stage 0.0 (TID 47) (d952e2b2ede8, executor driver, partition 47, PROCESS_LOCAL, 4553 bytes) taskResourceAssignments Map()
[2022-06-07 06:17:07,508] {subprocess.py:92} INFO - 22/06/07 06:17:07 INFO Executor: Finished task 42.0 in stage 0.0 (TID 42). 2646 bytes result sent to driver
[2022-06-07 06:17:07,512] {subprocess.py:92} INFO - 22/06/07 06:17:07 INFO TaskSetManager: Finished task 44.0 in stage 0.0 (TID 44) in 60 ms on d952e2b2ede8 (executor driver) (44/180)
[2022-06-07 06:17:07,516] {subprocess.py:92} INFO - 22/06/07 06:17:07 INFO TaskSetManager: Starting task 48.0 in stage 0.0 (TID 48) (d952e2b2ede8, executor driver, partition 48, PROCESS_LOCAL, 4553 bytes) taskResourceAssignments Map()
[2022-06-07 06:17:07,522] {subprocess.py:92} INFO - 22/06/07 06:17:07 INFO Executor: Finished task 46.0 in stage 0.0 (TID 46). 2646 bytes result sent to driver
[2022-06-07 06:17:07,523] {subprocess.py:92} INFO - 22/06/07 06:17:07 INFO Executor: Finished task 45.0 in stage 0.0 (TID 45). 2646 bytes result sent to driver
[2022-06-07 06:17:07,524] {subprocess.py:92} INFO - 22/06/07 06:17:07 INFO TaskSetManager: Finished task 42.0 in stage 0.0 (TID 42) in 86 ms on d952e2b2ede8 (executor driver) (45/180)
[2022-06-07 06:17:07,530] {subprocess.py:92} INFO - 22/06/07 06:17:07 INFO Executor: Running task 48.0 in stage 0.0 (TID 48)
[2022-06-07 06:17:07,541] {subprocess.py:92} INFO - 22/06/07 06:17:07 INFO TaskSetManager: Starting task 49.0 in stage 0.0 (TID 49) (d952e2b2ede8, executor driver, partition 49, PROCESS_LOCAL, 4553 bytes) taskResourceAssignments Map()
[2022-06-07 06:17:07,544] {subprocess.py:92} INFO - 22/06/07 06:17:07 INFO TaskSetManager: Finished task 46.0 in stage 0.0 (TID 46) in 61 ms on d952e2b2ede8 (executor driver) (46/180)
[2022-06-07 06:17:07,563] {subprocess.py:92} INFO - 22/06/07 06:17:07 INFO Executor: Running task 49.0 in stage 0.0 (TID 49)
[2022-06-07 06:17:07,568] {subprocess.py:92} INFO - 22/06/07 06:17:07 INFO TaskSetManager: Finished task 45.0 in stage 0.0 (TID 45) in 90 ms on d952e2b2ede8 (executor driver) (47/180)
[2022-06-07 06:17:07,572] {subprocess.py:92} INFO - 22/06/07 06:17:07 INFO TaskSetManager: Starting task 50.0 in stage 0.0 (TID 50) (d952e2b2ede8, executor driver, partition 50, PROCESS_LOCAL, 4553 bytes) taskResourceAssignments Map()
[2022-06-07 06:17:07,579] {subprocess.py:92} INFO - 22/06/07 06:17:07 INFO Executor: Running task 47.0 in stage 0.0 (TID 47)
[2022-06-07 06:17:07,581] {subprocess.py:92} INFO - 22/06/07 06:17:07 INFO Executor: Running task 50.0 in stage 0.0 (TID 50)
[2022-06-07 06:17:07,584] {subprocess.py:92} INFO - 22/06/07 06:17:07 INFO Executor: Finished task 48.0 in stage 0.0 (TID 48). 2646 bytes result sent to driver
[2022-06-07 06:17:07,585] {subprocess.py:92} INFO - 22/06/07 06:17:07 INFO TaskSetManager: Starting task 51.0 in stage 0.0 (TID 51) (d952e2b2ede8, executor driver, partition 51, PROCESS_LOCAL, 4553 bytes) taskResourceAssignments Map()
[2022-06-07 06:17:07,587] {subprocess.py:92} INFO - 22/06/07 06:17:07 INFO TaskSetManager: Finished task 48.0 in stage 0.0 (TID 48) in 70 ms on d952e2b2ede8 (executor driver) (48/180)
[2022-06-07 06:17:07,590] {subprocess.py:92} INFO - 22/06/07 06:17:07 INFO Executor: Running task 51.0 in stage 0.0 (TID 51)
[2022-06-07 06:17:07,591] {subprocess.py:92} INFO - 22/06/07 06:17:07 INFO Executor: Finished task 50.0 in stage 0.0 (TID 50). 2646 bytes result sent to driver
[2022-06-07 06:17:07,594] {subprocess.py:92} INFO - 22/06/07 06:17:07 INFO Executor: Finished task 47.0 in stage 0.0 (TID 47). 2646 bytes result sent to driver
[2022-06-07 06:17:07,596] {subprocess.py:92} INFO - 22/06/07 06:17:07 INFO TaskSetManager: Starting task 52.0 in stage 0.0 (TID 52) (d952e2b2ede8, executor driver, partition 52, PROCESS_LOCAL, 4553 bytes) taskResourceAssignments Map()
[2022-06-07 06:17:07,597] {subprocess.py:92} INFO - 22/06/07 06:17:07 INFO TaskSetManager: Finished task 50.0 in stage 0.0 (TID 50) in 40 ms on d952e2b2ede8 (executor driver) (49/180)
[2022-06-07 06:17:07,598] {subprocess.py:92} INFO - 22/06/07 06:17:07 INFO Executor: Running task 52.0 in stage 0.0 (TID 52)
[2022-06-07 06:17:07,604] {subprocess.py:92} INFO - 22/06/07 06:17:07 INFO TaskSetManager: Starting task 53.0 in stage 0.0 (TID 53) (d952e2b2ede8, executor driver, partition 53, PROCESS_LOCAL, 4553 bytes) taskResourceAssignments Map()
[2022-06-07 06:17:07,605] {subprocess.py:92} INFO - 22/06/07 06:17:07 INFO TaskSetManager: Finished task 47.0 in stage 0.0 (TID 47) in 101 ms on d952e2b2ede8 (executor driver) (50/180)
[2022-06-07 06:17:07,616] {subprocess.py:92} INFO - 22/06/07 06:17:07 INFO Executor: Running task 53.0 in stage 0.0 (TID 53)
[2022-06-07 06:17:07,617] {subprocess.py:92} INFO - 22/06/07 06:17:07 INFO Executor: Finished task 49.0 in stage 0.0 (TID 49). 2646 bytes result sent to driver
[2022-06-07 06:17:07,619] {subprocess.py:92} INFO - 22/06/07 06:17:07 INFO TaskSetManager: Starting task 54.0 in stage 0.0 (TID 54) (d952e2b2ede8, executor driver, partition 54, PROCESS_LOCAL, 4553 bytes) taskResourceAssignments Map()
[2022-06-07 06:17:07,620] {subprocess.py:92} INFO - 22/06/07 06:17:07 INFO Executor: Running task 54.0 in stage 0.0 (TID 54)
[2022-06-07 06:17:07,621] {subprocess.py:92} INFO - 22/06/07 06:17:07 INFO TaskSetManager: Finished task 49.0 in stage 0.0 (TID 49) in 95 ms on d952e2b2ede8 (executor driver) (51/180)
[2022-06-07 06:17:07,623] {subprocess.py:92} INFO - 22/06/07 06:17:07 INFO Executor: Finished task 52.0 in stage 0.0 (TID 52). 2646 bytes result sent to driver
[2022-06-07 06:17:07,626] {subprocess.py:92} INFO - 22/06/07 06:17:07 INFO TaskSetManager: Starting task 55.0 in stage 0.0 (TID 55) (d952e2b2ede8, executor driver, partition 55, PROCESS_LOCAL, 4553 bytes) taskResourceAssignments Map()
[2022-06-07 06:17:07,627] {subprocess.py:92} INFO - 22/06/07 06:17:07 INFO TaskSetManager: Finished task 52.0 in stage 0.0 (TID 52) in 31 ms on d952e2b2ede8 (executor driver) (52/180)
[2022-06-07 06:17:07,628] {subprocess.py:92} INFO - 22/06/07 06:17:07 INFO Executor: Running task 55.0 in stage 0.0 (TID 55)
[2022-06-07 06:17:07,656] {subprocess.py:92} INFO - 22/06/07 06:17:07 INFO Executor: Finished task 54.0 in stage 0.0 (TID 54). 2646 bytes result sent to driver
[2022-06-07 06:17:07,658] {subprocess.py:92} INFO - 22/06/07 06:17:07 INFO Executor: Finished task 53.0 in stage 0.0 (TID 53). 2646 bytes result sent to driver
[2022-06-07 06:17:07,663] {subprocess.py:92} INFO - 22/06/07 06:17:07 INFO TaskSetManager: Starting task 56.0 in stage 0.0 (TID 56) (d952e2b2ede8, executor driver, partition 56, PROCESS_LOCAL, 4553 bytes) taskResourceAssignments Map()
[2022-06-07 06:17:07,665] {subprocess.py:92} INFO - 22/06/07 06:17:07 INFO Executor: Running task 56.0 in stage 0.0 (TID 56)
[2022-06-07 06:17:07,666] {subprocess.py:92} INFO - 22/06/07 06:17:07 INFO TaskSetManager: Finished task 54.0 in stage 0.0 (TID 54) in 46 ms on d952e2b2ede8 (executor driver) (53/180)
[2022-06-07 06:17:07,669] {subprocess.py:92} INFO - 22/06/07 06:17:07 INFO Executor: Finished task 51.0 in stage 0.0 (TID 51). 2646 bytes result sent to driver
[2022-06-07 06:17:07,673] {subprocess.py:92} INFO - 22/06/07 06:17:07 INFO TaskSetManager: Starting task 57.0 in stage 0.0 (TID 57) (d952e2b2ede8, executor driver, partition 57, PROCESS_LOCAL, 4553 bytes) taskResourceAssignments Map()
[2022-06-07 06:17:07,675] {subprocess.py:92} INFO - 22/06/07 06:17:07 INFO Executor: Running task 57.0 in stage 0.0 (TID 57)
[2022-06-07 06:17:07,676] {subprocess.py:92} INFO - 22/06/07 06:17:07 INFO TaskSetManager: Starting task 58.0 in stage 0.0 (TID 58) (d952e2b2ede8, executor driver, partition 58, PROCESS_LOCAL, 4553 bytes) taskResourceAssignments Map()
[2022-06-07 06:17:07,678] {subprocess.py:92} INFO - 22/06/07 06:17:07 INFO Executor: Finished task 55.0 in stage 0.0 (TID 55). 2689 bytes result sent to driver
[2022-06-07 06:17:07,683] {subprocess.py:92} INFO - 22/06/07 06:17:07 INFO Executor: Running task 58.0 in stage 0.0 (TID 58)
[2022-06-07 06:17:07,684] {subprocess.py:92} INFO - 22/06/07 06:17:07 INFO TaskSetManager: Finished task 51.0 in stage 0.0 (TID 51) in 97 ms on d952e2b2ede8 (executor driver) (54/180)
[2022-06-07 06:17:07,687] {subprocess.py:92} INFO - 22/06/07 06:17:07 INFO TaskSetManager: Finished task 53.0 in stage 0.0 (TID 53) in 82 ms on d952e2b2ede8 (executor driver) (55/180)
[2022-06-07 06:17:07,696] {subprocess.py:92} INFO - 22/06/07 06:17:07 INFO TaskSetManager: Starting task 59.0 in stage 0.0 (TID 59) (d952e2b2ede8, executor driver, partition 59, PROCESS_LOCAL, 4553 bytes) taskResourceAssignments Map()
[2022-06-07 06:17:07,697] {subprocess.py:92} INFO - 22/06/07 06:17:07 INFO TaskSetManager: Finished task 55.0 in stage 0.0 (TID 55) in 72 ms on d952e2b2ede8 (executor driver) (56/180)
[2022-06-07 06:17:07,699] {subprocess.py:92} INFO - 22/06/07 06:17:07 INFO Executor: Running task 59.0 in stage 0.0 (TID 59)
[2022-06-07 06:17:07,705] {subprocess.py:92} INFO - 22/06/07 06:17:07 INFO Executor: Finished task 56.0 in stage 0.0 (TID 56). 2689 bytes result sent to driver
[2022-06-07 06:17:07,707] {subprocess.py:92} INFO - 22/06/07 06:17:07 INFO TaskSetManager: Starting task 60.0 in stage 0.0 (TID 60) (d952e2b2ede8, executor driver, partition 60, PROCESS_LOCAL, 4553 bytes) taskResourceAssignments Map()
[2022-06-07 06:17:07,709] {subprocess.py:92} INFO - 22/06/07 06:17:07 INFO TaskSetManager: Finished task 56.0 in stage 0.0 (TID 56) in 46 ms on d952e2b2ede8 (executor driver) (57/180)
[2022-06-07 06:17:07,711] {subprocess.py:92} INFO - 22/06/07 06:17:07 INFO Executor: Running task 60.0 in stage 0.0 (TID 60)
[2022-06-07 06:17:07,719] {subprocess.py:92} INFO - 22/06/07 06:17:07 INFO Executor: Finished task 59.0 in stage 0.0 (TID 59). 2646 bytes result sent to driver
[2022-06-07 06:17:07,721] {subprocess.py:92} INFO - 22/06/07 06:17:07 INFO TaskSetManager: Starting task 61.0 in stage 0.0 (TID 61) (d952e2b2ede8, executor driver, partition 61, PROCESS_LOCAL, 4553 bytes) taskResourceAssignments Map()
[2022-06-07 06:17:07,723] {subprocess.py:92} INFO - 22/06/07 06:17:07 INFO TaskSetManager: Finished task 59.0 in stage 0.0 (TID 59) in 27 ms on d952e2b2ede8 (executor driver) (58/180)
[2022-06-07 06:17:07,724] {subprocess.py:92} INFO - 22/06/07 06:17:07 INFO Executor: Running task 61.0 in stage 0.0 (TID 61)
[2022-06-07 06:17:07,730] {subprocess.py:92} INFO - 22/06/07 06:17:07 INFO Executor: Finished task 60.0 in stage 0.0 (TID 60). 2646 bytes result sent to driver
[2022-06-07 06:17:07,732] {subprocess.py:92} INFO - 22/06/07 06:17:07 INFO TaskSetManager: Starting task 62.0 in stage 0.0 (TID 62) (d952e2b2ede8, executor driver, partition 62, PROCESS_LOCAL, 4553 bytes) taskResourceAssignments Map()
[2022-06-07 06:17:07,734] {subprocess.py:92} INFO - 22/06/07 06:17:07 INFO TaskSetManager: Finished task 60.0 in stage 0.0 (TID 60) in 27 ms on d952e2b2ede8 (executor driver) (59/180)
[2022-06-07 06:17:07,735] {subprocess.py:92} INFO - 22/06/07 06:17:07 INFO Executor: Running task 62.0 in stage 0.0 (TID 62)
[2022-06-07 06:17:07,737] {subprocess.py:92} INFO - 22/06/07 06:17:07 INFO Executor: Finished task 57.0 in stage 0.0 (TID 57). 2646 bytes result sent to driver
[2022-06-07 06:17:07,741] {subprocess.py:92} INFO - 22/06/07 06:17:07 INFO TaskSetManager: Starting task 63.0 in stage 0.0 (TID 63) (d952e2b2ede8, executor driver, partition 63, PROCESS_LOCAL, 4553 bytes) taskResourceAssignments Map()
[2022-06-07 06:17:07,743] {subprocess.py:92} INFO - 22/06/07 06:17:07 INFO TaskSetManager: Finished task 57.0 in stage 0.0 (TID 57) in 73 ms on d952e2b2ede8 (executor driver) (60/180)
[2022-06-07 06:17:07,744] {subprocess.py:92} INFO - 22/06/07 06:17:07 INFO Executor: Running task 63.0 in stage 0.0 (TID 63)
[2022-06-07 06:17:07,749] {subprocess.py:92} INFO - 22/06/07 06:17:07 INFO Executor: Finished task 61.0 in stage 0.0 (TID 61). 2646 bytes result sent to driver
[2022-06-07 06:17:07,751] {subprocess.py:92} INFO - 22/06/07 06:17:07 INFO TaskSetManager: Starting task 64.0 in stage 0.0 (TID 64) (d952e2b2ede8, executor driver, partition 64, PROCESS_LOCAL, 4553 bytes) taskResourceAssignments Map()
[2022-06-07 06:17:07,753] {subprocess.py:92} INFO - 22/06/07 06:17:07 INFO TaskSetManager: Finished task 61.0 in stage 0.0 (TID 61) in 32 ms on d952e2b2ede8 (executor driver) (61/180)
[2022-06-07 06:17:07,755] {subprocess.py:92} INFO - 22/06/07 06:17:07 INFO Executor: Finished task 62.0 in stage 0.0 (TID 62). 2646 bytes result sent to driver
[2022-06-07 06:17:07,756] {subprocess.py:92} INFO - 22/06/07 06:17:07 INFO TaskSetManager: Starting task 65.0 in stage 0.0 (TID 65) (d952e2b2ede8, executor driver, partition 65, PROCESS_LOCAL, 4553 bytes) taskResourceAssignments Map()
[2022-06-07 06:17:07,758] {subprocess.py:92} INFO - 22/06/07 06:17:07 INFO TaskSetManager: Finished task 62.0 in stage 0.0 (TID 62) in 26 ms on d952e2b2ede8 (executor driver) (62/180)
[2022-06-07 06:17:07,762] {subprocess.py:92} INFO - 22/06/07 06:17:07 INFO Executor: Finished task 58.0 in stage 0.0 (TID 58). 2646 bytes result sent to driver
[2022-06-07 06:17:07,771] {subprocess.py:92} INFO - 22/06/07 06:17:07 INFO Executor: Running task 64.0 in stage 0.0 (TID 64)
[2022-06-07 06:17:07,772] {subprocess.py:92} INFO - 22/06/07 06:17:07 INFO TaskSetManager: Starting task 66.0 in stage 0.0 (TID 66) (d952e2b2ede8, executor driver, partition 66, PROCESS_LOCAL, 4553 bytes) taskResourceAssignments Map()
[2022-06-07 06:17:07,772] {subprocess.py:92} INFO - 22/06/07 06:17:07 INFO TaskSetManager: Finished task 58.0 in stage 0.0 (TID 58) in 95 ms on d952e2b2ede8 (executor driver) (63/180)
[2022-06-07 06:17:07,773] {subprocess.py:92} INFO - 22/06/07 06:17:07 INFO Executor: Running task 66.0 in stage 0.0 (TID 66)
[2022-06-07 06:17:07,774] {subprocess.py:92} INFO - 22/06/07 06:17:07 INFO Executor: Running task 65.0 in stage 0.0 (TID 65)
[2022-06-07 06:17:07,778] {subprocess.py:92} INFO - 22/06/07 06:17:07 INFO Executor: Finished task 63.0 in stage 0.0 (TID 63). 2646 bytes result sent to driver
[2022-06-07 06:17:07,783] {subprocess.py:92} INFO - 22/06/07 06:17:07 INFO TaskSetManager: Starting task 67.0 in stage 0.0 (TID 67) (d952e2b2ede8, executor driver, partition 67, PROCESS_LOCAL, 4553 bytes) taskResourceAssignments Map()
[2022-06-07 06:17:07,785] {subprocess.py:92} INFO - 22/06/07 06:17:07 INFO TaskSetManager: Finished task 63.0 in stage 0.0 (TID 63) in 44 ms on d952e2b2ede8 (executor driver) (64/180)
[2022-06-07 06:17:07,787] {subprocess.py:92} INFO - 22/06/07 06:17:07 INFO Executor: Running task 67.0 in stage 0.0 (TID 67)
[2022-06-07 06:17:07,789] {subprocess.py:92} INFO - 22/06/07 06:17:07 INFO Executor: Finished task 64.0 in stage 0.0 (TID 64). 2646 bytes result sent to driver
[2022-06-07 06:17:07,790] {subprocess.py:92} INFO - 22/06/07 06:17:07 INFO TaskSetManager: Starting task 68.0 in stage 0.0 (TID 68) (d952e2b2ede8, executor driver, partition 68, PROCESS_LOCAL, 4553 bytes) taskResourceAssignments Map()
[2022-06-07 06:17:07,792] {subprocess.py:92} INFO - 22/06/07 06:17:07 INFO TaskSetManager: Finished task 64.0 in stage 0.0 (TID 64) in 40 ms on d952e2b2ede8 (executor driver) (65/180)
[2022-06-07 06:17:07,793] {subprocess.py:92} INFO - 22/06/07 06:17:07 INFO Executor: Running task 68.0 in stage 0.0 (TID 68)
[2022-06-07 06:17:07,794] {subprocess.py:92} INFO - 22/06/07 06:17:07 INFO Executor: Finished task 65.0 in stage 0.0 (TID 65). 2646 bytes result sent to driver
[2022-06-07 06:17:07,796] {subprocess.py:92} INFO - 22/06/07 06:17:07 INFO TaskSetManager: Starting task 69.0 in stage 0.0 (TID 69) (d952e2b2ede8, executor driver, partition 69, PROCESS_LOCAL, 4553 bytes) taskResourceAssignments Map()
[2022-06-07 06:17:07,797] {subprocess.py:92} INFO - 22/06/07 06:17:07 INFO Executor: Running task 69.0 in stage 0.0 (TID 69)
[2022-06-07 06:17:07,802] {subprocess.py:92} INFO - 22/06/07 06:17:07 INFO TaskSetManager: Finished task 65.0 in stage 0.0 (TID 65) in 41 ms on d952e2b2ede8 (executor driver) (66/180)
[2022-06-07 06:17:07,809] {subprocess.py:92} INFO - 22/06/07 06:17:07 INFO Executor: Finished task 69.0 in stage 0.0 (TID 69). 2646 bytes result sent to driver
[2022-06-07 06:17:07,810] {subprocess.py:92} INFO - 22/06/07 06:17:07 INFO TaskSetManager: Starting task 70.0 in stage 0.0 (TID 70) (d952e2b2ede8, executor driver, partition 70, PROCESS_LOCAL, 4553 bytes) taskResourceAssignments Map()
[2022-06-07 06:17:07,811] {subprocess.py:92} INFO - 22/06/07 06:17:07 INFO Executor: Running task 70.0 in stage 0.0 (TID 70)
[2022-06-07 06:17:07,813] {subprocess.py:92} INFO - 22/06/07 06:17:07 INFO TaskSetManager: Finished task 69.0 in stage 0.0 (TID 69) in 17 ms on d952e2b2ede8 (executor driver) (67/180)
[2022-06-07 06:17:07,818] {subprocess.py:92} INFO - 22/06/07 06:17:07 INFO Executor: Finished task 66.0 in stage 0.0 (TID 66). 2646 bytes result sent to driver
[2022-06-07 06:17:07,826] {subprocess.py:92} INFO - 22/06/07 06:17:07 INFO TaskSetManager: Starting task 71.0 in stage 0.0 (TID 71) (d952e2b2ede8, executor driver, partition 71, PROCESS_LOCAL, 4553 bytes) taskResourceAssignments Map()
[2022-06-07 06:17:07,827] {subprocess.py:92} INFO - 22/06/07 06:17:07 INFO Executor: Finished task 68.0 in stage 0.0 (TID 68). 2646 bytes result sent to driver
[2022-06-07 06:17:07,829] {subprocess.py:92} INFO - 22/06/07 06:17:07 INFO Executor: Finished task 70.0 in stage 0.0 (TID 70). 2646 bytes result sent to driver
[2022-06-07 06:17:07,829] {subprocess.py:92} INFO - 22/06/07 06:17:07 INFO Executor: Running task 71.0 in stage 0.0 (TID 71)
[2022-06-07 06:17:07,830] {subprocess.py:92} INFO - 22/06/07 06:17:07 INFO TaskSetManager: Finished task 66.0 in stage 0.0 (TID 66) in 62 ms on d952e2b2ede8 (executor driver) (68/180)
[2022-06-07 06:17:07,832] {subprocess.py:92} INFO - 22/06/07 06:17:07 INFO TaskSetManager: Starting task 72.0 in stage 0.0 (TID 72) (d952e2b2ede8, executor driver, partition 72, PROCESS_LOCAL, 4553 bytes) taskResourceAssignments Map()
[2022-06-07 06:17:07,833] {subprocess.py:92} INFO - 22/06/07 06:17:07 INFO Executor: Running task 72.0 in stage 0.0 (TID 72)
[2022-06-07 06:17:07,834] {subprocess.py:92} INFO - 22/06/07 06:17:07 INFO TaskSetManager: Finished task 68.0 in stage 0.0 (TID 68) in 44 ms on d952e2b2ede8 (executor driver) (69/180)
[2022-06-07 06:17:07,836] {subprocess.py:92} INFO - 22/06/07 06:17:07 INFO TaskSetManager: Starting task 73.0 in stage 0.0 (TID 73) (d952e2b2ede8, executor driver, partition 73, PROCESS_LOCAL, 4553 bytes) taskResourceAssignments Map()
[2022-06-07 06:17:07,837] {subprocess.py:92} INFO - 22/06/07 06:17:07 INFO TaskSetManager: Finished task 70.0 in stage 0.0 (TID 70) in 26 ms on d952e2b2ede8 (executor driver) (70/180)
[2022-06-07 06:17:07,845] {subprocess.py:92} INFO - 22/06/07 06:17:07 INFO Executor: Running task 73.0 in stage 0.0 (TID 73)
[2022-06-07 06:17:07,848] {subprocess.py:92} INFO - 22/06/07 06:17:07 INFO Executor: Finished task 67.0 in stage 0.0 (TID 67). 2646 bytes result sent to driver
[2022-06-07 06:17:07,854] {subprocess.py:92} INFO - 22/06/07 06:17:07 INFO Executor: Finished task 72.0 in stage 0.0 (TID 72). 2646 bytes result sent to driver
[2022-06-07 06:17:07,863] {subprocess.py:92} INFO - 22/06/07 06:17:07 INFO TaskSetManager: Starting task 74.0 in stage 0.0 (TID 74) (d952e2b2ede8, executor driver, partition 74, PROCESS_LOCAL, 4553 bytes) taskResourceAssignments Map()
[2022-06-07 06:17:07,865] {subprocess.py:92} INFO - 22/06/07 06:17:07 INFO TaskSetManager: Starting task 75.0 in stage 0.0 (TID 75) (d952e2b2ede8, executor driver, partition 75, PROCESS_LOCAL, 4553 bytes) taskResourceAssignments Map()
[2022-06-07 06:17:07,867] {subprocess.py:92} INFO - 22/06/07 06:17:07 INFO Executor: Running task 74.0 in stage 0.0 (TID 74)
[2022-06-07 06:17:07,867] {subprocess.py:92} INFO - 22/06/07 06:17:07 INFO TaskSetManager: Finished task 72.0 in stage 0.0 (TID 72) in 36 ms on d952e2b2ede8 (executor driver) (71/180)
[2022-06-07 06:17:07,868] {subprocess.py:92} INFO - 22/06/07 06:17:07 INFO TaskSetManager: Finished task 67.0 in stage 0.0 (TID 67) in 85 ms on d952e2b2ede8 (executor driver) (72/180)
[2022-06-07 06:17:07,870] {subprocess.py:92} INFO - 22/06/07 06:17:07 INFO Executor: Running task 75.0 in stage 0.0 (TID 75)
[2022-06-07 06:17:07,881] {subprocess.py:92} INFO - 22/06/07 06:17:07 INFO Executor: Finished task 73.0 in stage 0.0 (TID 73). 2689 bytes result sent to driver
[2022-06-07 06:17:07,883] {subprocess.py:92} INFO - 22/06/07 06:17:07 INFO TaskSetManager: Starting task 76.0 in stage 0.0 (TID 76) (d952e2b2ede8, executor driver, partition 76, PROCESS_LOCAL, 4553 bytes) taskResourceAssignments Map()
[2022-06-07 06:17:07,885] {subprocess.py:92} INFO - 22/06/07 06:17:07 INFO Executor: Running task 76.0 in stage 0.0 (TID 76)
[2022-06-07 06:17:07,886] {subprocess.py:92} INFO - 22/06/07 06:17:07 INFO TaskSetManager: Finished task 73.0 in stage 0.0 (TID 73) in 49 ms on d952e2b2ede8 (executor driver) (73/180)
[2022-06-07 06:17:07,887] {subprocess.py:92} INFO - 22/06/07 06:17:07 INFO Executor: Finished task 71.0 in stage 0.0 (TID 71). 2646 bytes result sent to driver
[2022-06-07 06:17:07,890] {subprocess.py:92} INFO - 22/06/07 06:17:07 INFO Executor: Finished task 75.0 in stage 0.0 (TID 75). 2646 bytes result sent to driver
[2022-06-07 06:17:07,891] {subprocess.py:92} INFO - 22/06/07 06:17:07 INFO TaskSetManager: Starting task 77.0 in stage 0.0 (TID 77) (d952e2b2ede8, executor driver, partition 77, PROCESS_LOCAL, 4553 bytes) taskResourceAssignments Map()
[2022-06-07 06:17:07,893] {subprocess.py:92} INFO - 22/06/07 06:17:07 INFO Executor: Running task 77.0 in stage 0.0 (TID 77)
[2022-06-07 06:17:07,894] {subprocess.py:92} INFO - 22/06/07 06:17:07 INFO TaskSetManager: Starting task 78.0 in stage 0.0 (TID 78) (d952e2b2ede8, executor driver, partition 78, PROCESS_LOCAL, 4553 bytes) taskResourceAssignments Map()
[2022-06-07 06:17:07,896] {subprocess.py:92} INFO - 22/06/07 06:17:07 INFO TaskSetManager: Finished task 75.0 in stage 0.0 (TID 75) in 31 ms on d952e2b2ede8 (executor driver) (74/180)
[2022-06-07 06:17:07,897] {subprocess.py:92} INFO - 22/06/07 06:17:07 INFO TaskSetManager: Finished task 71.0 in stage 0.0 (TID 71) in 71 ms on d952e2b2ede8 (executor driver) (75/180)
[2022-06-07 06:17:07,899] {subprocess.py:92} INFO - 22/06/07 06:17:07 INFO Executor: Running task 78.0 in stage 0.0 (TID 78)
[2022-06-07 06:17:07,915] {subprocess.py:92} INFO - 22/06/07 06:17:07 INFO Executor: Finished task 78.0 in stage 0.0 (TID 78). 2646 bytes result sent to driver
[2022-06-07 06:17:07,970] {subprocess.py:92} INFO - 22/06/07 06:17:07 INFO TaskSetManager: Starting task 79.0 in stage 0.0 (TID 79) (d952e2b2ede8, executor driver, partition 79, PROCESS_LOCAL, 4553 bytes) taskResourceAssignments Map()
[2022-06-07 06:17:07,971] {subprocess.py:92} INFO - 22/06/07 06:17:07 INFO TaskSetManager: Finished task 78.0 in stage 0.0 (TID 78) in 78 ms on d952e2b2ede8 (executor driver) (76/180)
[2022-06-07 06:17:07,973] {subprocess.py:92} INFO - 22/06/07 06:17:07 INFO Executor: Finished task 76.0 in stage 0.0 (TID 76). 2732 bytes result sent to driver
[2022-06-07 06:17:07,974] {subprocess.py:92} INFO - 22/06/07 06:17:07 INFO Executor: Running task 79.0 in stage 0.0 (TID 79)
[2022-06-07 06:17:07,979] {subprocess.py:92} INFO - 22/06/07 06:17:07 INFO TaskSetManager: Starting task 80.0 in stage 0.0 (TID 80) (d952e2b2ede8, executor driver, partition 80, PROCESS_LOCAL, 4553 bytes) taskResourceAssignments Map()
[2022-06-07 06:17:07,981] {subprocess.py:92} INFO - 22/06/07 06:17:07 INFO Executor: Finished task 77.0 in stage 0.0 (TID 77). 2689 bytes result sent to driver
[2022-06-07 06:17:07,982] {subprocess.py:92} INFO - 22/06/07 06:17:07 INFO TaskSetManager: Finished task 76.0 in stage 0.0 (TID 76) in 99 ms on d952e2b2ede8 (executor driver) (77/180)
[2022-06-07 06:17:07,985] {subprocess.py:92} INFO - 22/06/07 06:17:07 INFO Executor: Finished task 74.0 in stage 0.0 (TID 74). 2689 bytes result sent to driver
[2022-06-07 06:17:07,986] {subprocess.py:92} INFO - 22/06/07 06:17:07 INFO Executor: Running task 80.0 in stage 0.0 (TID 80)
[2022-06-07 06:17:07,987] {subprocess.py:92} INFO - 22/06/07 06:17:07 INFO TaskSetManager: Finished task 77.0 in stage 0.0 (TID 77) in 98 ms on d952e2b2ede8 (executor driver) (78/180)
[2022-06-07 06:17:07,991] {subprocess.py:92} INFO - 22/06/07 06:17:07 INFO TaskSetManager: Starting task 81.0 in stage 0.0 (TID 81) (d952e2b2ede8, executor driver, partition 81, PROCESS_LOCAL, 4553 bytes) taskResourceAssignments Map()
[2022-06-07 06:17:08,002] {subprocess.py:92} INFO - 22/06/07 06:17:08 INFO Executor: Running task 81.0 in stage 0.0 (TID 81)
[2022-06-07 06:17:08,003] {subprocess.py:92} INFO - 22/06/07 06:17:08 INFO TaskSetManager: Finished task 74.0 in stage 0.0 (TID 74) in 138 ms on d952e2b2ede8 (executor driver) (79/180)
[2022-06-07 06:17:08,006] {subprocess.py:92} INFO - 22/06/07 06:17:08 INFO TaskSetManager: Starting task 82.0 in stage 0.0 (TID 82) (d952e2b2ede8, executor driver, partition 82, PROCESS_LOCAL, 4553 bytes) taskResourceAssignments Map()
[2022-06-07 06:17:08,016] {subprocess.py:92} INFO - 22/06/07 06:17:08 INFO Executor: Running task 82.0 in stage 0.0 (TID 82)
[2022-06-07 06:17:08,020] {subprocess.py:92} INFO - 22/06/07 06:17:08 INFO Executor: Finished task 81.0 in stage 0.0 (TID 81). 2646 bytes result sent to driver
[2022-06-07 06:17:08,022] {subprocess.py:92} INFO - 22/06/07 06:17:08 INFO TaskSetManager: Starting task 83.0 in stage 0.0 (TID 83) (d952e2b2ede8, executor driver, partition 83, PROCESS_LOCAL, 4553 bytes) taskResourceAssignments Map()
[2022-06-07 06:17:08,023] {subprocess.py:92} INFO - 22/06/07 06:17:08 INFO Executor: Running task 83.0 in stage 0.0 (TID 83)
[2022-06-07 06:17:08,024] {subprocess.py:92} INFO - 22/06/07 06:17:08 INFO Executor: Finished task 80.0 in stage 0.0 (TID 80). 2646 bytes result sent to driver
[2022-06-07 06:17:08,029] {subprocess.py:92} INFO - 22/06/07 06:17:08 INFO TaskSetManager: Finished task 81.0 in stage 0.0 (TID 81) in 38 ms on d952e2b2ede8 (executor driver) (80/180)
[2022-06-07 06:17:08,033] {subprocess.py:92} INFO - 22/06/07 06:17:08 INFO TaskSetManager: Finished task 80.0 in stage 0.0 (TID 80) in 54 ms on d952e2b2ede8 (executor driver) (81/180)
[2022-06-07 06:17:08,035] {subprocess.py:92} INFO - 22/06/07 06:17:08 INFO Executor: Finished task 83.0 in stage 0.0 (TID 83). 2646 bytes result sent to driver
[2022-06-07 06:17:08,037] {subprocess.py:92} INFO - 22/06/07 06:17:08 INFO TaskSetManager: Starting task 84.0 in stage 0.0 (TID 84) (d952e2b2ede8, executor driver, partition 84, PROCESS_LOCAL, 4553 bytes) taskResourceAssignments Map()
[2022-06-07 06:17:08,038] {subprocess.py:92} INFO - 22/06/07 06:17:08 INFO Executor: Running task 84.0 in stage 0.0 (TID 84)
[2022-06-07 06:17:08,043] {subprocess.py:92} INFO - 22/06/07 06:17:08 INFO TaskSetManager: Finished task 83.0 in stage 0.0 (TID 83) in 21 ms on d952e2b2ede8 (executor driver) (82/180)
[2022-06-07 06:17:08,046] {subprocess.py:92} INFO - 22/06/07 06:17:08 INFO TaskSetManager: Starting task 85.0 in stage 0.0 (TID 85) (d952e2b2ede8, executor driver, partition 85, PROCESS_LOCAL, 4553 bytes) taskResourceAssignments Map()
[2022-06-07 06:17:08,048] {subprocess.py:92} INFO - 22/06/07 06:17:08 INFO Executor: Running task 85.0 in stage 0.0 (TID 85)
[2022-06-07 06:17:08,049] {subprocess.py:92} INFO - 22/06/07 06:17:08 INFO Executor: Finished task 79.0 in stage 0.0 (TID 79). 2646 bytes result sent to driver
[2022-06-07 06:17:08,051] {subprocess.py:92} INFO - 22/06/07 06:17:08 INFO TaskSetManager: Starting task 86.0 in stage 0.0 (TID 86) (d952e2b2ede8, executor driver, partition 86, PROCESS_LOCAL, 4553 bytes) taskResourceAssignments Map()
[2022-06-07 06:17:08,052] {subprocess.py:92} INFO - 22/06/07 06:17:08 INFO TaskSetManager: Finished task 79.0 in stage 0.0 (TID 79) in 84 ms on d952e2b2ede8 (executor driver) (83/180)
[2022-06-07 06:17:08,054] {subprocess.py:92} INFO - 22/06/07 06:17:08 INFO Executor: Running task 86.0 in stage 0.0 (TID 86)
[2022-06-07 06:17:08,064] {subprocess.py:92} INFO - 22/06/07 06:17:08 INFO Executor: Finished task 82.0 in stage 0.0 (TID 82). 2646 bytes result sent to driver
[2022-06-07 06:17:08,065] {subprocess.py:92} INFO - 22/06/07 06:17:08 INFO Executor: Finished task 85.0 in stage 0.0 (TID 85). 2646 bytes result sent to driver
[2022-06-07 06:17:08,066] {subprocess.py:92} INFO - 22/06/07 06:17:08 INFO TaskSetManager: Starting task 87.0 in stage 0.0 (TID 87) (d952e2b2ede8, executor driver, partition 87, PROCESS_LOCAL, 4553 bytes) taskResourceAssignments Map()
[2022-06-07 06:17:08,068] {subprocess.py:92} INFO - 22/06/07 06:17:08 INFO TaskSetManager: Finished task 82.0 in stage 0.0 (TID 82) in 66 ms on d952e2b2ede8 (executor driver) (84/180)
[2022-06-07 06:17:08,068] {subprocess.py:92} INFO - 22/06/07 06:17:08 INFO Executor: Running task 87.0 in stage 0.0 (TID 87)
[2022-06-07 06:17:08,071] {subprocess.py:92} INFO - 22/06/07 06:17:08 INFO TaskSetManager: Starting task 88.0 in stage 0.0 (TID 88) (d952e2b2ede8, executor driver, partition 88, PROCESS_LOCAL, 4553 bytes) taskResourceAssignments Map()
[2022-06-07 06:17:08,072] {subprocess.py:92} INFO - 22/06/07 06:17:08 INFO TaskSetManager: Finished task 85.0 in stage 0.0 (TID 85) in 27 ms on d952e2b2ede8 (executor driver) (85/180)
[2022-06-07 06:17:08,075] {subprocess.py:92} INFO - 22/06/07 06:17:08 INFO Executor: Running task 88.0 in stage 0.0 (TID 88)
[2022-06-07 06:17:08,077] {subprocess.py:92} INFO - 22/06/07 06:17:08 INFO Executor: Finished task 86.0 in stage 0.0 (TID 86). 2646 bytes result sent to driver
[2022-06-07 06:17:08,077] {subprocess.py:92} INFO - 22/06/07 06:17:08 INFO TaskSetManager: Starting task 89.0 in stage 0.0 (TID 89) (d952e2b2ede8, executor driver, partition 89, PROCESS_LOCAL, 4553 bytes) taskResourceAssignments Map()
[2022-06-07 06:17:08,078] {subprocess.py:92} INFO - 22/06/07 06:17:08 INFO Executor: Running task 89.0 in stage 0.0 (TID 89)
[2022-06-07 06:17:08,080] {subprocess.py:92} INFO - 22/06/07 06:17:08 INFO TaskSetManager: Finished task 86.0 in stage 0.0 (TID 86) in 28 ms on d952e2b2ede8 (executor driver) (86/180)
[2022-06-07 06:17:08,082] {subprocess.py:92} INFO - 22/06/07 06:17:08 INFO Executor: Finished task 87.0 in stage 0.0 (TID 87). 2646 bytes result sent to driver
[2022-06-07 06:17:08,084] {subprocess.py:92} INFO - 22/06/07 06:17:08 INFO TaskSetManager: Starting task 90.0 in stage 0.0 (TID 90) (d952e2b2ede8, executor driver, partition 90, PROCESS_LOCAL, 4553 bytes) taskResourceAssignments Map()
[2022-06-07 06:17:08,085] {subprocess.py:92} INFO - 22/06/07 06:17:08 INFO Executor: Finished task 84.0 in stage 0.0 (TID 84). 2646 bytes result sent to driver
[2022-06-07 06:17:08,087] {subprocess.py:92} INFO - 22/06/07 06:17:08 INFO Executor: Running task 90.0 in stage 0.0 (TID 90)
[2022-06-07 06:17:08,088] {subprocess.py:92} INFO - 22/06/07 06:17:08 INFO TaskSetManager: Starting task 91.0 in stage 0.0 (TID 91) (d952e2b2ede8, executor driver, partition 91, PROCESS_LOCAL, 4553 bytes) taskResourceAssignments Map()
[2022-06-07 06:17:08,089] {subprocess.py:92} INFO - 22/06/07 06:17:08 INFO TaskSetManager: Finished task 87.0 in stage 0.0 (TID 87) in 22 ms on d952e2b2ede8 (executor driver) (87/180)
[2022-06-07 06:17:08,091] {subprocess.py:92} INFO - 22/06/07 06:17:08 INFO TaskSetManager: Finished task 84.0 in stage 0.0 (TID 84) in 53 ms on d952e2b2ede8 (executor driver) (88/180)
[2022-06-07 06:17:08,092] {subprocess.py:92} INFO - 22/06/07 06:17:08 INFO Executor: Running task 91.0 in stage 0.0 (TID 91)
[2022-06-07 06:17:08,100] {subprocess.py:92} INFO - 22/06/07 06:17:08 INFO Executor: Finished task 88.0 in stage 0.0 (TID 88). 2646 bytes result sent to driver
[2022-06-07 06:17:08,102] {subprocess.py:92} INFO - 22/06/07 06:17:08 INFO TaskSetManager: Starting task 92.0 in stage 0.0 (TID 92) (d952e2b2ede8, executor driver, partition 92, PROCESS_LOCAL, 4553 bytes) taskResourceAssignments Map()
[2022-06-07 06:17:08,104] {subprocess.py:92} INFO - 22/06/07 06:17:08 INFO Executor: Finished task 91.0 in stage 0.0 (TID 91). 2646 bytes result sent to driver
[2022-06-07 06:17:08,105] {subprocess.py:92} INFO - 22/06/07 06:17:08 INFO TaskSetManager: Finished task 88.0 in stage 0.0 (TID 88) in 33 ms on d952e2b2ede8 (executor driver) (89/180)
[2022-06-07 06:17:08,106] {subprocess.py:92} INFO - 22/06/07 06:17:08 INFO Executor: Running task 92.0 in stage 0.0 (TID 92)
[2022-06-07 06:17:08,110] {subprocess.py:92} INFO - 22/06/07 06:17:08 INFO TaskSetManager: Starting task 93.0 in stage 0.0 (TID 93) (d952e2b2ede8, executor driver, partition 93, PROCESS_LOCAL, 4553 bytes) taskResourceAssignments Map()
[2022-06-07 06:17:08,112] {subprocess.py:92} INFO - 22/06/07 06:17:08 INFO TaskSetManager: Finished task 91.0 in stage 0.0 (TID 91) in 25 ms on d952e2b2ede8 (executor driver) (90/180)
[2022-06-07 06:17:08,113] {subprocess.py:92} INFO - 22/06/07 06:17:08 INFO Executor: Running task 93.0 in stage 0.0 (TID 93)
[2022-06-07 06:17:08,117] {subprocess.py:92} INFO - 22/06/07 06:17:08 INFO Executor: Finished task 90.0 in stage 0.0 (TID 90). 2646 bytes result sent to driver
[2022-06-07 06:17:08,119] {subprocess.py:92} INFO - 22/06/07 06:17:08 INFO TaskSetManager: Starting task 94.0 in stage 0.0 (TID 94) (d952e2b2ede8, executor driver, partition 94, PROCESS_LOCAL, 4553 bytes) taskResourceAssignments Map()
[2022-06-07 06:17:08,120] {subprocess.py:92} INFO - 22/06/07 06:17:08 INFO Executor: Running task 94.0 in stage 0.0 (TID 94)
[2022-06-07 06:17:08,122] {subprocess.py:92} INFO - 22/06/07 06:17:08 INFO TaskSetManager: Finished task 90.0 in stage 0.0 (TID 90) in 38 ms on d952e2b2ede8 (executor driver) (91/180)
[2022-06-07 06:17:08,124] {subprocess.py:92} INFO - 22/06/07 06:17:08 INFO Executor: Finished task 93.0 in stage 0.0 (TID 93). 2646 bytes result sent to driver
[2022-06-07 06:17:08,126] {subprocess.py:92} INFO - 22/06/07 06:17:08 INFO TaskSetManager: Starting task 95.0 in stage 0.0 (TID 95) (d952e2b2ede8, executor driver, partition 95, PROCESS_LOCAL, 4553 bytes) taskResourceAssignments Map()
[2022-06-07 06:17:08,127] {subprocess.py:92} INFO - 22/06/07 06:17:08 INFO Executor: Running task 95.0 in stage 0.0 (TID 95)
[2022-06-07 06:17:08,128] {subprocess.py:92} INFO - 22/06/07 06:17:08 INFO TaskSetManager: Finished task 93.0 in stage 0.0 (TID 93) in 18 ms on d952e2b2ede8 (executor driver) (92/180)
[2022-06-07 06:17:08,130] {subprocess.py:92} INFO - 22/06/07 06:17:08 INFO Executor: Finished task 89.0 in stage 0.0 (TID 89). 2689 bytes result sent to driver
[2022-06-07 06:17:08,134] {subprocess.py:92} INFO - 22/06/07 06:17:08 INFO TaskSetManager: Starting task 96.0 in stage 0.0 (TID 96) (d952e2b2ede8, executor driver, partition 96, PROCESS_LOCAL, 4553 bytes) taskResourceAssignments Map()
[2022-06-07 06:17:08,136] {subprocess.py:92} INFO - 22/06/07 06:17:08 INFO TaskSetManager: Finished task 89.0 in stage 0.0 (TID 89) in 61 ms on d952e2b2ede8 (executor driver) (93/180)
[2022-06-07 06:17:08,138] {subprocess.py:92} INFO - 22/06/07 06:17:08 INFO Executor: Running task 96.0 in stage 0.0 (TID 96)
[2022-06-07 06:17:08,141] {subprocess.py:92} INFO - 22/06/07 06:17:08 INFO Executor: Finished task 92.0 in stage 0.0 (TID 92). 2646 bytes result sent to driver
[2022-06-07 06:17:08,144] {subprocess.py:92} INFO - 22/06/07 06:17:08 INFO TaskSetManager: Starting task 97.0 in stage 0.0 (TID 97) (d952e2b2ede8, executor driver, partition 97, PROCESS_LOCAL, 4553 bytes) taskResourceAssignments Map()
[2022-06-07 06:17:08,147] {subprocess.py:92} INFO - 22/06/07 06:17:08 INFO TaskSetManager: Finished task 92.0 in stage 0.0 (TID 92) in 45 ms on d952e2b2ede8 (executor driver) (94/180)
[2022-06-07 06:17:08,148] {subprocess.py:92} INFO - 22/06/07 06:17:08 INFO Executor: Finished task 95.0 in stage 0.0 (TID 95). 2646 bytes result sent to driver
[2022-06-07 06:17:08,149] {subprocess.py:92} INFO - 22/06/07 06:17:08 INFO Executor: Finished task 94.0 in stage 0.0 (TID 94). 2646 bytes result sent to driver
[2022-06-07 06:17:08,150] {subprocess.py:92} INFO - 22/06/07 06:17:08 INFO Executor: Running task 97.0 in stage 0.0 (TID 97)
[2022-06-07 06:17:08,154] {subprocess.py:92} INFO - 22/06/07 06:17:08 INFO TaskSetManager: Starting task 98.0 in stage 0.0 (TID 98) (d952e2b2ede8, executor driver, partition 98, PROCESS_LOCAL, 4553 bytes) taskResourceAssignments Map()
[2022-06-07 06:17:08,156] {subprocess.py:92} INFO - 22/06/07 06:17:08 INFO TaskSetManager: Finished task 95.0 in stage 0.0 (TID 95) in 30 ms on d952e2b2ede8 (executor driver) (95/180)
[2022-06-07 06:17:08,157] {subprocess.py:92} INFO - 22/06/07 06:17:08 INFO Executor: Running task 98.0 in stage 0.0 (TID 98)
[2022-06-07 06:17:08,160] {subprocess.py:92} INFO - 22/06/07 06:17:08 INFO TaskSetManager: Starting task 99.0 in stage 0.0 (TID 99) (d952e2b2ede8, executor driver, partition 99, PROCESS_LOCAL, 4553 bytes) taskResourceAssignments Map()
[2022-06-07 06:17:08,162] {subprocess.py:92} INFO - 22/06/07 06:17:08 INFO TaskSetManager: Finished task 94.0 in stage 0.0 (TID 94) in 43 ms on d952e2b2ede8 (executor driver) (96/180)
[2022-06-07 06:17:08,163] {subprocess.py:92} INFO - 22/06/07 06:17:08 INFO Executor: Running task 99.0 in stage 0.0 (TID 99)
[2022-06-07 06:17:08,173] {subprocess.py:92} INFO - 22/06/07 06:17:08 INFO Executor: Finished task 96.0 in stage 0.0 (TID 96). 2646 bytes result sent to driver
[2022-06-07 06:17:08,177] {subprocess.py:92} INFO - 22/06/07 06:17:08 INFO TaskSetManager: Starting task 100.0 in stage 0.0 (TID 100) (d952e2b2ede8, executor driver, partition 100, PROCESS_LOCAL, 4553 bytes) taskResourceAssignments Map()
[2022-06-07 06:17:08,178] {subprocess.py:92} INFO - 22/06/07 06:17:08 INFO Executor: Finished task 99.0 in stage 0.0 (TID 99). 2646 bytes result sent to driver
[2022-06-07 06:17:08,180] {subprocess.py:92} INFO - 22/06/07 06:17:08 INFO TaskSetManager: Finished task 96.0 in stage 0.0 (TID 96) in 47 ms on d952e2b2ede8 (executor driver) (97/180)
[2022-06-07 06:17:08,181] {subprocess.py:92} INFO - 22/06/07 06:17:08 INFO Executor: Finished task 97.0 in stage 0.0 (TID 97). 2646 bytes result sent to driver
[2022-06-07 06:17:08,182] {subprocess.py:92} INFO - 22/06/07 06:17:08 INFO Executor: Running task 100.0 in stage 0.0 (TID 100)
[2022-06-07 06:17:08,183] {subprocess.py:92} INFO - 22/06/07 06:17:08 INFO Executor: Finished task 98.0 in stage 0.0 (TID 98). 2646 bytes result sent to driver
[2022-06-07 06:17:08,184] {subprocess.py:92} INFO - 22/06/07 06:17:08 INFO TaskSetManager: Starting task 101.0 in stage 0.0 (TID 101) (d952e2b2ede8, executor driver, partition 101, PROCESS_LOCAL, 4553 bytes) taskResourceAssignments Map()
[2022-06-07 06:17:08,186] {subprocess.py:92} INFO - 22/06/07 06:17:08 INFO Executor: Running task 101.0 in stage 0.0 (TID 101)
[2022-06-07 06:17:08,188] {subprocess.py:92} INFO - 22/06/07 06:17:08 INFO TaskSetManager: Starting task 102.0 in stage 0.0 (TID 102) (d952e2b2ede8, executor driver, partition 102, PROCESS_LOCAL, 4553 bytes) taskResourceAssignments Map()
[2022-06-07 06:17:08,190] {subprocess.py:92} INFO - 22/06/07 06:17:08 INFO TaskSetManager: Finished task 99.0 in stage 0.0 (TID 99) in 31 ms on d952e2b2ede8 (executor driver) (98/180)
[2022-06-07 06:17:08,192] {subprocess.py:92} INFO - 22/06/07 06:17:08 INFO TaskSetManager: Finished task 97.0 in stage 0.0 (TID 97) in 48 ms on d952e2b2ede8 (executor driver) (99/180)
[2022-06-07 06:17:08,194] {subprocess.py:92} INFO - 22/06/07 06:17:08 INFO Executor: Running task 102.0 in stage 0.0 (TID 102)
[2022-06-07 06:17:08,196] {subprocess.py:92} INFO - 22/06/07 06:17:08 INFO TaskSetManager: Finished task 98.0 in stage 0.0 (TID 98) in 46 ms on d952e2b2ede8 (executor driver) (100/180)
[2022-06-07 06:17:08,200] {subprocess.py:92} INFO - 22/06/07 06:17:08 INFO TaskSetManager: Starting task 103.0 in stage 0.0 (TID 103) (d952e2b2ede8, executor driver, partition 103, PROCESS_LOCAL, 4553 bytes) taskResourceAssignments Map()
[2022-06-07 06:17:08,203] {subprocess.py:92} INFO - 22/06/07 06:17:08 INFO Executor: Running task 103.0 in stage 0.0 (TID 103)
[2022-06-07 06:17:08,205] {subprocess.py:92} INFO - 22/06/07 06:17:08 INFO Executor: Finished task 101.0 in stage 0.0 (TID 101). 2646 bytes result sent to driver
[2022-06-07 06:17:08,207] {subprocess.py:92} INFO - 22/06/07 06:17:08 INFO TaskSetManager: Starting task 104.0 in stage 0.0 (TID 104) (d952e2b2ede8, executor driver, partition 104, PROCESS_LOCAL, 4553 bytes) taskResourceAssignments Map()
[2022-06-07 06:17:08,208] {subprocess.py:92} INFO - 22/06/07 06:17:08 INFO Executor: Running task 104.0 in stage 0.0 (TID 104)
[2022-06-07 06:17:08,209] {subprocess.py:92} INFO - 22/06/07 06:17:08 INFO TaskSetManager: Finished task 101.0 in stage 0.0 (TID 101) in 27 ms on d952e2b2ede8 (executor driver) (101/180)
[2022-06-07 06:17:08,215] {subprocess.py:92} INFO - 22/06/07 06:17:08 INFO Executor: Finished task 100.0 in stage 0.0 (TID 100). 2646 bytes result sent to driver
[2022-06-07 06:17:08,217] {subprocess.py:92} INFO - 22/06/07 06:17:08 INFO TaskSetManager: Starting task 105.0 in stage 0.0 (TID 105) (d952e2b2ede8, executor driver, partition 105, PROCESS_LOCAL, 4553 bytes) taskResourceAssignments Map()
[2022-06-07 06:17:08,219] {subprocess.py:92} INFO - 22/06/07 06:17:08 INFO Executor: Running task 105.0 in stage 0.0 (TID 105)
[2022-06-07 06:17:08,220] {subprocess.py:92} INFO - 22/06/07 06:17:08 INFO TaskSetManager: Finished task 100.0 in stage 0.0 (TID 100) in 42 ms on d952e2b2ede8 (executor driver) (102/180)
[2022-06-07 06:17:08,224] {subprocess.py:92} INFO - 22/06/07 06:17:08 INFO Executor: Finished task 103.0 in stage 0.0 (TID 103). 2646 bytes result sent to driver
[2022-06-07 06:17:08,225] {subprocess.py:92} INFO - 22/06/07 06:17:08 INFO TaskSetManager: Starting task 106.0 in stage 0.0 (TID 106) (d952e2b2ede8, executor driver, partition 106, PROCESS_LOCAL, 4553 bytes) taskResourceAssignments Map()
[2022-06-07 06:17:08,227] {subprocess.py:92} INFO - 22/06/07 06:17:08 INFO Executor: Running task 106.0 in stage 0.0 (TID 106)
[2022-06-07 06:17:08,227] {subprocess.py:92} INFO - 22/06/07 06:17:08 INFO TaskSetManager: Finished task 103.0 in stage 0.0 (TID 103) in 29 ms on d952e2b2ede8 (executor driver) (103/180)
[2022-06-07 06:17:08,229] {subprocess.py:92} INFO - 22/06/07 06:17:08 INFO Executor: Finished task 104.0 in stage 0.0 (TID 104). 2646 bytes result sent to driver
[2022-06-07 06:17:08,230] {subprocess.py:92} INFO - 22/06/07 06:17:08 INFO Executor: Finished task 102.0 in stage 0.0 (TID 102). 2646 bytes result sent to driver
[2022-06-07 06:17:08,231] {subprocess.py:92} INFO - 22/06/07 06:17:08 INFO TaskSetManager: Starting task 107.0 in stage 0.0 (TID 107) (d952e2b2ede8, executor driver, partition 107, PROCESS_LOCAL, 4553 bytes) taskResourceAssignments Map()
[2022-06-07 06:17:08,233] {subprocess.py:92} INFO - 22/06/07 06:17:08 INFO TaskSetManager: Finished task 104.0 in stage 0.0 (TID 104) in 26 ms on d952e2b2ede8 (executor driver) (104/180)
[2022-06-07 06:17:08,234] {subprocess.py:92} INFO - 22/06/07 06:17:08 INFO Executor: Running task 107.0 in stage 0.0 (TID 107)
[2022-06-07 06:17:08,235] {subprocess.py:92} INFO - 22/06/07 06:17:08 INFO TaskSetManager: Starting task 108.0 in stage 0.0 (TID 108) (d952e2b2ede8, executor driver, partition 108, PROCESS_LOCAL, 4553 bytes) taskResourceAssignments Map()
[2022-06-07 06:17:08,236] {subprocess.py:92} INFO - 22/06/07 06:17:08 INFO TaskSetManager: Finished task 102.0 in stage 0.0 (TID 102) in 49 ms on d952e2b2ede8 (executor driver) (105/180)
[2022-06-07 06:17:08,238] {subprocess.py:92} INFO - 22/06/07 06:17:08 INFO Executor: Running task 108.0 in stage 0.0 (TID 108)
[2022-06-07 06:17:08,246] {subprocess.py:92} INFO - 22/06/07 06:17:08 INFO Executor: Finished task 105.0 in stage 0.0 (TID 105). 2646 bytes result sent to driver
[2022-06-07 06:17:08,248] {subprocess.py:92} INFO - 22/06/07 06:17:08 INFO TaskSetManager: Starting task 109.0 in stage 0.0 (TID 109) (d952e2b2ede8, executor driver, partition 109, PROCESS_LOCAL, 4553 bytes) taskResourceAssignments Map()
[2022-06-07 06:17:08,249] {subprocess.py:92} INFO - 22/06/07 06:17:08 INFO Executor: Finished task 108.0 in stage 0.0 (TID 108). 2646 bytes result sent to driver
[2022-06-07 06:17:08,250] {subprocess.py:92} INFO - 22/06/07 06:17:08 INFO TaskSetManager: Finished task 105.0 in stage 0.0 (TID 105) in 33 ms on d952e2b2ede8 (executor driver) (106/180)
[2022-06-07 06:17:08,251] {subprocess.py:92} INFO - 22/06/07 06:17:08 INFO Executor: Running task 109.0 in stage 0.0 (TID 109)
[2022-06-07 06:17:08,253] {subprocess.py:92} INFO - 22/06/07 06:17:08 INFO TaskSetManager: Starting task 110.0 in stage 0.0 (TID 110) (d952e2b2ede8, executor driver, partition 110, PROCESS_LOCAL, 4553 bytes) taskResourceAssignments Map()
[2022-06-07 06:17:08,254] {subprocess.py:92} INFO - 22/06/07 06:17:08 INFO Executor: Finished task 106.0 in stage 0.0 (TID 106). 2646 bytes result sent to driver
[2022-06-07 06:17:08,257] {subprocess.py:92} INFO - 22/06/07 06:17:08 INFO TaskSetManager: Finished task 108.0 in stage 0.0 (TID 108) in 20 ms on d952e2b2ede8 (executor driver) (107/180)
[2022-06-07 06:17:08,258] {subprocess.py:92} INFO - 22/06/07 06:17:08 INFO Executor: Running task 110.0 in stage 0.0 (TID 110)
[2022-06-07 06:17:08,260] {subprocess.py:92} INFO - 22/06/07 06:17:08 INFO TaskSetManager: Starting task 111.0 in stage 0.0 (TID 111) (d952e2b2ede8, executor driver, partition 111, PROCESS_LOCAL, 4553 bytes) taskResourceAssignments Map()
[2022-06-07 06:17:08,261] {subprocess.py:92} INFO - 22/06/07 06:17:08 INFO Executor: Finished task 107.0 in stage 0.0 (TID 107). 2646 bytes result sent to driver
[2022-06-07 06:17:08,263] {subprocess.py:92} INFO - 22/06/07 06:17:08 INFO TaskSetManager: Finished task 106.0 in stage 0.0 (TID 106) in 38 ms on d952e2b2ede8 (executor driver) (108/180)
[2022-06-07 06:17:08,264] {subprocess.py:92} INFO - 22/06/07 06:17:08 INFO Executor: Running task 111.0 in stage 0.0 (TID 111)
[2022-06-07 06:17:08,265] {subprocess.py:92} INFO - 22/06/07 06:17:08 INFO TaskSetManager: Starting task 112.0 in stage 0.0 (TID 112) (d952e2b2ede8, executor driver, partition 112, PROCESS_LOCAL, 4553 bytes) taskResourceAssignments Map()
[2022-06-07 06:17:08,266] {subprocess.py:92} INFO - 22/06/07 06:17:08 INFO Executor: Finished task 109.0 in stage 0.0 (TID 109). 2646 bytes result sent to driver
[2022-06-07 06:17:08,267] {subprocess.py:92} INFO - 22/06/07 06:17:08 INFO TaskSetManager: Finished task 107.0 in stage 0.0 (TID 107) in 35 ms on d952e2b2ede8 (executor driver) (109/180)
[2022-06-07 06:17:08,268] {subprocess.py:92} INFO - 22/06/07 06:17:08 INFO Executor: Running task 112.0 in stage 0.0 (TID 112)
[2022-06-07 06:17:08,270] {subprocess.py:92} INFO - 22/06/07 06:17:08 INFO TaskSetManager: Finished task 109.0 in stage 0.0 (TID 109) in 22 ms on d952e2b2ede8 (executor driver) (110/180)
[2022-06-07 06:17:08,272] {subprocess.py:92} INFO - 22/06/07 06:17:08 INFO TaskSetManager: Starting task 113.0 in stage 0.0 (TID 113) (d952e2b2ede8, executor driver, partition 113, PROCESS_LOCAL, 4553 bytes) taskResourceAssignments Map()
[2022-06-07 06:17:08,274] {subprocess.py:92} INFO - 22/06/07 06:17:08 INFO Executor: Running task 113.0 in stage 0.0 (TID 113)
[2022-06-07 06:17:08,276] {subprocess.py:92} INFO - 22/06/07 06:17:08 INFO Executor: Finished task 110.0 in stage 0.0 (TID 110). 2646 bytes result sent to driver
[2022-06-07 06:17:08,278] {subprocess.py:92} INFO - 22/06/07 06:17:08 INFO TaskSetManager: Starting task 114.0 in stage 0.0 (TID 114) (d952e2b2ede8, executor driver, partition 114, PROCESS_LOCAL, 4553 bytes) taskResourceAssignments Map()
[2022-06-07 06:17:08,279] {subprocess.py:92} INFO - 22/06/07 06:17:08 INFO Executor: Running task 114.0 in stage 0.0 (TID 114)
[2022-06-07 06:17:08,281] {subprocess.py:92} INFO - 22/06/07 06:17:08 INFO TaskSetManager: Finished task 110.0 in stage 0.0 (TID 110) in 27 ms on d952e2b2ede8 (executor driver) (111/180)
[2022-06-07 06:17:08,290] {subprocess.py:92} INFO - 22/06/07 06:17:08 INFO Executor: Finished task 112.0 in stage 0.0 (TID 112). 2646 bytes result sent to driver
[2022-06-07 06:17:08,294] {subprocess.py:92} INFO - 22/06/07 06:17:08 INFO Executor: Finished task 111.0 in stage 0.0 (TID 111). 2646 bytes result sent to driver
[2022-06-07 06:17:08,300] {subprocess.py:92} INFO - 22/06/07 06:17:08 INFO Executor: Finished task 113.0 in stage 0.0 (TID 113). 2646 bytes result sent to driver
[2022-06-07 06:17:08,303] {subprocess.py:92} INFO - 22/06/07 06:17:08 INFO Executor: Finished task 114.0 in stage 0.0 (TID 114). 2646 bytes result sent to driver
[2022-06-07 06:17:08,303] {subprocess.py:92} INFO - 22/06/07 06:17:08 INFO TaskSetManager: Starting task 115.0 in stage 0.0 (TID 115) (d952e2b2ede8, executor driver, partition 115, PROCESS_LOCAL, 4553 bytes) taskResourceAssignments Map()
[2022-06-07 06:17:08,306] {subprocess.py:92} INFO - 22/06/07 06:17:08 INFO TaskSetManager: Finished task 112.0 in stage 0.0 (TID 112) in 39 ms on d952e2b2ede8 (executor driver) (112/180)
[2022-06-07 06:17:08,309] {subprocess.py:92} INFO - 22/06/07 06:17:08 INFO Executor: Running task 115.0 in stage 0.0 (TID 115)
[2022-06-07 06:17:08,312] {subprocess.py:92} INFO - 22/06/07 06:17:08 INFO TaskSetManager: Starting task 116.0 in stage 0.0 (TID 116) (d952e2b2ede8, executor driver, partition 116, PROCESS_LOCAL, 4553 bytes) taskResourceAssignments Map()
[2022-06-07 06:17:08,314] {subprocess.py:92} INFO - 22/06/07 06:17:08 INFO TaskSetManager: Starting task 117.0 in stage 0.0 (TID 117) (d952e2b2ede8, executor driver, partition 117, PROCESS_LOCAL, 4553 bytes) taskResourceAssignments Map()
[2022-06-07 06:17:08,316] {subprocess.py:92} INFO - 22/06/07 06:17:08 INFO TaskSetManager: Starting task 118.0 in stage 0.0 (TID 118) (d952e2b2ede8, executor driver, partition 118, PROCESS_LOCAL, 4553 bytes) taskResourceAssignments Map()
[2022-06-07 06:17:08,317] {subprocess.py:92} INFO - 22/06/07 06:17:08 INFO Executor: Running task 118.0 in stage 0.0 (TID 118)
[2022-06-07 06:17:08,317] {subprocess.py:92} INFO - 22/06/07 06:17:08 INFO Executor: Running task 116.0 in stage 0.0 (TID 116)
[2022-06-07 06:17:08,318] {subprocess.py:92} INFO - 22/06/07 06:17:08 INFO Executor: Running task 117.0 in stage 0.0 (TID 117)
[2022-06-07 06:17:08,320] {subprocess.py:92} INFO - 22/06/07 06:17:08 INFO TaskSetManager: Finished task 111.0 in stage 0.0 (TID 111) in 60 ms on d952e2b2ede8 (executor driver) (113/180)
[2022-06-07 06:17:08,322] {subprocess.py:92} INFO - 22/06/07 06:17:08 INFO TaskSetManager: Finished task 113.0 in stage 0.0 (TID 113) in 51 ms on d952e2b2ede8 (executor driver) (114/180)
[2022-06-07 06:17:08,325] {subprocess.py:92} INFO - 22/06/07 06:17:08 INFO Executor: Finished task 115.0 in stage 0.0 (TID 115). 2646 bytes result sent to driver
[2022-06-07 06:17:08,327] {subprocess.py:92} INFO - 22/06/07 06:17:08 INFO Executor: Finished task 118.0 in stage 0.0 (TID 118). 2646 bytes result sent to driver
[2022-06-07 06:17:08,328] {subprocess.py:92} INFO - 22/06/07 06:17:08 INFO TaskSetManager: Starting task 119.0 in stage 0.0 (TID 119) (d952e2b2ede8, executor driver, partition 119, PROCESS_LOCAL, 4553 bytes) taskResourceAssignments Map()
[2022-06-07 06:17:08,329] {subprocess.py:92} INFO - 22/06/07 06:17:08 INFO TaskSetManager: Finished task 114.0 in stage 0.0 (TID 114) in 51 ms on d952e2b2ede8 (executor driver) (115/180)
[2022-06-07 06:17:08,330] {subprocess.py:92} INFO - 22/06/07 06:17:08 INFO Executor: Running task 119.0 in stage 0.0 (TID 119)
[2022-06-07 06:17:08,331] {subprocess.py:92} INFO - 22/06/07 06:17:08 INFO TaskSetManager: Starting task 120.0 in stage 0.0 (TID 120) (d952e2b2ede8, executor driver, partition 120, PROCESS_LOCAL, 4553 bytes) taskResourceAssignments Map()
[2022-06-07 06:17:08,332] {subprocess.py:92} INFO - 22/06/07 06:17:08 INFO TaskSetManager: Finished task 115.0 in stage 0.0 (TID 115) in 34 ms on d952e2b2ede8 (executor driver) (116/180)
[2022-06-07 06:17:08,333] {subprocess.py:92} INFO - 22/06/07 06:17:08 INFO Executor: Running task 120.0 in stage 0.0 (TID 120)
[2022-06-07 06:17:08,341] {subprocess.py:92} INFO - 22/06/07 06:17:08 INFO TaskSetManager: Finished task 118.0 in stage 0.0 (TID 118) in 23 ms on d952e2b2ede8 (executor driver) (117/180)
[2022-06-07 06:17:08,342] {subprocess.py:92} INFO - 22/06/07 06:17:08 INFO Executor: Finished task 117.0 in stage 0.0 (TID 117). 2646 bytes result sent to driver
[2022-06-07 06:17:08,343] {subprocess.py:92} INFO - 22/06/07 06:17:08 INFO TaskSetManager: Starting task 121.0 in stage 0.0 (TID 121) (d952e2b2ede8, executor driver, partition 121, PROCESS_LOCAL, 4553 bytes) taskResourceAssignments Map()
[2022-06-07 06:17:08,344] {subprocess.py:92} INFO - 22/06/07 06:17:08 INFO Executor: Running task 121.0 in stage 0.0 (TID 121)
[2022-06-07 06:17:08,346] {subprocess.py:92} INFO - 22/06/07 06:17:08 INFO TaskSetManager: Finished task 117.0 in stage 0.0 (TID 117) in 32 ms on d952e2b2ede8 (executor driver) (118/180)
[2022-06-07 06:17:08,347] {subprocess.py:92} INFO - 22/06/07 06:17:08 INFO Executor: Finished task 120.0 in stage 0.0 (TID 120). 2646 bytes result sent to driver
[2022-06-07 06:17:08,349] {subprocess.py:92} INFO - 22/06/07 06:17:08 INFO TaskSetManager: Starting task 122.0 in stage 0.0 (TID 122) (d952e2b2ede8, executor driver, partition 122, PROCESS_LOCAL, 4553 bytes) taskResourceAssignments Map()
[2022-06-07 06:17:08,350] {subprocess.py:92} INFO - 22/06/07 06:17:08 INFO TaskSetManager: Finished task 120.0 in stage 0.0 (TID 120) in 20 ms on d952e2b2ede8 (executor driver) (119/180)
[2022-06-07 06:17:08,352] {subprocess.py:92} INFO - 22/06/07 06:17:08 INFO Executor: Running task 122.0 in stage 0.0 (TID 122)
[2022-06-07 06:17:08,357] {subprocess.py:92} INFO - 22/06/07 06:17:08 INFO Executor: Finished task 119.0 in stage 0.0 (TID 119). 2646 bytes result sent to driver
[2022-06-07 06:17:08,358] {subprocess.py:92} INFO - 22/06/07 06:17:08 INFO Executor: Finished task 121.0 in stage 0.0 (TID 121). 2646 bytes result sent to driver
[2022-06-07 06:17:08,359] {subprocess.py:92} INFO - 22/06/07 06:17:08 INFO TaskSetManager: Finished task 119.0 in stage 0.0 (TID 119) in 32 ms on d952e2b2ede8 (executor driver) (120/180)
[2022-06-07 06:17:08,361] {subprocess.py:92} INFO - 22/06/07 06:17:08 INFO TaskSetManager: Starting task 123.0 in stage 0.0 (TID 123) (d952e2b2ede8, executor driver, partition 123, PROCESS_LOCAL, 4553 bytes) taskResourceAssignments Map()
[2022-06-07 06:17:08,362] {subprocess.py:92} INFO - 22/06/07 06:17:08 INFO Executor: Running task 123.0 in stage 0.0 (TID 123)
[2022-06-07 06:17:08,364] {subprocess.py:92} INFO - 22/06/07 06:17:08 INFO TaskSetManager: Starting task 124.0 in stage 0.0 (TID 124) (d952e2b2ede8, executor driver, partition 124, PROCESS_LOCAL, 4553 bytes) taskResourceAssignments Map()
[2022-06-07 06:17:08,365] {subprocess.py:92} INFO - 22/06/07 06:17:08 INFO Executor: Running task 124.0 in stage 0.0 (TID 124)
[2022-06-07 06:17:08,370] {subprocess.py:92} INFO - 22/06/07 06:17:08 INFO TaskSetManager: Finished task 121.0 in stage 0.0 (TID 121) in 26 ms on d952e2b2ede8 (executor driver) (121/180)
[2022-06-07 06:17:08,375] {subprocess.py:92} INFO - 22/06/07 06:17:08 INFO Executor: Finished task 116.0 in stage 0.0 (TID 116). 2646 bytes result sent to driver
[2022-06-07 06:17:08,376] {subprocess.py:92} INFO - 22/06/07 06:17:08 INFO TaskSetManager: Starting task 125.0 in stage 0.0 (TID 125) (d952e2b2ede8, executor driver, partition 125, PROCESS_LOCAL, 4553 bytes) taskResourceAssignments Map()
[2022-06-07 06:17:08,377] {subprocess.py:92} INFO - 22/06/07 06:17:08 INFO Executor: Running task 125.0 in stage 0.0 (TID 125)
[2022-06-07 06:17:08,379] {subprocess.py:92} INFO - 22/06/07 06:17:08 INFO TaskSetManager: Finished task 116.0 in stage 0.0 (TID 116) in 66 ms on d952e2b2ede8 (executor driver) (122/180)
[2022-06-07 06:17:08,380] {subprocess.py:92} INFO - 22/06/07 06:17:08 INFO Executor: Finished task 122.0 in stage 0.0 (TID 122). 2646 bytes result sent to driver
[2022-06-07 06:17:08,381] {subprocess.py:92} INFO - 22/06/07 06:17:08 INFO TaskSetManager: Starting task 126.0 in stage 0.0 (TID 126) (d952e2b2ede8, executor driver, partition 126, PROCESS_LOCAL, 4553 bytes) taskResourceAssignments Map()
[2022-06-07 06:17:08,382] {subprocess.py:92} INFO - 22/06/07 06:17:08 INFO TaskSetManager: Finished task 122.0 in stage 0.0 (TID 122) in 33 ms on d952e2b2ede8 (executor driver) (123/180)
[2022-06-07 06:17:08,383] {subprocess.py:92} INFO - 22/06/07 06:17:08 INFO Executor: Running task 126.0 in stage 0.0 (TID 126)
[2022-06-07 06:17:08,394] {subprocess.py:92} INFO - 22/06/07 06:17:08 INFO Executor: Finished task 125.0 in stage 0.0 (TID 125). 2646 bytes result sent to driver
[2022-06-07 06:17:08,396] {subprocess.py:92} INFO - 22/06/07 06:17:08 INFO Executor: Finished task 123.0 in stage 0.0 (TID 123). 2646 bytes result sent to driver
[2022-06-07 06:17:08,397] {subprocess.py:92} INFO - 22/06/07 06:17:08 INFO Executor: Finished task 124.0 in stage 0.0 (TID 124). 2646 bytes result sent to driver
[2022-06-07 06:17:08,399] {subprocess.py:92} INFO - 22/06/07 06:17:08 INFO TaskSetManager: Starting task 127.0 in stage 0.0 (TID 127) (d952e2b2ede8, executor driver, partition 127, PROCESS_LOCAL, 4553 bytes) taskResourceAssignments Map()
[2022-06-07 06:17:08,401] {subprocess.py:92} INFO - 22/06/07 06:17:08 INFO Executor: Running task 127.0 in stage 0.0 (TID 127)
