[2022-06-10 07:20:48,878] {taskinstance.py:1159} INFO - Dependencies all met for <TaskInstance: hands_on_test.spark_data_quality_check scheduled__2022-06-09T00:00:00+00:00 [queued]>
[2022-06-10 07:20:48,900] {taskinstance.py:1159} INFO - Dependencies all met for <TaskInstance: hands_on_test.spark_data_quality_check scheduled__2022-06-09T00:00:00+00:00 [queued]>
[2022-06-10 07:20:48,902] {taskinstance.py:1356} INFO - 
--------------------------------------------------------------------------------
[2022-06-10 07:20:48,902] {taskinstance.py:1357} INFO - Starting attempt 1 of 2
[2022-06-10 07:20:48,903] {taskinstance.py:1358} INFO - 
--------------------------------------------------------------------------------
[2022-06-10 07:20:48,925] {taskinstance.py:1377} INFO - Executing <Task(BashOperator): spark_data_quality_check> on 2022-06-09 00:00:00+00:00
[2022-06-10 07:20:48,932] {standard_task_runner.py:52} INFO - Started process 2039 to run task
[2022-06-10 07:20:48,936] {standard_task_runner.py:79} INFO - Running: ['***', 'tasks', 'run', 'hands_on_test', 'spark_data_quality_check', 'scheduled__2022-06-09T00:00:00+00:00', '--job-id', '64', '--raw', '--subdir', 'DAGS_FOLDER/dag.py', '--cfg-path', '/tmp/tmpbnder55q', '--error-file', '/tmp/tmp_yx74yda']
[2022-06-10 07:20:48,940] {standard_task_runner.py:80} INFO - Job 64: Subtask spark_data_quality_check
[2022-06-10 07:20:49,018] {task_command.py:369} INFO - Running <TaskInstance: hands_on_test.spark_data_quality_check scheduled__2022-06-09T00:00:00+00:00 [running]> on host a0fd966c00bf
[2022-06-10 07:20:49,119] {taskinstance.py:1571} INFO - Exporting the following env vars:
AIRFLOW_CTX_DAG_OWNER=***
AIRFLOW_CTX_DAG_ID=hands_on_test
AIRFLOW_CTX_TASK_ID=spark_data_quality_check
AIRFLOW_CTX_EXECUTION_DATE=2022-06-09T00:00:00+00:00
AIRFLOW_CTX_TRY_NUMBER=1
AIRFLOW_CTX_DAG_RUN_ID=scheduled__2022-06-09T00:00:00+00:00
[2022-06-10 07:20:49,121] {subprocess.py:62} INFO - Tmp dir root location: 
 /tmp
[2022-06-10 07:20:49,122] {subprocess.py:74} INFO - Running command: ['bash', '-c', 'docker exec spark-master /spark/bin/spark-submit --master local[*] --name spark_data_quality_check /home/script/dq_check.py ']
[2022-06-10 07:20:49,136] {subprocess.py:85} INFO - Output:
[2022-06-10 07:20:51,856] {subprocess.py:92} INFO - 22/06/10 07:20:51 WARN NativeCodeLoader: Unable to load native-hadoop library for your platform... using builtin-java classes where applicable
[2022-06-10 07:20:52,769] {subprocess.py:92} INFO - Using Spark's default log4j profile: org/apache/spark/log4j-defaults.properties
[2022-06-10 07:20:52,780] {subprocess.py:92} INFO - 22/06/10 07:20:52 INFO SparkContext: Running Spark version 3.1.1
[2022-06-10 07:20:52,832] {subprocess.py:92} INFO - 22/06/10 07:20:52 INFO ResourceUtils: ==============================================================
[2022-06-10 07:20:52,835] {subprocess.py:92} INFO - 22/06/10 07:20:52 INFO ResourceUtils: No custom resources configured for spark.driver.
[2022-06-10 07:20:52,836] {subprocess.py:92} INFO - 22/06/10 07:20:52 INFO ResourceUtils: ==============================================================
[2022-06-10 07:20:52,836] {subprocess.py:92} INFO - 22/06/10 07:20:52 INFO SparkContext: Submitted application: spark_data_quality_check
[2022-06-10 07:20:52,866] {subprocess.py:92} INFO - 22/06/10 07:20:52 INFO ResourceProfile: Default ResourceProfile created, executor resources: Map(cores -> name: cores, amount: 1, script: , vendor: , memory -> name: memory, amount: 1024, script: , vendor: , offHeap -> name: offHeap, amount: 0, script: , vendor: ), task resources: Map(cpus -> name: cpus, amount: 1.0)
[2022-06-10 07:20:52,884] {subprocess.py:92} INFO - 22/06/10 07:20:52 INFO ResourceProfile: Limiting resource is cpu
[2022-06-10 07:20:52,886] {subprocess.py:92} INFO - 22/06/10 07:20:52 INFO ResourceProfileManager: Added ResourceProfile id: 0
[2022-06-10 07:20:52,950] {subprocess.py:92} INFO - 22/06/10 07:20:52 INFO SecurityManager: Changing view acls to: root
[2022-06-10 07:20:52,951] {subprocess.py:92} INFO - 22/06/10 07:20:52 INFO SecurityManager: Changing modify acls to: root
[2022-06-10 07:20:52,952] {subprocess.py:92} INFO - 22/06/10 07:20:52 INFO SecurityManager: Changing view acls groups to:
[2022-06-10 07:20:52,953] {subprocess.py:92} INFO - 22/06/10 07:20:52 INFO SecurityManager: Changing modify acls groups to:
[2022-06-10 07:20:52,954] {subprocess.py:92} INFO - 22/06/10 07:20:52 INFO SecurityManager: SecurityManager: authentication disabled; ui acls disabled; users  with view permissions: Set(root); groups with view permissions: Set(); users  with modify permissions: Set(root); groups with modify permissions: Set()
[2022-06-10 07:20:53,244] {subprocess.py:92} INFO - 22/06/10 07:20:53 INFO Utils: Successfully started service 'sparkDriver' on port 36109.
[2022-06-10 07:20:53,300] {subprocess.py:92} INFO - 22/06/10 07:20:53 INFO SparkEnv: Registering MapOutputTracker
[2022-06-10 07:20:53,358] {subprocess.py:92} INFO - 22/06/10 07:20:53 INFO SparkEnv: Registering BlockManagerMaster
[2022-06-10 07:20:53,389] {subprocess.py:92} INFO - 22/06/10 07:20:53 INFO BlockManagerMasterEndpoint: Using org.apache.spark.storage.DefaultTopologyMapper for getting topology information
[2022-06-10 07:20:53,391] {subprocess.py:92} INFO - 22/06/10 07:20:53 INFO BlockManagerMasterEndpoint: BlockManagerMasterEndpoint up
[2022-06-10 07:20:53,401] {subprocess.py:92} INFO - 22/06/10 07:20:53 INFO SparkEnv: Registering BlockManagerMasterHeartbeat
[2022-06-10 07:20:53,421] {subprocess.py:92} INFO - 22/06/10 07:20:53 INFO DiskBlockManager: Created local directory at /tmp/blockmgr-009bb909-aa76-45c5-87fd-88bdd171dc9b
[2022-06-10 07:20:53,455] {subprocess.py:92} INFO - 22/06/10 07:20:53 INFO MemoryStore: MemoryStore started with capacity 366.3 MiB
[2022-06-10 07:20:53,481] {subprocess.py:92} INFO - 22/06/10 07:20:53 INFO SparkEnv: Registering OutputCommitCoordinator
[2022-06-10 07:20:53,841] {subprocess.py:92} INFO - 22/06/10 07:20:53 INFO Utils: Successfully started service 'SparkUI' on port 4040.
[2022-06-10 07:20:53,934] {subprocess.py:92} INFO - 22/06/10 07:20:53 INFO SparkUI: Bound SparkUI to 0.0.0.0, and started at http://d163094fab5f:4040
[2022-06-10 07:20:54,226] {subprocess.py:92} INFO - 22/06/10 07:20:54 INFO Executor: Starting executor ID driver on host d163094fab5f
[2022-06-10 07:20:54,289] {subprocess.py:92} INFO - 22/06/10 07:20:54 INFO Utils: Successfully started service 'org.apache.spark.network.netty.NettyBlockTransferService' on port 34565.
[2022-06-10 07:20:54,290] {subprocess.py:92} INFO - 22/06/10 07:20:54 INFO NettyBlockTransferService: Server created on d163094fab5f:34565
[2022-06-10 07:20:54,293] {subprocess.py:92} INFO - 22/06/10 07:20:54 INFO BlockManager: Using org.apache.spark.storage.RandomBlockReplicationPolicy for block replication policy
[2022-06-10 07:20:54,308] {subprocess.py:92} INFO - 22/06/10 07:20:54 INFO BlockManagerMaster: Registering BlockManager BlockManagerId(driver, d163094fab5f, 34565, None)
[2022-06-10 07:20:54,313] {subprocess.py:92} INFO - 22/06/10 07:20:54 INFO BlockManagerMasterEndpoint: Registering block manager d163094fab5f:34565 with 366.3 MiB RAM, BlockManagerId(driver, d163094fab5f, 34565, None)
[2022-06-10 07:20:54,316] {subprocess.py:92} INFO - 22/06/10 07:20:54 INFO BlockManagerMaster: Registered BlockManager BlockManagerId(driver, d163094fab5f, 34565, None)
[2022-06-10 07:20:54,318] {subprocess.py:92} INFO - 22/06/10 07:20:54 INFO BlockManager: Initialized BlockManager: BlockManagerId(driver, d163094fab5f, 34565, None)
[2022-06-10 07:20:54,933] {subprocess.py:92} INFO - 22/06/10 07:20:54 INFO SharedState: Setting hive.metastore.warehouse.dir ('null') to the value of spark.sql.warehouse.dir ('file:/spark-warehouse').
[2022-06-10 07:20:54,934] {subprocess.py:92} INFO - 22/06/10 07:20:54 INFO SharedState: Warehouse path is 'file:/spark-warehouse'.
[2022-06-10 07:20:56,791] {subprocess.py:92} INFO - 22/06/10 07:20:56 INFO HadoopFSUtils: Listing leaf files and directories in parallel under 180 paths. The first several paths are: hdfs://hive-namenode:8020/user/spark/transformed_order_detail/dt=20190101, hdfs://hive-namenode:8020/user/spark/transformed_order_detail/dt=20190102, hdfs://hive-namenode:8020/user/spark/transformed_order_detail/dt=20190103, hdfs://hive-namenode:8020/user/spark/transformed_order_detail/dt=20190104, hdfs://hive-namenode:8020/user/spark/transformed_order_detail/dt=20190105, hdfs://hive-namenode:8020/user/spark/transformed_order_detail/dt=20190106, hdfs://hive-namenode:8020/user/spark/transformed_order_detail/dt=20190107, hdfs://hive-namenode:8020/user/spark/transformed_order_detail/dt=20190108, hdfs://hive-namenode:8020/user/spark/transformed_order_detail/dt=20190109, hdfs://hive-namenode:8020/user/spark/transformed_order_detail/dt=20190110.
[2022-06-10 07:20:57,418] {subprocess.py:92} INFO - 22/06/10 07:20:57 INFO SparkContext: Starting job: parquet at NativeMethodAccessorImpl.java:0
[2022-06-10 07:20:57,458] {subprocess.py:92} INFO - 22/06/10 07:20:57 INFO DAGScheduler: Got job 0 (parquet at NativeMethodAccessorImpl.java:0) with 180 output partitions
[2022-06-10 07:20:57,459] {subprocess.py:92} INFO - 22/06/10 07:20:57 INFO DAGScheduler: Final stage: ResultStage 0 (parquet at NativeMethodAccessorImpl.java:0)
[2022-06-10 07:20:57,460] {subprocess.py:92} INFO - 22/06/10 07:20:57 INFO DAGScheduler: Parents of final stage: List()
[2022-06-10 07:20:57,464] {subprocess.py:92} INFO - 22/06/10 07:20:57 INFO DAGScheduler: Missing parents: List()
[2022-06-10 07:20:57,476] {subprocess.py:92} INFO - 22/06/10 07:20:57 INFO DAGScheduler: Submitting ResultStage 0 (MapPartitionsRDD[2] at parquet at NativeMethodAccessorImpl.java:0), which has no missing parents
[2022-06-10 07:20:57,609] {subprocess.py:92} INFO - 22/06/10 07:20:57 INFO MemoryStore: Block broadcast_0 stored as values in memory (estimated size 83.6 KiB, free 366.2 MiB)
[2022-06-10 07:20:57,653] {subprocess.py:92} INFO - 22/06/10 07:20:57 INFO MemoryStore: Block broadcast_0_piece0 stored as bytes in memory (estimated size 29.5 KiB, free 366.2 MiB)
[2022-06-10 07:20:57,657] {subprocess.py:92} INFO - 22/06/10 07:20:57 INFO BlockManagerInfo: Added broadcast_0_piece0 in memory on d163094fab5f:34565 (size: 29.5 KiB, free: 366.3 MiB)
[2022-06-10 07:20:57,666] {subprocess.py:92} INFO - 22/06/10 07:20:57 INFO SparkContext: Created broadcast 0 from broadcast at DAGScheduler.scala:1383
[2022-06-10 07:20:57,692] {subprocess.py:92} INFO - 22/06/10 07:20:57 INFO DAGScheduler: Submitting 180 missing tasks from ResultStage 0 (MapPartitionsRDD[2] at parquet at NativeMethodAccessorImpl.java:0) (first 15 tasks are for partitions Vector(0, 1, 2, 3, 4, 5, 6, 7, 8, 9, 10, 11, 12, 13, 14))
[2022-06-10 07:20:57,695] {subprocess.py:92} INFO - 22/06/10 07:20:57 INFO TaskSchedulerImpl: Adding task set 0.0 with 180 tasks resource profile 0
[2022-06-10 07:20:57,813] {subprocess.py:92} INFO - 22/06/10 07:20:57 INFO TaskSetManager: Starting task 0.0 in stage 0.0 (TID 0) (d163094fab5f, executor driver, partition 0, PROCESS_LOCAL, 4553 bytes) taskResourceAssignments Map()
[2022-06-10 07:20:57,823] {subprocess.py:92} INFO - 22/06/10 07:20:57 INFO TaskSetManager: Starting task 1.0 in stage 0.0 (TID 1) (d163094fab5f, executor driver, partition 1, PROCESS_LOCAL, 4553 bytes) taskResourceAssignments Map()
[2022-06-10 07:20:57,824] {subprocess.py:92} INFO - 22/06/10 07:20:57 INFO TaskSetManager: Starting task 2.0 in stage 0.0 (TID 2) (d163094fab5f, executor driver, partition 2, PROCESS_LOCAL, 4553 bytes) taskResourceAssignments Map()
[2022-06-10 07:20:57,826] {subprocess.py:92} INFO - 22/06/10 07:20:57 INFO TaskSetManager: Starting task 3.0 in stage 0.0 (TID 3) (d163094fab5f, executor driver, partition 3, PROCESS_LOCAL, 4553 bytes) taskResourceAssignments Map()
[2022-06-10 07:20:57,863] {subprocess.py:92} INFO - 22/06/10 07:20:57 INFO Executor: Running task 3.0 in stage 0.0 (TID 3)
[2022-06-10 07:20:57,864] {subprocess.py:92} INFO - 22/06/10 07:20:57 INFO Executor: Running task 2.0 in stage 0.0 (TID 2)
[2022-06-10 07:20:57,865] {subprocess.py:92} INFO - 22/06/10 07:20:57 INFO Executor: Running task 0.0 in stage 0.0 (TID 0)
[2022-06-10 07:20:57,865] {subprocess.py:92} INFO - 22/06/10 07:20:57 INFO Executor: Running task 1.0 in stage 0.0 (TID 1)
[2022-06-10 07:20:58,564] {subprocess.py:92} INFO - 22/06/10 07:20:58 INFO Executor: Finished task 3.0 in stage 0.0 (TID 3). 2732 bytes result sent to driver
[2022-06-10 07:20:58,566] {subprocess.py:92} INFO - 22/06/10 07:20:58 INFO Executor: Finished task 2.0 in stage 0.0 (TID 2). 2732 bytes result sent to driver
[2022-06-10 07:20:58,567] {subprocess.py:92} INFO - 22/06/10 07:20:58 INFO Executor: Finished task 1.0 in stage 0.0 (TID 1). 2732 bytes result sent to driver
[2022-06-10 07:20:58,569] {subprocess.py:92} INFO - 22/06/10 07:20:58 INFO Executor: Finished task 0.0 in stage 0.0 (TID 0). 2732 bytes result sent to driver
[2022-06-10 07:20:58,577] {subprocess.py:92} INFO - 22/06/10 07:20:58 INFO TaskSetManager: Starting task 4.0 in stage 0.0 (TID 4) (d163094fab5f, executor driver, partition 4, PROCESS_LOCAL, 4553 bytes) taskResourceAssignments Map()
[2022-06-10 07:20:58,579] {subprocess.py:92} INFO - 22/06/10 07:20:58 INFO Executor: Running task 4.0 in stage 0.0 (TID 4)
[2022-06-10 07:20:58,591] {subprocess.py:92} INFO - 22/06/10 07:20:58 INFO TaskSetManager: Starting task 5.0 in stage 0.0 (TID 5) (d163094fab5f, executor driver, partition 5, PROCESS_LOCAL, 4553 bytes) taskResourceAssignments Map()
[2022-06-10 07:20:58,592] {subprocess.py:92} INFO - 22/06/10 07:20:58 INFO Executor: Running task 5.0 in stage 0.0 (TID 5)
[2022-06-10 07:20:58,599] {subprocess.py:92} INFO - 22/06/10 07:20:58 INFO TaskSetManager: Starting task 6.0 in stage 0.0 (TID 6) (d163094fab5f, executor driver, partition 6, PROCESS_LOCAL, 4553 bytes) taskResourceAssignments Map()
[2022-06-10 07:20:58,600] {subprocess.py:92} INFO - 22/06/10 07:20:58 INFO Executor: Running task 6.0 in stage 0.0 (TID 6)
[2022-06-10 07:20:58,609] {subprocess.py:92} INFO - 22/06/10 07:20:58 INFO Executor: Finished task 4.0 in stage 0.0 (TID 4). 2646 bytes result sent to driver
[2022-06-10 07:20:58,614] {subprocess.py:92} INFO - 22/06/10 07:20:58 INFO Executor: Finished task 5.0 in stage 0.0 (TID 5). 2646 bytes result sent to driver
[2022-06-10 07:20:58,617] {subprocess.py:92} INFO - 22/06/10 07:20:58 INFO TaskSetManager: Starting task 7.0 in stage 0.0 (TID 7) (d163094fab5f, executor driver, partition 7, PROCESS_LOCAL, 4553 bytes) taskResourceAssignments Map()
[2022-06-10 07:20:58,619] {subprocess.py:92} INFO - 22/06/10 07:20:58 INFO Executor: Running task 7.0 in stage 0.0 (TID 7)
[2022-06-10 07:20:58,622] {subprocess.py:92} INFO - 22/06/10 07:20:58 INFO TaskSetManager: Starting task 8.0 in stage 0.0 (TID 8) (d163094fab5f, executor driver, partition 8, PROCESS_LOCAL, 4553 bytes) taskResourceAssignments Map()
[2022-06-10 07:20:58,624] {subprocess.py:92} INFO - 22/06/10 07:20:58 INFO Executor: Running task 8.0 in stage 0.0 (TID 8)
[2022-06-10 07:20:58,625] {subprocess.py:92} INFO - 22/06/10 07:20:58 INFO TaskSetManager: Starting task 9.0 in stage 0.0 (TID 9) (d163094fab5f, executor driver, partition 9, PROCESS_LOCAL, 4553 bytes) taskResourceAssignments Map()
[2022-06-10 07:20:58,628] {subprocess.py:92} INFO - 22/06/10 07:20:58 INFO TaskSetManager: Finished task 2.0 in stage 0.0 (TID 2) in 803 ms on d163094fab5f (executor driver) (1/180)
[2022-06-10 07:20:58,633] {subprocess.py:92} INFO - 22/06/10 07:20:58 INFO Executor: Running task 9.0 in stage 0.0 (TID 9)
[2022-06-10 07:20:58,658] {subprocess.py:92} INFO - 22/06/10 07:20:58 INFO Executor: Finished task 6.0 in stage 0.0 (TID 6). 2646 bytes result sent to driver
[2022-06-10 07:20:58,661] {subprocess.py:92} INFO - 22/06/10 07:20:58 INFO TaskSetManager: Finished task 4.0 in stage 0.0 (TID 4) in 89 ms on d163094fab5f (executor driver) (2/180)
[2022-06-10 07:20:58,663] {subprocess.py:92} INFO - 22/06/10 07:20:58 INFO TaskSetManager: Finished task 0.0 in stage 0.0 (TID 0) in 897 ms on d163094fab5f (executor driver) (3/180)
[2022-06-10 07:20:58,665] {subprocess.py:92} INFO - 22/06/10 07:20:58 INFO TaskSetManager: Starting task 10.0 in stage 0.0 (TID 10) (d163094fab5f, executor driver, partition 10, PROCESS_LOCAL, 4553 bytes) taskResourceAssignments Map()
[2022-06-10 07:20:58,667] {subprocess.py:92} INFO - 22/06/10 07:20:58 INFO TaskSetManager: Finished task 6.0 in stage 0.0 (TID 6) in 68 ms on d163094fab5f (executor driver) (4/180)
[2022-06-10 07:20:58,671] {subprocess.py:92} INFO - 22/06/10 07:20:58 INFO TaskSetManager: Finished task 1.0 in stage 0.0 (TID 1) in 847 ms on d163094fab5f (executor driver) (5/180)
[2022-06-10 07:20:58,673] {subprocess.py:92} INFO - 22/06/10 07:20:58 INFO TaskSetManager: Finished task 5.0 in stage 0.0 (TID 5) in 80 ms on d163094fab5f (executor driver) (6/180)
[2022-06-10 07:20:58,674] {subprocess.py:92} INFO - 22/06/10 07:20:58 INFO TaskSetManager: Finished task 3.0 in stage 0.0 (TID 3) in 846 ms on d163094fab5f (executor driver) (7/180)
[2022-06-10 07:20:58,679] {subprocess.py:92} INFO - 22/06/10 07:20:58 INFO Executor: Running task 10.0 in stage 0.0 (TID 10)
[2022-06-10 07:20:58,697] {subprocess.py:92} INFO - 22/06/10 07:20:58 INFO Executor: Finished task 9.0 in stage 0.0 (TID 9). 2646 bytes result sent to driver
[2022-06-10 07:20:58,703] {subprocess.py:92} INFO - 22/06/10 07:20:58 INFO Executor: Finished task 8.0 in stage 0.0 (TID 8). 2646 bytes result sent to driver
[2022-06-10 07:20:58,703] {subprocess.py:92} INFO - 22/06/10 07:20:58 INFO Executor: Finished task 7.0 in stage 0.0 (TID 7). 2646 bytes result sent to driver
[2022-06-10 07:20:58,704] {subprocess.py:92} INFO - 22/06/10 07:20:58 INFO TaskSetManager: Starting task 11.0 in stage 0.0 (TID 11) (d163094fab5f, executor driver, partition 11, PROCESS_LOCAL, 4553 bytes) taskResourceAssignments Map()
[2022-06-10 07:20:58,705] {subprocess.py:92} INFO - 22/06/10 07:20:58 INFO TaskSetManager: Finished task 9.0 in stage 0.0 (TID 9) in 84 ms on d163094fab5f (executor driver) (8/180)
[2022-06-10 07:20:58,706] {subprocess.py:92} INFO - 22/06/10 07:20:58 INFO Executor: Running task 11.0 in stage 0.0 (TID 11)
[2022-06-10 07:20:58,708] {subprocess.py:92} INFO - 22/06/10 07:20:58 INFO TaskSetManager: Starting task 12.0 in stage 0.0 (TID 12) (d163094fab5f, executor driver, partition 12, PROCESS_LOCAL, 4553 bytes) taskResourceAssignments Map()
[2022-06-10 07:20:58,709] {subprocess.py:92} INFO - 22/06/10 07:20:58 INFO Executor: Running task 12.0 in stage 0.0 (TID 12)
[2022-06-10 07:20:58,710] {subprocess.py:92} INFO - 22/06/10 07:20:58 INFO TaskSetManager: Starting task 13.0 in stage 0.0 (TID 13) (d163094fab5f, executor driver, partition 13, PROCESS_LOCAL, 4553 bytes) taskResourceAssignments Map()
[2022-06-10 07:20:58,711] {subprocess.py:92} INFO - 22/06/10 07:20:58 INFO TaskSetManager: Finished task 7.0 in stage 0.0 (TID 7) in 94 ms on d163094fab5f (executor driver) (9/180)
[2022-06-10 07:20:58,713] {subprocess.py:92} INFO - 22/06/10 07:20:58 INFO Executor: Running task 13.0 in stage 0.0 (TID 13)
[2022-06-10 07:20:58,714] {subprocess.py:92} INFO - 22/06/10 07:20:58 INFO TaskSetManager: Finished task 8.0 in stage 0.0 (TID 8) in 93 ms on d163094fab5f (executor driver) (10/180)
[2022-06-10 07:20:58,718] {subprocess.py:92} INFO - 22/06/10 07:20:58 INFO Executor: Finished task 10.0 in stage 0.0 (TID 10). 2646 bytes result sent to driver
[2022-06-10 07:20:58,721] {subprocess.py:92} INFO - 22/06/10 07:20:58 INFO TaskSetManager: Starting task 14.0 in stage 0.0 (TID 14) (d163094fab5f, executor driver, partition 14, PROCESS_LOCAL, 4553 bytes) taskResourceAssignments Map()
[2022-06-10 07:20:58,723] {subprocess.py:92} INFO - 22/06/10 07:20:58 INFO TaskSetManager: Finished task 10.0 in stage 0.0 (TID 10) in 58 ms on d163094fab5f (executor driver) (11/180)
[2022-06-10 07:20:58,724] {subprocess.py:92} INFO - 22/06/10 07:20:58 INFO Executor: Running task 14.0 in stage 0.0 (TID 14)
[2022-06-10 07:20:58,748] {subprocess.py:92} INFO - 22/06/10 07:20:58 INFO Executor: Finished task 14.0 in stage 0.0 (TID 14). 2646 bytes result sent to driver
[2022-06-10 07:20:58,750] {subprocess.py:92} INFO - 22/06/10 07:20:58 INFO Executor: Finished task 11.0 in stage 0.0 (TID 11). 2646 bytes result sent to driver
[2022-06-10 07:20:58,751] {subprocess.py:92} INFO - 22/06/10 07:20:58 INFO Executor: Finished task 12.0 in stage 0.0 (TID 12). 2646 bytes result sent to driver
[2022-06-10 07:20:58,751] {subprocess.py:92} INFO - 22/06/10 07:20:58 INFO Executor: Finished task 13.0 in stage 0.0 (TID 13). 2646 bytes result sent to driver
[2022-06-10 07:20:58,754] {subprocess.py:92} INFO - 22/06/10 07:20:58 INFO TaskSetManager: Starting task 15.0 in stage 0.0 (TID 15) (d163094fab5f, executor driver, partition 15, PROCESS_LOCAL, 4553 bytes) taskResourceAssignments Map()
[2022-06-10 07:20:58,755] {subprocess.py:92} INFO - 22/06/10 07:20:58 INFO TaskSetManager: Finished task 14.0 in stage 0.0 (TID 14) in 36 ms on d163094fab5f (executor driver) (12/180)
[2022-06-10 07:20:58,756] {subprocess.py:92} INFO - 22/06/10 07:20:58 INFO Executor: Running task 15.0 in stage 0.0 (TID 15)
[2022-06-10 07:20:58,758] {subprocess.py:92} INFO - 22/06/10 07:20:58 INFO TaskSetManager: Starting task 16.0 in stage 0.0 (TID 16) (d163094fab5f, executor driver, partition 16, PROCESS_LOCAL, 4553 bytes) taskResourceAssignments Map()
[2022-06-10 07:20:58,760] {subprocess.py:92} INFO - 22/06/10 07:20:58 INFO Executor: Running task 16.0 in stage 0.0 (TID 16)
[2022-06-10 07:20:58,761] {subprocess.py:92} INFO - 22/06/10 07:20:58 INFO TaskSetManager: Starting task 17.0 in stage 0.0 (TID 17) (d163094fab5f, executor driver, partition 17, PROCESS_LOCAL, 4553 bytes) taskResourceAssignments Map()
[2022-06-10 07:20:58,762] {subprocess.py:92} INFO - 22/06/10 07:20:58 INFO Executor: Running task 17.0 in stage 0.0 (TID 17)
[2022-06-10 07:20:58,765] {subprocess.py:92} INFO - 22/06/10 07:20:58 INFO TaskSetManager: Starting task 18.0 in stage 0.0 (TID 18) (d163094fab5f, executor driver, partition 18, PROCESS_LOCAL, 4553 bytes) taskResourceAssignments Map()
[2022-06-10 07:20:58,766] {subprocess.py:92} INFO - 22/06/10 07:20:58 INFO TaskSetManager: Finished task 12.0 in stage 0.0 (TID 12) in 58 ms on d163094fab5f (executor driver) (13/180)
[2022-06-10 07:20:58,767] {subprocess.py:92} INFO - 22/06/10 07:20:58 INFO Executor: Running task 18.0 in stage 0.0 (TID 18)
[2022-06-10 07:20:58,768] {subprocess.py:92} INFO - 22/06/10 07:20:58 INFO TaskSetManager: Finished task 13.0 in stage 0.0 (TID 13) in 57 ms on d163094fab5f (executor driver) (14/180)
[2022-06-10 07:20:58,769] {subprocess.py:92} INFO - 22/06/10 07:20:58 INFO TaskSetManager: Finished task 11.0 in stage 0.0 (TID 11) in 66 ms on d163094fab5f (executor driver) (15/180)
[2022-06-10 07:20:58,799] {subprocess.py:92} INFO - 22/06/10 07:20:58 INFO Executor: Finished task 16.0 in stage 0.0 (TID 16). 2646 bytes result sent to driver
[2022-06-10 07:20:58,800] {subprocess.py:92} INFO - 22/06/10 07:20:58 INFO Executor: Finished task 17.0 in stage 0.0 (TID 17). 2646 bytes result sent to driver
[2022-06-10 07:20:58,803] {subprocess.py:92} INFO - 22/06/10 07:20:58 INFO Executor: Finished task 15.0 in stage 0.0 (TID 15). 2646 bytes result sent to driver
[2022-06-10 07:20:58,805] {subprocess.py:92} INFO - 22/06/10 07:20:58 INFO TaskSetManager: Starting task 19.0 in stage 0.0 (TID 19) (d163094fab5f, executor driver, partition 19, PROCESS_LOCAL, 4553 bytes) taskResourceAssignments Map()
[2022-06-10 07:20:58,807] {subprocess.py:92} INFO - 22/06/10 07:20:58 INFO Executor: Running task 19.0 in stage 0.0 (TID 19)
[2022-06-10 07:20:58,808] {subprocess.py:92} INFO - 22/06/10 07:20:58 INFO TaskSetManager: Finished task 16.0 in stage 0.0 (TID 16) in 50 ms on d163094fab5f (executor driver) (16/180)
[2022-06-10 07:20:58,812] {subprocess.py:92} INFO - 22/06/10 07:20:58 INFO Executor: Finished task 18.0 in stage 0.0 (TID 18). 2646 bytes result sent to driver
[2022-06-10 07:20:58,815] {subprocess.py:92} INFO - 22/06/10 07:20:58 INFO TaskSetManager: Starting task 20.0 in stage 0.0 (TID 20) (d163094fab5f, executor driver, partition 20, PROCESS_LOCAL, 4553 bytes) taskResourceAssignments Map()
[2022-06-10 07:20:58,817] {subprocess.py:92} INFO - 22/06/10 07:20:58 INFO TaskSetManager: Finished task 18.0 in stage 0.0 (TID 18) in 52 ms on d163094fab5f (executor driver) (17/180)
[2022-06-10 07:20:58,828] {subprocess.py:92} INFO - 22/06/10 07:20:58 INFO TaskSetManager: Starting task 21.0 in stage 0.0 (TID 21) (d163094fab5f, executor driver, partition 21, PROCESS_LOCAL, 4553 bytes) taskResourceAssignments Map()
[2022-06-10 07:20:58,831] {subprocess.py:92} INFO - 22/06/10 07:20:58 INFO Executor: Running task 20.0 in stage 0.0 (TID 20)
[2022-06-10 07:20:58,832] {subprocess.py:92} INFO - 22/06/10 07:20:58 INFO TaskSetManager: Finished task 15.0 in stage 0.0 (TID 15) in 80 ms on d163094fab5f (executor driver) (18/180)
[2022-06-10 07:20:58,835] {subprocess.py:92} INFO - 22/06/10 07:20:58 INFO Executor: Running task 21.0 in stage 0.0 (TID 21)
[2022-06-10 07:20:58,836] {subprocess.py:92} INFO - 22/06/10 07:20:58 INFO TaskSetManager: Starting task 22.0 in stage 0.0 (TID 22) (d163094fab5f, executor driver, partition 22, PROCESS_LOCAL, 4553 bytes) taskResourceAssignments Map()
[2022-06-10 07:20:58,837] {subprocess.py:92} INFO - 22/06/10 07:20:58 INFO Executor: Finished task 19.0 in stage 0.0 (TID 19). 2646 bytes result sent to driver
[2022-06-10 07:20:58,838] {subprocess.py:92} INFO - 22/06/10 07:20:58 INFO TaskSetManager: Finished task 17.0 in stage 0.0 (TID 17) in 76 ms on d163094fab5f (executor driver) (19/180)
[2022-06-10 07:20:58,839] {subprocess.py:92} INFO - 22/06/10 07:20:58 INFO Executor: Running task 22.0 in stage 0.0 (TID 22)
[2022-06-10 07:20:58,841] {subprocess.py:92} INFO - 22/06/10 07:20:58 INFO TaskSetManager: Starting task 23.0 in stage 0.0 (TID 23) (d163094fab5f, executor driver, partition 23, PROCESS_LOCAL, 4553 bytes) taskResourceAssignments Map()
[2022-06-10 07:20:58,843] {subprocess.py:92} INFO - 22/06/10 07:20:58 INFO TaskSetManager: Finished task 19.0 in stage 0.0 (TID 19) in 38 ms on d163094fab5f (executor driver) (20/180)
[2022-06-10 07:20:58,844] {subprocess.py:92} INFO - 22/06/10 07:20:58 INFO Executor: Running task 23.0 in stage 0.0 (TID 23)
[2022-06-10 07:20:58,853] {subprocess.py:92} INFO - 22/06/10 07:20:58 INFO Executor: Finished task 21.0 in stage 0.0 (TID 21). 2646 bytes result sent to driver
[2022-06-10 07:20:58,854] {subprocess.py:92} INFO - 22/06/10 07:20:58 INFO TaskSetManager: Starting task 24.0 in stage 0.0 (TID 24) (d163094fab5f, executor driver, partition 24, PROCESS_LOCAL, 4553 bytes) taskResourceAssignments Map()
[2022-06-10 07:20:58,856] {subprocess.py:92} INFO - 22/06/10 07:20:58 INFO TaskSetManager: Finished task 21.0 in stage 0.0 (TID 21) in 28 ms on d163094fab5f (executor driver) (21/180)
[2022-06-10 07:20:58,856] {subprocess.py:92} INFO - 22/06/10 07:20:58 INFO Executor: Running task 24.0 in stage 0.0 (TID 24)
[2022-06-10 07:20:58,882] {subprocess.py:92} INFO - 22/06/10 07:20:58 INFO Executor: Finished task 24.0 in stage 0.0 (TID 24). 2689 bytes result sent to driver
[2022-06-10 07:20:58,884] {subprocess.py:92} INFO - 22/06/10 07:20:58 INFO Executor: Finished task 23.0 in stage 0.0 (TID 23). 2646 bytes result sent to driver
[2022-06-10 07:20:58,885] {subprocess.py:92} INFO - 22/06/10 07:20:58 INFO TaskSetManager: Finished task 24.0 in stage 0.0 (TID 24) in 29 ms on d163094fab5f (executor driver) (22/180)
[2022-06-10 07:20:58,887] {subprocess.py:92} INFO - 22/06/10 07:20:58 INFO TaskSetManager: Starting task 25.0 in stage 0.0 (TID 25) (d163094fab5f, executor driver, partition 25, PROCESS_LOCAL, 4553 bytes) taskResourceAssignments Map()
[2022-06-10 07:20:58,889] {subprocess.py:92} INFO - 22/06/10 07:20:58 INFO Executor: Running task 25.0 in stage 0.0 (TID 25)
[2022-06-10 07:20:58,891] {subprocess.py:92} INFO - 22/06/10 07:20:58 INFO TaskSetManager: Starting task 26.0 in stage 0.0 (TID 26) (d163094fab5f, executor driver, partition 26, PROCESS_LOCAL, 4553 bytes) taskResourceAssignments Map()
[2022-06-10 07:20:58,892] {subprocess.py:92} INFO - 22/06/10 07:20:58 INFO TaskSetManager: Finished task 23.0 in stage 0.0 (TID 23) in 52 ms on d163094fab5f (executor driver) (23/180)
[2022-06-10 07:20:58,893] {subprocess.py:92} INFO - 22/06/10 07:20:58 INFO Executor: Running task 26.0 in stage 0.0 (TID 26)
[2022-06-10 07:20:58,895] {subprocess.py:92} INFO - 22/06/10 07:20:58 INFO Executor: Finished task 20.0 in stage 0.0 (TID 20). 2646 bytes result sent to driver
[2022-06-10 07:20:58,897] {subprocess.py:92} INFO - 22/06/10 07:20:58 INFO TaskSetManager: Starting task 27.0 in stage 0.0 (TID 27) (d163094fab5f, executor driver, partition 27, PROCESS_LOCAL, 4553 bytes) taskResourceAssignments Map()
[2022-06-10 07:20:58,899] {subprocess.py:92} INFO - 22/06/10 07:20:58 INFO TaskSetManager: Finished task 20.0 in stage 0.0 (TID 20) in 84 ms on d163094fab5f (executor driver) (24/180)
[2022-06-10 07:20:58,904] {subprocess.py:92} INFO - 22/06/10 07:20:58 INFO Executor: Running task 27.0 in stage 0.0 (TID 27)
[2022-06-10 07:20:58,907] {subprocess.py:92} INFO - 22/06/10 07:20:58 INFO Executor: Finished task 22.0 in stage 0.0 (TID 22). 2646 bytes result sent to driver
[2022-06-10 07:20:58,910] {subprocess.py:92} INFO - 22/06/10 07:20:58 INFO TaskSetManager: Starting task 28.0 in stage 0.0 (TID 28) (d163094fab5f, executor driver, partition 28, PROCESS_LOCAL, 4553 bytes) taskResourceAssignments Map()
[2022-06-10 07:20:58,913] {subprocess.py:92} INFO - 22/06/10 07:20:58 INFO Executor: Finished task 25.0 in stage 0.0 (TID 25). 2646 bytes result sent to driver
[2022-06-10 07:20:58,914] {subprocess.py:92} INFO - 22/06/10 07:20:58 INFO TaskSetManager: Finished task 22.0 in stage 0.0 (TID 22) in 79 ms on d163094fab5f (executor driver) (25/180)
[2022-06-10 07:20:58,914] {subprocess.py:92} INFO - 22/06/10 07:20:58 INFO Executor: Running task 28.0 in stage 0.0 (TID 28)
[2022-06-10 07:20:58,915] {subprocess.py:92} INFO - 22/06/10 07:20:58 INFO TaskSetManager: Starting task 29.0 in stage 0.0 (TID 29) (d163094fab5f, executor driver, partition 29, PROCESS_LOCAL, 4553 bytes) taskResourceAssignments Map()
[2022-06-10 07:20:58,916] {subprocess.py:92} INFO - 22/06/10 07:20:58 INFO Executor: Running task 29.0 in stage 0.0 (TID 29)
[2022-06-10 07:20:58,919] {subprocess.py:92} INFO - 22/06/10 07:20:58 INFO TaskSetManager: Finished task 25.0 in stage 0.0 (TID 25) in 30 ms on d163094fab5f (executor driver) (26/180)
[2022-06-10 07:20:58,934] {subprocess.py:92} INFO - 22/06/10 07:20:58 INFO Executor: Finished task 26.0 in stage 0.0 (TID 26). 2646 bytes result sent to driver
[2022-06-10 07:20:58,936] {subprocess.py:92} INFO - 22/06/10 07:20:58 INFO TaskSetManager: Starting task 30.0 in stage 0.0 (TID 30) (d163094fab5f, executor driver, partition 30, PROCESS_LOCAL, 4553 bytes) taskResourceAssignments Map()
[2022-06-10 07:20:58,937] {subprocess.py:92} INFO - 22/06/10 07:20:58 INFO Executor: Finished task 27.0 in stage 0.0 (TID 27). 2646 bytes result sent to driver
[2022-06-10 07:20:58,939] {subprocess.py:92} INFO - 22/06/10 07:20:58 INFO Executor: Running task 30.0 in stage 0.0 (TID 30)
[2022-06-10 07:20:58,940] {subprocess.py:92} INFO - 22/06/10 07:20:58 INFO TaskSetManager: Finished task 26.0 in stage 0.0 (TID 26) in 49 ms on d163094fab5f (executor driver) (27/180)
[2022-06-10 07:20:58,942] {subprocess.py:92} INFO - 22/06/10 07:20:58 INFO Executor: Finished task 29.0 in stage 0.0 (TID 29). 2646 bytes result sent to driver
[2022-06-10 07:20:58,944] {subprocess.py:92} INFO - 22/06/10 07:20:58 INFO TaskSetManager: Starting task 31.0 in stage 0.0 (TID 31) (d163094fab5f, executor driver, partition 31, PROCESS_LOCAL, 4553 bytes) taskResourceAssignments Map()
[2022-06-10 07:20:58,945] {subprocess.py:92} INFO - 22/06/10 07:20:58 INFO Executor: Running task 31.0 in stage 0.0 (TID 31)
[2022-06-10 07:20:58,946] {subprocess.py:92} INFO - 22/06/10 07:20:58 INFO TaskSetManager: Finished task 29.0 in stage 0.0 (TID 29) in 32 ms on d163094fab5f (executor driver) (28/180)
[2022-06-10 07:20:58,950] {subprocess.py:92} INFO - 22/06/10 07:20:58 INFO TaskSetManager: Starting task 32.0 in stage 0.0 (TID 32) (d163094fab5f, executor driver, partition 32, PROCESS_LOCAL, 4553 bytes) taskResourceAssignments Map()
[2022-06-10 07:20:58,952] {subprocess.py:92} INFO - 22/06/10 07:20:58 INFO Executor: Running task 32.0 in stage 0.0 (TID 32)
[2022-06-10 07:20:58,953] {subprocess.py:92} INFO - 22/06/10 07:20:58 INFO TaskSetManager: Finished task 27.0 in stage 0.0 (TID 27) in 55 ms on d163094fab5f (executor driver) (29/180)
[2022-06-10 07:20:58,967] {subprocess.py:92} INFO - 22/06/10 07:20:58 INFO Executor: Finished task 30.0 in stage 0.0 (TID 30). 2646 bytes result sent to driver
[2022-06-10 07:20:58,970] {subprocess.py:92} INFO - 22/06/10 07:20:58 INFO Executor: Finished task 28.0 in stage 0.0 (TID 28). 2646 bytes result sent to driver
[2022-06-10 07:20:58,971] {subprocess.py:92} INFO - 22/06/10 07:20:58 INFO TaskSetManager: Starting task 33.0 in stage 0.0 (TID 33) (d163094fab5f, executor driver, partition 33, PROCESS_LOCAL, 4553 bytes) taskResourceAssignments Map()
[2022-06-10 07:20:58,973] {subprocess.py:92} INFO - 22/06/10 07:20:58 INFO Executor: Running task 33.0 in stage 0.0 (TID 33)
[2022-06-10 07:20:58,974] {subprocess.py:92} INFO - 22/06/10 07:20:58 INFO TaskSetManager: Starting task 34.0 in stage 0.0 (TID 34) (d163094fab5f, executor driver, partition 34, PROCESS_LOCAL, 4553 bytes) taskResourceAssignments Map()
[2022-06-10 07:20:58,975] {subprocess.py:92} INFO - 22/06/10 07:20:58 INFO Executor: Finished task 31.0 in stage 0.0 (TID 31). 2646 bytes result sent to driver
[2022-06-10 07:20:58,976] {subprocess.py:92} INFO - 22/06/10 07:20:58 INFO TaskSetManager: Finished task 30.0 in stage 0.0 (TID 30) in 39 ms on d163094fab5f (executor driver) (30/180)
[2022-06-10 07:20:58,977] {subprocess.py:92} INFO - 22/06/10 07:20:58 INFO Executor: Running task 34.0 in stage 0.0 (TID 34)
[2022-06-10 07:20:58,978] {subprocess.py:92} INFO - 22/06/10 07:20:58 INFO TaskSetManager: Finished task 28.0 in stage 0.0 (TID 28) in 66 ms on d163094fab5f (executor driver) (31/180)
[2022-06-10 07:20:58,979] {subprocess.py:92} INFO - 22/06/10 07:20:58 INFO TaskSetManager: Finished task 31.0 in stage 0.0 (TID 31) in 36 ms on d163094fab5f (executor driver) (32/180)
[2022-06-10 07:20:58,981] {subprocess.py:92} INFO - 22/06/10 07:20:58 INFO Executor: Finished task 32.0 in stage 0.0 (TID 32). 2646 bytes result sent to driver
[2022-06-10 07:20:58,982] {subprocess.py:92} INFO - 22/06/10 07:20:58 INFO TaskSetManager: Starting task 35.0 in stage 0.0 (TID 35) (d163094fab5f, executor driver, partition 35, PROCESS_LOCAL, 4553 bytes) taskResourceAssignments Map()
[2022-06-10 07:20:58,988] {subprocess.py:92} INFO - 22/06/10 07:20:58 INFO Executor: Running task 35.0 in stage 0.0 (TID 35)
[2022-06-10 07:20:58,988] {subprocess.py:92} INFO - 22/06/10 07:20:58 INFO TaskSetManager: Finished task 32.0 in stage 0.0 (TID 32) in 35 ms on d163094fab5f (executor driver) (33/180)
[2022-06-10 07:20:58,990] {subprocess.py:92} INFO - 22/06/10 07:20:58 INFO TaskSetManager: Starting task 36.0 in stage 0.0 (TID 36) (d163094fab5f, executor driver, partition 36, PROCESS_LOCAL, 4553 bytes) taskResourceAssignments Map()
[2022-06-10 07:20:58,991] {subprocess.py:92} INFO - 22/06/10 07:20:58 INFO Executor: Running task 36.0 in stage 0.0 (TID 36)
[2022-06-10 07:20:59,005] {subprocess.py:92} INFO - 22/06/10 07:20:59 INFO Executor: Finished task 34.0 in stage 0.0 (TID 34). 2646 bytes result sent to driver
[2022-06-10 07:20:59,008] {subprocess.py:92} INFO - 22/06/10 07:20:59 INFO TaskSetManager: Starting task 37.0 in stage 0.0 (TID 37) (d163094fab5f, executor driver, partition 37, PROCESS_LOCAL, 4553 bytes) taskResourceAssignments Map()
[2022-06-10 07:20:59,011] {subprocess.py:92} INFO - 22/06/10 07:20:59 INFO TaskSetManager: Finished task 34.0 in stage 0.0 (TID 34) in 37 ms on d163094fab5f (executor driver) (34/180)
[2022-06-10 07:20:59,017] {subprocess.py:92} INFO - 22/06/10 07:20:59 INFO Executor: Finished task 33.0 in stage 0.0 (TID 33). 2646 bytes result sent to driver
[2022-06-10 07:20:59,019] {subprocess.py:92} INFO - 22/06/10 07:20:59 INFO TaskSetManager: Starting task 38.0 in stage 0.0 (TID 38) (d163094fab5f, executor driver, partition 38, PROCESS_LOCAL, 4553 bytes) taskResourceAssignments Map()
[2022-06-10 07:20:59,021] {subprocess.py:92} INFO - 22/06/10 07:20:59 INFO Executor: Running task 38.0 in stage 0.0 (TID 38)
[2022-06-10 07:20:59,022] {subprocess.py:92} INFO - 22/06/10 07:20:59 INFO TaskSetManager: Finished task 33.0 in stage 0.0 (TID 33) in 51 ms on d163094fab5f (executor driver) (35/180)
[2022-06-10 07:20:59,023] {subprocess.py:92} INFO - 22/06/10 07:20:59 INFO Executor: Running task 37.0 in stage 0.0 (TID 37)
[2022-06-10 07:20:59,024] {subprocess.py:92} INFO - 22/06/10 07:20:59 INFO Executor: Finished task 36.0 in stage 0.0 (TID 36). 2646 bytes result sent to driver
[2022-06-10 07:20:59,025] {subprocess.py:92} INFO - 22/06/10 07:20:59 INFO TaskSetManager: Finished task 36.0 in stage 0.0 (TID 36) in 38 ms on d163094fab5f (executor driver) (36/180)
[2022-06-10 07:20:59,027] {subprocess.py:92} INFO - 22/06/10 07:20:59 INFO TaskSetManager: Starting task 39.0 in stage 0.0 (TID 39) (d163094fab5f, executor driver, partition 39, PROCESS_LOCAL, 4553 bytes) taskResourceAssignments Map()
[2022-06-10 07:20:59,029] {subprocess.py:92} INFO - 22/06/10 07:20:59 INFO Executor: Running task 39.0 in stage 0.0 (TID 39)
[2022-06-10 07:20:59,031] {subprocess.py:92} INFO - 22/06/10 07:20:59 INFO Executor: Finished task 35.0 in stage 0.0 (TID 35). 2646 bytes result sent to driver
[2022-06-10 07:20:59,034] {subprocess.py:92} INFO - 22/06/10 07:20:59 INFO TaskSetManager: Starting task 40.0 in stage 0.0 (TID 40) (d163094fab5f, executor driver, partition 40, PROCESS_LOCAL, 4553 bytes) taskResourceAssignments Map()
[2022-06-10 07:20:59,035] {subprocess.py:92} INFO - 22/06/10 07:20:59 INFO Executor: Running task 40.0 in stage 0.0 (TID 40)
[2022-06-10 07:20:59,036] {subprocess.py:92} INFO - 22/06/10 07:20:59 INFO TaskSetManager: Finished task 35.0 in stage 0.0 (TID 35) in 54 ms on d163094fab5f (executor driver) (37/180)
[2022-06-10 07:20:59,050] {subprocess.py:92} INFO - 22/06/10 07:20:59 INFO Executor: Finished task 37.0 in stage 0.0 (TID 37). 2646 bytes result sent to driver
[2022-06-10 07:20:59,053] {subprocess.py:92} INFO - 22/06/10 07:20:59 INFO TaskSetManager: Starting task 41.0 in stage 0.0 (TID 41) (d163094fab5f, executor driver, partition 41, PROCESS_LOCAL, 4553 bytes) taskResourceAssignments Map()
[2022-06-10 07:20:59,057] {subprocess.py:92} INFO - 22/06/10 07:20:59 INFO Executor: Running task 41.0 in stage 0.0 (TID 41)
[2022-06-10 07:20:59,058] {subprocess.py:92} INFO - 22/06/10 07:20:59 INFO TaskSetManager: Finished task 37.0 in stage 0.0 (TID 37) in 50 ms on d163094fab5f (executor driver) (38/180)
[2022-06-10 07:20:59,063] {subprocess.py:92} INFO - 22/06/10 07:20:59 INFO Executor: Finished task 39.0 in stage 0.0 (TID 39). 2646 bytes result sent to driver
[2022-06-10 07:20:59,065] {subprocess.py:92} INFO - 22/06/10 07:20:59 INFO Executor: Finished task 40.0 in stage 0.0 (TID 40). 2646 bytes result sent to driver
[2022-06-10 07:20:59,070] {subprocess.py:92} INFO - 22/06/10 07:20:59 INFO TaskSetManager: Starting task 42.0 in stage 0.0 (TID 42) (d163094fab5f, executor driver, partition 42, PROCESS_LOCAL, 4553 bytes) taskResourceAssignments Map()
[2022-06-10 07:20:59,072] {subprocess.py:92} INFO - 22/06/10 07:20:59 INFO TaskSetManager: Starting task 43.0 in stage 0.0 (TID 43) (d163094fab5f, executor driver, partition 43, PROCESS_LOCAL, 4553 bytes) taskResourceAssignments Map()
[2022-06-10 07:20:59,073] {subprocess.py:92} INFO - 22/06/10 07:20:59 INFO Executor: Running task 42.0 in stage 0.0 (TID 42)
[2022-06-10 07:20:59,074] {subprocess.py:92} INFO - 22/06/10 07:20:59 INFO Executor: Running task 43.0 in stage 0.0 (TID 43)
[2022-06-10 07:20:59,075] {subprocess.py:92} INFO - 22/06/10 07:20:59 INFO TaskSetManager: Finished task 40.0 in stage 0.0 (TID 40) in 42 ms on d163094fab5f (executor driver) (39/180)
[2022-06-10 07:20:59,077] {subprocess.py:92} INFO - 22/06/10 07:20:59 INFO TaskSetManager: Finished task 39.0 in stage 0.0 (TID 39) in 51 ms on d163094fab5f (executor driver) (40/180)
[2022-06-10 07:20:59,080] {subprocess.py:92} INFO - 22/06/10 07:20:59 INFO Executor: Finished task 41.0 in stage 0.0 (TID 41). 2646 bytes result sent to driver
[2022-06-10 07:20:59,081] {subprocess.py:92} INFO - 22/06/10 07:20:59 INFO TaskSetManager: Starting task 44.0 in stage 0.0 (TID 44) (d163094fab5f, executor driver, partition 44, PROCESS_LOCAL, 4553 bytes) taskResourceAssignments Map()
[2022-06-10 07:20:59,082] {subprocess.py:92} INFO - 22/06/10 07:20:59 INFO TaskSetManager: Finished task 41.0 in stage 0.0 (TID 41) in 27 ms on d163094fab5f (executor driver) (41/180)
[2022-06-10 07:20:59,084] {subprocess.py:92} INFO - 22/06/10 07:20:59 INFO Executor: Running task 44.0 in stage 0.0 (TID 44)
[2022-06-10 07:20:59,086] {subprocess.py:92} INFO - 22/06/10 07:20:59 INFO Executor: Finished task 38.0 in stage 0.0 (TID 38). 2689 bytes result sent to driver
[2022-06-10 07:20:59,090] {subprocess.py:92} INFO - 22/06/10 07:20:59 INFO TaskSetManager: Starting task 45.0 in stage 0.0 (TID 45) (d163094fab5f, executor driver, partition 45, PROCESS_LOCAL, 4553 bytes) taskResourceAssignments Map()
[2022-06-10 07:20:59,091] {subprocess.py:92} INFO - 22/06/10 07:20:59 INFO TaskSetManager: Finished task 38.0 in stage 0.0 (TID 38) in 70 ms on d163094fab5f (executor driver) (42/180)
[2022-06-10 07:20:59,092] {subprocess.py:92} INFO - 22/06/10 07:20:59 INFO Executor: Running task 45.0 in stage 0.0 (TID 45)
[2022-06-10 07:20:59,101] {subprocess.py:92} INFO - 22/06/10 07:20:59 INFO Executor: Finished task 43.0 in stage 0.0 (TID 43). 2646 bytes result sent to driver
[2022-06-10 07:20:59,103] {subprocess.py:92} INFO - 22/06/10 07:20:59 INFO Executor: Finished task 44.0 in stage 0.0 (TID 44). 2646 bytes result sent to driver
[2022-06-10 07:20:59,106] {subprocess.py:92} INFO - 22/06/10 07:20:59 INFO TaskSetManager: Starting task 46.0 in stage 0.0 (TID 46) (d163094fab5f, executor driver, partition 46, PROCESS_LOCAL, 4553 bytes) taskResourceAssignments Map()
[2022-06-10 07:20:59,107] {subprocess.py:92} INFO - 22/06/10 07:20:59 INFO TaskSetManager: Finished task 43.0 in stage 0.0 (TID 43) in 34 ms on d163094fab5f (executor driver) (43/180)
[2022-06-10 07:20:59,108] {subprocess.py:92} INFO - 22/06/10 07:20:59 INFO Executor: Running task 46.0 in stage 0.0 (TID 46)
[2022-06-10 07:20:59,110] {subprocess.py:92} INFO - 22/06/10 07:20:59 INFO TaskSetManager: Starting task 47.0 in stage 0.0 (TID 47) (d163094fab5f, executor driver, partition 47, PROCESS_LOCAL, 4553 bytes) taskResourceAssignments Map()
[2022-06-10 07:20:59,111] {subprocess.py:92} INFO - 22/06/10 07:20:59 INFO TaskSetManager: Finished task 44.0 in stage 0.0 (TID 44) in 32 ms on d163094fab5f (executor driver) (44/180)
[2022-06-10 07:20:59,113] {subprocess.py:92} INFO - 22/06/10 07:20:59 INFO Executor: Running task 47.0 in stage 0.0 (TID 47)
[2022-06-10 07:20:59,116] {subprocess.py:92} INFO - 22/06/10 07:20:59 INFO Executor: Finished task 42.0 in stage 0.0 (TID 42). 2646 bytes result sent to driver
[2022-06-10 07:20:59,118] {subprocess.py:92} INFO - 22/06/10 07:20:59 INFO TaskSetManager: Starting task 48.0 in stage 0.0 (TID 48) (d163094fab5f, executor driver, partition 48, PROCESS_LOCAL, 4553 bytes) taskResourceAssignments Map()
[2022-06-10 07:20:59,119] {subprocess.py:92} INFO - 22/06/10 07:20:59 INFO Executor: Running task 48.0 in stage 0.0 (TID 48)
[2022-06-10 07:20:59,120] {subprocess.py:92} INFO - 22/06/10 07:20:59 INFO TaskSetManager: Finished task 42.0 in stage 0.0 (TID 42) in 55 ms on d163094fab5f (executor driver) (45/180)
[2022-06-10 07:20:59,122] {subprocess.py:92} INFO - 22/06/10 07:20:59 INFO Executor: Finished task 45.0 in stage 0.0 (TID 45). 2646 bytes result sent to driver
[2022-06-10 07:20:59,124] {subprocess.py:92} INFO - 22/06/10 07:20:59 INFO TaskSetManager: Starting task 49.0 in stage 0.0 (TID 49) (d163094fab5f, executor driver, partition 49, PROCESS_LOCAL, 4553 bytes) taskResourceAssignments Map()
[2022-06-10 07:20:59,126] {subprocess.py:92} INFO - 22/06/10 07:20:59 INFO Executor: Running task 49.0 in stage 0.0 (TID 49)
[2022-06-10 07:20:59,126] {subprocess.py:92} INFO - 22/06/10 07:20:59 INFO TaskSetManager: Finished task 45.0 in stage 0.0 (TID 45) in 38 ms on d163094fab5f (executor driver) (46/180)
[2022-06-10 07:20:59,135] {subprocess.py:92} INFO - 22/06/10 07:20:59 INFO Executor: Finished task 47.0 in stage 0.0 (TID 47). 2646 bytes result sent to driver
[2022-06-10 07:20:59,137] {subprocess.py:92} INFO - 22/06/10 07:20:59 INFO TaskSetManager: Starting task 50.0 in stage 0.0 (TID 50) (d163094fab5f, executor driver, partition 50, PROCESS_LOCAL, 4553 bytes) taskResourceAssignments Map()
[2022-06-10 07:20:59,139] {subprocess.py:92} INFO - 22/06/10 07:20:59 INFO Executor: Finished task 49.0 in stage 0.0 (TID 49). 2646 bytes result sent to driver
[2022-06-10 07:20:59,140] {subprocess.py:92} INFO - 22/06/10 07:20:59 INFO TaskSetManager: Finished task 47.0 in stage 0.0 (TID 47) in 29 ms on d163094fab5f (executor driver) (47/180)
[2022-06-10 07:20:59,142] {subprocess.py:92} INFO - 22/06/10 07:20:59 INFO TaskSetManager: Starting task 51.0 in stage 0.0 (TID 51) (d163094fab5f, executor driver, partition 51, PROCESS_LOCAL, 4553 bytes) taskResourceAssignments Map()
[2022-06-10 07:20:59,142] {subprocess.py:92} INFO - 22/06/10 07:20:59 INFO Executor: Finished task 46.0 in stage 0.0 (TID 46). 2646 bytes result sent to driver
[2022-06-10 07:20:59,144] {subprocess.py:92} INFO - 22/06/10 07:20:59 INFO Executor: Running task 51.0 in stage 0.0 (TID 51)
[2022-06-10 07:20:59,145] {subprocess.py:92} INFO - 22/06/10 07:20:59 INFO Executor: Finished task 48.0 in stage 0.0 (TID 48). 2646 bytes result sent to driver
[2022-06-10 07:20:59,146] {subprocess.py:92} INFO - 22/06/10 07:20:59 INFO TaskSetManager: Starting task 52.0 in stage 0.0 (TID 52) (d163094fab5f, executor driver, partition 52, PROCESS_LOCAL, 4553 bytes) taskResourceAssignments Map()
[2022-06-10 07:20:59,148] {subprocess.py:92} INFO - 22/06/10 07:20:59 INFO TaskSetManager: Finished task 49.0 in stage 0.0 (TID 49) in 23 ms on d163094fab5f (executor driver) (48/180)
[2022-06-10 07:20:59,149] {subprocess.py:92} INFO - 22/06/10 07:20:59 INFO TaskSetManager: Finished task 46.0 in stage 0.0 (TID 46) in 43 ms on d163094fab5f (executor driver) (49/180)
[2022-06-10 07:20:59,150] {subprocess.py:92} INFO - 22/06/10 07:20:59 INFO TaskSetManager: Finished task 48.0 in stage 0.0 (TID 48) in 33 ms on d163094fab5f (executor driver) (50/180)
[2022-06-10 07:20:59,152] {subprocess.py:92} INFO - 22/06/10 07:20:59 INFO Executor: Running task 50.0 in stage 0.0 (TID 50)
[2022-06-10 07:20:59,153] {subprocess.py:92} INFO - 22/06/10 07:20:59 INFO TaskSetManager: Starting task 53.0 in stage 0.0 (TID 53) (d163094fab5f, executor driver, partition 53, PROCESS_LOCAL, 4553 bytes) taskResourceAssignments Map()
[2022-06-10 07:20:59,153] {subprocess.py:92} INFO - 22/06/10 07:20:59 INFO Executor: Running task 52.0 in stage 0.0 (TID 52)
[2022-06-10 07:20:59,154] {subprocess.py:92} INFO - 22/06/10 07:20:59 INFO Executor: Running task 53.0 in stage 0.0 (TID 53)
[2022-06-10 07:20:59,204] {subprocess.py:92} INFO - 22/06/10 07:20:59 INFO Executor: Finished task 50.0 in stage 0.0 (TID 50). 2689 bytes result sent to driver
[2022-06-10 07:20:59,206] {subprocess.py:92} INFO - 22/06/10 07:20:59 INFO TaskSetManager: Starting task 54.0 in stage 0.0 (TID 54) (d163094fab5f, executor driver, partition 54, PROCESS_LOCAL, 4553 bytes) taskResourceAssignments Map()
[2022-06-10 07:20:59,214] {subprocess.py:92} INFO - 22/06/10 07:20:59 INFO Executor: Running task 54.0 in stage 0.0 (TID 54)
[2022-06-10 07:20:59,215] {subprocess.py:92} INFO - 22/06/10 07:20:59 INFO TaskSetManager: Finished task 50.0 in stage 0.0 (TID 50) in 76 ms on d163094fab5f (executor driver) (51/180)
[2022-06-10 07:20:59,216] {subprocess.py:92} INFO - 22/06/10 07:20:59 INFO Executor: Finished task 53.0 in stage 0.0 (TID 53). 2689 bytes result sent to driver
[2022-06-10 07:20:59,223] {subprocess.py:92} INFO - 22/06/10 07:20:59 INFO TaskSetManager: Starting task 55.0 in stage 0.0 (TID 55) (d163094fab5f, executor driver, partition 55, PROCESS_LOCAL, 4553 bytes) taskResourceAssignments Map()
[2022-06-10 07:20:59,225] {subprocess.py:92} INFO - 22/06/10 07:20:59 INFO Executor: Running task 55.0 in stage 0.0 (TID 55)
[2022-06-10 07:20:59,226] {subprocess.py:92} INFO - 22/06/10 07:20:59 INFO TaskSetManager: Finished task 53.0 in stage 0.0 (TID 53) in 74 ms on d163094fab5f (executor driver) (52/180)
[2022-06-10 07:20:59,236] {subprocess.py:92} INFO - 22/06/10 07:20:59 INFO Executor: Finished task 55.0 in stage 0.0 (TID 55). 2646 bytes result sent to driver
[2022-06-10 07:20:59,239] {subprocess.py:92} INFO - 22/06/10 07:20:59 INFO TaskSetManager: Starting task 56.0 in stage 0.0 (TID 56) (d163094fab5f, executor driver, partition 56, PROCESS_LOCAL, 4553 bytes) taskResourceAssignments Map()
[2022-06-10 07:20:59,242] {subprocess.py:92} INFO - 22/06/10 07:20:59 INFO TaskSetManager: Finished task 55.0 in stage 0.0 (TID 55) in 20 ms on d163094fab5f (executor driver) (53/180)
[2022-06-10 07:20:59,243] {subprocess.py:92} INFO - 22/06/10 07:20:59 INFO Executor: Running task 56.0 in stage 0.0 (TID 56)
[2022-06-10 07:20:59,249] {subprocess.py:92} INFO - 22/06/10 07:20:59 INFO Executor: Finished task 54.0 in stage 0.0 (TID 54). 2646 bytes result sent to driver
[2022-06-10 07:20:59,251] {subprocess.py:92} INFO - 22/06/10 07:20:59 INFO TaskSetManager: Starting task 57.0 in stage 0.0 (TID 57) (d163094fab5f, executor driver, partition 57, PROCESS_LOCAL, 4553 bytes) taskResourceAssignments Map()
[2022-06-10 07:20:59,252] {subprocess.py:92} INFO - 22/06/10 07:20:59 INFO Executor: Running task 57.0 in stage 0.0 (TID 57)
[2022-06-10 07:20:59,253] {subprocess.py:92} INFO - 22/06/10 07:20:59 INFO TaskSetManager: Finished task 54.0 in stage 0.0 (TID 54) in 47 ms on d163094fab5f (executor driver) (54/180)
[2022-06-10 07:20:59,254] {subprocess.py:92} INFO - 22/06/10 07:20:59 INFO Executor: Finished task 56.0 in stage 0.0 (TID 56). 2646 bytes result sent to driver
[2022-06-10 07:20:59,256] {subprocess.py:92} INFO - 22/06/10 07:20:59 INFO TaskSetManager: Starting task 58.0 in stage 0.0 (TID 58) (d163094fab5f, executor driver, partition 58, PROCESS_LOCAL, 4553 bytes) taskResourceAssignments Map()
[2022-06-10 07:20:59,258] {subprocess.py:92} INFO - 22/06/10 07:20:59 INFO TaskSetManager: Finished task 56.0 in stage 0.0 (TID 56) in 19 ms on d163094fab5f (executor driver) (55/180)
[2022-06-10 07:20:59,259] {subprocess.py:92} INFO - 22/06/10 07:20:59 INFO Executor: Running task 58.0 in stage 0.0 (TID 58)
[2022-06-10 07:20:59,264] {subprocess.py:92} INFO - 22/06/10 07:20:59 INFO Executor: Finished task 51.0 in stage 0.0 (TID 51). 2689 bytes result sent to driver
[2022-06-10 07:20:59,266] {subprocess.py:92} INFO - 22/06/10 07:20:59 INFO TaskSetManager: Starting task 59.0 in stage 0.0 (TID 59) (d163094fab5f, executor driver, partition 59, PROCESS_LOCAL, 4553 bytes) taskResourceAssignments Map()
[2022-06-10 07:20:59,267] {subprocess.py:92} INFO - 22/06/10 07:20:59 INFO Executor: Finished task 52.0 in stage 0.0 (TID 52). 2689 bytes result sent to driver
[2022-06-10 07:20:59,268] {subprocess.py:92} INFO - 22/06/10 07:20:59 INFO TaskSetManager: Finished task 51.0 in stage 0.0 (TID 51) in 126 ms on d163094fab5f (executor driver) (56/180)
[2022-06-10 07:20:59,269] {subprocess.py:92} INFO - 22/06/10 07:20:59 INFO Executor: Running task 59.0 in stage 0.0 (TID 59)
[2022-06-10 07:20:59,270] {subprocess.py:92} INFO - 22/06/10 07:20:59 INFO TaskSetManager: Starting task 60.0 in stage 0.0 (TID 60) (d163094fab5f, executor driver, partition 60, PROCESS_LOCAL, 4553 bytes) taskResourceAssignments Map()
[2022-06-10 07:20:59,272] {subprocess.py:92} INFO - 22/06/10 07:20:59 INFO Executor: Running task 60.0 in stage 0.0 (TID 60)
[2022-06-10 07:20:59,274] {subprocess.py:92} INFO - 22/06/10 07:20:59 INFO TaskSetManager: Finished task 52.0 in stage 0.0 (TID 52) in 126 ms on d163094fab5f (executor driver) (57/180)
[2022-06-10 07:20:59,279] {subprocess.py:92} INFO - 22/06/10 07:20:59 INFO Executor: Finished task 58.0 in stage 0.0 (TID 58). 2646 bytes result sent to driver
[2022-06-10 07:20:59,281] {subprocess.py:92} INFO - 22/06/10 07:20:59 INFO TaskSetManager: Starting task 61.0 in stage 0.0 (TID 61) (d163094fab5f, executor driver, partition 61, PROCESS_LOCAL, 4553 bytes) taskResourceAssignments Map()
[2022-06-10 07:20:59,283] {subprocess.py:92} INFO - 22/06/10 07:20:59 INFO Executor: Running task 61.0 in stage 0.0 (TID 61)
[2022-06-10 07:20:59,287] {subprocess.py:92} INFO - 22/06/10 07:20:59 INFO TaskSetManager: Finished task 58.0 in stage 0.0 (TID 58) in 28 ms on d163094fab5f (executor driver) (58/180)
[2022-06-10 07:20:59,291] {subprocess.py:92} INFO - 22/06/10 07:20:59 INFO Executor: Finished task 57.0 in stage 0.0 (TID 57). 2646 bytes result sent to driver
[2022-06-10 07:20:59,293] {subprocess.py:92} INFO - 22/06/10 07:20:59 INFO TaskSetManager: Starting task 62.0 in stage 0.0 (TID 62) (d163094fab5f, executor driver, partition 62, PROCESS_LOCAL, 4553 bytes) taskResourceAssignments Map()
[2022-06-10 07:20:59,295] {subprocess.py:92} INFO - 22/06/10 07:20:59 INFO TaskSetManager: Finished task 57.0 in stage 0.0 (TID 57) in 44 ms on d163094fab5f (executor driver) (59/180)
[2022-06-10 07:20:59,296] {subprocess.py:92} INFO - 22/06/10 07:20:59 INFO Executor: Running task 62.0 in stage 0.0 (TID 62)
[2022-06-10 07:20:59,300] {subprocess.py:92} INFO - 22/06/10 07:20:59 INFO Executor: Finished task 61.0 in stage 0.0 (TID 61). 2646 bytes result sent to driver
[2022-06-10 07:20:59,301] {subprocess.py:92} INFO - 22/06/10 07:20:59 INFO TaskSetManager: Starting task 63.0 in stage 0.0 (TID 63) (d163094fab5f, executor driver, partition 63, PROCESS_LOCAL, 4553 bytes) taskResourceAssignments Map()
[2022-06-10 07:20:59,303] {subprocess.py:92} INFO - 22/06/10 07:20:59 INFO TaskSetManager: Finished task 61.0 in stage 0.0 (TID 61) in 22 ms on d163094fab5f (executor driver) (60/180)
[2022-06-10 07:20:59,304] {subprocess.py:92} INFO - 22/06/10 07:20:59 INFO Executor: Running task 63.0 in stage 0.0 (TID 63)
[2022-06-10 07:20:59,308] {subprocess.py:92} INFO - 22/06/10 07:20:59 INFO Executor: Finished task 60.0 in stage 0.0 (TID 60). 2689 bytes result sent to driver
[2022-06-10 07:20:59,310] {subprocess.py:92} INFO - 22/06/10 07:20:59 INFO Executor: Finished task 59.0 in stage 0.0 (TID 59). 2646 bytes result sent to driver
[2022-06-10 07:20:59,311] {subprocess.py:92} INFO - 22/06/10 07:20:59 INFO TaskSetManager: Starting task 64.0 in stage 0.0 (TID 64) (d163094fab5f, executor driver, partition 64, PROCESS_LOCAL, 4553 bytes) taskResourceAssignments Map()
[2022-06-10 07:20:59,312] {subprocess.py:92} INFO - 22/06/10 07:20:59 INFO Executor: Running task 64.0 in stage 0.0 (TID 64)
[2022-06-10 07:20:59,313] {subprocess.py:92} INFO - 22/06/10 07:20:59 INFO TaskSetManager: Starting task 65.0 in stage 0.0 (TID 65) (d163094fab5f, executor driver, partition 65, PROCESS_LOCAL, 4553 bytes) taskResourceAssignments Map()
[2022-06-10 07:20:59,315] {subprocess.py:92} INFO - 22/06/10 07:20:59 INFO Executor: Running task 65.0 in stage 0.0 (TID 65)
[2022-06-10 07:20:59,316] {subprocess.py:92} INFO - 22/06/10 07:20:59 INFO TaskSetManager: Finished task 60.0 in stage 0.0 (TID 60) in 46 ms on d163094fab5f (executor driver) (61/180)
[2022-06-10 07:20:59,316] {subprocess.py:92} INFO - 22/06/10 07:20:59 INFO TaskSetManager: Finished task 59.0 in stage 0.0 (TID 59) in 50 ms on d163094fab5f (executor driver) (62/180)
[2022-06-10 07:20:59,324] {subprocess.py:92} INFO - 22/06/10 07:20:59 INFO Executor: Finished task 63.0 in stage 0.0 (TID 63). 2646 bytes result sent to driver
[2022-06-10 07:20:59,325] {subprocess.py:92} INFO - 22/06/10 07:20:59 INFO TaskSetManager: Starting task 66.0 in stage 0.0 (TID 66) (d163094fab5f, executor driver, partition 66, PROCESS_LOCAL, 4553 bytes) taskResourceAssignments Map()
[2022-06-10 07:20:59,327] {subprocess.py:92} INFO - 22/06/10 07:20:59 INFO TaskSetManager: Finished task 63.0 in stage 0.0 (TID 63) in 26 ms on d163094fab5f (executor driver) (63/180)
[2022-06-10 07:20:59,328] {subprocess.py:92} INFO - 22/06/10 07:20:59 INFO Executor: Running task 66.0 in stage 0.0 (TID 66)
[2022-06-10 07:20:59,329] {subprocess.py:92} INFO - 22/06/10 07:20:59 INFO Executor: Finished task 62.0 in stage 0.0 (TID 62). 2646 bytes result sent to driver
[2022-06-10 07:20:59,330] {subprocess.py:92} INFO - 22/06/10 07:20:59 INFO TaskSetManager: Starting task 67.0 in stage 0.0 (TID 67) (d163094fab5f, executor driver, partition 67, PROCESS_LOCAL, 4553 bytes) taskResourceAssignments Map()
[2022-06-10 07:20:59,331] {subprocess.py:92} INFO - 22/06/10 07:20:59 INFO Executor: Running task 67.0 in stage 0.0 (TID 67)
[2022-06-10 07:20:59,332] {subprocess.py:92} INFO - 22/06/10 07:20:59 INFO TaskSetManager: Finished task 62.0 in stage 0.0 (TID 62) in 39 ms on d163094fab5f (executor driver) (64/180)
[2022-06-10 07:20:59,343] {subprocess.py:92} INFO - 22/06/10 07:20:59 INFO Executor: Finished task 66.0 in stage 0.0 (TID 66). 2646 bytes result sent to driver
[2022-06-10 07:20:59,345] {subprocess.py:92} INFO - 22/06/10 07:20:59 INFO TaskSetManager: Starting task 68.0 in stage 0.0 (TID 68) (d163094fab5f, executor driver, partition 68, PROCESS_LOCAL, 4553 bytes) taskResourceAssignments Map()
[2022-06-10 07:20:59,347] {subprocess.py:92} INFO - 22/06/10 07:20:59 INFO TaskSetManager: Finished task 66.0 in stage 0.0 (TID 66) in 22 ms on d163094fab5f (executor driver) (65/180)
[2022-06-10 07:20:59,348] {subprocess.py:92} INFO - 22/06/10 07:20:59 INFO Executor: Running task 68.0 in stage 0.0 (TID 68)
[2022-06-10 07:20:59,350] {subprocess.py:92} INFO - 22/06/10 07:20:59 INFO Executor: Finished task 65.0 in stage 0.0 (TID 65). 2646 bytes result sent to driver
[2022-06-10 07:20:59,352] {subprocess.py:92} INFO - 22/06/10 07:20:59 INFO TaskSetManager: Starting task 69.0 in stage 0.0 (TID 69) (d163094fab5f, executor driver, partition 69, PROCESS_LOCAL, 4553 bytes) taskResourceAssignments Map()
[2022-06-10 07:20:59,353] {subprocess.py:92} INFO - 22/06/10 07:20:59 INFO Executor: Running task 69.0 in stage 0.0 (TID 69)
[2022-06-10 07:20:59,356] {subprocess.py:92} INFO - 22/06/10 07:20:59 INFO TaskSetManager: Finished task 65.0 in stage 0.0 (TID 65) in 39 ms on d163094fab5f (executor driver) (66/180)
[2022-06-10 07:20:59,356] {subprocess.py:92} INFO - 22/06/10 07:20:59 INFO Executor: Finished task 67.0 in stage 0.0 (TID 67). 2646 bytes result sent to driver
[2022-06-10 07:20:59,357] {subprocess.py:92} INFO - 22/06/10 07:20:59 INFO TaskSetManager: Starting task 70.0 in stage 0.0 (TID 70) (d163094fab5f, executor driver, partition 70, PROCESS_LOCAL, 4553 bytes) taskResourceAssignments Map()
[2022-06-10 07:20:59,358] {subprocess.py:92} INFO - 22/06/10 07:20:59 INFO Executor: Finished task 64.0 in stage 0.0 (TID 64). 2646 bytes result sent to driver
[2022-06-10 07:20:59,358] {subprocess.py:92} INFO - 22/06/10 07:20:59 INFO TaskSetManager: Finished task 67.0 in stage 0.0 (TID 67) in 27 ms on d163094fab5f (executor driver) (67/180)
[2022-06-10 07:20:59,359] {subprocess.py:92} INFO - 22/06/10 07:20:59 INFO Executor: Running task 70.0 in stage 0.0 (TID 70)
[2022-06-10 07:20:59,360] {subprocess.py:92} INFO - 22/06/10 07:20:59 INFO Executor: Finished task 68.0 in stage 0.0 (TID 68). 2646 bytes result sent to driver
[2022-06-10 07:20:59,362] {subprocess.py:92} INFO - 22/06/10 07:20:59 INFO TaskSetManager: Starting task 71.0 in stage 0.0 (TID 71) (d163094fab5f, executor driver, partition 71, PROCESS_LOCAL, 4553 bytes) taskResourceAssignments Map()
[2022-06-10 07:20:59,364] {subprocess.py:92} INFO - 22/06/10 07:20:59 INFO TaskSetManager: Finished task 64.0 in stage 0.0 (TID 64) in 54 ms on d163094fab5f (executor driver) (68/180)
[2022-06-10 07:20:59,364] {subprocess.py:92} INFO - 22/06/10 07:20:59 INFO Executor: Running task 71.0 in stage 0.0 (TID 71)
[2022-06-10 07:20:59,366] {subprocess.py:92} INFO - 22/06/10 07:20:59 INFO TaskSetManager: Starting task 72.0 in stage 0.0 (TID 72) (d163094fab5f, executor driver, partition 72, PROCESS_LOCAL, 4553 bytes) taskResourceAssignments Map()
[2022-06-10 07:20:59,368] {subprocess.py:92} INFO - 22/06/10 07:20:59 INFO Executor: Running task 72.0 in stage 0.0 (TID 72)
[2022-06-10 07:20:59,369] {subprocess.py:92} INFO - 22/06/10 07:20:59 INFO TaskSetManager: Finished task 68.0 in stage 0.0 (TID 68) in 23 ms on d163094fab5f (executor driver) (69/180)
[2022-06-10 07:20:59,383] {subprocess.py:92} INFO - 22/06/10 07:20:59 INFO Executor: Finished task 72.0 in stage 0.0 (TID 72). 2646 bytes result sent to driver
[2022-06-10 07:20:59,384] {subprocess.py:92} INFO - 22/06/10 07:20:59 INFO Executor: Finished task 70.0 in stage 0.0 (TID 70). 2646 bytes result sent to driver
[2022-06-10 07:20:59,385] {subprocess.py:92} INFO - 22/06/10 07:20:59 INFO TaskSetManager: Starting task 73.0 in stage 0.0 (TID 73) (d163094fab5f, executor driver, partition 73, PROCESS_LOCAL, 4553 bytes) taskResourceAssignments Map()
[2022-06-10 07:20:59,386] {subprocess.py:92} INFO - 22/06/10 07:20:59 INFO Executor: Finished task 71.0 in stage 0.0 (TID 71). 2646 bytes result sent to driver
[2022-06-10 07:20:59,387] {subprocess.py:92} INFO - 22/06/10 07:20:59 INFO Executor: Finished task 69.0 in stage 0.0 (TID 69). 2646 bytes result sent to driver
[2022-06-10 07:20:59,388] {subprocess.py:92} INFO - 22/06/10 07:20:59 INFO Executor: Running task 73.0 in stage 0.0 (TID 73)
[2022-06-10 07:20:59,390] {subprocess.py:92} INFO - 22/06/10 07:20:59 INFO TaskSetManager: Starting task 74.0 in stage 0.0 (TID 74) (d163094fab5f, executor driver, partition 74, PROCESS_LOCAL, 4553 bytes) taskResourceAssignments Map()
[2022-06-10 07:20:59,391] {subprocess.py:92} INFO - 22/06/10 07:20:59 INFO TaskSetManager: Finished task 72.0 in stage 0.0 (TID 72) in 22 ms on d163094fab5f (executor driver) (70/180)
[2022-06-10 07:20:59,392] {subprocess.py:92} INFO - 22/06/10 07:20:59 INFO Executor: Running task 74.0 in stage 0.0 (TID 74)
[2022-06-10 07:20:59,393] {subprocess.py:92} INFO - 22/06/10 07:20:59 INFO TaskSetManager: Finished task 70.0 in stage 0.0 (TID 70) in 34 ms on d163094fab5f (executor driver) (71/180)
[2022-06-10 07:20:59,393] {subprocess.py:92} INFO - 22/06/10 07:20:59 INFO TaskSetManager: Finished task 71.0 in stage 0.0 (TID 71) in 30 ms on d163094fab5f (executor driver) (72/180)
[2022-06-10 07:20:59,394] {subprocess.py:92} INFO - 22/06/10 07:20:59 INFO TaskSetManager: Starting task 75.0 in stage 0.0 (TID 75) (d163094fab5f, executor driver, partition 75, PROCESS_LOCAL, 4553 bytes) taskResourceAssignments Map()
[2022-06-10 07:20:59,395] {subprocess.py:92} INFO - 22/06/10 07:20:59 INFO Executor: Running task 75.0 in stage 0.0 (TID 75)
[2022-06-10 07:20:59,396] {subprocess.py:92} INFO - 22/06/10 07:20:59 INFO TaskSetManager: Starting task 76.0 in stage 0.0 (TID 76) (d163094fab5f, executor driver, partition 76, PROCESS_LOCAL, 4553 bytes) taskResourceAssignments Map()
[2022-06-10 07:20:59,396] {subprocess.py:92} INFO - 22/06/10 07:20:59 INFO TaskSetManager: Finished task 69.0 in stage 0.0 (TID 69) in 44 ms on d163094fab5f (executor driver) (73/180)
[2022-06-10 07:20:59,397] {subprocess.py:92} INFO - 22/06/10 07:20:59 INFO Executor: Running task 76.0 in stage 0.0 (TID 76)
[2022-06-10 07:20:59,416] {subprocess.py:92} INFO - 22/06/10 07:20:59 INFO Executor: Finished task 74.0 in stage 0.0 (TID 74). 2646 bytes result sent to driver
[2022-06-10 07:20:59,417] {subprocess.py:92} INFO - 22/06/10 07:20:59 INFO Executor: Finished task 73.0 in stage 0.0 (TID 73). 2646 bytes result sent to driver
[2022-06-10 07:20:59,418] {subprocess.py:92} INFO - 22/06/10 07:20:59 INFO Executor: Finished task 76.0 in stage 0.0 (TID 76). 2646 bytes result sent to driver
[2022-06-10 07:20:59,419] {subprocess.py:92} INFO - 22/06/10 07:20:59 INFO TaskSetManager: Starting task 77.0 in stage 0.0 (TID 77) (d163094fab5f, executor driver, partition 77, PROCESS_LOCAL, 4553 bytes) taskResourceAssignments Map()
[2022-06-10 07:20:59,420] {subprocess.py:92} INFO - 22/06/10 07:20:59 INFO Executor: Running task 77.0 in stage 0.0 (TID 77)
[2022-06-10 07:20:59,424] {subprocess.py:92} INFO - 22/06/10 07:20:59 INFO TaskSetManager: Starting task 78.0 in stage 0.0 (TID 78) (d163094fab5f, executor driver, partition 78, PROCESS_LOCAL, 4553 bytes) taskResourceAssignments Map()
[2022-06-10 07:20:59,430] {subprocess.py:92} INFO - 22/06/10 07:20:59 INFO TaskSetManager: Finished task 74.0 in stage 0.0 (TID 74) in 41 ms on d163094fab5f (executor driver) (74/180)
[2022-06-10 07:20:59,434] {subprocess.py:92} INFO - 22/06/10 07:20:59 INFO TaskSetManager: Finished task 73.0 in stage 0.0 (TID 73) in 44 ms on d163094fab5f (executor driver) (75/180)
[2022-06-10 07:20:59,434] {subprocess.py:92} INFO - 22/06/10 07:20:59 INFO Executor: Running task 78.0 in stage 0.0 (TID 78)
[2022-06-10 07:20:59,438] {subprocess.py:92} INFO - 22/06/10 07:20:59 INFO TaskSetManager: Starting task 79.0 in stage 0.0 (TID 79) (d163094fab5f, executor driver, partition 79, PROCESS_LOCAL, 4553 bytes) taskResourceAssignments Map()
[2022-06-10 07:20:59,439] {subprocess.py:92} INFO - 22/06/10 07:20:59 INFO Executor: Finished task 75.0 in stage 0.0 (TID 75). 2646 bytes result sent to driver
[2022-06-10 07:20:59,440] {subprocess.py:92} INFO - 22/06/10 07:20:59 INFO TaskSetManager: Finished task 76.0 in stage 0.0 (TID 76) in 42 ms on d163094fab5f (executor driver) (76/180)
[2022-06-10 07:20:59,441] {subprocess.py:92} INFO - 22/06/10 07:20:59 INFO Executor: Running task 79.0 in stage 0.0 (TID 79)
[2022-06-10 07:20:59,443] {subprocess.py:92} INFO - 22/06/10 07:20:59 INFO TaskSetManager: Starting task 80.0 in stage 0.0 (TID 80) (d163094fab5f, executor driver, partition 80, PROCESS_LOCAL, 4553 bytes) taskResourceAssignments Map()
[2022-06-10 07:20:59,447] {subprocess.py:92} INFO - 22/06/10 07:20:59 INFO Executor: Finished task 78.0 in stage 0.0 (TID 78). 2646 bytes result sent to driver
[2022-06-10 07:20:59,447] {subprocess.py:92} INFO - 22/06/10 07:20:59 INFO Executor: Running task 80.0 in stage 0.0 (TID 80)
[2022-06-10 07:20:59,448] {subprocess.py:92} INFO - 22/06/10 07:20:59 INFO Executor: Finished task 77.0 in stage 0.0 (TID 77). 2646 bytes result sent to driver
[2022-06-10 07:20:59,450] {subprocess.py:92} INFO - 22/06/10 07:20:59 INFO Executor: Finished task 79.0 in stage 0.0 (TID 79). 2646 bytes result sent to driver
[2022-06-10 07:20:59,453] {subprocess.py:92} INFO - 22/06/10 07:20:59 INFO TaskSetManager: Starting task 81.0 in stage 0.0 (TID 81) (d163094fab5f, executor driver, partition 81, PROCESS_LOCAL, 4553 bytes) taskResourceAssignments Map()
[2022-06-10 07:20:59,455] {subprocess.py:92} INFO - 22/06/10 07:20:59 INFO TaskSetManager: Finished task 75.0 in stage 0.0 (TID 75) in 64 ms on d163094fab5f (executor driver) (77/180)
[2022-06-10 07:20:59,456] {subprocess.py:92} INFO - 22/06/10 07:20:59 INFO Executor: Running task 81.0 in stage 0.0 (TID 81)
[2022-06-10 07:20:59,461] {subprocess.py:92} INFO - 22/06/10 07:20:59 INFO TaskSetManager: Starting task 82.0 in stage 0.0 (TID 82) (d163094fab5f, executor driver, partition 82, PROCESS_LOCAL, 4553 bytes) taskResourceAssignments Map()
[2022-06-10 07:20:59,462] {subprocess.py:92} INFO - 22/06/10 07:20:59 INFO Executor: Finished task 80.0 in stage 0.0 (TID 80). 2646 bytes result sent to driver
[2022-06-10 07:20:59,464] {subprocess.py:92} INFO - 22/06/10 07:20:59 INFO Executor: Running task 82.0 in stage 0.0 (TID 82)
[2022-06-10 07:20:59,468] {subprocess.py:92} INFO - 22/06/10 07:20:59 INFO TaskSetManager: Starting task 83.0 in stage 0.0 (TID 83) (d163094fab5f, executor driver, partition 83, PROCESS_LOCAL, 4553 bytes) taskResourceAssignments Map()
[2022-06-10 07:20:59,470] {subprocess.py:92} INFO - 22/06/10 07:20:59 INFO Executor: Finished task 81.0 in stage 0.0 (TID 81). 2646 bytes result sent to driver
[2022-06-10 07:20:59,473] {subprocess.py:92} INFO - 22/06/10 07:20:59 INFO Executor: Finished task 82.0 in stage 0.0 (TID 82). 2646 bytes result sent to driver
[2022-06-10 07:20:59,477] {subprocess.py:92} INFO - 22/06/10 07:20:59 INFO TaskSetManager: Finished task 78.0 in stage 0.0 (TID 78) in 56 ms on d163094fab5f (executor driver) (78/180)
[2022-06-10 07:20:59,478] {subprocess.py:92} INFO - 22/06/10 07:20:59 INFO Executor: Running task 83.0 in stage 0.0 (TID 83)
[2022-06-10 07:20:59,479] {subprocess.py:92} INFO - 22/06/10 07:20:59 INFO TaskSetManager: Finished task 77.0 in stage 0.0 (TID 77) in 61 ms on d163094fab5f (executor driver) (79/180)
[2022-06-10 07:20:59,479] {subprocess.py:92} INFO - 22/06/10 07:20:59 INFO TaskSetManager: Finished task 79.0 in stage 0.0 (TID 79) in 46 ms on d163094fab5f (executor driver) (80/180)
[2022-06-10 07:20:59,481] {subprocess.py:92} INFO - 22/06/10 07:20:59 INFO TaskSetManager: Starting task 84.0 in stage 0.0 (TID 84) (d163094fab5f, executor driver, partition 84, PROCESS_LOCAL, 4553 bytes) taskResourceAssignments Map()
[2022-06-10 07:20:59,482] {subprocess.py:92} INFO - 22/06/10 07:20:59 INFO Executor: Running task 84.0 in stage 0.0 (TID 84)
[2022-06-10 07:20:59,485] {subprocess.py:92} INFO - 22/06/10 07:20:59 INFO TaskSetManager: Starting task 85.0 in stage 0.0 (TID 85) (d163094fab5f, executor driver, partition 85, PROCESS_LOCAL, 4553 bytes) taskResourceAssignments Map()
[2022-06-10 07:20:59,486] {subprocess.py:92} INFO - 22/06/10 07:20:59 INFO TaskSetManager: Finished task 80.0 in stage 0.0 (TID 80) in 46 ms on d163094fab5f (executor driver) (81/180)
[2022-06-10 07:20:59,488] {subprocess.py:92} INFO - 22/06/10 07:20:59 INFO TaskSetManager: Finished task 81.0 in stage 0.0 (TID 81) in 35 ms on d163094fab5f (executor driver) (82/180)
[2022-06-10 07:20:59,490] {subprocess.py:92} INFO - 22/06/10 07:20:59 INFO Executor: Running task 85.0 in stage 0.0 (TID 85)
[2022-06-10 07:20:59,493] {subprocess.py:92} INFO - 22/06/10 07:20:59 INFO Executor: Finished task 84.0 in stage 0.0 (TID 84). 2646 bytes result sent to driver
[2022-06-10 07:20:59,499] {subprocess.py:92} INFO - 22/06/10 07:20:59 INFO TaskSetManager: Starting task 86.0 in stage 0.0 (TID 86) (d163094fab5f, executor driver, partition 86, PROCESS_LOCAL, 4553 bytes) taskResourceAssignments Map()
[2022-06-10 07:20:59,500] {subprocess.py:92} INFO - 22/06/10 07:20:59 INFO TaskSetManager: Finished task 82.0 in stage 0.0 (TID 82) in 40 ms on d163094fab5f (executor driver) (83/180)
[2022-06-10 07:20:59,502] {subprocess.py:92} INFO - 22/06/10 07:20:59 INFO Executor: Running task 86.0 in stage 0.0 (TID 86)
[2022-06-10 07:20:59,503] {subprocess.py:92} INFO - 22/06/10 07:20:59 INFO TaskSetManager: Finished task 84.0 in stage 0.0 (TID 84) in 21 ms on d163094fab5f (executor driver) (84/180)
[2022-06-10 07:20:59,505] {subprocess.py:92} INFO - 22/06/10 07:20:59 INFO Executor: Finished task 83.0 in stage 0.0 (TID 83). 2646 bytes result sent to driver
[2022-06-10 07:20:59,509] {subprocess.py:92} INFO - 22/06/10 07:20:59 INFO TaskSetManager: Starting task 87.0 in stage 0.0 (TID 87) (d163094fab5f, executor driver, partition 87, PROCESS_LOCAL, 4553 bytes) taskResourceAssignments Map()
[2022-06-10 07:20:59,510] {subprocess.py:92} INFO - 22/06/10 07:20:59 INFO Executor: Running task 87.0 in stage 0.0 (TID 87)
[2022-06-10 07:20:59,511] {subprocess.py:92} INFO - 22/06/10 07:20:59 INFO TaskSetManager: Starting task 88.0 in stage 0.0 (TID 88) (d163094fab5f, executor driver, partition 88, PROCESS_LOCAL, 4553 bytes) taskResourceAssignments Map()
[2022-06-10 07:20:59,514] {subprocess.py:92} INFO - 22/06/10 07:20:59 INFO TaskSetManager: Finished task 83.0 in stage 0.0 (TID 83) in 45 ms on d163094fab5f (executor driver) (85/180)
[2022-06-10 07:20:59,517] {subprocess.py:92} INFO - 22/06/10 07:20:59 INFO Executor: Finished task 86.0 in stage 0.0 (TID 86). 2646 bytes result sent to driver
[2022-06-10 07:20:59,517] {subprocess.py:92} INFO - 22/06/10 07:20:59 INFO Executor: Running task 88.0 in stage 0.0 (TID 88)
[2022-06-10 07:20:59,527] {subprocess.py:92} INFO - 22/06/10 07:20:59 INFO Executor: Finished task 87.0 in stage 0.0 (TID 87). 2646 bytes result sent to driver
[2022-06-10 07:20:59,530] {subprocess.py:92} INFO - 22/06/10 07:20:59 INFO Executor: Finished task 88.0 in stage 0.0 (TID 88). 2646 bytes result sent to driver
[2022-06-10 07:20:59,531] {subprocess.py:92} INFO - 22/06/10 07:20:59 INFO TaskSetManager: Starting task 89.0 in stage 0.0 (TID 89) (d163094fab5f, executor driver, partition 89, PROCESS_LOCAL, 4553 bytes) taskResourceAssignments Map()
[2022-06-10 07:20:59,532] {subprocess.py:92} INFO - 22/06/10 07:20:59 INFO Executor: Running task 89.0 in stage 0.0 (TID 89)
[2022-06-10 07:20:59,533] {subprocess.py:92} INFO - 22/06/10 07:20:59 INFO TaskSetManager: Finished task 86.0 in stage 0.0 (TID 86) in 34 ms on d163094fab5f (executor driver) (86/180)
[2022-06-10 07:20:59,534] {subprocess.py:92} INFO - 22/06/10 07:20:59 INFO Executor: Finished task 85.0 in stage 0.0 (TID 85). 2646 bytes result sent to driver
[2022-06-10 07:20:59,536] {subprocess.py:92} INFO - 22/06/10 07:20:59 INFO TaskSetManager: Starting task 90.0 in stage 0.0 (TID 90) (d163094fab5f, executor driver, partition 90, PROCESS_LOCAL, 4553 bytes) taskResourceAssignments Map()
[2022-06-10 07:20:59,538] {subprocess.py:92} INFO - 22/06/10 07:20:59 INFO TaskSetManager: Finished task 87.0 in stage 0.0 (TID 87) in 32 ms on d163094fab5f (executor driver) (87/180)
[2022-06-10 07:20:59,539] {subprocess.py:92} INFO - 22/06/10 07:20:59 INFO Executor: Running task 90.0 in stage 0.0 (TID 90)
[2022-06-10 07:20:59,542] {subprocess.py:92} INFO - 22/06/10 07:20:59 INFO TaskSetManager: Finished task 88.0 in stage 0.0 (TID 88) in 32 ms on d163094fab5f (executor driver) (88/180)
[2022-06-10 07:20:59,546] {subprocess.py:92} INFO - 22/06/10 07:20:59 INFO TaskSetManager: Starting task 91.0 in stage 0.0 (TID 91) (d163094fab5f, executor driver, partition 91, PROCESS_LOCAL, 4553 bytes) taskResourceAssignments Map()
[2022-06-10 07:20:59,548] {subprocess.py:92} INFO - 22/06/10 07:20:59 INFO Executor: Running task 91.0 in stage 0.0 (TID 91)
[2022-06-10 07:20:59,549] {subprocess.py:92} INFO - 22/06/10 07:20:59 INFO TaskSetManager: Starting task 92.0 in stage 0.0 (TID 92) (d163094fab5f, executor driver, partition 92, PROCESS_LOCAL, 4553 bytes) taskResourceAssignments Map()
[2022-06-10 07:20:59,550] {subprocess.py:92} INFO - 22/06/10 07:20:59 INFO Executor: Running task 92.0 in stage 0.0 (TID 92)
[2022-06-10 07:20:59,550] {subprocess.py:92} INFO - 22/06/10 07:20:59 INFO TaskSetManager: Finished task 85.0 in stage 0.0 (TID 85) in 67 ms on d163094fab5f (executor driver) (89/180)
[2022-06-10 07:20:59,560] {subprocess.py:92} INFO - 22/06/10 07:20:59 INFO Executor: Finished task 91.0 in stage 0.0 (TID 91). 2646 bytes result sent to driver
[2022-06-10 07:20:59,565] {subprocess.py:92} INFO - 22/06/10 07:20:59 INFO Executor: Finished task 92.0 in stage 0.0 (TID 92). 2646 bytes result sent to driver
[2022-06-10 07:20:59,568] {subprocess.py:92} INFO - 22/06/10 07:20:59 INFO TaskSetManager: Starting task 93.0 in stage 0.0 (TID 93) (d163094fab5f, executor driver, partition 93, PROCESS_LOCAL, 4553 bytes) taskResourceAssignments Map()
[2022-06-10 07:20:59,569] {subprocess.py:92} INFO - 22/06/10 07:20:59 INFO TaskSetManager: Starting task 94.0 in stage 0.0 (TID 94) (d163094fab5f, executor driver, partition 94, PROCESS_LOCAL, 4553 bytes) taskResourceAssignments Map()
[2022-06-10 07:20:59,571] {subprocess.py:92} INFO - 22/06/10 07:20:59 INFO Executor: Running task 93.0 in stage 0.0 (TID 93)
[2022-06-10 07:20:59,573] {subprocess.py:92} INFO - 22/06/10 07:20:59 INFO TaskSetManager: Finished task 92.0 in stage 0.0 (TID 92) in 15 ms on d163094fab5f (executor driver) (90/180)
[2022-06-10 07:20:59,574] {subprocess.py:92} INFO - 22/06/10 07:20:59 INFO TaskSetManager: Finished task 91.0 in stage 0.0 (TID 91) in 21 ms on d163094fab5f (executor driver) (91/180)
[2022-06-10 07:20:59,576] {subprocess.py:92} INFO - 22/06/10 07:20:59 INFO Executor: Running task 94.0 in stage 0.0 (TID 94)
[2022-06-10 07:20:59,577] {subprocess.py:92} INFO - 22/06/10 07:20:59 INFO Executor: Finished task 89.0 in stage 0.0 (TID 89). 2646 bytes result sent to driver
[2022-06-10 07:20:59,578] {subprocess.py:92} INFO - 22/06/10 07:20:59 INFO Executor: Finished task 90.0 in stage 0.0 (TID 90). 2646 bytes result sent to driver
[2022-06-10 07:20:59,579] {subprocess.py:92} INFO - 22/06/10 07:20:59 INFO TaskSetManager: Starting task 95.0 in stage 0.0 (TID 95) (d163094fab5f, executor driver, partition 95, PROCESS_LOCAL, 4553 bytes) taskResourceAssignments Map()
[2022-06-10 07:20:59,580] {subprocess.py:92} INFO - 22/06/10 07:20:59 INFO Executor: Running task 95.0 in stage 0.0 (TID 95)
[2022-06-10 07:20:59,581] {subprocess.py:92} INFO - 22/06/10 07:20:59 INFO TaskSetManager: Starting task 96.0 in stage 0.0 (TID 96) (d163094fab5f, executor driver, partition 96, PROCESS_LOCAL, 4553 bytes) taskResourceAssignments Map()
[2022-06-10 07:20:59,583] {subprocess.py:92} INFO - 22/06/10 07:20:59 INFO TaskSetManager: Finished task 89.0 in stage 0.0 (TID 89) in 53 ms on d163094fab5f (executor driver) (92/180)
[2022-06-10 07:20:59,584] {subprocess.py:92} INFO - 22/06/10 07:20:59 INFO TaskSetManager: Finished task 90.0 in stage 0.0 (TID 90) in 48 ms on d163094fab5f (executor driver) (93/180)
[2022-06-10 07:20:59,586] {subprocess.py:92} INFO - 22/06/10 07:20:59 INFO Executor: Running task 96.0 in stage 0.0 (TID 96)
[2022-06-10 07:20:59,588] {subprocess.py:92} INFO - 22/06/10 07:20:59 INFO Executor: Finished task 93.0 in stage 0.0 (TID 93). 2646 bytes result sent to driver
[2022-06-10 07:20:59,590] {subprocess.py:92} INFO - 22/06/10 07:20:59 INFO TaskSetManager: Starting task 97.0 in stage 0.0 (TID 97) (d163094fab5f, executor driver, partition 97, PROCESS_LOCAL, 4553 bytes) taskResourceAssignments Map()
[2022-06-10 07:20:59,591] {subprocess.py:92} INFO - 22/06/10 07:20:59 INFO TaskSetManager: Finished task 93.0 in stage 0.0 (TID 93) in 30 ms on d163094fab5f (executor driver) (94/180)
[2022-06-10 07:20:59,592] {subprocess.py:92} INFO - 22/06/10 07:20:59 INFO Executor: Running task 97.0 in stage 0.0 (TID 97)
[2022-06-10 07:20:59,602] {subprocess.py:92} INFO - 22/06/10 07:20:59 INFO Executor: Finished task 97.0 in stage 0.0 (TID 97). 2646 bytes result sent to driver
[2022-06-10 07:20:59,604] {subprocess.py:92} INFO - 22/06/10 07:20:59 INFO TaskSetManager: Starting task 98.0 in stage 0.0 (TID 98) (d163094fab5f, executor driver, partition 98, PROCESS_LOCAL, 4553 bytes) taskResourceAssignments Map()
[2022-06-10 07:20:59,605] {subprocess.py:92} INFO - 22/06/10 07:20:59 INFO TaskSetManager: Finished task 97.0 in stage 0.0 (TID 97) in 16 ms on d163094fab5f (executor driver) (95/180)
[2022-06-10 07:20:59,606] {subprocess.py:92} INFO - 22/06/10 07:20:59 INFO Executor: Running task 98.0 in stage 0.0 (TID 98)
[2022-06-10 07:20:59,606] {subprocess.py:92} INFO - 22/06/10 07:20:59 INFO Executor: Finished task 96.0 in stage 0.0 (TID 96). 2689 bytes result sent to driver
[2022-06-10 07:20:59,608] {subprocess.py:92} INFO - 22/06/10 07:20:59 INFO Executor: Finished task 95.0 in stage 0.0 (TID 95). 2646 bytes result sent to driver
[2022-06-10 07:20:59,608] {subprocess.py:92} INFO - 22/06/10 07:20:59 INFO TaskSetManager: Starting task 99.0 in stage 0.0 (TID 99) (d163094fab5f, executor driver, partition 99, PROCESS_LOCAL, 4553 bytes) taskResourceAssignments Map()
[2022-06-10 07:20:59,609] {subprocess.py:92} INFO - 22/06/10 07:20:59 INFO TaskSetManager: Finished task 96.0 in stage 0.0 (TID 96) in 29 ms on d163094fab5f (executor driver) (96/180)
[2022-06-10 07:20:59,610] {subprocess.py:92} INFO - 22/06/10 07:20:59 INFO Executor: Running task 99.0 in stage 0.0 (TID 99)
[2022-06-10 07:20:59,611] {subprocess.py:92} INFO - 22/06/10 07:20:59 INFO TaskSetManager: Starting task 100.0 in stage 0.0 (TID 100) (d163094fab5f, executor driver, partition 100, PROCESS_LOCAL, 4553 bytes) taskResourceAssignments Map()
[2022-06-10 07:20:59,612] {subprocess.py:92} INFO - 22/06/10 07:20:59 INFO TaskSetManager: Finished task 95.0 in stage 0.0 (TID 95) in 37 ms on d163094fab5f (executor driver) (97/180)
[2022-06-10 07:20:59,613] {subprocess.py:92} INFO - 22/06/10 07:20:59 INFO Executor: Running task 100.0 in stage 0.0 (TID 100)
[2022-06-10 07:20:59,615] {subprocess.py:92} INFO - 22/06/10 07:20:59 INFO Executor: Finished task 94.0 in stage 0.0 (TID 94). 2646 bytes result sent to driver
[2022-06-10 07:20:59,617] {subprocess.py:92} INFO - 22/06/10 07:20:59 INFO TaskSetManager: Starting task 101.0 in stage 0.0 (TID 101) (d163094fab5f, executor driver, partition 101, PROCESS_LOCAL, 4553 bytes) taskResourceAssignments Map()
[2022-06-10 07:20:59,618] {subprocess.py:92} INFO - 22/06/10 07:20:59 INFO TaskSetManager: Finished task 94.0 in stage 0.0 (TID 94) in 56 ms on d163094fab5f (executor driver) (98/180)
[2022-06-10 07:20:59,619] {subprocess.py:92} INFO - 22/06/10 07:20:59 INFO Executor: Running task 101.0 in stage 0.0 (TID 101)
[2022-06-10 07:20:59,620] {subprocess.py:92} INFO - 22/06/10 07:20:59 INFO Executor: Finished task 98.0 in stage 0.0 (TID 98). 2646 bytes result sent to driver
[2022-06-10 07:20:59,622] {subprocess.py:92} INFO - 22/06/10 07:20:59 INFO TaskSetManager: Starting task 102.0 in stage 0.0 (TID 102) (d163094fab5f, executor driver, partition 102, PROCESS_LOCAL, 4553 bytes) taskResourceAssignments Map()
[2022-06-10 07:20:59,623] {subprocess.py:92} INFO - 22/06/10 07:20:59 INFO TaskSetManager: Finished task 98.0 in stage 0.0 (TID 98) in 19 ms on d163094fab5f (executor driver) (99/180)
[2022-06-10 07:20:59,624] {subprocess.py:92} INFO - 22/06/10 07:20:59 INFO Executor: Running task 102.0 in stage 0.0 (TID 102)
[2022-06-10 07:20:59,636] {subprocess.py:92} INFO - 22/06/10 07:20:59 INFO Executor: Finished task 102.0 in stage 0.0 (TID 102). 2646 bytes result sent to driver
[2022-06-10 07:20:59,639] {subprocess.py:92} INFO - 22/06/10 07:20:59 INFO TaskSetManager: Starting task 103.0 in stage 0.0 (TID 103) (d163094fab5f, executor driver, partition 103, PROCESS_LOCAL, 4553 bytes) taskResourceAssignments Map()
[2022-06-10 07:20:59,641] {subprocess.py:92} INFO - 22/06/10 07:20:59 INFO Executor: Finished task 101.0 in stage 0.0 (TID 101). 2646 bytes result sent to driver
[2022-06-10 07:20:59,644] {subprocess.py:92} INFO - 22/06/10 07:20:59 INFO Executor: Finished task 100.0 in stage 0.0 (TID 100). 2646 bytes result sent to driver
[2022-06-10 07:20:59,644] {subprocess.py:92} INFO - 22/06/10 07:20:59 INFO Executor: Running task 103.0 in stage 0.0 (TID 103)
[2022-06-10 07:20:59,645] {subprocess.py:92} INFO - 22/06/10 07:20:59 INFO TaskSetManager: Finished task 102.0 in stage 0.0 (TID 102) in 19 ms on d163094fab5f (executor driver) (100/180)
[2022-06-10 07:20:59,646] {subprocess.py:92} INFO - 22/06/10 07:20:59 INFO TaskSetManager: Starting task 104.0 in stage 0.0 (TID 104) (d163094fab5f, executor driver, partition 104, PROCESS_LOCAL, 4553 bytes) taskResourceAssignments Map()
[2022-06-10 07:20:59,650] {subprocess.py:92} INFO - 22/06/10 07:20:59 INFO TaskSetManager: Starting task 105.0 in stage 0.0 (TID 105) (d163094fab5f, executor driver, partition 105, PROCESS_LOCAL, 4553 bytes) taskResourceAssignments Map()
[2022-06-10 07:20:59,651] {subprocess.py:92} INFO - 22/06/10 07:20:59 INFO TaskSetManager: Finished task 101.0 in stage 0.0 (TID 101) in 31 ms on d163094fab5f (executor driver) (101/180)
[2022-06-10 07:20:59,652] {subprocess.py:92} INFO - 22/06/10 07:20:59 INFO Executor: Running task 105.0 in stage 0.0 (TID 105)
[2022-06-10 07:20:59,653] {subprocess.py:92} INFO - 22/06/10 07:20:59 INFO Executor: Running task 104.0 in stage 0.0 (TID 104)
[2022-06-10 07:20:59,653] {subprocess.py:92} INFO - 22/06/10 07:20:59 INFO TaskSetManager: Finished task 100.0 in stage 0.0 (TID 100) in 38 ms on d163094fab5f (executor driver) (102/180)
[2022-06-10 07:20:59,654] {subprocess.py:92} INFO - 22/06/10 07:20:59 INFO Executor: Finished task 99.0 in stage 0.0 (TID 99). 2646 bytes result sent to driver
[2022-06-10 07:20:59,655] {subprocess.py:92} INFO - 22/06/10 07:20:59 INFO TaskSetManager: Starting task 106.0 in stage 0.0 (TID 106) (d163094fab5f, executor driver, partition 106, PROCESS_LOCAL, 4553 bytes) taskResourceAssignments Map()
[2022-06-10 07:20:59,656] {subprocess.py:92} INFO - 22/06/10 07:20:59 INFO Executor: Running task 106.0 in stage 0.0 (TID 106)
[2022-06-10 07:20:59,660] {subprocess.py:92} INFO - 22/06/10 07:20:59 INFO Executor: Finished task 103.0 in stage 0.0 (TID 103). 2646 bytes result sent to driver
[2022-06-10 07:20:59,662] {subprocess.py:92} INFO - 22/06/10 07:20:59 INFO TaskSetManager: Finished task 99.0 in stage 0.0 (TID 99) in 47 ms on d163094fab5f (executor driver) (103/180)
[2022-06-10 07:20:59,663] {subprocess.py:92} INFO - 22/06/10 07:20:59 INFO TaskSetManager: Starting task 107.0 in stage 0.0 (TID 107) (d163094fab5f, executor driver, partition 107, PROCESS_LOCAL, 4553 bytes) taskResourceAssignments Map()
[2022-06-10 07:20:59,663] {subprocess.py:92} INFO - 22/06/10 07:20:59 INFO TaskSetManager: Finished task 103.0 in stage 0.0 (TID 103) in 18 ms on d163094fab5f (executor driver) (104/180)
[2022-06-10 07:20:59,664] {subprocess.py:92} INFO - 22/06/10 07:20:59 INFO Executor: Running task 107.0 in stage 0.0 (TID 107)
[2022-06-10 07:20:59,665] {subprocess.py:92} INFO - 22/06/10 07:20:59 INFO Executor: Finished task 105.0 in stage 0.0 (TID 105). 2646 bytes result sent to driver
[2022-06-10 07:20:59,667] {subprocess.py:92} INFO - 22/06/10 07:20:59 INFO TaskSetManager: Starting task 108.0 in stage 0.0 (TID 108) (d163094fab5f, executor driver, partition 108, PROCESS_LOCAL, 4553 bytes) taskResourceAssignments Map()
[2022-06-10 07:20:59,668] {subprocess.py:92} INFO - 22/06/10 07:20:59 INFO TaskSetManager: Finished task 105.0 in stage 0.0 (TID 105) in 22 ms on d163094fab5f (executor driver) (105/180)
[2022-06-10 07:20:59,669] {subprocess.py:92} INFO - 22/06/10 07:20:59 INFO Executor: Running task 108.0 in stage 0.0 (TID 108)
[2022-06-10 07:20:59,671] {subprocess.py:92} INFO - 22/06/10 07:20:59 INFO Executor: Finished task 107.0 in stage 0.0 (TID 107). 2646 bytes result sent to driver
[2022-06-10 07:20:59,673] {subprocess.py:92} INFO - 22/06/10 07:20:59 INFO TaskSetManager: Starting task 109.0 in stage 0.0 (TID 109) (d163094fab5f, executor driver, partition 109, PROCESS_LOCAL, 4553 bytes) taskResourceAssignments Map()
[2022-06-10 07:20:59,674] {subprocess.py:92} INFO - 22/06/10 07:20:59 INFO Executor: Running task 109.0 in stage 0.0 (TID 109)
[2022-06-10 07:20:59,675] {subprocess.py:92} INFO - 22/06/10 07:20:59 INFO TaskSetManager: Finished task 107.0 in stage 0.0 (TID 107) in 19 ms on d163094fab5f (executor driver) (106/180)
[2022-06-10 07:20:59,677] {subprocess.py:92} INFO - 22/06/10 07:20:59 INFO Executor: Finished task 104.0 in stage 0.0 (TID 104). 2646 bytes result sent to driver
[2022-06-10 07:20:59,678] {subprocess.py:92} INFO - 22/06/10 07:20:59 INFO TaskSetManager: Starting task 110.0 in stage 0.0 (TID 110) (d163094fab5f, executor driver, partition 110, PROCESS_LOCAL, 4553 bytes) taskResourceAssignments Map()
[2022-06-10 07:20:59,679] {subprocess.py:92} INFO - 22/06/10 07:20:59 INFO TaskSetManager: Finished task 104.0 in stage 0.0 (TID 104) in 35 ms on d163094fab5f (executor driver) (107/180)
[2022-06-10 07:20:59,681] {subprocess.py:92} INFO - 22/06/10 07:20:59 INFO Executor: Running task 110.0 in stage 0.0 (TID 110)
[2022-06-10 07:20:59,683] {subprocess.py:92} INFO - 22/06/10 07:20:59 INFO Executor: Finished task 106.0 in stage 0.0 (TID 106). 2646 bytes result sent to driver
[2022-06-10 07:20:59,684] {subprocess.py:92} INFO - 22/06/10 07:20:59 INFO TaskSetManager: Starting task 111.0 in stage 0.0 (TID 111) (d163094fab5f, executor driver, partition 111, PROCESS_LOCAL, 4553 bytes) taskResourceAssignments Map()
[2022-06-10 07:20:59,686] {subprocess.py:92} INFO - 22/06/10 07:20:59 INFO TaskSetManager: Finished task 106.0 in stage 0.0 (TID 106) in 33 ms on d163094fab5f (executor driver) (108/180)
[2022-06-10 07:20:59,687] {subprocess.py:92} INFO - 22/06/10 07:20:59 INFO Executor: Running task 111.0 in stage 0.0 (TID 111)
[2022-06-10 07:20:59,692] {subprocess.py:92} INFO - 22/06/10 07:20:59 INFO Executor: Finished task 109.0 in stage 0.0 (TID 109). 2646 bytes result sent to driver
[2022-06-10 07:20:59,694] {subprocess.py:92} INFO - 22/06/10 07:20:59 INFO TaskSetManager: Starting task 112.0 in stage 0.0 (TID 112) (d163094fab5f, executor driver, partition 112, PROCESS_LOCAL, 4553 bytes) taskResourceAssignments Map()
[2022-06-10 07:20:59,695] {subprocess.py:92} INFO - 22/06/10 07:20:59 INFO Executor: Running task 112.0 in stage 0.0 (TID 112)
[2022-06-10 07:20:59,695] {subprocess.py:92} INFO - 22/06/10 07:20:59 INFO TaskSetManager: Finished task 109.0 in stage 0.0 (TID 109) in 22 ms on d163094fab5f (executor driver) (109/180)
[2022-06-10 07:20:59,697] {subprocess.py:92} INFO - 22/06/10 07:20:59 INFO Executor: Finished task 108.0 in stage 0.0 (TID 108). 2689 bytes result sent to driver
[2022-06-10 07:20:59,698] {subprocess.py:92} INFO - 22/06/10 07:20:59 INFO TaskSetManager: Starting task 113.0 in stage 0.0 (TID 113) (d163094fab5f, executor driver, partition 113, PROCESS_LOCAL, 4553 bytes) taskResourceAssignments Map()
[2022-06-10 07:20:59,699] {subprocess.py:92} INFO - 22/06/10 07:20:59 INFO TaskSetManager: Finished task 108.0 in stage 0.0 (TID 108) in 33 ms on d163094fab5f (executor driver) (110/180)
[2022-06-10 07:20:59,700] {subprocess.py:92} INFO - 22/06/10 07:20:59 INFO Executor: Running task 113.0 in stage 0.0 (TID 113)
[2022-06-10 07:20:59,713] {subprocess.py:92} INFO - 22/06/10 07:20:59 INFO Executor: Finished task 112.0 in stage 0.0 (TID 112). 2646 bytes result sent to driver
[2022-06-10 07:20:59,715] {subprocess.py:92} INFO - 22/06/10 07:20:59 INFO Executor: Finished task 110.0 in stage 0.0 (TID 110). 2646 bytes result sent to driver
[2022-06-10 07:20:59,716] {subprocess.py:92} INFO - 22/06/10 07:20:59 INFO TaskSetManager: Starting task 114.0 in stage 0.0 (TID 114) (d163094fab5f, executor driver, partition 114, PROCESS_LOCAL, 4553 bytes) taskResourceAssignments Map()
[2022-06-10 07:20:59,717] {subprocess.py:92} INFO - 22/06/10 07:20:59 INFO Executor: Running task 114.0 in stage 0.0 (TID 114)
[2022-06-10 07:20:59,718] {subprocess.py:92} INFO - 22/06/10 07:20:59 INFO Executor: Finished task 111.0 in stage 0.0 (TID 111). 2646 bytes result sent to driver
[2022-06-10 07:20:59,719] {subprocess.py:92} INFO - 22/06/10 07:20:59 INFO Executor: Finished task 113.0 in stage 0.0 (TID 113). 2646 bytes result sent to driver
[2022-06-10 07:20:59,720] {subprocess.py:92} INFO - 22/06/10 07:20:59 INFO TaskSetManager: Starting task 115.0 in stage 0.0 (TID 115) (d163094fab5f, executor driver, partition 115, PROCESS_LOCAL, 4553 bytes) taskResourceAssignments Map()
[2022-06-10 07:20:59,721] {subprocess.py:92} INFO - 22/06/10 07:20:59 INFO TaskSetManager: Finished task 112.0 in stage 0.0 (TID 112) in 27 ms on d163094fab5f (executor driver) (111/180)
[2022-06-10 07:20:59,721] {subprocess.py:92} INFO - 22/06/10 07:20:59 INFO Executor: Running task 115.0 in stage 0.0 (TID 115)
[2022-06-10 07:20:59,724] {subprocess.py:92} INFO - 22/06/10 07:20:59 INFO TaskSetManager: Starting task 116.0 in stage 0.0 (TID 116) (d163094fab5f, executor driver, partition 116, PROCESS_LOCAL, 4553 bytes) taskResourceAssignments Map()
[2022-06-10 07:20:59,725] {subprocess.py:92} INFO - 22/06/10 07:20:59 INFO TaskSetManager: Finished task 110.0 in stage 0.0 (TID 110) in 47 ms on d163094fab5f (executor driver) (112/180)
[2022-06-10 07:20:59,726] {subprocess.py:92} INFO - 22/06/10 07:20:59 INFO Executor: Running task 116.0 in stage 0.0 (TID 116)
[2022-06-10 07:20:59,728] {subprocess.py:92} INFO - 22/06/10 07:20:59 INFO TaskSetManager: Starting task 117.0 in stage 0.0 (TID 117) (d163094fab5f, executor driver, partition 117, PROCESS_LOCAL, 4553 bytes) taskResourceAssignments Map()
[2022-06-10 07:20:59,729] {subprocess.py:92} INFO - 22/06/10 07:20:59 INFO Executor: Running task 117.0 in stage 0.0 (TID 117)
[2022-06-10 07:20:59,731] {subprocess.py:92} INFO - 22/06/10 07:20:59 INFO TaskSetManager: Finished task 113.0 in stage 0.0 (TID 113) in 32 ms on d163094fab5f (executor driver) (113/180)
[2022-06-10 07:20:59,731] {subprocess.py:92} INFO - 22/06/10 07:20:59 INFO TaskSetManager: Finished task 111.0 in stage 0.0 (TID 111) in 47 ms on d163094fab5f (executor driver) (114/180)
[2022-06-10 07:20:59,739] {subprocess.py:92} INFO - 22/06/10 07:20:59 INFO Executor: Finished task 117.0 in stage 0.0 (TID 117). 2646 bytes result sent to driver
[2022-06-10 07:20:59,741] {subprocess.py:92} INFO - 22/06/10 07:20:59 INFO TaskSetManager: Starting task 118.0 in stage 0.0 (TID 118) (d163094fab5f, executor driver, partition 118, PROCESS_LOCAL, 4553 bytes) taskResourceAssignments Map()
[2022-06-10 07:20:59,742] {subprocess.py:92} INFO - 22/06/10 07:20:59 INFO TaskSetManager: Finished task 117.0 in stage 0.0 (TID 117) in 15 ms on d163094fab5f (executor driver) (115/180)
[2022-06-10 07:20:59,742] {subprocess.py:92} INFO - 22/06/10 07:20:59 INFO Executor: Running task 118.0 in stage 0.0 (TID 118)
[2022-06-10 07:20:59,746] {subprocess.py:92} INFO - 22/06/10 07:20:59 INFO Executor: Finished task 115.0 in stage 0.0 (TID 115). 2646 bytes result sent to driver
[2022-06-10 07:20:59,747] {subprocess.py:92} INFO - 22/06/10 07:20:59 INFO Executor: Finished task 116.0 in stage 0.0 (TID 116). 2646 bytes result sent to driver
[2022-06-10 07:20:59,748] {subprocess.py:92} INFO - 22/06/10 07:20:59 INFO TaskSetManager: Starting task 119.0 in stage 0.0 (TID 119) (d163094fab5f, executor driver, partition 119, PROCESS_LOCAL, 4553 bytes) taskResourceAssignments Map()
[2022-06-10 07:20:59,749] {subprocess.py:92} INFO - 22/06/10 07:20:59 INFO TaskSetManager: Finished task 115.0 in stage 0.0 (TID 115) in 32 ms on d163094fab5f (executor driver) (116/180)
[2022-06-10 07:20:59,750] {subprocess.py:92} INFO - 22/06/10 07:20:59 INFO Executor: Running task 119.0 in stage 0.0 (TID 119)
[2022-06-10 07:20:59,753] {subprocess.py:92} INFO - 22/06/10 07:20:59 INFO Executor: Finished task 118.0 in stage 0.0 (TID 118). 2646 bytes result sent to driver
[2022-06-10 07:20:59,754] {subprocess.py:92} INFO - 22/06/10 07:20:59 INFO TaskSetManager: Starting task 120.0 in stage 0.0 (TID 120) (d163094fab5f, executor driver, partition 120, PROCESS_LOCAL, 4553 bytes) taskResourceAssignments Map()
[2022-06-10 07:20:59,755] {subprocess.py:92} INFO - 22/06/10 07:20:59 INFO Executor: Running task 120.0 in stage 0.0 (TID 120)
[2022-06-10 07:20:59,757] {subprocess.py:92} INFO - 22/06/10 07:20:59 INFO TaskSetManager: Starting task 121.0 in stage 0.0 (TID 121) (d163094fab5f, executor driver, partition 121, PROCESS_LOCAL, 4553 bytes) taskResourceAssignments Map()
[2022-06-10 07:20:59,758] {subprocess.py:92} INFO - 22/06/10 07:20:59 INFO TaskSetManager: Finished task 118.0 in stage 0.0 (TID 118) in 17 ms on d163094fab5f (executor driver) (117/180)
[2022-06-10 07:20:59,758] {subprocess.py:92} INFO - 22/06/10 07:20:59 INFO TaskSetManager: Finished task 116.0 in stage 0.0 (TID 116) in 35 ms on d163094fab5f (executor driver) (118/180)
[2022-06-10 07:20:59,759] {subprocess.py:92} INFO - 22/06/10 07:20:59 INFO Executor: Running task 121.0 in stage 0.0 (TID 121)
[2022-06-10 07:20:59,764] {subprocess.py:92} INFO - 22/06/10 07:20:59 INFO Executor: Finished task 114.0 in stage 0.0 (TID 114). 2646 bytes result sent to driver
[2022-06-10 07:20:59,765] {subprocess.py:92} INFO - 22/06/10 07:20:59 INFO TaskSetManager: Starting task 122.0 in stage 0.0 (TID 122) (d163094fab5f, executor driver, partition 122, PROCESS_LOCAL, 4553 bytes) taskResourceAssignments Map()
[2022-06-10 07:20:59,766] {subprocess.py:92} INFO - 22/06/10 07:20:59 INFO TaskSetManager: Finished task 114.0 in stage 0.0 (TID 114) in 51 ms on d163094fab5f (executor driver) (119/180)
[2022-06-10 07:20:59,767] {subprocess.py:92} INFO - 22/06/10 07:20:59 INFO Executor: Running task 122.0 in stage 0.0 (TID 122)
[2022-06-10 07:20:59,769] {subprocess.py:92} INFO - 22/06/10 07:20:59 INFO Executor: Finished task 119.0 in stage 0.0 (TID 119). 2646 bytes result sent to driver
[2022-06-10 07:20:59,771] {subprocess.py:92} INFO - 22/06/10 07:20:59 INFO TaskSetManager: Starting task 123.0 in stage 0.0 (TID 123) (d163094fab5f, executor driver, partition 123, PROCESS_LOCAL, 4553 bytes) taskResourceAssignments Map()
[2022-06-10 07:20:59,771] {subprocess.py:92} INFO - 22/06/10 07:20:59 INFO Executor: Finished task 120.0 in stage 0.0 (TID 120). 2646 bytes result sent to driver
[2022-06-10 07:20:59,772] {subprocess.py:92} INFO - 22/06/10 07:20:59 INFO TaskSetManager: Finished task 119.0 in stage 0.0 (TID 119) in 24 ms on d163094fab5f (executor driver) (120/180)
[2022-06-10 07:20:59,774] {subprocess.py:92} INFO - 22/06/10 07:20:59 INFO Executor: Running task 123.0 in stage 0.0 (TID 123)
[2022-06-10 07:20:59,775] {subprocess.py:92} INFO - 22/06/10 07:20:59 INFO TaskSetManager: Starting task 124.0 in stage 0.0 (TID 124) (d163094fab5f, executor driver, partition 124, PROCESS_LOCAL, 4553 bytes) taskResourceAssignments Map()
[2022-06-10 07:20:59,776] {subprocess.py:92} INFO - 22/06/10 07:20:59 INFO TaskSetManager: Finished task 120.0 in stage 0.0 (TID 120) in 23 ms on d163094fab5f (executor driver) (121/180)
[2022-06-10 07:20:59,777] {subprocess.py:92} INFO - 22/06/10 07:20:59 INFO Executor: Running task 124.0 in stage 0.0 (TID 124)
[2022-06-10 07:20:59,782] {subprocess.py:92} INFO - 22/06/10 07:20:59 INFO Executor: Finished task 121.0 in stage 0.0 (TID 121). 2646 bytes result sent to driver
[2022-06-10 07:20:59,784] {subprocess.py:92} INFO - 22/06/10 07:20:59 INFO TaskSetManager: Starting task 125.0 in stage 0.0 (TID 125) (d163094fab5f, executor driver, partition 125, PROCESS_LOCAL, 4553 bytes) taskResourceAssignments Map()
[2022-06-10 07:20:59,785] {subprocess.py:92} INFO - 22/06/10 07:20:59 INFO TaskSetManager: Finished task 121.0 in stage 0.0 (TID 121) in 28 ms on d163094fab5f (executor driver) (122/180)
[2022-06-10 07:20:59,792] {subprocess.py:92} INFO - 22/06/10 07:20:59 INFO Executor: Running task 125.0 in stage 0.0 (TID 125)
[2022-06-10 07:20:59,797] {subprocess.py:92} INFO - 22/06/10 07:20:59 INFO Executor: Finished task 124.0 in stage 0.0 (TID 124). 2646 bytes result sent to driver
[2022-06-10 07:20:59,798] {subprocess.py:92} INFO - 22/06/10 07:20:59 INFO TaskSetManager: Starting task 126.0 in stage 0.0 (TID 126) (d163094fab5f, executor driver, partition 126, PROCESS_LOCAL, 4553 bytes) taskResourceAssignments Map()
[2022-06-10 07:20:59,799] {subprocess.py:92} INFO - 22/06/10 07:20:59 INFO Executor: Running task 126.0 in stage 0.0 (TID 126)
[2022-06-10 07:20:59,800] {subprocess.py:92} INFO - 22/06/10 07:20:59 INFO TaskSetManager: Finished task 124.0 in stage 0.0 (TID 124) in 24 ms on d163094fab5f (executor driver) (123/180)
[2022-06-10 07:20:59,804] {subprocess.py:92} INFO - 22/06/10 07:20:59 INFO Executor: Finished task 123.0 in stage 0.0 (TID 123). 2646 bytes result sent to driver
[2022-06-10 07:20:59,805] {subprocess.py:92} INFO - 22/06/10 07:20:59 INFO TaskSetManager: Starting task 127.0 in stage 0.0 (TID 127) (d163094fab5f, executor driver, partition 127, PROCESS_LOCAL, 4553 bytes) taskResourceAssignments Map()
[2022-06-10 07:20:59,806] {subprocess.py:92} INFO - 22/06/10 07:20:59 INFO Executor: Finished task 122.0 in stage 0.0 (TID 122). 2646 bytes result sent to driver
[2022-06-10 07:20:59,807] {subprocess.py:92} INFO - 22/06/10 07:20:59 INFO TaskSetManager: Finished task 123.0 in stage 0.0 (TID 123) in 36 ms on d163094fab5f (executor driver) (124/180)
[2022-06-10 07:20:59,808] {subprocess.py:92} INFO - 22/06/10 07:20:59 INFO Executor: Running task 127.0 in stage 0.0 (TID 127)
