[2022-06-07 06:47:56,620] {taskinstance.py:1159} INFO - Dependencies all met for <TaskInstance: hands_on_test.generate_sql_requirement scheduled__2022-06-06T00:00:00+00:00 [queued]>
[2022-06-07 06:47:56,637] {taskinstance.py:1159} INFO - Dependencies all met for <TaskInstance: hands_on_test.generate_sql_requirement scheduled__2022-06-06T00:00:00+00:00 [queued]>
[2022-06-07 06:47:56,638] {taskinstance.py:1356} INFO - 
--------------------------------------------------------------------------------
[2022-06-07 06:47:56,639] {taskinstance.py:1357} INFO - Starting attempt 1 of 2
[2022-06-07 06:47:56,640] {taskinstance.py:1358} INFO - 
--------------------------------------------------------------------------------
[2022-06-07 06:47:56,659] {taskinstance.py:1377} INFO - Executing <Task(BashOperator): generate_sql_requirement> on 2022-06-06 00:00:00+00:00
[2022-06-07 06:47:56,667] {standard_task_runner.py:52} INFO - Started process 8455 to run task
[2022-06-07 06:47:56,672] {standard_task_runner.py:79} INFO - Running: ['***', 'tasks', 'run', 'hands_on_test', 'generate_sql_requirement', 'scheduled__2022-06-06T00:00:00+00:00', '--job-id', '59', '--raw', '--subdir', 'DAGS_FOLDER/dag.py', '--cfg-path', '/tmp/tmpld1c8apd', '--error-file', '/tmp/tmpb8w18duj']
[2022-06-07 06:47:56,674] {standard_task_runner.py:80} INFO - Job 59: Subtask generate_sql_requirement
[2022-06-07 06:47:56,756] {task_command.py:369} INFO - Running <TaskInstance: hands_on_test.generate_sql_requirement scheduled__2022-06-06T00:00:00+00:00 [running]> on host a4a1e1d603db
[2022-06-07 06:47:56,875] {taskinstance.py:1571} INFO - Exporting the following env vars:
AIRFLOW_CTX_DAG_OWNER=pathairs
AIRFLOW_CTX_DAG_ID=hands_on_test
AIRFLOW_CTX_TASK_ID=generate_sql_requirement
AIRFLOW_CTX_EXECUTION_DATE=2022-06-06T00:00:00+00:00
AIRFLOW_CTX_TRY_NUMBER=1
AIRFLOW_CTX_DAG_RUN_ID=scheduled__2022-06-06T00:00:00+00:00
[2022-06-07 06:47:56,878] {subprocess.py:62} INFO - Tmp dir root location: 
 /tmp
[2022-06-07 06:47:56,880] {subprocess.py:74} INFO - Running command: ['bash', '-c', 'docker exec spark-master /spark/bin/spark-submit --master local[*] --name spark_create_restaurant_detail_new /home/script/sql_requirement.py ']
[2022-06-07 06:47:56,894] {subprocess.py:85} INFO - Output:
[2022-06-07 06:47:59,423] {subprocess.py:92} INFO - 22/06/07 06:47:59 WARN NativeCodeLoader: Unable to load native-hadoop library for your platform... using builtin-java classes where applicable
[2022-06-07 06:48:00,303] {subprocess.py:92} INFO - Using Spark's default log4j profile: org/apache/spark/log4j-defaults.properties
[2022-06-07 06:48:00,321] {subprocess.py:92} INFO - 22/06/07 06:48:00 INFO SparkContext: Running Spark version 3.1.1
[2022-06-07 06:48:00,379] {subprocess.py:92} INFO - 22/06/07 06:48:00 INFO ResourceUtils: ==============================================================
[2022-06-07 06:48:00,381] {subprocess.py:92} INFO - 22/06/07 06:48:00 INFO ResourceUtils: No custom resources configured for spark.driver.
[2022-06-07 06:48:00,382] {subprocess.py:92} INFO - 22/06/07 06:48:00 INFO ResourceUtils: ==============================================================
[2022-06-07 06:48:00,383] {subprocess.py:92} INFO - 22/06/07 06:48:00 INFO SparkContext: Submitted application: spark_create_restaurant_detail_new
[2022-06-07 06:48:00,411] {subprocess.py:92} INFO - 22/06/07 06:48:00 INFO ResourceProfile: Default ResourceProfile created, executor resources: Map(cores -> name: cores, amount: 1, script: , vendor: , memory -> name: memory, amount: 1024, script: , vendor: , offHeap -> name: offHeap, amount: 0, script: , vendor: ), task resources: Map(cpus -> name: cpus, amount: 1.0)
[2022-06-07 06:48:00,430] {subprocess.py:92} INFO - 22/06/07 06:48:00 INFO ResourceProfile: Limiting resource is cpu
[2022-06-07 06:48:00,431] {subprocess.py:92} INFO - 22/06/07 06:48:00 INFO ResourceProfileManager: Added ResourceProfile id: 0
[2022-06-07 06:48:00,499] {subprocess.py:92} INFO - 22/06/07 06:48:00 INFO SecurityManager: Changing view acls to: root
[2022-06-07 06:48:00,500] {subprocess.py:92} INFO - 22/06/07 06:48:00 INFO SecurityManager: Changing modify acls to: root
[2022-06-07 06:48:00,502] {subprocess.py:92} INFO - 22/06/07 06:48:00 INFO SecurityManager: Changing view acls groups to:
[2022-06-07 06:48:00,503] {subprocess.py:92} INFO - 22/06/07 06:48:00 INFO SecurityManager: Changing modify acls groups to:
[2022-06-07 06:48:00,504] {subprocess.py:92} INFO - 22/06/07 06:48:00 INFO SecurityManager: SecurityManager: authentication disabled; ui acls disabled; users  with view permissions: Set(root); groups with view permissions: Set(); users  with modify permissions: Set(root); groups with modify permissions: Set()
[2022-06-07 06:48:00,766] {subprocess.py:92} INFO - 22/06/07 06:48:00 INFO Utils: Successfully started service 'sparkDriver' on port 35889.
[2022-06-07 06:48:00,803] {subprocess.py:92} INFO - 22/06/07 06:48:00 INFO SparkEnv: Registering MapOutputTracker
[2022-06-07 06:48:00,856] {subprocess.py:92} INFO - 22/06/07 06:48:00 INFO SparkEnv: Registering BlockManagerMaster
[2022-06-07 06:48:00,880] {subprocess.py:92} INFO - 22/06/07 06:48:00 INFO BlockManagerMasterEndpoint: Using org.apache.spark.storage.DefaultTopologyMapper for getting topology information
[2022-06-07 06:48:00,882] {subprocess.py:92} INFO - 22/06/07 06:48:00 INFO BlockManagerMasterEndpoint: BlockManagerMasterEndpoint up
[2022-06-07 06:48:00,887] {subprocess.py:92} INFO - 22/06/07 06:48:00 INFO SparkEnv: Registering BlockManagerMasterHeartbeat
[2022-06-07 06:48:00,905] {subprocess.py:92} INFO - 22/06/07 06:48:00 INFO DiskBlockManager: Created local directory at /tmp/blockmgr-41ed72be-20dc-4bd4-8669-5b0da32ef8dd
[2022-06-07 06:48:00,940] {subprocess.py:92} INFO - 22/06/07 06:48:00 INFO MemoryStore: MemoryStore started with capacity 366.3 MiB
[2022-06-07 06:48:00,974] {subprocess.py:92} INFO - 22/06/07 06:48:00 INFO SparkEnv: Registering OutputCommitCoordinator
[2022-06-07 06:48:01,314] {subprocess.py:92} INFO - 22/06/07 06:48:01 INFO Utils: Successfully started service 'SparkUI' on port 4040.
[2022-06-07 06:48:01,389] {subprocess.py:92} INFO - 22/06/07 06:48:01 INFO SparkUI: Bound SparkUI to 0.0.0.0, and started at http://d952e2b2ede8:4040
[2022-06-07 06:48:01,709] {subprocess.py:92} INFO - 22/06/07 06:48:01 INFO Executor: Starting executor ID driver on host d952e2b2ede8
[2022-06-07 06:48:01,746] {subprocess.py:92} INFO - 22/06/07 06:48:01 INFO Utils: Successfully started service 'org.apache.spark.network.netty.NettyBlockTransferService' on port 38993.
[2022-06-07 06:48:01,748] {subprocess.py:92} INFO - 22/06/07 06:48:01 INFO NettyBlockTransferService: Server created on d952e2b2ede8:38993
[2022-06-07 06:48:01,749] {subprocess.py:92} INFO - 22/06/07 06:48:01 INFO BlockManager: Using org.apache.spark.storage.RandomBlockReplicationPolicy for block replication policy
[2022-06-07 06:48:01,756] {subprocess.py:92} INFO - 22/06/07 06:48:01 INFO BlockManagerMaster: Registering BlockManager BlockManagerId(driver, d952e2b2ede8, 38993, None)
[2022-06-07 06:48:01,760] {subprocess.py:92} INFO - 22/06/07 06:48:01 INFO BlockManagerMasterEndpoint: Registering block manager d952e2b2ede8:38993 with 366.3 MiB RAM, BlockManagerId(driver, d952e2b2ede8, 38993, None)
[2022-06-07 06:48:01,764] {subprocess.py:92} INFO - 22/06/07 06:48:01 INFO BlockManagerMaster: Registered BlockManager BlockManagerId(driver, d952e2b2ede8, 38993, None)
[2022-06-07 06:48:01,765] {subprocess.py:92} INFO - 22/06/07 06:48:01 INFO BlockManager: Initialized BlockManager: BlockManagerId(driver, d952e2b2ede8, 38993, None)
[2022-06-07 06:48:02,411] {subprocess.py:92} INFO - 22/06/07 06:48:02 INFO SharedState: Setting hive.metastore.warehouse.dir ('null') to the value of spark.sql.warehouse.dir ('file:/spark-warehouse').
[2022-06-07 06:48:02,413] {subprocess.py:92} INFO - 22/06/07 06:48:02 INFO SharedState: Warehouse path is 'file:/spark-warehouse'.
[2022-06-07 06:48:04,534] {subprocess.py:92} INFO - 22/06/07 06:48:04 INFO HadoopFSUtils: Listing leaf files and directories in parallel under 180 paths. The first several paths are: hdfs://hive-namenode:8020/user/spark/order_detail_new/dt=20190101, hdfs://hive-namenode:8020/user/spark/order_detail_new/dt=20190102, hdfs://hive-namenode:8020/user/spark/order_detail_new/dt=20190103, hdfs://hive-namenode:8020/user/spark/order_detail_new/dt=20190104, hdfs://hive-namenode:8020/user/spark/order_detail_new/dt=20190105, hdfs://hive-namenode:8020/user/spark/order_detail_new/dt=20190106, hdfs://hive-namenode:8020/user/spark/order_detail_new/dt=20190107, hdfs://hive-namenode:8020/user/spark/order_detail_new/dt=20190108, hdfs://hive-namenode:8020/user/spark/order_detail_new/dt=20190109, hdfs://hive-namenode:8020/user/spark/order_detail_new/dt=20190110.
[2022-06-07 06:48:05,108] {subprocess.py:92} INFO - 22/06/07 06:48:05 INFO SparkContext: Starting job: parquet at NativeMethodAccessorImpl.java:0
[2022-06-07 06:48:05,155] {subprocess.py:92} INFO - 22/06/07 06:48:05 INFO DAGScheduler: Got job 0 (parquet at NativeMethodAccessorImpl.java:0) with 180 output partitions
[2022-06-07 06:48:05,156] {subprocess.py:92} INFO - 22/06/07 06:48:05 INFO DAGScheduler: Final stage: ResultStage 0 (parquet at NativeMethodAccessorImpl.java:0)
[2022-06-07 06:48:05,158] {subprocess.py:92} INFO - 22/06/07 06:48:05 INFO DAGScheduler: Parents of final stage: List()
[2022-06-07 06:48:05,162] {subprocess.py:92} INFO - 22/06/07 06:48:05 INFO DAGScheduler: Missing parents: List()
[2022-06-07 06:48:05,175] {subprocess.py:92} INFO - 22/06/07 06:48:05 INFO DAGScheduler: Submitting ResultStage 0 (MapPartitionsRDD[2] at parquet at NativeMethodAccessorImpl.java:0), which has no missing parents
[2022-06-07 06:48:05,297] {subprocess.py:92} INFO - 22/06/07 06:48:05 INFO MemoryStore: Block broadcast_0 stored as values in memory (estimated size 83.6 KiB, free 366.2 MiB)
[2022-06-07 06:48:05,365] {subprocess.py:92} INFO - 22/06/07 06:48:05 INFO MemoryStore: Block broadcast_0_piece0 stored as bytes in memory (estimated size 29.5 KiB, free 366.2 MiB)
[2022-06-07 06:48:05,369] {subprocess.py:92} INFO - 22/06/07 06:48:05 INFO BlockManagerInfo: Added broadcast_0_piece0 in memory on d952e2b2ede8:38993 (size: 29.5 KiB, free: 366.3 MiB)
[2022-06-07 06:48:05,374] {subprocess.py:92} INFO - 22/06/07 06:48:05 INFO SparkContext: Created broadcast 0 from broadcast at DAGScheduler.scala:1383
[2022-06-07 06:48:05,406] {subprocess.py:92} INFO - 22/06/07 06:48:05 INFO DAGScheduler: Submitting 180 missing tasks from ResultStage 0 (MapPartitionsRDD[2] at parquet at NativeMethodAccessorImpl.java:0) (first 15 tasks are for partitions Vector(0, 1, 2, 3, 4, 5, 6, 7, 8, 9, 10, 11, 12, 13, 14))
[2022-06-07 06:48:05,409] {subprocess.py:92} INFO - 22/06/07 06:48:05 INFO TaskSchedulerImpl: Adding task set 0.0 with 180 tasks resource profile 0
[2022-06-07 06:48:05,516] {subprocess.py:92} INFO - 22/06/07 06:48:05 INFO TaskSetManager: Starting task 0.0 in stage 0.0 (TID 0) (d952e2b2ede8, executor driver, partition 0, PROCESS_LOCAL, 4545 bytes) taskResourceAssignments Map()
[2022-06-07 06:48:05,521] {subprocess.py:92} INFO - 22/06/07 06:48:05 INFO TaskSetManager: Starting task 1.0 in stage 0.0 (TID 1) (d952e2b2ede8, executor driver, partition 1, PROCESS_LOCAL, 4545 bytes) taskResourceAssignments Map()
[2022-06-07 06:48:05,522] {subprocess.py:92} INFO - 22/06/07 06:48:05 INFO TaskSetManager: Starting task 2.0 in stage 0.0 (TID 2) (d952e2b2ede8, executor driver, partition 2, PROCESS_LOCAL, 4545 bytes) taskResourceAssignments Map()
[2022-06-07 06:48:05,524] {subprocess.py:92} INFO - 22/06/07 06:48:05 INFO TaskSetManager: Starting task 3.0 in stage 0.0 (TID 3) (d952e2b2ede8, executor driver, partition 3, PROCESS_LOCAL, 4545 bytes) taskResourceAssignments Map()
[2022-06-07 06:48:05,545] {subprocess.py:92} INFO - 22/06/07 06:48:05 INFO Executor: Running task 0.0 in stage 0.0 (TID 0)
[2022-06-07 06:48:05,546] {subprocess.py:92} INFO - 22/06/07 06:48:05 INFO Executor: Running task 1.0 in stage 0.0 (TID 1)
[2022-06-07 06:48:05,546] {subprocess.py:92} INFO - 22/06/07 06:48:05 INFO Executor: Running task 2.0 in stage 0.0 (TID 2)
[2022-06-07 06:48:05,549] {subprocess.py:92} INFO - 22/06/07 06:48:05 INFO Executor: Running task 3.0 in stage 0.0 (TID 3)
[2022-06-07 06:48:06,496] {subprocess.py:92} INFO - 22/06/07 06:48:06 INFO Executor: Finished task 3.0 in stage 0.0 (TID 3). 2649 bytes result sent to driver
[2022-06-07 06:48:06,499] {subprocess.py:92} INFO - 22/06/07 06:48:06 INFO Executor: Finished task 1.0 in stage 0.0 (TID 1). 2410 bytes result sent to driver
[2022-06-07 06:48:06,500] {subprocess.py:92} INFO - 22/06/07 06:48:06 INFO Executor: Finished task 0.0 in stage 0.0 (TID 0). 2649 bytes result sent to driver
[2022-06-07 06:48:06,507] {subprocess.py:92} INFO - 22/06/07 06:48:06 INFO TaskSetManager: Starting task 4.0 in stage 0.0 (TID 4) (d952e2b2ede8, executor driver, partition 4, PROCESS_LOCAL, 4545 bytes) taskResourceAssignments Map()
[2022-06-07 06:48:06,510] {subprocess.py:92} INFO - 22/06/07 06:48:06 INFO Executor: Running task 4.0 in stage 0.0 (TID 4)
[2022-06-07 06:48:06,512] {subprocess.py:92} INFO - 22/06/07 06:48:06 INFO Executor: Finished task 2.0 in stage 0.0 (TID 2). 2410 bytes result sent to driver
[2022-06-07 06:48:06,518] {subprocess.py:92} INFO - 22/06/07 06:48:06 INFO TaskSetManager: Starting task 5.0 in stage 0.0 (TID 5) (d952e2b2ede8, executor driver, partition 5, PROCESS_LOCAL, 4545 bytes) taskResourceAssignments Map()
[2022-06-07 06:48:06,519] {subprocess.py:92} INFO - 22/06/07 06:48:06 INFO Executor: Running task 5.0 in stage 0.0 (TID 5)
[2022-06-07 06:48:06,532] {subprocess.py:92} INFO - 22/06/07 06:48:06 INFO TaskSetManager: Starting task 6.0 in stage 0.0 (TID 6) (d952e2b2ede8, executor driver, partition 6, PROCESS_LOCAL, 4545 bytes) taskResourceAssignments Map()
[2022-06-07 06:48:06,539] {subprocess.py:92} INFO - 22/06/07 06:48:06 INFO Executor: Finished task 4.0 in stage 0.0 (TID 4). 2606 bytes result sent to driver
[2022-06-07 06:48:06,542] {subprocess.py:92} INFO - 22/06/07 06:48:06 INFO Executor: Running task 6.0 in stage 0.0 (TID 6)
[2022-06-07 06:48:06,548] {subprocess.py:92} INFO - 22/06/07 06:48:06 INFO TaskSetManager: Starting task 7.0 in stage 0.0 (TID 7) (d952e2b2ede8, executor driver, partition 7, PROCESS_LOCAL, 4545 bytes) taskResourceAssignments Map()
[2022-06-07 06:48:06,557] {subprocess.py:92} INFO - 22/06/07 06:48:06 INFO TaskSetManager: Finished task 3.0 in stage 0.0 (TID 3) in 1027 ms on d952e2b2ede8 (executor driver) (1/180)
[2022-06-07 06:48:06,575] {subprocess.py:92} INFO - 22/06/07 06:48:06 INFO Executor: Running task 7.0 in stage 0.0 (TID 7)
[2022-06-07 06:48:06,582] {subprocess.py:92} INFO - 22/06/07 06:48:06 INFO TaskSetManager: Finished task 0.0 in stage 0.0 (TID 0) in 1106 ms on d952e2b2ede8 (executor driver) (2/180)
[2022-06-07 06:48:06,583] {subprocess.py:92} INFO - 22/06/07 06:48:06 INFO TaskSetManager: Finished task 1.0 in stage 0.0 (TID 1) in 1061 ms on d952e2b2ede8 (executor driver) (3/180)
[2022-06-07 06:48:06,584] {subprocess.py:92} INFO - 22/06/07 06:48:06 INFO TaskSetManager: Finished task 2.0 in stage 0.0 (TID 2) in 1062 ms on d952e2b2ede8 (executor driver) (4/180)
[2022-06-07 06:48:06,587] {subprocess.py:92} INFO - 22/06/07 06:48:06 INFO TaskSetManager: Starting task 8.0 in stage 0.0 (TID 8) (d952e2b2ede8, executor driver, partition 8, PROCESS_LOCAL, 4545 bytes) taskResourceAssignments Map()
[2022-06-07 06:48:06,588] {subprocess.py:92} INFO - 22/06/07 06:48:06 INFO Executor: Running task 8.0 in stage 0.0 (TID 8)
[2022-06-07 06:48:06,593] {subprocess.py:92} INFO - 22/06/07 06:48:06 INFO TaskSetManager: Finished task 4.0 in stage 0.0 (TID 4) in 87 ms on d952e2b2ede8 (executor driver) (5/180)
[2022-06-07 06:48:06,599] {subprocess.py:92} INFO - 22/06/07 06:48:06 INFO Executor: Finished task 5.0 in stage 0.0 (TID 5). 2649 bytes result sent to driver
[2022-06-07 06:48:06,608] {subprocess.py:92} INFO - 22/06/07 06:48:06 INFO TaskSetManager: Starting task 9.0 in stage 0.0 (TID 9) (d952e2b2ede8, executor driver, partition 9, PROCESS_LOCAL, 4545 bytes) taskResourceAssignments Map()
[2022-06-07 06:48:06,617] {subprocess.py:92} INFO - 22/06/07 06:48:06 INFO Executor: Running task 9.0 in stage 0.0 (TID 9)
[2022-06-07 06:48:06,623] {subprocess.py:92} INFO - 22/06/07 06:48:06 INFO Executor: Finished task 6.0 in stage 0.0 (TID 6). 2410 bytes result sent to driver
[2022-06-07 06:48:06,626] {subprocess.py:92} INFO - 22/06/07 06:48:06 INFO TaskSetManager: Starting task 10.0 in stage 0.0 (TID 10) (d952e2b2ede8, executor driver, partition 10, PROCESS_LOCAL, 4545 bytes) taskResourceAssignments Map()
[2022-06-07 06:48:06,627] {subprocess.py:92} INFO - 22/06/07 06:48:06 INFO TaskSetManager: Finished task 5.0 in stage 0.0 (TID 5) in 110 ms on d952e2b2ede8 (executor driver) (6/180)
[2022-06-07 06:48:06,628] {subprocess.py:92} INFO - 22/06/07 06:48:06 INFO TaskSetManager: Finished task 6.0 in stage 0.0 (TID 6) in 96 ms on d952e2b2ede8 (executor driver) (7/180)
[2022-06-07 06:48:06,639] {subprocess.py:92} INFO - 22/06/07 06:48:06 INFO Executor: Running task 10.0 in stage 0.0 (TID 10)
[2022-06-07 06:48:06,644] {subprocess.py:92} INFO - 22/06/07 06:48:06 INFO Executor: Finished task 7.0 in stage 0.0 (TID 7). 2367 bytes result sent to driver
[2022-06-07 06:48:06,645] {subprocess.py:92} INFO - 22/06/07 06:48:06 INFO TaskSetManager: Starting task 11.0 in stage 0.0 (TID 11) (d952e2b2ede8, executor driver, partition 11, PROCESS_LOCAL, 4545 bytes) taskResourceAssignments Map()
[2022-06-07 06:48:06,646] {subprocess.py:92} INFO - 22/06/07 06:48:06 INFO TaskSetManager: Finished task 7.0 in stage 0.0 (TID 7) in 99 ms on d952e2b2ede8 (executor driver) (8/180)
[2022-06-07 06:48:06,653] {subprocess.py:92} INFO - 22/06/07 06:48:06 INFO Executor: Running task 11.0 in stage 0.0 (TID 11)
[2022-06-07 06:48:06,672] {subprocess.py:92} INFO - 22/06/07 06:48:06 INFO Executor: Finished task 8.0 in stage 0.0 (TID 8). 2367 bytes result sent to driver
[2022-06-07 06:48:06,674] {subprocess.py:92} INFO - 22/06/07 06:48:06 INFO TaskSetManager: Starting task 12.0 in stage 0.0 (TID 12) (d952e2b2ede8, executor driver, partition 12, PROCESS_LOCAL, 4545 bytes) taskResourceAssignments Map()
[2022-06-07 06:48:06,676] {subprocess.py:92} INFO - 22/06/07 06:48:06 INFO Executor: Running task 12.0 in stage 0.0 (TID 12)
[2022-06-07 06:48:06,677] {subprocess.py:92} INFO - 22/06/07 06:48:06 INFO TaskSetManager: Finished task 8.0 in stage 0.0 (TID 8) in 89 ms on d952e2b2ede8 (executor driver) (9/180)
[2022-06-07 06:48:06,684] {subprocess.py:92} INFO - 22/06/07 06:48:06 INFO Executor: Finished task 9.0 in stage 0.0 (TID 9). 2367 bytes result sent to driver
[2022-06-07 06:48:06,685] {subprocess.py:92} INFO - 22/06/07 06:48:06 INFO TaskSetManager: Starting task 13.0 in stage 0.0 (TID 13) (d952e2b2ede8, executor driver, partition 13, PROCESS_LOCAL, 4545 bytes) taskResourceAssignments Map()
[2022-06-07 06:48:06,686] {subprocess.py:92} INFO - 22/06/07 06:48:06 INFO TaskSetManager: Finished task 9.0 in stage 0.0 (TID 9) in 80 ms on d952e2b2ede8 (executor driver) (10/180)
[2022-06-07 06:48:06,687] {subprocess.py:92} INFO - 22/06/07 06:48:06 INFO Executor: Finished task 11.0 in stage 0.0 (TID 11). 2367 bytes result sent to driver
[2022-06-07 06:48:06,688] {subprocess.py:92} INFO - 22/06/07 06:48:06 INFO TaskSetManager: Finished task 11.0 in stage 0.0 (TID 11) in 43 ms on d952e2b2ede8 (executor driver) (11/180)
[2022-06-07 06:48:06,689] {subprocess.py:92} INFO - 22/06/07 06:48:06 INFO TaskSetManager: Starting task 14.0 in stage 0.0 (TID 14) (d952e2b2ede8, executor driver, partition 14, PROCESS_LOCAL, 4545 bytes) taskResourceAssignments Map()
[2022-06-07 06:48:06,690] {subprocess.py:92} INFO - 22/06/07 06:48:06 INFO Executor: Running task 13.0 in stage 0.0 (TID 13)
[2022-06-07 06:48:06,691] {subprocess.py:92} INFO - 22/06/07 06:48:06 INFO Executor: Running task 14.0 in stage 0.0 (TID 14)
[2022-06-07 06:48:06,708] {subprocess.py:92} INFO - 22/06/07 06:48:06 INFO Executor: Finished task 10.0 in stage 0.0 (TID 10). 2367 bytes result sent to driver
[2022-06-07 06:48:06,710] {subprocess.py:92} INFO - 22/06/07 06:48:06 INFO TaskSetManager: Starting task 15.0 in stage 0.0 (TID 15) (d952e2b2ede8, executor driver, partition 15, PROCESS_LOCAL, 4545 bytes) taskResourceAssignments Map()
[2022-06-07 06:48:06,711] {subprocess.py:92} INFO - 22/06/07 06:48:06 INFO TaskSetManager: Finished task 10.0 in stage 0.0 (TID 10) in 87 ms on d952e2b2ede8 (executor driver) (12/180)
[2022-06-07 06:48:06,716] {subprocess.py:92} INFO - 22/06/07 06:48:06 INFO Executor: Finished task 12.0 in stage 0.0 (TID 12). 2606 bytes result sent to driver
[2022-06-07 06:48:06,717] {subprocess.py:92} INFO - 22/06/07 06:48:06 INFO Executor: Running task 15.0 in stage 0.0 (TID 15)
[2022-06-07 06:48:06,719] {subprocess.py:92} INFO - 22/06/07 06:48:06 INFO TaskSetManager: Starting task 16.0 in stage 0.0 (TID 16) (d952e2b2ede8, executor driver, partition 16, PROCESS_LOCAL, 4545 bytes) taskResourceAssignments Map()
[2022-06-07 06:48:06,721] {subprocess.py:92} INFO - 22/06/07 06:48:06 INFO Executor: Running task 16.0 in stage 0.0 (TID 16)
[2022-06-07 06:48:06,722] {subprocess.py:92} INFO - 22/06/07 06:48:06 INFO Executor: Finished task 13.0 in stage 0.0 (TID 13). 2367 bytes result sent to driver
[2022-06-07 06:48:06,723] {subprocess.py:92} INFO - 22/06/07 06:48:06 INFO TaskSetManager: Starting task 17.0 in stage 0.0 (TID 17) (d952e2b2ede8, executor driver, partition 17, PROCESS_LOCAL, 4545 bytes) taskResourceAssignments Map()
[2022-06-07 06:48:06,724] {subprocess.py:92} INFO - 22/06/07 06:48:06 INFO Executor: Finished task 14.0 in stage 0.0 (TID 14). 2606 bytes result sent to driver
[2022-06-07 06:48:06,725] {subprocess.py:92} INFO - 22/06/07 06:48:06 INFO Executor: Running task 17.0 in stage 0.0 (TID 17)
[2022-06-07 06:48:06,725] {subprocess.py:92} INFO - 22/06/07 06:48:06 INFO TaskSetManager: Finished task 13.0 in stage 0.0 (TID 13) in 39 ms on d952e2b2ede8 (executor driver) (13/180)
[2022-06-07 06:48:06,726] {subprocess.py:92} INFO - 22/06/07 06:48:06 INFO TaskSetManager: Finished task 12.0 in stage 0.0 (TID 12) in 51 ms on d952e2b2ede8 (executor driver) (14/180)
[2022-06-07 06:48:06,727] {subprocess.py:92} INFO - 22/06/07 06:48:06 INFO TaskSetManager: Starting task 18.0 in stage 0.0 (TID 18) (d952e2b2ede8, executor driver, partition 18, PROCESS_LOCAL, 4545 bytes) taskResourceAssignments Map()
[2022-06-07 06:48:06,728] {subprocess.py:92} INFO - 22/06/07 06:48:06 INFO Executor: Running task 18.0 in stage 0.0 (TID 18)
[2022-06-07 06:48:06,729] {subprocess.py:92} INFO - 22/06/07 06:48:06 INFO TaskSetManager: Finished task 14.0 in stage 0.0 (TID 14) in 40 ms on d952e2b2ede8 (executor driver) (15/180)
[2022-06-07 06:48:06,765] {subprocess.py:92} INFO - 22/06/07 06:48:06 INFO Executor: Finished task 18.0 in stage 0.0 (TID 18). 2367 bytes result sent to driver
[2022-06-07 06:48:06,767] {subprocess.py:92} INFO - 22/06/07 06:48:06 INFO Executor: Finished task 17.0 in stage 0.0 (TID 17). 2606 bytes result sent to driver
[2022-06-07 06:48:06,770] {subprocess.py:92} INFO - 22/06/07 06:48:06 INFO TaskSetManager: Starting task 19.0 in stage 0.0 (TID 19) (d952e2b2ede8, executor driver, partition 19, PROCESS_LOCAL, 4545 bytes) taskResourceAssignments Map()
[2022-06-07 06:48:06,773] {subprocess.py:92} INFO - 22/06/07 06:48:06 INFO TaskSetManager: Finished task 18.0 in stage 0.0 (TID 18) in 46 ms on d952e2b2ede8 (executor driver) (16/180)
[2022-06-07 06:48:06,774] {subprocess.py:92} INFO - 22/06/07 06:48:06 INFO Executor: Running task 19.0 in stage 0.0 (TID 19)
[2022-06-07 06:48:06,778] {subprocess.py:92} INFO - 22/06/07 06:48:06 INFO TaskSetManager: Starting task 20.0 in stage 0.0 (TID 20) (d952e2b2ede8, executor driver, partition 20, PROCESS_LOCAL, 4545 bytes) taskResourceAssignments Map()
[2022-06-07 06:48:06,779] {subprocess.py:92} INFO - 22/06/07 06:48:06 INFO TaskSetManager: Finished task 17.0 in stage 0.0 (TID 17) in 56 ms on d952e2b2ede8 (executor driver) (17/180)
[2022-06-07 06:48:06,781] {subprocess.py:92} INFO - 22/06/07 06:48:06 INFO Executor: Running task 20.0 in stage 0.0 (TID 20)
[2022-06-07 06:48:06,784] {subprocess.py:92} INFO - 22/06/07 06:48:06 INFO Executor: Finished task 16.0 in stage 0.0 (TID 16). 2367 bytes result sent to driver
[2022-06-07 06:48:06,790] {subprocess.py:92} INFO - 22/06/07 06:48:06 INFO TaskSetManager: Starting task 21.0 in stage 0.0 (TID 21) (d952e2b2ede8, executor driver, partition 21, PROCESS_LOCAL, 4545 bytes) taskResourceAssignments Map()
[2022-06-07 06:48:06,791] {subprocess.py:92} INFO - 22/06/07 06:48:06 INFO Executor: Running task 21.0 in stage 0.0 (TID 21)
[2022-06-07 06:48:06,792] {subprocess.py:92} INFO - 22/06/07 06:48:06 INFO Executor: Finished task 15.0 in stage 0.0 (TID 15). 2367 bytes result sent to driver
[2022-06-07 06:48:06,794] {subprocess.py:92} INFO - 22/06/07 06:48:06 INFO TaskSetManager: Starting task 22.0 in stage 0.0 (TID 22) (d952e2b2ede8, executor driver, partition 22, PROCESS_LOCAL, 4545 bytes) taskResourceAssignments Map()
[2022-06-07 06:48:06,795] {subprocess.py:92} INFO - 22/06/07 06:48:06 INFO Executor: Running task 22.0 in stage 0.0 (TID 22)
[2022-06-07 06:48:06,795] {subprocess.py:92} INFO - 22/06/07 06:48:06 INFO TaskSetManager: Finished task 15.0 in stage 0.0 (TID 15) in 85 ms on d952e2b2ede8 (executor driver) (18/180)
[2022-06-07 06:48:06,797] {subprocess.py:92} INFO - 22/06/07 06:48:06 INFO TaskSetManager: Finished task 16.0 in stage 0.0 (TID 16) in 78 ms on d952e2b2ede8 (executor driver) (19/180)
[2022-06-07 06:48:06,807] {subprocess.py:92} INFO - 22/06/07 06:48:06 INFO Executor: Finished task 20.0 in stage 0.0 (TID 20). 2606 bytes result sent to driver
[2022-06-07 06:48:06,808] {subprocess.py:92} INFO - 22/06/07 06:48:06 INFO Executor: Finished task 19.0 in stage 0.0 (TID 19). 2606 bytes result sent to driver
[2022-06-07 06:48:06,811] {subprocess.py:92} INFO - 22/06/07 06:48:06 INFO TaskSetManager: Starting task 23.0 in stage 0.0 (TID 23) (d952e2b2ede8, executor driver, partition 23, PROCESS_LOCAL, 4545 bytes) taskResourceAssignments Map()
[2022-06-07 06:48:06,812] {subprocess.py:92} INFO - 22/06/07 06:48:06 INFO TaskSetManager: Finished task 20.0 in stage 0.0 (TID 20) in 38 ms on d952e2b2ede8 (executor driver) (20/180)
[2022-06-07 06:48:06,816] {subprocess.py:92} INFO - 22/06/07 06:48:06 INFO TaskSetManager: Starting task 24.0 in stage 0.0 (TID 24) (d952e2b2ede8, executor driver, partition 24, PROCESS_LOCAL, 4545 bytes) taskResourceAssignments Map()
[2022-06-07 06:48:06,817] {subprocess.py:92} INFO - 22/06/07 06:48:06 INFO Executor: Running task 24.0 in stage 0.0 (TID 24)
[2022-06-07 06:48:06,821] {subprocess.py:92} INFO - 22/06/07 06:48:06 INFO Executor: Running task 23.0 in stage 0.0 (TID 23)
[2022-06-07 06:48:06,822] {subprocess.py:92} INFO - 22/06/07 06:48:06 INFO TaskSetManager: Finished task 19.0 in stage 0.0 (TID 19) in 48 ms on d952e2b2ede8 (executor driver) (21/180)
[2022-06-07 06:48:06,825] {subprocess.py:92} INFO - 22/06/07 06:48:06 INFO Executor: Finished task 22.0 in stage 0.0 (TID 22). 2606 bytes result sent to driver
[2022-06-07 06:48:06,830] {subprocess.py:92} INFO - 22/06/07 06:48:06 INFO TaskSetManager: Starting task 25.0 in stage 0.0 (TID 25) (d952e2b2ede8, executor driver, partition 25, PROCESS_LOCAL, 4545 bytes) taskResourceAssignments Map()
[2022-06-07 06:48:06,831] {subprocess.py:92} INFO - 22/06/07 06:48:06 INFO TaskSetManager: Finished task 22.0 in stage 0.0 (TID 22) in 38 ms on d952e2b2ede8 (executor driver) (22/180)
[2022-06-07 06:48:06,832] {subprocess.py:92} INFO - 22/06/07 06:48:06 INFO Executor: Running task 25.0 in stage 0.0 (TID 25)
[2022-06-07 06:48:06,834] {subprocess.py:92} INFO - 22/06/07 06:48:06 INFO Executor: Finished task 21.0 in stage 0.0 (TID 21). 2606 bytes result sent to driver
[2022-06-07 06:48:06,839] {subprocess.py:92} INFO - 22/06/07 06:48:06 INFO TaskSetManager: Starting task 26.0 in stage 0.0 (TID 26) (d952e2b2ede8, executor driver, partition 26, PROCESS_LOCAL, 4545 bytes) taskResourceAssignments Map()
[2022-06-07 06:48:06,840] {subprocess.py:92} INFO - 22/06/07 06:48:06 INFO TaskSetManager: Finished task 21.0 in stage 0.0 (TID 21) in 51 ms on d952e2b2ede8 (executor driver) (23/180)
[2022-06-07 06:48:06,845] {subprocess.py:92} INFO - 22/06/07 06:48:06 INFO Executor: Finished task 24.0 in stage 0.0 (TID 24). 2606 bytes result sent to driver
[2022-06-07 06:48:06,848] {subprocess.py:92} INFO - 22/06/07 06:48:06 INFO Executor: Running task 26.0 in stage 0.0 (TID 26)
[2022-06-07 06:48:06,850] {subprocess.py:92} INFO - 22/06/07 06:48:06 INFO TaskSetManager: Starting task 27.0 in stage 0.0 (TID 27) (d952e2b2ede8, executor driver, partition 27, PROCESS_LOCAL, 4545 bytes) taskResourceAssignments Map()
[2022-06-07 06:48:06,852] {subprocess.py:92} INFO - 22/06/07 06:48:06 INFO TaskSetManager: Finished task 24.0 in stage 0.0 (TID 24) in 36 ms on d952e2b2ede8 (executor driver) (24/180)
[2022-06-07 06:48:06,853] {subprocess.py:92} INFO - 22/06/07 06:48:06 INFO Executor: Running task 27.0 in stage 0.0 (TID 27)
[2022-06-07 06:48:06,854] {subprocess.py:92} INFO - 22/06/07 06:48:06 INFO Executor: Finished task 25.0 in stage 0.0 (TID 25). 2606 bytes result sent to driver
[2022-06-07 06:48:06,856] {subprocess.py:92} INFO - 22/06/07 06:48:06 INFO TaskSetManager: Starting task 28.0 in stage 0.0 (TID 28) (d952e2b2ede8, executor driver, partition 28, PROCESS_LOCAL, 4545 bytes) taskResourceAssignments Map()
[2022-06-07 06:48:06,857] {subprocess.py:92} INFO - 22/06/07 06:48:06 INFO Executor: Finished task 23.0 in stage 0.0 (TID 23). 2606 bytes result sent to driver
[2022-06-07 06:48:06,858] {subprocess.py:92} INFO - 22/06/07 06:48:06 INFO TaskSetManager: Finished task 25.0 in stage 0.0 (TID 25) in 32 ms on d952e2b2ede8 (executor driver) (25/180)
[2022-06-07 06:48:06,859] {subprocess.py:92} INFO - 22/06/07 06:48:06 INFO Executor: Running task 28.0 in stage 0.0 (TID 28)
[2022-06-07 06:48:06,861] {subprocess.py:92} INFO - 22/06/07 06:48:06 INFO TaskSetManager: Starting task 29.0 in stage 0.0 (TID 29) (d952e2b2ede8, executor driver, partition 29, PROCESS_LOCAL, 4545 bytes) taskResourceAssignments Map()
[2022-06-07 06:48:06,862] {subprocess.py:92} INFO - 22/06/07 06:48:06 INFO TaskSetManager: Finished task 23.0 in stage 0.0 (TID 23) in 53 ms on d952e2b2ede8 (executor driver) (26/180)
[2022-06-07 06:48:06,863] {subprocess.py:92} INFO - 22/06/07 06:48:06 INFO Executor: Running task 29.0 in stage 0.0 (TID 29)
[2022-06-07 06:48:06,873] {subprocess.py:92} INFO - 22/06/07 06:48:06 INFO Executor: Finished task 26.0 in stage 0.0 (TID 26). 2367 bytes result sent to driver
[2022-06-07 06:48:06,878] {subprocess.py:92} INFO - 22/06/07 06:48:06 INFO TaskSetManager: Starting task 30.0 in stage 0.0 (TID 30) (d952e2b2ede8, executor driver, partition 30, PROCESS_LOCAL, 4545 bytes) taskResourceAssignments Map()
[2022-06-07 06:48:06,880] {subprocess.py:92} INFO - 22/06/07 06:48:06 INFO TaskSetManager: Finished task 26.0 in stage 0.0 (TID 26) in 41 ms on d952e2b2ede8 (executor driver) (27/180)
[2022-06-07 06:48:06,881] {subprocess.py:92} INFO - 22/06/07 06:48:06 INFO Executor: Running task 30.0 in stage 0.0 (TID 30)
[2022-06-07 06:48:06,886] {subprocess.py:92} INFO - 22/06/07 06:48:06 INFO Executor: Finished task 29.0 in stage 0.0 (TID 29). 2128 bytes result sent to driver
[2022-06-07 06:48:06,892] {subprocess.py:92} INFO - 22/06/07 06:48:06 INFO Executor: Finished task 28.0 in stage 0.0 (TID 28). 2606 bytes result sent to driver
[2022-06-07 06:48:06,897] {subprocess.py:92} INFO - 22/06/07 06:48:06 INFO TaskSetManager: Starting task 31.0 in stage 0.0 (TID 31) (d952e2b2ede8, executor driver, partition 31, PROCESS_LOCAL, 4545 bytes) taskResourceAssignments Map()
[2022-06-07 06:48:06,899] {subprocess.py:92} INFO - 22/06/07 06:48:06 INFO TaskSetManager: Starting task 32.0 in stage 0.0 (TID 32) (d952e2b2ede8, executor driver, partition 32, PROCESS_LOCAL, 4545 bytes) taskResourceAssignments Map()
[2022-06-07 06:48:06,900] {subprocess.py:92} INFO - 22/06/07 06:48:06 INFO TaskSetManager: Finished task 29.0 in stage 0.0 (TID 29) in 39 ms on d952e2b2ede8 (executor driver) (28/180)
[2022-06-07 06:48:06,901] {subprocess.py:92} INFO - 22/06/07 06:48:06 INFO Executor: Running task 31.0 in stage 0.0 (TID 31)
[2022-06-07 06:48:06,902] {subprocess.py:92} INFO - 22/06/07 06:48:06 INFO TaskSetManager: Finished task 28.0 in stage 0.0 (TID 28) in 45 ms on d952e2b2ede8 (executor driver) (29/180)
[2022-06-07 06:48:06,903] {subprocess.py:92} INFO - 22/06/07 06:48:06 INFO Executor: Running task 32.0 in stage 0.0 (TID 32)
[2022-06-07 06:48:06,906] {subprocess.py:92} INFO - 22/06/07 06:48:06 INFO Executor: Finished task 30.0 in stage 0.0 (TID 30). 2128 bytes result sent to driver
[2022-06-07 06:48:06,908] {subprocess.py:92} INFO - 22/06/07 06:48:06 INFO TaskSetManager: Starting task 33.0 in stage 0.0 (TID 33) (d952e2b2ede8, executor driver, partition 33, PROCESS_LOCAL, 4545 bytes) taskResourceAssignments Map()
[2022-06-07 06:48:06,911] {subprocess.py:92} INFO - 22/06/07 06:48:06 INFO TaskSetManager: Finished task 30.0 in stage 0.0 (TID 30) in 31 ms on d952e2b2ede8 (executor driver) (30/180)
[2022-06-07 06:48:06,915] {subprocess.py:92} INFO - 22/06/07 06:48:06 INFO Executor: Running task 33.0 in stage 0.0 (TID 33)
[2022-06-07 06:48:06,932] {subprocess.py:92} INFO - 22/06/07 06:48:06 INFO Executor: Finished task 27.0 in stage 0.0 (TID 27). 2367 bytes result sent to driver
[2022-06-07 06:48:06,934] {subprocess.py:92} INFO - 22/06/07 06:48:06 INFO TaskSetManager: Starting task 34.0 in stage 0.0 (TID 34) (d952e2b2ede8, executor driver, partition 34, PROCESS_LOCAL, 4545 bytes) taskResourceAssignments Map()
[2022-06-07 06:48:06,935] {subprocess.py:92} INFO - 22/06/07 06:48:06 INFO Executor: Running task 34.0 in stage 0.0 (TID 34)
[2022-06-07 06:48:06,936] {subprocess.py:92} INFO - 22/06/07 06:48:06 INFO TaskSetManager: Finished task 27.0 in stage 0.0 (TID 27) in 89 ms on d952e2b2ede8 (executor driver) (31/180)
[2022-06-07 06:48:06,938] {subprocess.py:92} INFO - 22/06/07 06:48:06 INFO Executor: Finished task 32.0 in stage 0.0 (TID 32). 2367 bytes result sent to driver
[2022-06-07 06:48:06,946] {subprocess.py:92} INFO - 22/06/07 06:48:06 INFO Executor: Finished task 33.0 in stage 0.0 (TID 33). 2128 bytes result sent to driver
[2022-06-07 06:48:06,947] {subprocess.py:92} INFO - 22/06/07 06:48:06 INFO Executor: Finished task 31.0 in stage 0.0 (TID 31). 2367 bytes result sent to driver
[2022-06-07 06:48:06,951] {subprocess.py:92} INFO - 22/06/07 06:48:06 INFO TaskSetManager: Starting task 35.0 in stage 0.0 (TID 35) (d952e2b2ede8, executor driver, partition 35, PROCESS_LOCAL, 4545 bytes) taskResourceAssignments Map()
[2022-06-07 06:48:06,952] {subprocess.py:92} INFO - 22/06/07 06:48:06 INFO TaskSetManager: Finished task 32.0 in stage 0.0 (TID 32) in 53 ms on d952e2b2ede8 (executor driver) (32/180)
[2022-06-07 06:48:06,954] {subprocess.py:92} INFO - 22/06/07 06:48:06 INFO Executor: Running task 35.0 in stage 0.0 (TID 35)
[2022-06-07 06:48:06,956] {subprocess.py:92} INFO - 22/06/07 06:48:06 INFO TaskSetManager: Starting task 36.0 in stage 0.0 (TID 36) (d952e2b2ede8, executor driver, partition 36, PROCESS_LOCAL, 4545 bytes) taskResourceAssignments Map()
[2022-06-07 06:48:06,958] {subprocess.py:92} INFO - 22/06/07 06:48:06 INFO Executor: Running task 36.0 in stage 0.0 (TID 36)
[2022-06-07 06:48:06,960] {subprocess.py:92} INFO - 22/06/07 06:48:06 INFO Executor: Finished task 34.0 in stage 0.0 (TID 34). 2128 bytes result sent to driver
[2022-06-07 06:48:06,961] {subprocess.py:92} INFO - 22/06/07 06:48:06 INFO TaskSetManager: Finished task 33.0 in stage 0.0 (TID 33) in 50 ms on d952e2b2ede8 (executor driver) (33/180)
[2022-06-07 06:48:06,962] {subprocess.py:92} INFO - 22/06/07 06:48:06 INFO TaskSetManager: Finished task 31.0 in stage 0.0 (TID 31) in 63 ms on d952e2b2ede8 (executor driver) (34/180)
[2022-06-07 06:48:06,963] {subprocess.py:92} INFO - 22/06/07 06:48:06 INFO TaskSetManager: Starting task 37.0 in stage 0.0 (TID 37) (d952e2b2ede8, executor driver, partition 37, PROCESS_LOCAL, 4545 bytes) taskResourceAssignments Map()
[2022-06-07 06:48:06,964] {subprocess.py:92} INFO - 22/06/07 06:48:06 INFO Executor: Running task 37.0 in stage 0.0 (TID 37)
[2022-06-07 06:48:06,965] {subprocess.py:92} INFO - 22/06/07 06:48:06 INFO TaskSetManager: Starting task 38.0 in stage 0.0 (TID 38) (d952e2b2ede8, executor driver, partition 38, PROCESS_LOCAL, 4545 bytes) taskResourceAssignments Map()
[2022-06-07 06:48:06,966] {subprocess.py:92} INFO - 22/06/07 06:48:06 INFO Executor: Running task 38.0 in stage 0.0 (TID 38)
[2022-06-07 06:48:06,967] {subprocess.py:92} INFO - 22/06/07 06:48:06 INFO TaskSetManager: Finished task 34.0 in stage 0.0 (TID 34) in 30 ms on d952e2b2ede8 (executor driver) (35/180)
[2022-06-07 06:48:06,980] {subprocess.py:92} INFO - 22/06/07 06:48:06 INFO Executor: Finished task 36.0 in stage 0.0 (TID 36). 2128 bytes result sent to driver
[2022-06-07 06:48:06,982] {subprocess.py:92} INFO - 22/06/07 06:48:06 INFO Executor: Finished task 35.0 in stage 0.0 (TID 35). 2128 bytes result sent to driver
[2022-06-07 06:48:06,984] {subprocess.py:92} INFO - 22/06/07 06:48:06 INFO TaskSetManager: Starting task 39.0 in stage 0.0 (TID 39) (d952e2b2ede8, executor driver, partition 39, PROCESS_LOCAL, 4545 bytes) taskResourceAssignments Map()
[2022-06-07 06:48:06,985] {subprocess.py:92} INFO - 22/06/07 06:48:06 INFO Executor: Running task 39.0 in stage 0.0 (TID 39)
[2022-06-07 06:48:06,986] {subprocess.py:92} INFO - 22/06/07 06:48:06 INFO TaskSetManager: Finished task 36.0 in stage 0.0 (TID 36) in 30 ms on d952e2b2ede8 (executor driver) (36/180)
[2022-06-07 06:48:06,988] {subprocess.py:92} INFO - 22/06/07 06:48:06 INFO TaskSetManager: Finished task 35.0 in stage 0.0 (TID 35) in 35 ms on d952e2b2ede8 (executor driver) (37/180)
[2022-06-07 06:48:06,991] {subprocess.py:92} INFO - 22/06/07 06:48:06 INFO TaskSetManager: Starting task 40.0 in stage 0.0 (TID 40) (d952e2b2ede8, executor driver, partition 40, PROCESS_LOCAL, 4545 bytes) taskResourceAssignments Map()
[2022-06-07 06:48:06,993] {subprocess.py:92} INFO - 22/06/07 06:48:06 INFO Executor: Running task 40.0 in stage 0.0 (TID 40)
[2022-06-07 06:48:07,005] {subprocess.py:92} INFO - 22/06/07 06:48:07 INFO Executor: Finished task 39.0 in stage 0.0 (TID 39). 2367 bytes result sent to driver
[2022-06-07 06:48:07,008] {subprocess.py:92} INFO - 22/06/07 06:48:07 INFO TaskSetManager: Starting task 41.0 in stage 0.0 (TID 41) (d952e2b2ede8, executor driver, partition 41, PROCESS_LOCAL, 4545 bytes) taskResourceAssignments Map()
[2022-06-07 06:48:07,011] {subprocess.py:92} INFO - 22/06/07 06:48:07 INFO Executor: Finished task 38.0 in stage 0.0 (TID 38). 2367 bytes result sent to driver
[2022-06-07 06:48:07,013] {subprocess.py:92} INFO - 22/06/07 06:48:07 INFO TaskSetManager: Starting task 42.0 in stage 0.0 (TID 42) (d952e2b2ede8, executor driver, partition 42, PROCESS_LOCAL, 4545 bytes) taskResourceAssignments Map()
[2022-06-07 06:48:07,015] {subprocess.py:92} INFO - 22/06/07 06:48:07 INFO TaskSetManager: Finished task 39.0 in stage 0.0 (TID 39) in 33 ms on d952e2b2ede8 (executor driver) (38/180)
[2022-06-07 06:48:07,016] {subprocess.py:92} INFO - 22/06/07 06:48:07 INFO Executor: Running task 42.0 in stage 0.0 (TID 42)
[2022-06-07 06:48:07,017] {subprocess.py:92} INFO - 22/06/07 06:48:07 INFO TaskSetManager: Finished task 38.0 in stage 0.0 (TID 38) in 52 ms on d952e2b2ede8 (executor driver) (39/180)
[2022-06-07 06:48:07,019] {subprocess.py:92} INFO - 22/06/07 06:48:07 INFO Executor: Running task 41.0 in stage 0.0 (TID 41)
[2022-06-07 06:48:07,029] {subprocess.py:92} INFO - 22/06/07 06:48:07 INFO Executor: Finished task 37.0 in stage 0.0 (TID 37). 2367 bytes result sent to driver
[2022-06-07 06:48:07,037] {subprocess.py:92} INFO - 22/06/07 06:48:07 INFO Executor: Finished task 41.0 in stage 0.0 (TID 41). 2367 bytes result sent to driver
[2022-06-07 06:48:07,038] {subprocess.py:92} INFO - 22/06/07 06:48:07 INFO Executor: Finished task 40.0 in stage 0.0 (TID 40). 2128 bytes result sent to driver
[2022-06-07 06:48:07,040] {subprocess.py:92} INFO - 22/06/07 06:48:07 INFO TaskSetManager: Starting task 43.0 in stage 0.0 (TID 43) (d952e2b2ede8, executor driver, partition 43, PROCESS_LOCAL, 4545 bytes) taskResourceAssignments Map()
[2022-06-07 06:48:07,042] {subprocess.py:92} INFO - 22/06/07 06:48:07 INFO Executor: Running task 43.0 in stage 0.0 (TID 43)
[2022-06-07 06:48:07,043] {subprocess.py:92} INFO - 22/06/07 06:48:07 INFO TaskSetManager: Starting task 44.0 in stage 0.0 (TID 44) (d952e2b2ede8, executor driver, partition 44, PROCESS_LOCAL, 4545 bytes) taskResourceAssignments Map()
[2022-06-07 06:48:07,044] {subprocess.py:92} INFO - 22/06/07 06:48:07 INFO TaskSetManager: Finished task 41.0 in stage 0.0 (TID 41) in 37 ms on d952e2b2ede8 (executor driver) (40/180)
[2022-06-07 06:48:07,046] {subprocess.py:92} INFO - 22/06/07 06:48:07 INFO TaskSetManager: Finished task 37.0 in stage 0.0 (TID 37) in 84 ms on d952e2b2ede8 (executor driver) (41/180)
[2022-06-07 06:48:07,048] {subprocess.py:92} INFO - 22/06/07 06:48:07 INFO Executor: Running task 44.0 in stage 0.0 (TID 44)
[2022-06-07 06:48:07,049] {subprocess.py:92} INFO - 22/06/07 06:48:07 INFO TaskSetManager: Finished task 40.0 in stage 0.0 (TID 40) in 58 ms on d952e2b2ede8 (executor driver) (42/180)
[2022-06-07 06:48:07,051] {subprocess.py:92} INFO - 22/06/07 06:48:07 INFO TaskSetManager: Starting task 45.0 in stage 0.0 (TID 45) (d952e2b2ede8, executor driver, partition 45, PROCESS_LOCAL, 4545 bytes) taskResourceAssignments Map()
[2022-06-07 06:48:07,058] {subprocess.py:92} INFO - 22/06/07 06:48:07 INFO Executor: Running task 45.0 in stage 0.0 (TID 45)
[2022-06-07 06:48:07,060] {subprocess.py:92} INFO - 22/06/07 06:48:07 INFO Executor: Finished task 44.0 in stage 0.0 (TID 44). 2128 bytes result sent to driver
[2022-06-07 06:48:07,061] {subprocess.py:92} INFO - 22/06/07 06:48:07 INFO Executor: Finished task 42.0 in stage 0.0 (TID 42). 2367 bytes result sent to driver
[2022-06-07 06:48:07,069] {subprocess.py:92} INFO - 22/06/07 06:48:07 INFO TaskSetManager: Starting task 46.0 in stage 0.0 (TID 46) (d952e2b2ede8, executor driver, partition 46, PROCESS_LOCAL, 4545 bytes) taskResourceAssignments Map()
[2022-06-07 06:48:07,070] {subprocess.py:92} INFO - 22/06/07 06:48:07 INFO Executor: Running task 46.0 in stage 0.0 (TID 46)
[2022-06-07 06:48:07,071] {subprocess.py:92} INFO - 22/06/07 06:48:07 INFO TaskSetManager: Starting task 47.0 in stage 0.0 (TID 47) (d952e2b2ede8, executor driver, partition 47, PROCESS_LOCAL, 4545 bytes) taskResourceAssignments Map()
[2022-06-07 06:48:07,072] {subprocess.py:92} INFO - 22/06/07 06:48:07 INFO TaskSetManager: Finished task 42.0 in stage 0.0 (TID 42) in 58 ms on d952e2b2ede8 (executor driver) (43/180)
[2022-06-07 06:48:07,073] {subprocess.py:92} INFO - 22/06/07 06:48:07 INFO Executor: Running task 47.0 in stage 0.0 (TID 47)
[2022-06-07 06:48:07,074] {subprocess.py:92} INFO - 22/06/07 06:48:07 INFO TaskSetManager: Finished task 44.0 in stage 0.0 (TID 44) in 31 ms on d952e2b2ede8 (executor driver) (44/180)
[2022-06-07 06:48:07,085] {subprocess.py:92} INFO - 22/06/07 06:48:07 INFO Executor: Finished task 43.0 in stage 0.0 (TID 43). 2606 bytes result sent to driver
[2022-06-07 06:48:07,086] {subprocess.py:92} INFO - 22/06/07 06:48:07 INFO TaskSetManager: Starting task 48.0 in stage 0.0 (TID 48) (d952e2b2ede8, executor driver, partition 48, PROCESS_LOCAL, 4545 bytes) taskResourceAssignments Map()
[2022-06-07 06:48:07,088] {subprocess.py:92} INFO - 22/06/07 06:48:07 INFO TaskSetManager: Finished task 43.0 in stage 0.0 (TID 43) in 49 ms on d952e2b2ede8 (executor driver) (45/180)
[2022-06-07 06:48:07,089] {subprocess.py:92} INFO - 22/06/07 06:48:07 INFO Executor: Running task 48.0 in stage 0.0 (TID 48)
[2022-06-07 06:48:07,094] {subprocess.py:92} INFO - 22/06/07 06:48:07 INFO Executor: Finished task 47.0 in stage 0.0 (TID 47). 2128 bytes result sent to driver
[2022-06-07 06:48:07,095] {subprocess.py:92} INFO - 22/06/07 06:48:07 INFO TaskSetManager: Starting task 49.0 in stage 0.0 (TID 49) (d952e2b2ede8, executor driver, partition 49, PROCESS_LOCAL, 4545 bytes) taskResourceAssignments Map()
[2022-06-07 06:48:07,096] {subprocess.py:92} INFO - 22/06/07 06:48:07 INFO Executor: Running task 49.0 in stage 0.0 (TID 49)
[2022-06-07 06:48:07,097] {subprocess.py:92} INFO - 22/06/07 06:48:07 INFO TaskSetManager: Finished task 47.0 in stage 0.0 (TID 47) in 25 ms on d952e2b2ede8 (executor driver) (46/180)
[2022-06-07 06:48:07,098] {subprocess.py:92} INFO - 22/06/07 06:48:07 INFO Executor: Finished task 45.0 in stage 0.0 (TID 45). 2367 bytes result sent to driver
[2022-06-07 06:48:07,100] {subprocess.py:92} INFO - 22/06/07 06:48:07 INFO Executor: Finished task 46.0 in stage 0.0 (TID 46). 2367 bytes result sent to driver
[2022-06-07 06:48:07,100] {subprocess.py:92} INFO - 22/06/07 06:48:07 INFO TaskSetManager: Starting task 50.0 in stage 0.0 (TID 50) (d952e2b2ede8, executor driver, partition 50, PROCESS_LOCAL, 4545 bytes) taskResourceAssignments Map()
[2022-06-07 06:48:07,102] {subprocess.py:92} INFO - 22/06/07 06:48:07 INFO Executor: Running task 50.0 in stage 0.0 (TID 50)
[2022-06-07 06:48:07,107] {subprocess.py:92} INFO - 22/06/07 06:48:07 INFO TaskSetManager: Starting task 51.0 in stage 0.0 (TID 51) (d952e2b2ede8, executor driver, partition 51, PROCESS_LOCAL, 4545 bytes) taskResourceAssignments Map()
[2022-06-07 06:48:07,108] {subprocess.py:92} INFO - 22/06/07 06:48:07 INFO TaskSetManager: Finished task 45.0 in stage 0.0 (TID 45) in 58 ms on d952e2b2ede8 (executor driver) (47/180)
[2022-06-07 06:48:07,109] {subprocess.py:92} INFO - 22/06/07 06:48:07 INFO Executor: Running task 51.0 in stage 0.0 (TID 51)
[2022-06-07 06:48:07,109] {subprocess.py:92} INFO - 22/06/07 06:48:07 INFO TaskSetManager: Finished task 46.0 in stage 0.0 (TID 46) in 40 ms on d952e2b2ede8 (executor driver) (48/180)
[2022-06-07 06:48:07,117] {subprocess.py:92} INFO - 22/06/07 06:48:07 INFO Executor: Finished task 49.0 in stage 0.0 (TID 49). 2367 bytes result sent to driver
[2022-06-07 06:48:07,119] {subprocess.py:92} INFO - 22/06/07 06:48:07 INFO TaskSetManager: Starting task 52.0 in stage 0.0 (TID 52) (d952e2b2ede8, executor driver, partition 52, PROCESS_LOCAL, 4545 bytes) taskResourceAssignments Map()
[2022-06-07 06:48:07,120] {subprocess.py:92} INFO - 22/06/07 06:48:07 INFO TaskSetManager: Finished task 49.0 in stage 0.0 (TID 49) in 25 ms on d952e2b2ede8 (executor driver) (49/180)
[2022-06-07 06:48:07,121] {subprocess.py:92} INFO - 22/06/07 06:48:07 INFO Executor: Running task 52.0 in stage 0.0 (TID 52)
[2022-06-07 06:48:07,122] {subprocess.py:92} INFO - 22/06/07 06:48:07 INFO Executor: Finished task 50.0 in stage 0.0 (TID 50). 2128 bytes result sent to driver
[2022-06-07 06:48:07,124] {subprocess.py:92} INFO - 22/06/07 06:48:07 INFO Executor: Finished task 48.0 in stage 0.0 (TID 48). 2367 bytes result sent to driver
[2022-06-07 06:48:07,125] {subprocess.py:92} INFO - 22/06/07 06:48:07 INFO TaskSetManager: Starting task 53.0 in stage 0.0 (TID 53) (d952e2b2ede8, executor driver, partition 53, PROCESS_LOCAL, 4545 bytes) taskResourceAssignments Map()
[2022-06-07 06:48:07,126] {subprocess.py:92} INFO - 22/06/07 06:48:07 INFO Executor: Running task 53.0 in stage 0.0 (TID 53)
[2022-06-07 06:48:07,126] {subprocess.py:92} INFO - 22/06/07 06:48:07 INFO TaskSetManager: Starting task 54.0 in stage 0.0 (TID 54) (d952e2b2ede8, executor driver, partition 54, PROCESS_LOCAL, 4545 bytes) taskResourceAssignments Map()
[2022-06-07 06:48:07,127] {subprocess.py:92} INFO - 22/06/07 06:48:07 INFO TaskSetManager: Finished task 50.0 in stage 0.0 (TID 50) in 27 ms on d952e2b2ede8 (executor driver) (50/180)
[2022-06-07 06:48:07,128] {subprocess.py:92} INFO - 22/06/07 06:48:07 INFO Executor: Running task 54.0 in stage 0.0 (TID 54)
[2022-06-07 06:48:07,129] {subprocess.py:92} INFO - 22/06/07 06:48:07 INFO TaskSetManager: Finished task 48.0 in stage 0.0 (TID 48) in 41 ms on d952e2b2ede8 (executor driver) (51/180)
[2022-06-07 06:48:07,132] {subprocess.py:92} INFO - 22/06/07 06:48:07 INFO Executor: Finished task 51.0 in stage 0.0 (TID 51). 2128 bytes result sent to driver
[2022-06-07 06:48:07,133] {subprocess.py:92} INFO - 22/06/07 06:48:07 INFO TaskSetManager: Starting task 55.0 in stage 0.0 (TID 55) (d952e2b2ede8, executor driver, partition 55, PROCESS_LOCAL, 4545 bytes) taskResourceAssignments Map()
[2022-06-07 06:48:07,134] {subprocess.py:92} INFO - 22/06/07 06:48:07 INFO TaskSetManager: Finished task 51.0 in stage 0.0 (TID 51) in 31 ms on d952e2b2ede8 (executor driver) (52/180)
[2022-06-07 06:48:07,135] {subprocess.py:92} INFO - 22/06/07 06:48:07 INFO Executor: Running task 55.0 in stage 0.0 (TID 55)
[2022-06-07 06:48:07,142] {subprocess.py:92} INFO - 22/06/07 06:48:07 INFO Executor: Finished task 54.0 in stage 0.0 (TID 54). 2367 bytes result sent to driver
[2022-06-07 06:48:07,144] {subprocess.py:92} INFO - 22/06/07 06:48:07 INFO TaskSetManager: Starting task 56.0 in stage 0.0 (TID 56) (d952e2b2ede8, executor driver, partition 56, PROCESS_LOCAL, 4545 bytes) taskResourceAssignments Map()
[2022-06-07 06:48:07,145] {subprocess.py:92} INFO - 22/06/07 06:48:07 INFO Executor: Running task 56.0 in stage 0.0 (TID 56)
[2022-06-07 06:48:07,146] {subprocess.py:92} INFO - 22/06/07 06:48:07 INFO TaskSetManager: Finished task 54.0 in stage 0.0 (TID 54) in 19 ms on d952e2b2ede8 (executor driver) (53/180)
[2022-06-07 06:48:07,149] {subprocess.py:92} INFO - 22/06/07 06:48:07 INFO Executor: Finished task 55.0 in stage 0.0 (TID 55). 2128 bytes result sent to driver
[2022-06-07 06:48:07,151] {subprocess.py:92} INFO - 22/06/07 06:48:07 INFO TaskSetManager: Starting task 57.0 in stage 0.0 (TID 57) (d952e2b2ede8, executor driver, partition 57, PROCESS_LOCAL, 4545 bytes) taskResourceAssignments Map()
[2022-06-07 06:48:07,151] {subprocess.py:92} INFO - 22/06/07 06:48:07 INFO Executor: Finished task 52.0 in stage 0.0 (TID 52). 2367 bytes result sent to driver
[2022-06-07 06:48:07,152] {subprocess.py:92} INFO - 22/06/07 06:48:07 INFO Executor: Running task 57.0 in stage 0.0 (TID 57)
[2022-06-07 06:48:07,154] {subprocess.py:92} INFO - 22/06/07 06:48:07 INFO TaskSetManager: Finished task 55.0 in stage 0.0 (TID 55) in 19 ms on d952e2b2ede8 (executor driver) (54/180)
[2022-06-07 06:48:07,157] {subprocess.py:92} INFO - 22/06/07 06:48:07 INFO TaskSetManager: Starting task 58.0 in stage 0.0 (TID 58) (d952e2b2ede8, executor driver, partition 58, PROCESS_LOCAL, 4545 bytes) taskResourceAssignments Map()
[2022-06-07 06:48:07,158] {subprocess.py:92} INFO - 22/06/07 06:48:07 INFO Executor: Running task 58.0 in stage 0.0 (TID 58)
[2022-06-07 06:48:07,158] {subprocess.py:92} INFO - 22/06/07 06:48:07 INFO TaskSetManager: Finished task 52.0 in stage 0.0 (TID 52) in 38 ms on d952e2b2ede8 (executor driver) (55/180)
[2022-06-07 06:48:07,160] {subprocess.py:92} INFO - 22/06/07 06:48:07 INFO Executor: Finished task 53.0 in stage 0.0 (TID 53). 2367 bytes result sent to driver
[2022-06-07 06:48:07,160] {subprocess.py:92} INFO - 22/06/07 06:48:07 INFO Executor: Finished task 56.0 in stage 0.0 (TID 56). 2128 bytes result sent to driver
[2022-06-07 06:48:07,163] {subprocess.py:92} INFO - 22/06/07 06:48:07 INFO TaskSetManager: Starting task 59.0 in stage 0.0 (TID 59) (d952e2b2ede8, executor driver, partition 59, PROCESS_LOCAL, 4545 bytes) taskResourceAssignments Map()
[2022-06-07 06:48:07,164] {subprocess.py:92} INFO - 22/06/07 06:48:07 INFO TaskSetManager: Finished task 53.0 in stage 0.0 (TID 53) in 41 ms on d952e2b2ede8 (executor driver) (56/180)
[2022-06-07 06:48:07,165] {subprocess.py:92} INFO - 22/06/07 06:48:07 INFO Executor: Running task 59.0 in stage 0.0 (TID 59)
[2022-06-07 06:48:07,167] {subprocess.py:92} INFO - 22/06/07 06:48:07 INFO TaskSetManager: Starting task 60.0 in stage 0.0 (TID 60) (d952e2b2ede8, executor driver, partition 60, PROCESS_LOCAL, 4545 bytes) taskResourceAssignments Map()
[2022-06-07 06:48:07,169] {subprocess.py:92} INFO - 22/06/07 06:48:07 INFO TaskSetManager: Finished task 56.0 in stage 0.0 (TID 56) in 24 ms on d952e2b2ede8 (executor driver) (57/180)
[2022-06-07 06:48:07,170] {subprocess.py:92} INFO - 22/06/07 06:48:07 INFO Executor: Running task 60.0 in stage 0.0 (TID 60)
[2022-06-07 06:48:07,171] {subprocess.py:92} INFO - 22/06/07 06:48:07 INFO Executor: Finished task 57.0 in stage 0.0 (TID 57). 2128 bytes result sent to driver
[2022-06-07 06:48:07,172] {subprocess.py:92} INFO - 22/06/07 06:48:07 INFO TaskSetManager: Starting task 61.0 in stage 0.0 (TID 61) (d952e2b2ede8, executor driver, partition 61, PROCESS_LOCAL, 4545 bytes) taskResourceAssignments Map()
[2022-06-07 06:48:07,173] {subprocess.py:92} INFO - 22/06/07 06:48:07 INFO Executor: Running task 61.0 in stage 0.0 (TID 61)
[2022-06-07 06:48:07,174] {subprocess.py:92} INFO - 22/06/07 06:48:07 INFO TaskSetManager: Finished task 57.0 in stage 0.0 (TID 57) in 21 ms on d952e2b2ede8 (executor driver) (58/180)
[2022-06-07 06:48:07,181] {subprocess.py:92} INFO - 22/06/07 06:48:07 INFO Executor: Finished task 59.0 in stage 0.0 (TID 59). 2367 bytes result sent to driver
[2022-06-07 06:48:07,182] {subprocess.py:92} INFO - 22/06/07 06:48:07 INFO Executor: Finished task 58.0 in stage 0.0 (TID 58). 2128 bytes result sent to driver
[2022-06-07 06:48:07,184] {subprocess.py:92} INFO - 22/06/07 06:48:07 INFO TaskSetManager: Starting task 62.0 in stage 0.0 (TID 62) (d952e2b2ede8, executor driver, partition 62, PROCESS_LOCAL, 4545 bytes) taskResourceAssignments Map()
[2022-06-07 06:48:07,185] {subprocess.py:92} INFO - 22/06/07 06:48:07 INFO Executor: Running task 62.0 in stage 0.0 (TID 62)
[2022-06-07 06:48:07,186] {subprocess.py:92} INFO - 22/06/07 06:48:07 INFO TaskSetManager: Finished task 59.0 in stage 0.0 (TID 59) in 23 ms on d952e2b2ede8 (executor driver) (59/180)
[2022-06-07 06:48:07,189] {subprocess.py:92} INFO - 22/06/07 06:48:07 INFO TaskSetManager: Starting task 63.0 in stage 0.0 (TID 63) (d952e2b2ede8, executor driver, partition 63, PROCESS_LOCAL, 4545 bytes) taskResourceAssignments Map()
[2022-06-07 06:48:07,190] {subprocess.py:92} INFO - 22/06/07 06:48:07 INFO TaskSetManager: Finished task 58.0 in stage 0.0 (TID 58) in 35 ms on d952e2b2ede8 (executor driver) (60/180)
[2022-06-07 06:48:07,191] {subprocess.py:92} INFO - 22/06/07 06:48:07 INFO Executor: Running task 63.0 in stage 0.0 (TID 63)
[2022-06-07 06:48:07,192] {subprocess.py:92} INFO - 22/06/07 06:48:07 INFO Executor: Finished task 61.0 in stage 0.0 (TID 61). 2649 bytes result sent to driver
[2022-06-07 06:48:07,194] {subprocess.py:92} INFO - 22/06/07 06:48:07 INFO TaskSetManager: Starting task 64.0 in stage 0.0 (TID 64) (d952e2b2ede8, executor driver, partition 64, PROCESS_LOCAL, 4545 bytes) taskResourceAssignments Map()
[2022-06-07 06:48:07,194] {subprocess.py:92} INFO - 22/06/07 06:48:07 INFO Executor: Running task 64.0 in stage 0.0 (TID 64)
[2022-06-07 06:48:07,195] {subprocess.py:92} INFO - 22/06/07 06:48:07 INFO TaskSetManager: Finished task 61.0 in stage 0.0 (TID 61) in 24 ms on d952e2b2ede8 (executor driver) (61/180)
[2022-06-07 06:48:07,207] {subprocess.py:92} INFO - 22/06/07 06:48:07 INFO Executor: Finished task 60.0 in stage 0.0 (TID 60). 2367 bytes result sent to driver
[2022-06-07 06:48:07,208] {subprocess.py:92} INFO - 22/06/07 06:48:07 INFO Executor: Finished task 64.0 in stage 0.0 (TID 64). 2367 bytes result sent to driver
[2022-06-07 06:48:07,211] {subprocess.py:92} INFO - 22/06/07 06:48:07 INFO TaskSetManager: Starting task 65.0 in stage 0.0 (TID 65) (d952e2b2ede8, executor driver, partition 65, PROCESS_LOCAL, 4545 bytes) taskResourceAssignments Map()
[2022-06-07 06:48:07,212] {subprocess.py:92} INFO - 22/06/07 06:48:07 INFO TaskSetManager: Finished task 60.0 in stage 0.0 (TID 60) in 45 ms on d952e2b2ede8 (executor driver) (62/180)
[2022-06-07 06:48:07,213] {subprocess.py:92} INFO - 22/06/07 06:48:07 INFO Executor: Running task 65.0 in stage 0.0 (TID 65)
[2022-06-07 06:48:07,221] {subprocess.py:92} INFO - 22/06/07 06:48:07 INFO Executor: Finished task 62.0 in stage 0.0 (TID 62). 2367 bytes result sent to driver
[2022-06-07 06:48:07,224] {subprocess.py:92} INFO - 22/06/07 06:48:07 INFO TaskSetManager: Starting task 66.0 in stage 0.0 (TID 66) (d952e2b2ede8, executor driver, partition 66, PROCESS_LOCAL, 4545 bytes) taskResourceAssignments Map()
[2022-06-07 06:48:07,225] {subprocess.py:92} INFO - 22/06/07 06:48:07 INFO Executor: Running task 66.0 in stage 0.0 (TID 66)
[2022-06-07 06:48:07,227] {subprocess.py:92} INFO - 22/06/07 06:48:07 INFO TaskSetManager: Starting task 67.0 in stage 0.0 (TID 67) (d952e2b2ede8, executor driver, partition 67, PROCESS_LOCAL, 4545 bytes) taskResourceAssignments Map()
[2022-06-07 06:48:07,228] {subprocess.py:92} INFO - 22/06/07 06:48:07 INFO TaskSetManager: Finished task 62.0 in stage 0.0 (TID 62) in 44 ms on d952e2b2ede8 (executor driver) (63/180)
[2022-06-07 06:48:07,229] {subprocess.py:92} INFO - 22/06/07 06:48:07 INFO Executor: Finished task 63.0 in stage 0.0 (TID 63). 2367 bytes result sent to driver
[2022-06-07 06:48:07,230] {subprocess.py:92} INFO - 22/06/07 06:48:07 INFO TaskSetManager: Finished task 64.0 in stage 0.0 (TID 64) in 35 ms on d952e2b2ede8 (executor driver) (64/180)
[2022-06-07 06:48:07,232] {subprocess.py:92} INFO - 22/06/07 06:48:07 INFO TaskSetManager: Starting task 68.0 in stage 0.0 (TID 68) (d952e2b2ede8, executor driver, partition 68, PROCESS_LOCAL, 4545 bytes) taskResourceAssignments Map()
[2022-06-07 06:48:07,233] {subprocess.py:92} INFO - 22/06/07 06:48:07 INFO Executor: Running task 67.0 in stage 0.0 (TID 67)
[2022-06-07 06:48:07,234] {subprocess.py:92} INFO - 22/06/07 06:48:07 INFO TaskSetManager: Finished task 63.0 in stage 0.0 (TID 63) in 48 ms on d952e2b2ede8 (executor driver) (65/180)
[2022-06-07 06:48:07,235] {subprocess.py:92} INFO - 22/06/07 06:48:07 INFO Executor: Running task 68.0 in stage 0.0 (TID 68)
[2022-06-07 06:48:07,245] {subprocess.py:92} INFO - 22/06/07 06:48:07 INFO Executor: Finished task 66.0 in stage 0.0 (TID 66). 2606 bytes result sent to driver
[2022-06-07 06:48:07,246] {subprocess.py:92} INFO - 22/06/07 06:48:07 INFO TaskSetManager: Starting task 69.0 in stage 0.0 (TID 69) (d952e2b2ede8, executor driver, partition 69, PROCESS_LOCAL, 4545 bytes) taskResourceAssignments Map()
[2022-06-07 06:48:07,254] {subprocess.py:92} INFO - 22/06/07 06:48:07 INFO Executor: Finished task 68.0 in stage 0.0 (TID 68). 2367 bytes result sent to driver
[2022-06-07 06:48:07,256] {subprocess.py:92} INFO - 22/06/07 06:48:07 INFO Executor: Finished task 65.0 in stage 0.0 (TID 65). 2367 bytes result sent to driver
[2022-06-07 06:48:07,257] {subprocess.py:92} INFO - 22/06/07 06:48:07 INFO Executor: Finished task 67.0 in stage 0.0 (TID 67). 2606 bytes result sent to driver
[2022-06-07 06:48:07,258] {subprocess.py:92} INFO - 22/06/07 06:48:07 INFO TaskSetManager: Finished task 66.0 in stage 0.0 (TID 66) in 35 ms on d952e2b2ede8 (executor driver) (66/180)
[2022-06-07 06:48:07,259] {subprocess.py:92} INFO - 22/06/07 06:48:07 INFO Executor: Running task 69.0 in stage 0.0 (TID 69)
[2022-06-07 06:48:07,260] {subprocess.py:92} INFO - 22/06/07 06:48:07 INFO TaskSetManager: Starting task 70.0 in stage 0.0 (TID 70) (d952e2b2ede8, executor driver, partition 70, PROCESS_LOCAL, 4545 bytes) taskResourceAssignments Map()
[2022-06-07 06:48:07,261] {subprocess.py:92} INFO - 22/06/07 06:48:07 INFO Executor: Running task 70.0 in stage 0.0 (TID 70)
[2022-06-07 06:48:07,262] {subprocess.py:92} INFO - 22/06/07 06:48:07 INFO TaskSetManager: Starting task 71.0 in stage 0.0 (TID 71) (d952e2b2ede8, executor driver, partition 71, PROCESS_LOCAL, 4545 bytes) taskResourceAssignments Map()
[2022-06-07 06:48:07,263] {subprocess.py:92} INFO - 22/06/07 06:48:07 INFO TaskSetManager: Finished task 68.0 in stage 0.0 (TID 68) in 31 ms on d952e2b2ede8 (executor driver) (67/180)
[2022-06-07 06:48:07,264] {subprocess.py:92} INFO - 22/06/07 06:48:07 INFO TaskSetManager: Finished task 65.0 in stage 0.0 (TID 65) in 53 ms on d952e2b2ede8 (executor driver) (68/180)
[2022-06-07 06:48:07,264] {subprocess.py:92} INFO - 22/06/07 06:48:07 INFO Executor: Running task 71.0 in stage 0.0 (TID 71)
[2022-06-07 06:48:07,265] {subprocess.py:92} INFO - 22/06/07 06:48:07 INFO TaskSetManager: Starting task 72.0 in stage 0.0 (TID 72) (d952e2b2ede8, executor driver, partition 72, PROCESS_LOCAL, 4545 bytes) taskResourceAssignments Map()
[2022-06-07 06:48:07,266] {subprocess.py:92} INFO - 22/06/07 06:48:07 INFO Executor: Running task 72.0 in stage 0.0 (TID 72)
[2022-06-07 06:48:07,267] {subprocess.py:92} INFO - 22/06/07 06:48:07 INFO TaskSetManager: Finished task 67.0 in stage 0.0 (TID 67) in 43 ms on d952e2b2ede8 (executor driver) (69/180)
[2022-06-07 06:48:07,277] {subprocess.py:92} INFO - 22/06/07 06:48:07 INFO Executor: Finished task 70.0 in stage 0.0 (TID 70). 2606 bytes result sent to driver
[2022-06-07 06:48:07,279] {subprocess.py:92} INFO - 22/06/07 06:48:07 INFO TaskSetManager: Starting task 73.0 in stage 0.0 (TID 73) (d952e2b2ede8, executor driver, partition 73, PROCESS_LOCAL, 4545 bytes) taskResourceAssignments Map()
[2022-06-07 06:48:07,280] {subprocess.py:92} INFO - 22/06/07 06:48:07 INFO TaskSetManager: Finished task 70.0 in stage 0.0 (TID 70) in 20 ms on d952e2b2ede8 (executor driver) (70/180)
[2022-06-07 06:48:07,281] {subprocess.py:92} INFO - 22/06/07 06:48:07 INFO Executor: Running task 73.0 in stage 0.0 (TID 73)
[2022-06-07 06:48:07,292] {subprocess.py:92} INFO - 22/06/07 06:48:07 INFO Executor: Finished task 72.0 in stage 0.0 (TID 72). 2367 bytes result sent to driver
[2022-06-07 06:48:07,294] {subprocess.py:92} INFO - 22/06/07 06:48:07 INFO TaskSetManager: Starting task 74.0 in stage 0.0 (TID 74) (d952e2b2ede8, executor driver, partition 74, PROCESS_LOCAL, 4545 bytes) taskResourceAssignments Map()
[2022-06-07 06:48:07,296] {subprocess.py:92} INFO - 22/06/07 06:48:07 INFO Executor: Running task 74.0 in stage 0.0 (TID 74)
[2022-06-07 06:48:07,296] {subprocess.py:92} INFO - 22/06/07 06:48:07 INFO TaskSetManager: Finished task 72.0 in stage 0.0 (TID 72) in 32 ms on d952e2b2ede8 (executor driver) (71/180)
[2022-06-07 06:48:07,303] {subprocess.py:92} INFO - 22/06/07 06:48:07 INFO Executor: Finished task 71.0 in stage 0.0 (TID 71). 2367 bytes result sent to driver
[2022-06-07 06:48:07,304] {subprocess.py:92} INFO - 22/06/07 06:48:07 INFO TaskSetManager: Starting task 75.0 in stage 0.0 (TID 75) (d952e2b2ede8, executor driver, partition 75, PROCESS_LOCAL, 4545 bytes) taskResourceAssignments Map()
[2022-06-07 06:48:07,305] {subprocess.py:92} INFO - 22/06/07 06:48:07 INFO TaskSetManager: Finished task 71.0 in stage 0.0 (TID 71) in 43 ms on d952e2b2ede8 (executor driver) (72/180)
[2022-06-07 06:48:07,313] {subprocess.py:92} INFO - 22/06/07 06:48:07 INFO Executor: Running task 75.0 in stage 0.0 (TID 75)
[2022-06-07 06:48:07,317] {subprocess.py:92} INFO - 22/06/07 06:48:07 INFO Executor: Finished task 69.0 in stage 0.0 (TID 69). 2367 bytes result sent to driver
[2022-06-07 06:48:07,320] {subprocess.py:92} INFO - 22/06/07 06:48:07 INFO TaskSetManager: Starting task 76.0 in stage 0.0 (TID 76) (d952e2b2ede8, executor driver, partition 76, PROCESS_LOCAL, 4545 bytes) taskResourceAssignments Map()
[2022-06-07 06:48:07,320] {subprocess.py:92} INFO - 22/06/07 06:48:07 INFO Executor: Running task 76.0 in stage 0.0 (TID 76)
[2022-06-07 06:48:07,321] {subprocess.py:92} INFO - 22/06/07 06:48:07 INFO TaskSetManager: Finished task 69.0 in stage 0.0 (TID 69) in 76 ms on d952e2b2ede8 (executor driver) (73/180)
[2022-06-07 06:48:07,328] {subprocess.py:92} INFO - 22/06/07 06:48:07 INFO Executor: Finished task 73.0 in stage 0.0 (TID 73). 2367 bytes result sent to driver
[2022-06-07 06:48:07,329] {subprocess.py:92} INFO - 22/06/07 06:48:07 INFO Executor: Finished task 74.0 in stage 0.0 (TID 74). 2606 bytes result sent to driver
[2022-06-07 06:48:07,330] {subprocess.py:92} INFO - 22/06/07 06:48:07 INFO TaskSetManager: Starting task 77.0 in stage 0.0 (TID 77) (d952e2b2ede8, executor driver, partition 77, PROCESS_LOCAL, 4545 bytes) taskResourceAssignments Map()
[2022-06-07 06:48:07,331] {subprocess.py:92} INFO - 22/06/07 06:48:07 INFO TaskSetManager: Finished task 73.0 in stage 0.0 (TID 73) in 53 ms on d952e2b2ede8 (executor driver) (74/180)
[2022-06-07 06:48:07,333] {subprocess.py:92} INFO - 22/06/07 06:48:07 INFO Executor: Running task 77.0 in stage 0.0 (TID 77)
[2022-06-07 06:48:07,334] {subprocess.py:92} INFO - 22/06/07 06:48:07 INFO TaskSetManager: Starting task 78.0 in stage 0.0 (TID 78) (d952e2b2ede8, executor driver, partition 78, PROCESS_LOCAL, 4545 bytes) taskResourceAssignments Map()
[2022-06-07 06:48:07,335] {subprocess.py:92} INFO - 22/06/07 06:48:07 INFO TaskSetManager: Finished task 74.0 in stage 0.0 (TID 74) in 39 ms on d952e2b2ede8 (executor driver) (75/180)
[2022-06-07 06:48:07,335] {subprocess.py:92} INFO - 22/06/07 06:48:07 INFO Executor: Running task 78.0 in stage 0.0 (TID 78)
[2022-06-07 06:48:07,339] {subprocess.py:92} INFO - 22/06/07 06:48:07 INFO Executor: Finished task 76.0 in stage 0.0 (TID 76). 2367 bytes result sent to driver
[2022-06-07 06:48:07,343] {subprocess.py:92} INFO - 22/06/07 06:48:07 INFO Executor: Finished task 75.0 in stage 0.0 (TID 75). 2367 bytes result sent to driver
[2022-06-07 06:48:07,343] {subprocess.py:92} INFO - 22/06/07 06:48:07 INFO TaskSetManager: Starting task 79.0 in stage 0.0 (TID 79) (d952e2b2ede8, executor driver, partition 79, PROCESS_LOCAL, 4545 bytes) taskResourceAssignments Map()
[2022-06-07 06:48:07,346] {subprocess.py:92} INFO - 22/06/07 06:48:07 INFO TaskSetManager: Finished task 76.0 in stage 0.0 (TID 76) in 25 ms on d952e2b2ede8 (executor driver) (76/180)
[2022-06-07 06:48:07,347] {subprocess.py:92} INFO - 22/06/07 06:48:07 INFO TaskSetManager: Starting task 80.0 in stage 0.0 (TID 80) (d952e2b2ede8, executor driver, partition 80, PROCESS_LOCAL, 4545 bytes) taskResourceAssignments Map()
[2022-06-07 06:48:07,347] {subprocess.py:92} INFO - 22/06/07 06:48:07 INFO Executor: Running task 79.0 in stage 0.0 (TID 79)
[2022-06-07 06:48:07,348] {subprocess.py:92} INFO - 22/06/07 06:48:07 INFO Executor: Finished task 78.0 in stage 0.0 (TID 78). 2367 bytes result sent to driver
[2022-06-07 06:48:07,349] {subprocess.py:92} INFO - 22/06/07 06:48:07 INFO Executor: Running task 80.0 in stage 0.0 (TID 80)
[2022-06-07 06:48:07,350] {subprocess.py:92} INFO - 22/06/07 06:48:07 INFO TaskSetManager: Starting task 81.0 in stage 0.0 (TID 81) (d952e2b2ede8, executor driver, partition 81, PROCESS_LOCAL, 4545 bytes) taskResourceAssignments Map()
[2022-06-07 06:48:07,351] {subprocess.py:92} INFO - 22/06/07 06:48:07 INFO TaskSetManager: Finished task 75.0 in stage 0.0 (TID 75) in 47 ms on d952e2b2ede8 (executor driver) (77/180)
[2022-06-07 06:48:07,351] {subprocess.py:92} INFO - 22/06/07 06:48:07 INFO TaskSetManager: Finished task 78.0 in stage 0.0 (TID 78) in 19 ms on d952e2b2ede8 (executor driver) (78/180)
[2022-06-07 06:48:07,352] {subprocess.py:92} INFO - 22/06/07 06:48:07 INFO Executor: Running task 81.0 in stage 0.0 (TID 81)
[2022-06-07 06:48:07,363] {subprocess.py:92} INFO - 22/06/07 06:48:07 INFO Executor: Finished task 79.0 in stage 0.0 (TID 79). 2606 bytes result sent to driver
[2022-06-07 06:48:07,365] {subprocess.py:92} INFO - 22/06/07 06:48:07 INFO TaskSetManager: Starting task 82.0 in stage 0.0 (TID 82) (d952e2b2ede8, executor driver, partition 82, PROCESS_LOCAL, 4545 bytes) taskResourceAssignments Map()
[2022-06-07 06:48:07,367] {subprocess.py:92} INFO - 22/06/07 06:48:07 INFO TaskSetManager: Finished task 79.0 in stage 0.0 (TID 79) in 24 ms on d952e2b2ede8 (executor driver) (79/180)
[2022-06-07 06:48:07,369] {subprocess.py:92} INFO - 22/06/07 06:48:07 INFO Executor: Finished task 77.0 in stage 0.0 (TID 77). 2367 bytes result sent to driver
[2022-06-07 06:48:07,370] {subprocess.py:92} INFO - 22/06/07 06:48:07 INFO Executor: Finished task 80.0 in stage 0.0 (TID 80). 2606 bytes result sent to driver
[2022-06-07 06:48:07,370] {subprocess.py:92} INFO - 22/06/07 06:48:07 INFO Executor: Running task 82.0 in stage 0.0 (TID 82)
[2022-06-07 06:48:07,371] {subprocess.py:92} INFO - 22/06/07 06:48:07 INFO TaskSetManager: Starting task 83.0 in stage 0.0 (TID 83) (d952e2b2ede8, executor driver, partition 83, PROCESS_LOCAL, 4545 bytes) taskResourceAssignments Map()
[2022-06-07 06:48:07,372] {subprocess.py:92} INFO - 22/06/07 06:48:07 INFO Executor: Running task 83.0 in stage 0.0 (TID 83)
[2022-06-07 06:48:07,373] {subprocess.py:92} INFO - 22/06/07 06:48:07 INFO TaskSetManager: Finished task 77.0 in stage 0.0 (TID 77) in 43 ms on d952e2b2ede8 (executor driver) (80/180)
[2022-06-07 06:48:07,424] {subprocess.py:92} INFO - 22/06/07 06:48:07 INFO TaskSetManager: Starting task 84.0 in stage 0.0 (TID 84) (d952e2b2ede8, executor driver, partition 84, PROCESS_LOCAL, 4545 bytes) taskResourceAssignments Map()
[2022-06-07 06:48:07,425] {subprocess.py:92} INFO - 22/06/07 06:48:07 INFO Executor: Running task 84.0 in stage 0.0 (TID 84)
[2022-06-07 06:48:07,426] {subprocess.py:92} INFO - 22/06/07 06:48:07 INFO TaskSetManager: Finished task 80.0 in stage 0.0 (TID 80) in 79 ms on d952e2b2ede8 (executor driver) (81/180)
[2022-06-07 06:48:07,432] {subprocess.py:92} INFO - 22/06/07 06:48:07 INFO Executor: Finished task 81.0 in stage 0.0 (TID 81). 2453 bytes result sent to driver
[2022-06-07 06:48:07,433] {subprocess.py:92} INFO - 22/06/07 06:48:07 INFO TaskSetManager: Starting task 85.0 in stage 0.0 (TID 85) (d952e2b2ede8, executor driver, partition 85, PROCESS_LOCAL, 4545 bytes) taskResourceAssignments Map()
[2022-06-07 06:48:07,435] {subprocess.py:92} INFO - 22/06/07 06:48:07 INFO TaskSetManager: Finished task 81.0 in stage 0.0 (TID 81) in 86 ms on d952e2b2ede8 (executor driver) (82/180)
[2022-06-07 06:48:07,436] {subprocess.py:92} INFO - 22/06/07 06:48:07 INFO Executor: Running task 85.0 in stage 0.0 (TID 85)
[2022-06-07 06:48:07,440] {subprocess.py:92} INFO - 22/06/07 06:48:07 INFO Executor: Finished task 84.0 in stage 0.0 (TID 84). 2367 bytes result sent to driver
[2022-06-07 06:48:07,442] {subprocess.py:92} INFO - 22/06/07 06:48:07 INFO TaskSetManager: Starting task 86.0 in stage 0.0 (TID 86) (d952e2b2ede8, executor driver, partition 86, PROCESS_LOCAL, 4545 bytes) taskResourceAssignments Map()
[2022-06-07 06:48:07,443] {subprocess.py:92} INFO - 22/06/07 06:48:07 INFO TaskSetManager: Finished task 84.0 in stage 0.0 (TID 84) in 70 ms on d952e2b2ede8 (executor driver) (83/180)
[2022-06-07 06:48:07,445] {subprocess.py:92} INFO - 22/06/07 06:48:07 INFO Executor: Finished task 82.0 in stage 0.0 (TID 82). 2649 bytes result sent to driver
[2022-06-07 06:48:07,448] {subprocess.py:92} INFO - 22/06/07 06:48:07 INFO TaskSetManager: Starting task 87.0 in stage 0.0 (TID 87) (d952e2b2ede8, executor driver, partition 87, PROCESS_LOCAL, 4545 bytes) taskResourceAssignments Map()
[2022-06-07 06:48:07,449] {subprocess.py:92} INFO - 22/06/07 06:48:07 INFO Executor: Running task 87.0 in stage 0.0 (TID 87)
[2022-06-07 06:48:07,450] {subprocess.py:92} INFO - 22/06/07 06:48:07 INFO TaskSetManager: Finished task 82.0 in stage 0.0 (TID 82) in 85 ms on d952e2b2ede8 (executor driver) (84/180)
[2022-06-07 06:48:07,451] {subprocess.py:92} INFO - 22/06/07 06:48:07 INFO Executor: Running task 86.0 in stage 0.0 (TID 86)
[2022-06-07 06:48:07,454] {subprocess.py:92} INFO - 22/06/07 06:48:07 INFO Executor: Finished task 83.0 in stage 0.0 (TID 83). 2410 bytes result sent to driver
[2022-06-07 06:48:07,458] {subprocess.py:92} INFO - 22/06/07 06:48:07 INFO TaskSetManager: Starting task 88.0 in stage 0.0 (TID 88) (d952e2b2ede8, executor driver, partition 88, PROCESS_LOCAL, 4545 bytes) taskResourceAssignments Map()
[2022-06-07 06:48:07,461] {subprocess.py:92} INFO - 22/06/07 06:48:07 INFO TaskSetManager: Finished task 83.0 in stage 0.0 (TID 83) in 90 ms on d952e2b2ede8 (executor driver) (85/180)
[2022-06-07 06:48:07,463] {subprocess.py:92} INFO - 22/06/07 06:48:07 INFO Executor: Running task 88.0 in stage 0.0 (TID 88)
[2022-06-07 06:48:07,465] {subprocess.py:92} INFO - 22/06/07 06:48:07 INFO Executor: Finished task 85.0 in stage 0.0 (TID 85). 2367 bytes result sent to driver
[2022-06-07 06:48:07,466] {subprocess.py:92} INFO - 22/06/07 06:48:07 INFO TaskSetManager: Starting task 89.0 in stage 0.0 (TID 89) (d952e2b2ede8, executor driver, partition 89, PROCESS_LOCAL, 4545 bytes) taskResourceAssignments Map()
[2022-06-07 06:48:07,467] {subprocess.py:92} INFO - 22/06/07 06:48:07 INFO Executor: Running task 89.0 in stage 0.0 (TID 89)
[2022-06-07 06:48:07,468] {subprocess.py:92} INFO - 22/06/07 06:48:07 INFO TaskSetManager: Finished task 85.0 in stage 0.0 (TID 85) in 36 ms on d952e2b2ede8 (executor driver) (86/180)
[2022-06-07 06:48:07,473] {subprocess.py:92} INFO - 22/06/07 06:48:07 INFO Executor: Finished task 86.0 in stage 0.0 (TID 86). 2367 bytes result sent to driver
[2022-06-07 06:48:07,474] {subprocess.py:92} INFO - 22/06/07 06:48:07 INFO TaskSetManager: Starting task 90.0 in stage 0.0 (TID 90) (d952e2b2ede8, executor driver, partition 90, PROCESS_LOCAL, 4545 bytes) taskResourceAssignments Map()
[2022-06-07 06:48:07,476] {subprocess.py:92} INFO - 22/06/07 06:48:07 INFO TaskSetManager: Finished task 86.0 in stage 0.0 (TID 86) in 34 ms on d952e2b2ede8 (executor driver) (87/180)
[2022-06-07 06:48:07,477] {subprocess.py:92} INFO - 22/06/07 06:48:07 INFO Executor: Running task 90.0 in stage 0.0 (TID 90)
[2022-06-07 06:48:07,480] {subprocess.py:92} INFO - 22/06/07 06:48:07 INFO Executor: Finished task 87.0 in stage 0.0 (TID 87). 2410 bytes result sent to driver
[2022-06-07 06:48:07,482] {subprocess.py:92} INFO - 22/06/07 06:48:07 INFO TaskSetManager: Starting task 91.0 in stage 0.0 (TID 91) (d952e2b2ede8, executor driver, partition 91, PROCESS_LOCAL, 4545 bytes) taskResourceAssignments Map()
[2022-06-07 06:48:07,485] {subprocess.py:92} INFO - 22/06/07 06:48:07 INFO TaskSetManager: Finished task 87.0 in stage 0.0 (TID 87) in 38 ms on d952e2b2ede8 (executor driver) (88/180)
[2022-06-07 06:48:07,486] {subprocess.py:92} INFO - 22/06/07 06:48:07 INFO Executor: Running task 91.0 in stage 0.0 (TID 91)
[2022-06-07 06:48:07,489] {subprocess.py:92} INFO - 22/06/07 06:48:07 INFO Executor: Finished task 88.0 in stage 0.0 (TID 88). 2606 bytes result sent to driver
[2022-06-07 06:48:07,491] {subprocess.py:92} INFO - 22/06/07 06:48:07 INFO TaskSetManager: Starting task 92.0 in stage 0.0 (TID 92) (d952e2b2ede8, executor driver, partition 92, PROCESS_LOCAL, 4545 bytes) taskResourceAssignments Map()
[2022-06-07 06:48:07,493] {subprocess.py:92} INFO - 22/06/07 06:48:07 INFO Executor: Finished task 89.0 in stage 0.0 (TID 89). 2367 bytes result sent to driver
[2022-06-07 06:48:07,494] {subprocess.py:92} INFO - 22/06/07 06:48:07 INFO Executor: Running task 92.0 in stage 0.0 (TID 92)
[2022-06-07 06:48:07,495] {subprocess.py:92} INFO - 22/06/07 06:48:07 INFO TaskSetManager: Starting task 93.0 in stage 0.0 (TID 93) (d952e2b2ede8, executor driver, partition 93, PROCESS_LOCAL, 4545 bytes) taskResourceAssignments Map()
[2022-06-07 06:48:07,495] {subprocess.py:92} INFO - 22/06/07 06:48:07 INFO TaskSetManager: Finished task 88.0 in stage 0.0 (TID 88) in 37 ms on d952e2b2ede8 (executor driver) (89/180)
[2022-06-07 06:48:07,496] {subprocess.py:92} INFO - 22/06/07 06:48:07 INFO TaskSetManager: Finished task 89.0 in stage 0.0 (TID 89) in 30 ms on d952e2b2ede8 (executor driver) (90/180)
[2022-06-07 06:48:07,497] {subprocess.py:92} INFO - 22/06/07 06:48:07 INFO Executor: Running task 93.0 in stage 0.0 (TID 93)
[2022-06-07 06:48:07,502] {subprocess.py:92} INFO - 22/06/07 06:48:07 INFO Executor: Finished task 91.0 in stage 0.0 (TID 91). 2367 bytes result sent to driver
[2022-06-07 06:48:07,504] {subprocess.py:92} INFO - 22/06/07 06:48:07 INFO TaskSetManager: Starting task 94.0 in stage 0.0 (TID 94) (d952e2b2ede8, executor driver, partition 94, PROCESS_LOCAL, 4545 bytes) taskResourceAssignments Map()
[2022-06-07 06:48:07,505] {subprocess.py:92} INFO - 22/06/07 06:48:07 INFO TaskSetManager: Finished task 91.0 in stage 0.0 (TID 91) in 22 ms on d952e2b2ede8 (executor driver) (91/180)
[2022-06-07 06:48:07,506] {subprocess.py:92} INFO - 22/06/07 06:48:07 INFO Executor: Running task 94.0 in stage 0.0 (TID 94)
[2022-06-07 06:48:07,509] {subprocess.py:92} INFO - 22/06/07 06:48:07 INFO Executor: Finished task 90.0 in stage 0.0 (TID 90). 2367 bytes result sent to driver
[2022-06-07 06:48:07,511] {subprocess.py:92} INFO - 22/06/07 06:48:07 INFO TaskSetManager: Starting task 95.0 in stage 0.0 (TID 95) (d952e2b2ede8, executor driver, partition 95, PROCESS_LOCAL, 4545 bytes) taskResourceAssignments Map()
[2022-06-07 06:48:07,515] {subprocess.py:92} INFO - 22/06/07 06:48:07 INFO TaskSetManager: Finished task 90.0 in stage 0.0 (TID 90) in 38 ms on d952e2b2ede8 (executor driver) (92/180)
[2022-06-07 06:48:07,516] {subprocess.py:92} INFO - 22/06/07 06:48:07 INFO Executor: Running task 95.0 in stage 0.0 (TID 95)
[2022-06-07 06:48:07,519] {subprocess.py:92} INFO - 22/06/07 06:48:07 INFO Executor: Finished task 93.0 in stage 0.0 (TID 93). 2606 bytes result sent to driver
[2022-06-07 06:48:07,522] {subprocess.py:92} INFO - 22/06/07 06:48:07 INFO TaskSetManager: Starting task 96.0 in stage 0.0 (TID 96) (d952e2b2ede8, executor driver, partition 96, PROCESS_LOCAL, 4545 bytes) taskResourceAssignments Map()
[2022-06-07 06:48:07,523] {subprocess.py:92} INFO - 22/06/07 06:48:07 INFO TaskSetManager: Finished task 93.0 in stage 0.0 (TID 93) in 31 ms on d952e2b2ede8 (executor driver) (93/180)
[2022-06-07 06:48:07,524] {subprocess.py:92} INFO - 22/06/07 06:48:07 INFO Executor: Running task 96.0 in stage 0.0 (TID 96)
[2022-06-07 06:48:07,525] {subprocess.py:92} INFO - 22/06/07 06:48:07 INFO Executor: Finished task 94.0 in stage 0.0 (TID 94). 2367 bytes result sent to driver
[2022-06-07 06:48:07,527] {subprocess.py:92} INFO - 22/06/07 06:48:07 INFO TaskSetManager: Starting task 97.0 in stage 0.0 (TID 97) (d952e2b2ede8, executor driver, partition 97, PROCESS_LOCAL, 4545 bytes) taskResourceAssignments Map()
[2022-06-07 06:48:07,528] {subprocess.py:92} INFO - 22/06/07 06:48:07 INFO TaskSetManager: Finished task 94.0 in stage 0.0 (TID 94) in 25 ms on d952e2b2ede8 (executor driver) (94/180)
[2022-06-07 06:48:07,529] {subprocess.py:92} INFO - 22/06/07 06:48:07 INFO Executor: Running task 97.0 in stage 0.0 (TID 97)
[2022-06-07 06:48:07,530] {subprocess.py:92} INFO - 22/06/07 06:48:07 INFO Executor: Finished task 92.0 in stage 0.0 (TID 92). 2649 bytes result sent to driver
[2022-06-07 06:48:07,532] {subprocess.py:92} INFO - 22/06/07 06:48:07 INFO TaskSetManager: Starting task 98.0 in stage 0.0 (TID 98) (d952e2b2ede8, executor driver, partition 98, PROCESS_LOCAL, 4545 bytes) taskResourceAssignments Map()
[2022-06-07 06:48:07,533] {subprocess.py:92} INFO - 22/06/07 06:48:07 INFO TaskSetManager: Finished task 92.0 in stage 0.0 (TID 92) in 42 ms on d952e2b2ede8 (executor driver) (95/180)
[2022-06-07 06:48:07,535] {subprocess.py:92} INFO - 22/06/07 06:48:07 INFO Executor: Running task 98.0 in stage 0.0 (TID 98)
[2022-06-07 06:48:07,538] {subprocess.py:92} INFO - 22/06/07 06:48:07 INFO Executor: Finished task 95.0 in stage 0.0 (TID 95). 2367 bytes result sent to driver
[2022-06-07 06:48:07,539] {subprocess.py:92} INFO - 22/06/07 06:48:07 INFO TaskSetManager: Starting task 99.0 in stage 0.0 (TID 99) (d952e2b2ede8, executor driver, partition 99, PROCESS_LOCAL, 4545 bytes) taskResourceAssignments Map()
[2022-06-07 06:48:07,541] {subprocess.py:92} INFO - 22/06/07 06:48:07 INFO Executor: Running task 99.0 in stage 0.0 (TID 99)
[2022-06-07 06:48:07,542] {subprocess.py:92} INFO - 22/06/07 06:48:07 INFO TaskSetManager: Finished task 95.0 in stage 0.0 (TID 95) in 30 ms on d952e2b2ede8 (executor driver) (96/180)
[2022-06-07 06:48:07,551] {subprocess.py:92} INFO - 22/06/07 06:48:07 INFO Executor: Finished task 96.0 in stage 0.0 (TID 96). 2367 bytes result sent to driver
[2022-06-07 06:48:07,553] {subprocess.py:92} INFO - 22/06/07 06:48:07 INFO TaskSetManager: Starting task 100.0 in stage 0.0 (TID 100) (d952e2b2ede8, executor driver, partition 100, PROCESS_LOCAL, 4545 bytes) taskResourceAssignments Map()
[2022-06-07 06:48:07,555] {subprocess.py:92} INFO - 22/06/07 06:48:07 INFO TaskSetManager: Finished task 96.0 in stage 0.0 (TID 96) in 33 ms on d952e2b2ede8 (executor driver) (97/180)
[2022-06-07 06:48:07,558] {subprocess.py:92} INFO - 22/06/07 06:48:07 INFO Executor: Running task 100.0 in stage 0.0 (TID 100)
[2022-06-07 06:48:07,561] {subprocess.py:92} INFO - 22/06/07 06:48:07 INFO Executor: Finished task 99.0 in stage 0.0 (TID 99). 2367 bytes result sent to driver
[2022-06-07 06:48:07,562] {subprocess.py:92} INFO - 22/06/07 06:48:07 INFO Executor: Finished task 97.0 in stage 0.0 (TID 97). 2606 bytes result sent to driver
[2022-06-07 06:48:07,571] {subprocess.py:92} INFO - 22/06/07 06:48:07 INFO TaskSetManager: Starting task 101.0 in stage 0.0 (TID 101) (d952e2b2ede8, executor driver, partition 101, PROCESS_LOCAL, 4545 bytes) taskResourceAssignments Map()
[2022-06-07 06:48:07,572] {subprocess.py:92} INFO - 22/06/07 06:48:07 INFO TaskSetManager: Finished task 99.0 in stage 0.0 (TID 99) in 34 ms on d952e2b2ede8 (executor driver) (98/180)
[2022-06-07 06:48:07,573] {subprocess.py:92} INFO - 22/06/07 06:48:07 INFO Executor: Finished task 98.0 in stage 0.0 (TID 98). 2367 bytes result sent to driver
[2022-06-07 06:48:07,575] {subprocess.py:92} INFO - 22/06/07 06:48:07 INFO Executor: Running task 101.0 in stage 0.0 (TID 101)
[2022-06-07 06:48:07,575] {subprocess.py:92} INFO - 22/06/07 06:48:07 INFO TaskSetManager: Starting task 102.0 in stage 0.0 (TID 102) (d952e2b2ede8, executor driver, partition 102, PROCESS_LOCAL, 4545 bytes) taskResourceAssignments Map()
[2022-06-07 06:48:07,577] {subprocess.py:92} INFO - 22/06/07 06:48:07 INFO TaskSetManager: Finished task 97.0 in stage 0.0 (TID 97) in 50 ms on d952e2b2ede8 (executor driver) (99/180)
[2022-06-07 06:48:07,578] {subprocess.py:92} INFO - 22/06/07 06:48:07 INFO Executor: Running task 102.0 in stage 0.0 (TID 102)
[2022-06-07 06:48:07,579] {subprocess.py:92} INFO - 22/06/07 06:48:07 INFO TaskSetManager: Starting task 103.0 in stage 0.0 (TID 103) (d952e2b2ede8, executor driver, partition 103, PROCESS_LOCAL, 4545 bytes) taskResourceAssignments Map()
[2022-06-07 06:48:07,580] {subprocess.py:92} INFO - 22/06/07 06:48:07 INFO Executor: Finished task 100.0 in stage 0.0 (TID 100). 2128 bytes result sent to driver
[2022-06-07 06:48:07,581] {subprocess.py:92} INFO - 22/06/07 06:48:07 INFO TaskSetManager: Finished task 100.0 in stage 0.0 (TID 100) in 28 ms on d952e2b2ede8 (executor driver) (100/180)
[2022-06-07 06:48:07,582] {subprocess.py:92} INFO - 22/06/07 06:48:07 INFO TaskSetManager: Finished task 98.0 in stage 0.0 (TID 98) in 50 ms on d952e2b2ede8 (executor driver) (101/180)
[2022-06-07 06:48:07,584] {subprocess.py:92} INFO - 22/06/07 06:48:07 INFO TaskSetManager: Starting task 104.0 in stage 0.0 (TID 104) (d952e2b2ede8, executor driver, partition 104, PROCESS_LOCAL, 4545 bytes) taskResourceAssignments Map()
[2022-06-07 06:48:07,585] {subprocess.py:92} INFO - 22/06/07 06:48:07 INFO Executor: Running task 104.0 in stage 0.0 (TID 104)
[2022-06-07 06:48:07,586] {subprocess.py:92} INFO - 22/06/07 06:48:07 INFO Executor: Running task 103.0 in stage 0.0 (TID 103)
[2022-06-07 06:48:07,593] {subprocess.py:92} INFO - 22/06/07 06:48:07 INFO Executor: Finished task 101.0 in stage 0.0 (TID 101). 2128 bytes result sent to driver
[2022-06-07 06:48:07,595] {subprocess.py:92} INFO - 22/06/07 06:48:07 INFO TaskSetManager: Starting task 105.0 in stage 0.0 (TID 105) (d952e2b2ede8, executor driver, partition 105, PROCESS_LOCAL, 4545 bytes) taskResourceAssignments Map()
[2022-06-07 06:48:07,596] {subprocess.py:92} INFO - 22/06/07 06:48:07 INFO TaskSetManager: Finished task 101.0 in stage 0.0 (TID 101) in 26 ms on d952e2b2ede8 (executor driver) (102/180)
[2022-06-07 06:48:07,597] {subprocess.py:92} INFO - 22/06/07 06:48:07 INFO Executor: Running task 105.0 in stage 0.0 (TID 105)
[2022-06-07 06:48:07,600] {subprocess.py:92} INFO - 22/06/07 06:48:07 INFO Executor: Finished task 104.0 in stage 0.0 (TID 104). 2367 bytes result sent to driver
[2022-06-07 06:48:07,601] {subprocess.py:92} INFO - 22/06/07 06:48:07 INFO TaskSetManager: Starting task 106.0 in stage 0.0 (TID 106) (d952e2b2ede8, executor driver, partition 106, PROCESS_LOCAL, 4545 bytes) taskResourceAssignments Map()
[2022-06-07 06:48:07,602] {subprocess.py:92} INFO - 22/06/07 06:48:07 INFO TaskSetManager: Finished task 104.0 in stage 0.0 (TID 104) in 19 ms on d952e2b2ede8 (executor driver) (103/180)
[2022-06-07 06:48:07,604] {subprocess.py:92} INFO - 22/06/07 06:48:07 INFO Executor: Finished task 103.0 in stage 0.0 (TID 103). 2367 bytes result sent to driver
[2022-06-07 06:48:07,606] {subprocess.py:92} INFO - 22/06/07 06:48:07 INFO Executor: Running task 106.0 in stage 0.0 (TID 106)
[2022-06-07 06:48:07,606] {subprocess.py:92} INFO - 22/06/07 06:48:07 INFO TaskSetManager: Starting task 107.0 in stage 0.0 (TID 107) (d952e2b2ede8, executor driver, partition 107, PROCESS_LOCAL, 4545 bytes) taskResourceAssignments Map()
[2022-06-07 06:48:07,607] {subprocess.py:92} INFO - 22/06/07 06:48:07 INFO TaskSetManager: Finished task 103.0 in stage 0.0 (TID 103) in 28 ms on d952e2b2ede8 (executor driver) (104/180)
[2022-06-07 06:48:07,608] {subprocess.py:92} INFO - 22/06/07 06:48:07 INFO Executor: Running task 107.0 in stage 0.0 (TID 107)
[2022-06-07 06:48:07,612] {subprocess.py:92} INFO - 22/06/07 06:48:07 INFO Executor: Finished task 102.0 in stage 0.0 (TID 102). 2367 bytes result sent to driver
[2022-06-07 06:48:07,614] {subprocess.py:92} INFO - 22/06/07 06:48:07 INFO TaskSetManager: Starting task 108.0 in stage 0.0 (TID 108) (d952e2b2ede8, executor driver, partition 108, PROCESS_LOCAL, 4545 bytes) taskResourceAssignments Map()
[2022-06-07 06:48:07,615] {subprocess.py:92} INFO - 22/06/07 06:48:07 INFO TaskSetManager: Finished task 102.0 in stage 0.0 (TID 102) in 40 ms on d952e2b2ede8 (executor driver) (105/180)
[2022-06-07 06:48:07,617] {subprocess.py:92} INFO - 22/06/07 06:48:07 INFO Executor: Running task 108.0 in stage 0.0 (TID 108)
[2022-06-07 06:48:07,620] {subprocess.py:92} INFO - 22/06/07 06:48:07 INFO Executor: Finished task 105.0 in stage 0.0 (TID 105). 2410 bytes result sent to driver
[2022-06-07 06:48:07,621] {subprocess.py:92} INFO - 22/06/07 06:48:07 INFO TaskSetManager: Starting task 109.0 in stage 0.0 (TID 109) (d952e2b2ede8, executor driver, partition 109, PROCESS_LOCAL, 4545 bytes) taskResourceAssignments Map()
[2022-06-07 06:48:07,621] {subprocess.py:92} INFO - 22/06/07 06:48:07 INFO Executor: Running task 109.0 in stage 0.0 (TID 109)
[2022-06-07 06:48:07,622] {subprocess.py:92} INFO - 22/06/07 06:48:07 INFO TaskSetManager: Finished task 105.0 in stage 0.0 (TID 105) in 27 ms on d952e2b2ede8 (executor driver) (106/180)
[2022-06-07 06:48:07,623] {subprocess.py:92} INFO - 22/06/07 06:48:07 INFO Executor: Finished task 107.0 in stage 0.0 (TID 107). 1886 bytes result sent to driver
[2022-06-07 06:48:07,624] {subprocess.py:92} INFO - 22/06/07 06:48:07 INFO TaskSetManager: Starting task 110.0 in stage 0.0 (TID 110) (d952e2b2ede8, executor driver, partition 110, PROCESS_LOCAL, 4545 bytes) taskResourceAssignments Map()
[2022-06-07 06:48:07,625] {subprocess.py:92} INFO - 22/06/07 06:48:07 INFO TaskSetManager: Finished task 107.0 in stage 0.0 (TID 107) in 21 ms on d952e2b2ede8 (executor driver) (107/180)
[2022-06-07 06:48:07,626] {subprocess.py:92} INFO - 22/06/07 06:48:07 INFO Executor: Running task 110.0 in stage 0.0 (TID 110)
[2022-06-07 06:48:07,630] {subprocess.py:92} INFO - 22/06/07 06:48:07 INFO Executor: Finished task 106.0 in stage 0.0 (TID 106). 2128 bytes result sent to driver
[2022-06-07 06:48:07,631] {subprocess.py:92} INFO - 22/06/07 06:48:07 INFO TaskSetManager: Starting task 111.0 in stage 0.0 (TID 111) (d952e2b2ede8, executor driver, partition 111, PROCESS_LOCAL, 4545 bytes) taskResourceAssignments Map()
[2022-06-07 06:48:07,632] {subprocess.py:92} INFO - 22/06/07 06:48:07 INFO TaskSetManager: Finished task 106.0 in stage 0.0 (TID 106) in 32 ms on d952e2b2ede8 (executor driver) (108/180)
[2022-06-07 06:48:07,634] {subprocess.py:92} INFO - 22/06/07 06:48:07 INFO Executor: Running task 111.0 in stage 0.0 (TID 111)
[2022-06-07 06:48:07,640] {subprocess.py:92} INFO - 22/06/07 06:48:07 INFO Executor: Finished task 109.0 in stage 0.0 (TID 109). 2128 bytes result sent to driver
[2022-06-07 06:48:07,641] {subprocess.py:92} INFO - 22/06/07 06:48:07 INFO TaskSetManager: Starting task 112.0 in stage 0.0 (TID 112) (d952e2b2ede8, executor driver, partition 112, PROCESS_LOCAL, 4545 bytes) taskResourceAssignments Map()
[2022-06-07 06:48:07,642] {subprocess.py:92} INFO - 22/06/07 06:48:07 INFO TaskSetManager: Finished task 109.0 in stage 0.0 (TID 109) in 21 ms on d952e2b2ede8 (executor driver) (109/180)
[2022-06-07 06:48:07,643] {subprocess.py:92} INFO - 22/06/07 06:48:07 INFO Executor: Running task 112.0 in stage 0.0 (TID 112)
[2022-06-07 06:48:07,644] {subprocess.py:92} INFO - 22/06/07 06:48:07 INFO Executor: Finished task 108.0 in stage 0.0 (TID 108). 1886 bytes result sent to driver
[2022-06-07 06:48:07,645] {subprocess.py:92} INFO - 22/06/07 06:48:07 INFO TaskSetManager: Starting task 113.0 in stage 0.0 (TID 113) (d952e2b2ede8, executor driver, partition 113, PROCESS_LOCAL, 4545 bytes) taskResourceAssignments Map()
[2022-06-07 06:48:07,646] {subprocess.py:92} INFO - 22/06/07 06:48:07 INFO TaskSetManager: Finished task 108.0 in stage 0.0 (TID 108) in 31 ms on d952e2b2ede8 (executor driver) (110/180)
[2022-06-07 06:48:07,647] {subprocess.py:92} INFO - 22/06/07 06:48:07 INFO Executor: Running task 113.0 in stage 0.0 (TID 113)
[2022-06-07 06:48:07,650] {subprocess.py:92} INFO - 22/06/07 06:48:07 INFO Executor: Finished task 111.0 in stage 0.0 (TID 111). 2606 bytes result sent to driver
[2022-06-07 06:48:07,651] {subprocess.py:92} INFO - 22/06/07 06:48:07 INFO TaskSetManager: Starting task 114.0 in stage 0.0 (TID 114) (d952e2b2ede8, executor driver, partition 114, PROCESS_LOCAL, 4545 bytes) taskResourceAssignments Map()
[2022-06-07 06:48:07,653] {subprocess.py:92} INFO - 22/06/07 06:48:07 INFO TaskSetManager: Finished task 111.0 in stage 0.0 (TID 111) in 22 ms on d952e2b2ede8 (executor driver) (111/180)
[2022-06-07 06:48:07,655] {subprocess.py:92} INFO - 22/06/07 06:48:07 INFO Executor: Finished task 110.0 in stage 0.0 (TID 110). 2128 bytes result sent to driver
[2022-06-07 06:48:07,656] {subprocess.py:92} INFO - 22/06/07 06:48:07 INFO Executor: Running task 114.0 in stage 0.0 (TID 114)
[2022-06-07 06:48:07,657] {subprocess.py:92} INFO - 22/06/07 06:48:07 INFO TaskSetManager: Starting task 115.0 in stage 0.0 (TID 115) (d952e2b2ede8, executor driver, partition 115, PROCESS_LOCAL, 4545 bytes) taskResourceAssignments Map()
[2022-06-07 06:48:07,658] {subprocess.py:92} INFO - 22/06/07 06:48:07 INFO TaskSetManager: Finished task 110.0 in stage 0.0 (TID 110) in 34 ms on d952e2b2ede8 (executor driver) (112/180)
[2022-06-07 06:48:07,660] {subprocess.py:92} INFO - 22/06/07 06:48:07 INFO Executor: Running task 115.0 in stage 0.0 (TID 115)
[2022-06-07 06:48:07,663] {subprocess.py:92} INFO - 22/06/07 06:48:07 INFO Executor: Finished task 113.0 in stage 0.0 (TID 113). 2649 bytes result sent to driver
[2022-06-07 06:48:07,665] {subprocess.py:92} INFO - 22/06/07 06:48:07 INFO TaskSetManager: Starting task 116.0 in stage 0.0 (TID 116) (d952e2b2ede8, executor driver, partition 116, PROCESS_LOCAL, 4545 bytes) taskResourceAssignments Map()
[2022-06-07 06:48:07,666] {subprocess.py:92} INFO - 22/06/07 06:48:07 INFO Executor: Running task 116.0 in stage 0.0 (TID 116)
[2022-06-07 06:48:07,667] {subprocess.py:92} INFO - 22/06/07 06:48:07 INFO TaskSetManager: Finished task 113.0 in stage 0.0 (TID 113) in 23 ms on d952e2b2ede8 (executor driver) (113/180)
[2022-06-07 06:48:07,668] {subprocess.py:92} INFO - 22/06/07 06:48:07 INFO Executor: Finished task 115.0 in stage 0.0 (TID 115). 2128 bytes result sent to driver
[2022-06-07 06:48:07,670] {subprocess.py:92} INFO - 22/06/07 06:48:07 INFO TaskSetManager: Starting task 117.0 in stage 0.0 (TID 117) (d952e2b2ede8, executor driver, partition 117, PROCESS_LOCAL, 4545 bytes) taskResourceAssignments Map()
[2022-06-07 06:48:07,671] {subprocess.py:92} INFO - 22/06/07 06:48:07 INFO TaskSetManager: Finished task 115.0 in stage 0.0 (TID 115) in 15 ms on d952e2b2ede8 (executor driver) (114/180)
[2022-06-07 06:48:07,672] {subprocess.py:92} INFO - 22/06/07 06:48:07 INFO Executor: Finished task 112.0 in stage 0.0 (TID 112). 2367 bytes result sent to driver
[2022-06-07 06:48:07,673] {subprocess.py:92} INFO - 22/06/07 06:48:07 INFO TaskSetManager: Starting task 118.0 in stage 0.0 (TID 118) (d952e2b2ede8, executor driver, partition 118, PROCESS_LOCAL, 4545 bytes) taskResourceAssignments Map()
[2022-06-07 06:48:07,675] {subprocess.py:92} INFO - 22/06/07 06:48:07 INFO TaskSetManager: Finished task 112.0 in stage 0.0 (TID 112) in 34 ms on d952e2b2ede8 (executor driver) (115/180)
[2022-06-07 06:48:07,676] {subprocess.py:92} INFO - 22/06/07 06:48:07 INFO Executor: Running task 117.0 in stage 0.0 (TID 117)
[2022-06-07 06:48:07,677] {subprocess.py:92} INFO - 22/06/07 06:48:07 INFO Executor: Running task 118.0 in stage 0.0 (TID 118)
[2022-06-07 06:48:07,681] {subprocess.py:92} INFO - 22/06/07 06:48:07 INFO Executor: Finished task 114.0 in stage 0.0 (TID 114). 2128 bytes result sent to driver
[2022-06-07 06:48:07,686] {subprocess.py:92} INFO - 22/06/07 06:48:07 INFO TaskSetManager: Starting task 119.0 in stage 0.0 (TID 119) (d952e2b2ede8, executor driver, partition 119, PROCESS_LOCAL, 4545 bytes) taskResourceAssignments Map()
[2022-06-07 06:48:07,687] {subprocess.py:92} INFO - 22/06/07 06:48:07 INFO TaskSetManager: Finished task 114.0 in stage 0.0 (TID 114) in 36 ms on d952e2b2ede8 (executor driver) (116/180)
[2022-06-07 06:48:07,688] {subprocess.py:92} INFO - 22/06/07 06:48:07 INFO Executor: Running task 119.0 in stage 0.0 (TID 119)
[2022-06-07 06:48:07,689] {subprocess.py:92} INFO - 22/06/07 06:48:07 INFO Executor: Finished task 116.0 in stage 0.0 (TID 116). 2367 bytes result sent to driver
[2022-06-07 06:48:07,689] {subprocess.py:92} INFO - 22/06/07 06:48:07 INFO Executor: Finished task 117.0 in stage 0.0 (TID 117). 2128 bytes result sent to driver
[2022-06-07 06:48:07,691] {subprocess.py:92} INFO - 22/06/07 06:48:07 INFO TaskSetManager: Starting task 120.0 in stage 0.0 (TID 120) (d952e2b2ede8, executor driver, partition 120, PROCESS_LOCAL, 4545 bytes) taskResourceAssignments Map()
[2022-06-07 06:48:07,691] {subprocess.py:92} INFO - 22/06/07 06:48:07 INFO TaskSetManager: Finished task 116.0 in stage 0.0 (TID 116) in 26 ms on d952e2b2ede8 (executor driver) (117/180)
[2022-06-07 06:48:07,692] {subprocess.py:92} INFO - 22/06/07 06:48:07 INFO Executor: Running task 120.0 in stage 0.0 (TID 120)
[2022-06-07 06:48:07,693] {subprocess.py:92} INFO - 22/06/07 06:48:07 INFO TaskSetManager: Starting task 121.0 in stage 0.0 (TID 121) (d952e2b2ede8, executor driver, partition 121, PROCESS_LOCAL, 4545 bytes) taskResourceAssignments Map()
[2022-06-07 06:48:07,696] {subprocess.py:92} INFO - 22/06/07 06:48:07 INFO Executor: Running task 121.0 in stage 0.0 (TID 121)
[2022-06-07 06:48:07,697] {subprocess.py:92} INFO - 22/06/07 06:48:07 INFO TaskSetManager: Finished task 117.0 in stage 0.0 (TID 117) in 25 ms on d952e2b2ede8 (executor driver) (118/180)
[2022-06-07 06:48:07,704] {subprocess.py:92} INFO - 22/06/07 06:48:07 INFO Executor: Finished task 120.0 in stage 0.0 (TID 120). 2367 bytes result sent to driver
[2022-06-07 06:48:07,706] {subprocess.py:92} INFO - 22/06/07 06:48:07 INFO TaskSetManager: Starting task 122.0 in stage 0.0 (TID 122) (d952e2b2ede8, executor driver, partition 122, PROCESS_LOCAL, 4545 bytes) taskResourceAssignments Map()
[2022-06-07 06:48:07,709] {subprocess.py:92} INFO - 22/06/07 06:48:07 INFO Executor: Finished task 118.0 in stage 0.0 (TID 118). 2128 bytes result sent to driver
[2022-06-07 06:48:07,709] {subprocess.py:92} INFO - 22/06/07 06:48:07 INFO TaskSetManager: Finished task 120.0 in stage 0.0 (TID 120) in 18 ms on d952e2b2ede8 (executor driver) (119/180)
[2022-06-07 06:48:07,710] {subprocess.py:92} INFO - 22/06/07 06:48:07 INFO Executor: Finished task 121.0 in stage 0.0 (TID 121). 2367 bytes result sent to driver
[2022-06-07 06:48:07,711] {subprocess.py:92} INFO - 22/06/07 06:48:07 INFO Executor: Running task 122.0 in stage 0.0 (TID 122)
[2022-06-07 06:48:07,712] {subprocess.py:92} INFO - 22/06/07 06:48:07 INFO TaskSetManager: Starting task 123.0 in stage 0.0 (TID 123) (d952e2b2ede8, executor driver, partition 123, PROCESS_LOCAL, 4545 bytes) taskResourceAssignments Map()
[2022-06-07 06:48:07,714] {subprocess.py:92} INFO - 22/06/07 06:48:07 INFO TaskSetManager: Starting task 124.0 in stage 0.0 (TID 124) (d952e2b2ede8, executor driver, partition 124, PROCESS_LOCAL, 4545 bytes) taskResourceAssignments Map()
[2022-06-07 06:48:07,715] {subprocess.py:92} INFO - 22/06/07 06:48:07 INFO TaskSetManager: Finished task 121.0 in stage 0.0 (TID 121) in 22 ms on d952e2b2ede8 (executor driver) (120/180)
[2022-06-07 06:48:07,715] {subprocess.py:92} INFO - 22/06/07 06:48:07 INFO TaskSetManager: Finished task 118.0 in stage 0.0 (TID 118) in 42 ms on d952e2b2ede8 (executor driver) (121/180)
[2022-06-07 06:48:07,716] {subprocess.py:92} INFO - 22/06/07 06:48:07 INFO Executor: Running task 123.0 in stage 0.0 (TID 123)
[2022-06-07 06:48:07,717] {subprocess.py:92} INFO - 22/06/07 06:48:07 INFO Executor: Running task 124.0 in stage 0.0 (TID 124)
[2022-06-07 06:48:07,718] {subprocess.py:92} INFO - 22/06/07 06:48:07 INFO Executor: Finished task 119.0 in stage 0.0 (TID 119). 2410 bytes result sent to driver
[2022-06-07 06:48:07,720] {subprocess.py:92} INFO - 22/06/07 06:48:07 INFO TaskSetManager: Starting task 125.0 in stage 0.0 (TID 125) (d952e2b2ede8, executor driver, partition 125, PROCESS_LOCAL, 4545 bytes) taskResourceAssignments Map()
[2022-06-07 06:48:07,721] {subprocess.py:92} INFO - 22/06/07 06:48:07 INFO TaskSetManager: Finished task 119.0 in stage 0.0 (TID 119) in 35 ms on d952e2b2ede8 (executor driver) (122/180)
[2022-06-07 06:48:07,722] {subprocess.py:92} INFO - 22/06/07 06:48:07 INFO Executor: Running task 125.0 in stage 0.0 (TID 125)
[2022-06-07 06:48:07,727] {subprocess.py:92} INFO - 22/06/07 06:48:07 INFO Executor: Finished task 123.0 in stage 0.0 (TID 123). 2128 bytes result sent to driver
[2022-06-07 06:48:07,729] {subprocess.py:92} INFO - 22/06/07 06:48:07 INFO TaskSetManager: Starting task 126.0 in stage 0.0 (TID 126) (d952e2b2ede8, executor driver, partition 126, PROCESS_LOCAL, 4545 bytes) taskResourceAssignments Map()
[2022-06-07 06:48:07,730] {subprocess.py:92} INFO - 22/06/07 06:48:07 INFO Executor: Running task 126.0 in stage 0.0 (TID 126)
[2022-06-07 06:48:07,731] {subprocess.py:92} INFO - 22/06/07 06:48:07 INFO TaskSetManager: Finished task 123.0 in stage 0.0 (TID 123) in 18 ms on d952e2b2ede8 (executor driver) (123/180)
[2022-06-07 06:48:07,732] {subprocess.py:92} INFO - 22/06/07 06:48:07 INFO Executor: Finished task 124.0 in stage 0.0 (TID 124). 2367 bytes result sent to driver
[2022-06-07 06:48:07,734] {subprocess.py:92} INFO - 22/06/07 06:48:07 INFO TaskSetManager: Starting task 127.0 in stage 0.0 (TID 127) (d952e2b2ede8, executor driver, partition 127, PROCESS_LOCAL, 4545 bytes) taskResourceAssignments Map()
[2022-06-07 06:48:07,735] {subprocess.py:92} INFO - 22/06/07 06:48:07 INFO Executor: Running task 127.0 in stage 0.0 (TID 127)
[2022-06-07 06:48:07,736] {subprocess.py:92} INFO - 22/06/07 06:48:07 INFO TaskSetManager: Finished task 124.0 in stage 0.0 (TID 124) in 21 ms on d952e2b2ede8 (executor driver) (124/180)
[2022-06-07 06:48:07,738] {subprocess.py:92} INFO - 22/06/07 06:48:07 INFO Executor: Finished task 122.0 in stage 0.0 (TID 122). 2410 bytes result sent to driver
