[2022-06-07 06:16:03,427] {taskinstance.py:1159} INFO - Dependencies all met for <TaskInstance: hands_on_test.spark_create_order_detail_new scheduled__2022-06-06T00:00:00+00:00 [queued]>
[2022-06-07 06:16:03,442] {taskinstance.py:1159} INFO - Dependencies all met for <TaskInstance: hands_on_test.spark_create_order_detail_new scheduled__2022-06-06T00:00:00+00:00 [queued]>
[2022-06-07 06:16:03,443] {taskinstance.py:1356} INFO - 
--------------------------------------------------------------------------------
[2022-06-07 06:16:03,444] {taskinstance.py:1357} INFO - Starting attempt 1 of 2
[2022-06-07 06:16:03,445] {taskinstance.py:1358} INFO - 
--------------------------------------------------------------------------------
[2022-06-07 06:16:03,464] {taskinstance.py:1377} INFO - Executing <Task(BashOperator): spark_create_order_detail_new> on 2022-06-06 00:00:00+00:00
[2022-06-07 06:16:03,470] {standard_task_runner.py:52} INFO - Started process 6379 to run task
[2022-06-07 06:16:03,476] {standard_task_runner.py:79} INFO - Running: ['***', 'tasks', 'run', 'hands_on_test', 'spark_create_order_detail_new', 'scheduled__2022-06-06T00:00:00+00:00', '--job-id', '43', '--raw', '--subdir', 'DAGS_FOLDER/dag.py', '--cfg-path', '/tmp/tmps5ooku2e', '--error-file', '/tmp/tmpffz2cpr6']
[2022-06-07 06:16:03,478] {standard_task_runner.py:80} INFO - Job 43: Subtask spark_create_order_detail_new
[2022-06-07 06:16:03,555] {task_command.py:369} INFO - Running <TaskInstance: hands_on_test.spark_create_order_detail_new scheduled__2022-06-06T00:00:00+00:00 [running]> on host a4a1e1d603db
[2022-06-07 06:16:03,666] {taskinstance.py:1571} INFO - Exporting the following env vars:
AIRFLOW_CTX_DAG_OWNER=pathairs
AIRFLOW_CTX_DAG_ID=hands_on_test
AIRFLOW_CTX_TASK_ID=spark_create_order_detail_new
AIRFLOW_CTX_EXECUTION_DATE=2022-06-06T00:00:00+00:00
AIRFLOW_CTX_TRY_NUMBER=1
AIRFLOW_CTX_DAG_RUN_ID=scheduled__2022-06-06T00:00:00+00:00
[2022-06-07 06:16:03,668] {subprocess.py:62} INFO - Tmp dir root location: 
 /tmp
[2022-06-07 06:16:03,669] {subprocess.py:74} INFO - Running command: ['bash', '-c', 'docker exec spark-master /spark/bin/spark-submit --master local[*] --name spark_create_order_detail_new /home/script/create_order_detail_new.py ']
[2022-06-07 06:16:03,683] {subprocess.py:85} INFO - Output:
[2022-06-07 06:16:06,165] {subprocess.py:92} INFO - 22/06/07 06:16:06 WARN NativeCodeLoader: Unable to load native-hadoop library for your platform... using builtin-java classes where applicable
[2022-06-07 06:16:06,983] {subprocess.py:92} INFO - Using Spark's default log4j profile: org/apache/spark/log4j-defaults.properties
[2022-06-07 06:16:06,996] {subprocess.py:92} INFO - 22/06/07 06:16:06 INFO SparkContext: Running Spark version 3.1.1
[2022-06-07 06:16:07,048] {subprocess.py:92} INFO - 22/06/07 06:16:07 INFO ResourceUtils: ==============================================================
[2022-06-07 06:16:07,049] {subprocess.py:92} INFO - 22/06/07 06:16:07 INFO ResourceUtils: No custom resources configured for spark.driver.
[2022-06-07 06:16:07,050] {subprocess.py:92} INFO - 22/06/07 06:16:07 INFO ResourceUtils: ==============================================================
[2022-06-07 06:16:07,051] {subprocess.py:92} INFO - 22/06/07 06:16:07 INFO SparkContext: Submitted application: spark_create_order_detail_new
[2022-06-07 06:16:07,081] {subprocess.py:92} INFO - 22/06/07 06:16:07 INFO ResourceProfile: Default ResourceProfile created, executor resources: Map(cores -> name: cores, amount: 1, script: , vendor: , memory -> name: memory, amount: 1024, script: , vendor: , offHeap -> name: offHeap, amount: 0, script: , vendor: ), task resources: Map(cpus -> name: cpus, amount: 1.0)
[2022-06-07 06:16:07,110] {subprocess.py:92} INFO - 22/06/07 06:16:07 INFO ResourceProfile: Limiting resource is cpu
[2022-06-07 06:16:07,111] {subprocess.py:92} INFO - 22/06/07 06:16:07 INFO ResourceProfileManager: Added ResourceProfile id: 0
[2022-06-07 06:16:07,178] {subprocess.py:92} INFO - 22/06/07 06:16:07 INFO SecurityManager: Changing view acls to: root
[2022-06-07 06:16:07,179] {subprocess.py:92} INFO - 22/06/07 06:16:07 INFO SecurityManager: Changing modify acls to: root
[2022-06-07 06:16:07,181] {subprocess.py:92} INFO - 22/06/07 06:16:07 INFO SecurityManager: Changing view acls groups to:
[2022-06-07 06:16:07,182] {subprocess.py:92} INFO - 22/06/07 06:16:07 INFO SecurityManager: Changing modify acls groups to:
[2022-06-07 06:16:07,183] {subprocess.py:92} INFO - 22/06/07 06:16:07 INFO SecurityManager: SecurityManager: authentication disabled; ui acls disabled; users  with view permissions: Set(root); groups with view permissions: Set(); users  with modify permissions: Set(root); groups with modify permissions: Set()
[2022-06-07 06:16:07,452] {subprocess.py:92} INFO - 22/06/07 06:16:07 INFO Utils: Successfully started service 'sparkDriver' on port 43389.
[2022-06-07 06:16:07,505] {subprocess.py:92} INFO - 22/06/07 06:16:07 INFO SparkEnv: Registering MapOutputTracker
[2022-06-07 06:16:07,574] {subprocess.py:92} INFO - 22/06/07 06:16:07 INFO SparkEnv: Registering BlockManagerMaster
[2022-06-07 06:16:07,603] {subprocess.py:92} INFO - 22/06/07 06:16:07 INFO BlockManagerMasterEndpoint: Using org.apache.spark.storage.DefaultTopologyMapper for getting topology information
[2022-06-07 06:16:07,604] {subprocess.py:92} INFO - 22/06/07 06:16:07 INFO BlockManagerMasterEndpoint: BlockManagerMasterEndpoint up
[2022-06-07 06:16:07,613] {subprocess.py:92} INFO - 22/06/07 06:16:07 INFO SparkEnv: Registering BlockManagerMasterHeartbeat
[2022-06-07 06:16:07,636] {subprocess.py:92} INFO - 22/06/07 06:16:07 INFO DiskBlockManager: Created local directory at /tmp/blockmgr-f9ce2739-eab5-42c2-a2ef-faf7e69cfbc7
[2022-06-07 06:16:07,674] {subprocess.py:92} INFO - 22/06/07 06:16:07 INFO MemoryStore: MemoryStore started with capacity 366.3 MiB
[2022-06-07 06:16:07,700] {subprocess.py:92} INFO - 22/06/07 06:16:07 INFO SparkEnv: Registering OutputCommitCoordinator
[2022-06-07 06:16:08,076] {subprocess.py:92} INFO - 22/06/07 06:16:08 INFO Utils: Successfully started service 'SparkUI' on port 4040.
[2022-06-07 06:16:08,159] {subprocess.py:92} INFO - 22/06/07 06:16:08 INFO SparkUI: Bound SparkUI to 0.0.0.0, and started at http://d952e2b2ede8:4040
[2022-06-07 06:16:08,430] {subprocess.py:92} INFO - 22/06/07 06:16:08 INFO Executor: Starting executor ID driver on host d952e2b2ede8
[2022-06-07 06:16:08,476] {subprocess.py:92} INFO - 22/06/07 06:16:08 INFO Utils: Successfully started service 'org.apache.spark.network.netty.NettyBlockTransferService' on port 32975.
[2022-06-07 06:16:08,477] {subprocess.py:92} INFO - 22/06/07 06:16:08 INFO NettyBlockTransferService: Server created on d952e2b2ede8:32975
[2022-06-07 06:16:08,479] {subprocess.py:92} INFO - 22/06/07 06:16:08 INFO BlockManager: Using org.apache.spark.storage.RandomBlockReplicationPolicy for block replication policy
[2022-06-07 06:16:08,488] {subprocess.py:92} INFO - 22/06/07 06:16:08 INFO BlockManagerMaster: Registering BlockManager BlockManagerId(driver, d952e2b2ede8, 32975, None)
[2022-06-07 06:16:08,493] {subprocess.py:92} INFO - 22/06/07 06:16:08 INFO BlockManagerMasterEndpoint: Registering block manager d952e2b2ede8:32975 with 366.3 MiB RAM, BlockManagerId(driver, d952e2b2ede8, 32975, None)
[2022-06-07 06:16:08,496] {subprocess.py:92} INFO - 22/06/07 06:16:08 INFO BlockManagerMaster: Registered BlockManager BlockManagerId(driver, d952e2b2ede8, 32975, None)
[2022-06-07 06:16:08,498] {subprocess.py:92} INFO - 22/06/07 06:16:08 INFO BlockManager: Initialized BlockManager: BlockManagerId(driver, d952e2b2ede8, 32975, None)
[2022-06-07 06:16:09,044] {subprocess.py:92} INFO - 22/06/07 06:16:09 INFO SharedState: Setting hive.metastore.warehouse.dir ('null') to the value of spark.sql.warehouse.dir ('file:/spark-warehouse').
[2022-06-07 06:16:09,045] {subprocess.py:92} INFO - 22/06/07 06:16:09 INFO SharedState: Warehouse path is 'file:/spark-warehouse'.
[2022-06-07 06:16:10,723] {subprocess.py:92} INFO - 22/06/07 06:16:10 INFO HadoopFSUtils: Listing leaf files and directories in parallel under 180 paths. The first several paths are: hdfs://hive-namenode:8020/user/spark/transformed_order_detail/dt=20190101, hdfs://hive-namenode:8020/user/spark/transformed_order_detail/dt=20190102, hdfs://hive-namenode:8020/user/spark/transformed_order_detail/dt=20190103, hdfs://hive-namenode:8020/user/spark/transformed_order_detail/dt=20190104, hdfs://hive-namenode:8020/user/spark/transformed_order_detail/dt=20190105, hdfs://hive-namenode:8020/user/spark/transformed_order_detail/dt=20190106, hdfs://hive-namenode:8020/user/spark/transformed_order_detail/dt=20190107, hdfs://hive-namenode:8020/user/spark/transformed_order_detail/dt=20190108, hdfs://hive-namenode:8020/user/spark/transformed_order_detail/dt=20190109, hdfs://hive-namenode:8020/user/spark/transformed_order_detail/dt=20190110.
[2022-06-07 06:16:11,372] {subprocess.py:92} INFO - 22/06/07 06:16:11 INFO SparkContext: Starting job: parquet at NativeMethodAccessorImpl.java:0
[2022-06-07 06:16:11,396] {subprocess.py:92} INFO - 22/06/07 06:16:11 INFO DAGScheduler: Got job 0 (parquet at NativeMethodAccessorImpl.java:0) with 180 output partitions
[2022-06-07 06:16:11,397] {subprocess.py:92} INFO - 22/06/07 06:16:11 INFO DAGScheduler: Final stage: ResultStage 0 (parquet at NativeMethodAccessorImpl.java:0)
[2022-06-07 06:16:11,399] {subprocess.py:92} INFO - 22/06/07 06:16:11 INFO DAGScheduler: Parents of final stage: List()
[2022-06-07 06:16:11,401] {subprocess.py:92} INFO - 22/06/07 06:16:11 INFO DAGScheduler: Missing parents: List()
[2022-06-07 06:16:11,409] {subprocess.py:92} INFO - 22/06/07 06:16:11 INFO DAGScheduler: Submitting ResultStage 0 (MapPartitionsRDD[2] at parquet at NativeMethodAccessorImpl.java:0), which has no missing parents
[2022-06-07 06:16:11,525] {subprocess.py:92} INFO - 22/06/07 06:16:11 INFO MemoryStore: Block broadcast_0 stored as values in memory (estimated size 83.6 KiB, free 366.2 MiB)
[2022-06-07 06:16:11,567] {subprocess.py:92} INFO - 22/06/07 06:16:11 INFO MemoryStore: Block broadcast_0_piece0 stored as bytes in memory (estimated size 29.5 KiB, free 366.2 MiB)
[2022-06-07 06:16:11,572] {subprocess.py:92} INFO - 22/06/07 06:16:11 INFO BlockManagerInfo: Added broadcast_0_piece0 in memory on d952e2b2ede8:32975 (size: 29.5 KiB, free: 366.3 MiB)
[2022-06-07 06:16:11,575] {subprocess.py:92} INFO - 22/06/07 06:16:11 INFO SparkContext: Created broadcast 0 from broadcast at DAGScheduler.scala:1383
[2022-06-07 06:16:11,598] {subprocess.py:92} INFO - 22/06/07 06:16:11 INFO DAGScheduler: Submitting 180 missing tasks from ResultStage 0 (MapPartitionsRDD[2] at parquet at NativeMethodAccessorImpl.java:0) (first 15 tasks are for partitions Vector(0, 1, 2, 3, 4, 5, 6, 7, 8, 9, 10, 11, 12, 13, 14))
[2022-06-07 06:16:11,600] {subprocess.py:92} INFO - 22/06/07 06:16:11 INFO TaskSchedulerImpl: Adding task set 0.0 with 180 tasks resource profile 0
[2022-06-07 06:16:11,701] {subprocess.py:92} INFO - 22/06/07 06:16:11 INFO TaskSetManager: Starting task 0.0 in stage 0.0 (TID 0) (d952e2b2ede8, executor driver, partition 0, PROCESS_LOCAL, 4553 bytes) taskResourceAssignments Map()
[2022-06-07 06:16:11,707] {subprocess.py:92} INFO - 22/06/07 06:16:11 INFO TaskSetManager: Starting task 1.0 in stage 0.0 (TID 1) (d952e2b2ede8, executor driver, partition 1, PROCESS_LOCAL, 4553 bytes) taskResourceAssignments Map()
[2022-06-07 06:16:11,708] {subprocess.py:92} INFO - 22/06/07 06:16:11 INFO TaskSetManager: Starting task 2.0 in stage 0.0 (TID 2) (d952e2b2ede8, executor driver, partition 2, PROCESS_LOCAL, 4553 bytes) taskResourceAssignments Map()
[2022-06-07 06:16:11,711] {subprocess.py:92} INFO - 22/06/07 06:16:11 INFO TaskSetManager: Starting task 3.0 in stage 0.0 (TID 3) (d952e2b2ede8, executor driver, partition 3, PROCESS_LOCAL, 4553 bytes) taskResourceAssignments Map()
[2022-06-07 06:16:11,738] {subprocess.py:92} INFO - 22/06/07 06:16:11 INFO Executor: Running task 2.0 in stage 0.0 (TID 2)
[2022-06-07 06:16:11,739] {subprocess.py:92} INFO - 22/06/07 06:16:11 INFO Executor: Running task 0.0 in stage 0.0 (TID 0)
[2022-06-07 06:16:11,741] {subprocess.py:92} INFO - 22/06/07 06:16:11 INFO Executor: Running task 3.0 in stage 0.0 (TID 3)
[2022-06-07 06:16:11,741] {subprocess.py:92} INFO - 22/06/07 06:16:11 INFO Executor: Running task 1.0 in stage 0.0 (TID 1)
[2022-06-07 06:16:12,387] {subprocess.py:92} INFO - 22/06/07 06:16:12 INFO Executor: Finished task 3.0 in stage 0.0 (TID 3). 2732 bytes result sent to driver
[2022-06-07 06:16:12,389] {subprocess.py:92} INFO - 22/06/07 06:16:12 INFO Executor: Finished task 2.0 in stage 0.0 (TID 2). 2732 bytes result sent to driver
[2022-06-07 06:16:12,389] {subprocess.py:92} INFO - 22/06/07 06:16:12 INFO Executor: Finished task 0.0 in stage 0.0 (TID 0). 2732 bytes result sent to driver
[2022-06-07 06:16:12,390] {subprocess.py:92} INFO - 22/06/07 06:16:12 INFO Executor: Finished task 1.0 in stage 0.0 (TID 1). 2732 bytes result sent to driver
[2022-06-07 06:16:12,395] {subprocess.py:92} INFO - 22/06/07 06:16:12 INFO TaskSetManager: Starting task 4.0 in stage 0.0 (TID 4) (d952e2b2ede8, executor driver, partition 4, PROCESS_LOCAL, 4553 bytes) taskResourceAssignments Map()
[2022-06-07 06:16:12,397] {subprocess.py:92} INFO - 22/06/07 06:16:12 INFO Executor: Running task 4.0 in stage 0.0 (TID 4)
[2022-06-07 06:16:12,406] {subprocess.py:92} INFO - 22/06/07 06:16:12 INFO TaskSetManager: Starting task 5.0 in stage 0.0 (TID 5) (d952e2b2ede8, executor driver, partition 5, PROCESS_LOCAL, 4553 bytes) taskResourceAssignments Map()
[2022-06-07 06:16:12,408] {subprocess.py:92} INFO - 22/06/07 06:16:12 INFO Executor: Running task 5.0 in stage 0.0 (TID 5)
[2022-06-07 06:16:12,415] {subprocess.py:92} INFO - 22/06/07 06:16:12 INFO Executor: Finished task 4.0 in stage 0.0 (TID 4). 2646 bytes result sent to driver
[2022-06-07 06:16:12,430] {subprocess.py:92} INFO - 22/06/07 06:16:12 INFO TaskSetManager: Starting task 6.0 in stage 0.0 (TID 6) (d952e2b2ede8, executor driver, partition 6, PROCESS_LOCAL, 4553 bytes) taskResourceAssignments Map()
[2022-06-07 06:16:12,434] {subprocess.py:92} INFO - 22/06/07 06:16:12 INFO Executor: Running task 6.0 in stage 0.0 (TID 6)
[2022-06-07 06:16:12,438] {subprocess.py:92} INFO - 22/06/07 06:16:12 INFO Executor: Finished task 5.0 in stage 0.0 (TID 5). 2646 bytes result sent to driver
[2022-06-07 06:16:12,441] {subprocess.py:92} INFO - 22/06/07 06:16:12 INFO TaskSetManager: Starting task 7.0 in stage 0.0 (TID 7) (d952e2b2ede8, executor driver, partition 7, PROCESS_LOCAL, 4553 bytes) taskResourceAssignments Map()
[2022-06-07 06:16:12,443] {subprocess.py:92} INFO - 22/06/07 06:16:12 INFO TaskSetManager: Starting task 8.0 in stage 0.0 (TID 8) (d952e2b2ede8, executor driver, partition 8, PROCESS_LOCAL, 4553 bytes) taskResourceAssignments Map()
[2022-06-07 06:16:12,444] {subprocess.py:92} INFO - 22/06/07 06:16:12 INFO Executor: Running task 8.0 in stage 0.0 (TID 8)
[2022-06-07 06:16:12,446] {subprocess.py:92} INFO - 22/06/07 06:16:12 INFO TaskSetManager: Finished task 2.0 in stage 0.0 (TID 2) in 736 ms on d952e2b2ede8 (executor driver) (1/180)
[2022-06-07 06:16:12,449] {subprocess.py:92} INFO - 22/06/07 06:16:12 INFO TaskSetManager: Finished task 4.0 in stage 0.0 (TID 4) in 56 ms on d952e2b2ede8 (executor driver) (2/180)
[2022-06-07 06:16:12,450] {subprocess.py:92} INFO - 22/06/07 06:16:12 INFO TaskSetManager: Finished task 0.0 in stage 0.0 (TID 0) in 789 ms on d952e2b2ede8 (executor driver) (3/180)
[2022-06-07 06:16:12,451] {subprocess.py:92} INFO - 22/06/07 06:16:12 INFO TaskSetManager: Finished task 3.0 in stage 0.0 (TID 3) in 741 ms on d952e2b2ede8 (executor driver) (4/180)
[2022-06-07 06:16:12,452] {subprocess.py:92} INFO - 22/06/07 06:16:12 INFO TaskSetManager: Finished task 1.0 in stage 0.0 (TID 1) in 746 ms on d952e2b2ede8 (executor driver) (5/180)
[2022-06-07 06:16:12,455] {subprocess.py:92} INFO - 22/06/07 06:16:12 INFO TaskSetManager: Starting task 9.0 in stage 0.0 (TID 9) (d952e2b2ede8, executor driver, partition 9, PROCESS_LOCAL, 4553 bytes) taskResourceAssignments Map()
[2022-06-07 06:16:12,456] {subprocess.py:92} INFO - 22/06/07 06:16:12 INFO Executor: Running task 9.0 in stage 0.0 (TID 9)
[2022-06-07 06:16:12,457] {subprocess.py:92} INFO - 22/06/07 06:16:12 INFO TaskSetManager: Finished task 5.0 in stage 0.0 (TID 5) in 51 ms on d952e2b2ede8 (executor driver) (6/180)
[2022-06-07 06:16:12,463] {subprocess.py:92} INFO - 22/06/07 06:16:12 INFO Executor: Running task 7.0 in stage 0.0 (TID 7)
[2022-06-07 06:16:12,486] {subprocess.py:92} INFO - 22/06/07 06:16:12 INFO Executor: Finished task 6.0 in stage 0.0 (TID 6). 2646 bytes result sent to driver
[2022-06-07 06:16:12,490] {subprocess.py:92} INFO - 22/06/07 06:16:12 INFO Executor: Finished task 8.0 in stage 0.0 (TID 8). 2646 bytes result sent to driver
[2022-06-07 06:16:12,492] {subprocess.py:92} INFO - 22/06/07 06:16:12 INFO Executor: Finished task 7.0 in stage 0.0 (TID 7). 2646 bytes result sent to driver
[2022-06-07 06:16:12,493] {subprocess.py:92} INFO - 22/06/07 06:16:12 INFO Executor: Finished task 9.0 in stage 0.0 (TID 9). 2646 bytes result sent to driver
[2022-06-07 06:16:12,494] {subprocess.py:92} INFO - 22/06/07 06:16:12 INFO TaskSetManager: Starting task 10.0 in stage 0.0 (TID 10) (d952e2b2ede8, executor driver, partition 10, PROCESS_LOCAL, 4553 bytes) taskResourceAssignments Map()
[2022-06-07 06:16:12,495] {subprocess.py:92} INFO - 22/06/07 06:16:12 INFO TaskSetManager: Finished task 6.0 in stage 0.0 (TID 6) in 65 ms on d952e2b2ede8 (executor driver) (7/180)
[2022-06-07 06:16:12,496] {subprocess.py:92} INFO - 22/06/07 06:16:12 INFO Executor: Running task 10.0 in stage 0.0 (TID 10)
[2022-06-07 06:16:12,497] {subprocess.py:92} INFO - 22/06/07 06:16:12 INFO TaskSetManager: Starting task 11.0 in stage 0.0 (TID 11) (d952e2b2ede8, executor driver, partition 11, PROCESS_LOCAL, 4553 bytes) taskResourceAssignments Map()
[2022-06-07 06:16:12,499] {subprocess.py:92} INFO - 22/06/07 06:16:12 INFO Executor: Running task 11.0 in stage 0.0 (TID 11)
[2022-06-07 06:16:12,500] {subprocess.py:92} INFO - 22/06/07 06:16:12 INFO TaskSetManager: Finished task 8.0 in stage 0.0 (TID 8) in 56 ms on d952e2b2ede8 (executor driver) (8/180)
[2022-06-07 06:16:12,502] {subprocess.py:92} INFO - 22/06/07 06:16:12 INFO TaskSetManager: Finished task 7.0 in stage 0.0 (TID 7) in 61 ms on d952e2b2ede8 (executor driver) (9/180)
[2022-06-07 06:16:12,503] {subprocess.py:92} INFO - 22/06/07 06:16:12 INFO TaskSetManager: Starting task 12.0 in stage 0.0 (TID 12) (d952e2b2ede8, executor driver, partition 12, PROCESS_LOCAL, 4553 bytes) taskResourceAssignments Map()
[2022-06-07 06:16:12,505] {subprocess.py:92} INFO - 22/06/07 06:16:12 INFO Executor: Running task 12.0 in stage 0.0 (TID 12)
[2022-06-07 06:16:12,507] {subprocess.py:92} INFO - 22/06/07 06:16:12 INFO TaskSetManager: Finished task 9.0 in stage 0.0 (TID 9) in 53 ms on d952e2b2ede8 (executor driver) (10/180)
[2022-06-07 06:16:12,509] {subprocess.py:92} INFO - 22/06/07 06:16:12 INFO TaskSetManager: Starting task 13.0 in stage 0.0 (TID 13) (d952e2b2ede8, executor driver, partition 13, PROCESS_LOCAL, 4553 bytes) taskResourceAssignments Map()
[2022-06-07 06:16:12,511] {subprocess.py:92} INFO - 22/06/07 06:16:12 INFO Executor: Running task 13.0 in stage 0.0 (TID 13)
[2022-06-07 06:16:12,533] {subprocess.py:92} INFO - 22/06/07 06:16:12 INFO Executor: Finished task 10.0 in stage 0.0 (TID 10). 2646 bytes result sent to driver
[2022-06-07 06:16:12,535] {subprocess.py:92} INFO - 22/06/07 06:16:12 INFO TaskSetManager: Starting task 14.0 in stage 0.0 (TID 14) (d952e2b2ede8, executor driver, partition 14, PROCESS_LOCAL, 4553 bytes) taskResourceAssignments Map()
[2022-06-07 06:16:12,537] {subprocess.py:92} INFO - 22/06/07 06:16:12 INFO TaskSetManager: Finished task 10.0 in stage 0.0 (TID 10) in 49 ms on d952e2b2ede8 (executor driver) (11/180)
[2022-06-07 06:16:12,537] {subprocess.py:92} INFO - 22/06/07 06:16:12 INFO Executor: Finished task 11.0 in stage 0.0 (TID 11). 2646 bytes result sent to driver
[2022-06-07 06:16:12,538] {subprocess.py:92} INFO - 22/06/07 06:16:12 INFO Executor: Running task 14.0 in stage 0.0 (TID 14)
[2022-06-07 06:16:12,540] {subprocess.py:92} INFO - 22/06/07 06:16:12 INFO Executor: Finished task 12.0 in stage 0.0 (TID 12). 2689 bytes result sent to driver
[2022-06-07 06:16:12,541] {subprocess.py:92} INFO - 22/06/07 06:16:12 INFO TaskSetManager: Starting task 15.0 in stage 0.0 (TID 15) (d952e2b2ede8, executor driver, partition 15, PROCESS_LOCAL, 4553 bytes) taskResourceAssignments Map()
[2022-06-07 06:16:12,547] {subprocess.py:92} INFO - 22/06/07 06:16:12 INFO Executor: Running task 15.0 in stage 0.0 (TID 15)
[2022-06-07 06:16:12,548] {subprocess.py:92} INFO - 22/06/07 06:16:12 INFO TaskSetManager: Starting task 16.0 in stage 0.0 (TID 16) (d952e2b2ede8, executor driver, partition 16, PROCESS_LOCAL, 4553 bytes) taskResourceAssignments Map()
[2022-06-07 06:16:12,549] {subprocess.py:92} INFO - 22/06/07 06:16:12 INFO TaskSetManager: Finished task 11.0 in stage 0.0 (TID 11) in 46 ms on d952e2b2ede8 (executor driver) (12/180)
[2022-06-07 06:16:12,549] {subprocess.py:92} INFO - 22/06/07 06:16:12 INFO Executor: Running task 16.0 in stage 0.0 (TID 16)
[2022-06-07 06:16:12,550] {subprocess.py:92} INFO - 22/06/07 06:16:12 INFO TaskSetManager: Finished task 12.0 in stage 0.0 (TID 12) in 41 ms on d952e2b2ede8 (executor driver) (13/180)
[2022-06-07 06:16:12,560] {subprocess.py:92} INFO - 22/06/07 06:16:12 INFO Executor: Finished task 13.0 in stage 0.0 (TID 13). 2689 bytes result sent to driver
[2022-06-07 06:16:12,561] {subprocess.py:92} INFO - 22/06/07 06:16:12 INFO TaskSetManager: Starting task 17.0 in stage 0.0 (TID 17) (d952e2b2ede8, executor driver, partition 17, PROCESS_LOCAL, 4553 bytes) taskResourceAssignments Map()
[2022-06-07 06:16:12,572] {subprocess.py:92} INFO - 22/06/07 06:16:12 INFO Executor: Running task 17.0 in stage 0.0 (TID 17)
[2022-06-07 06:16:12,579] {subprocess.py:92} INFO - 22/06/07 06:16:12 INFO TaskSetManager: Finished task 13.0 in stage 0.0 (TID 13) in 70 ms on d952e2b2ede8 (executor driver) (14/180)
[2022-06-07 06:16:12,581] {subprocess.py:92} INFO - 22/06/07 06:16:12 INFO Executor: Finished task 14.0 in stage 0.0 (TID 14). 2646 bytes result sent to driver
[2022-06-07 06:16:12,584] {subprocess.py:92} INFO - 22/06/07 06:16:12 INFO TaskSetManager: Starting task 18.0 in stage 0.0 (TID 18) (d952e2b2ede8, executor driver, partition 18, PROCESS_LOCAL, 4553 bytes) taskResourceAssignments Map()
[2022-06-07 06:16:12,585] {subprocess.py:92} INFO - 22/06/07 06:16:12 INFO Executor: Running task 18.0 in stage 0.0 (TID 18)
[2022-06-07 06:16:12,587] {subprocess.py:92} INFO - 22/06/07 06:16:12 INFO TaskSetManager: Finished task 14.0 in stage 0.0 (TID 14) in 52 ms on d952e2b2ede8 (executor driver) (15/180)
[2022-06-07 06:16:12,600] {subprocess.py:92} INFO - 22/06/07 06:16:12 INFO Executor: Finished task 16.0 in stage 0.0 (TID 16). 2646 bytes result sent to driver
[2022-06-07 06:16:12,603] {subprocess.py:92} INFO - 22/06/07 06:16:12 INFO Executor: Finished task 15.0 in stage 0.0 (TID 15). 2646 bytes result sent to driver
[2022-06-07 06:16:12,610] {subprocess.py:92} INFO - 22/06/07 06:16:12 INFO TaskSetManager: Starting task 19.0 in stage 0.0 (TID 19) (d952e2b2ede8, executor driver, partition 19, PROCESS_LOCAL, 4553 bytes) taskResourceAssignments Map()
[2022-06-07 06:16:12,613] {subprocess.py:92} INFO - 22/06/07 06:16:12 INFO Executor: Running task 19.0 in stage 0.0 (TID 19)
[2022-06-07 06:16:12,614] {subprocess.py:92} INFO - 22/06/07 06:16:12 INFO TaskSetManager: Starting task 20.0 in stage 0.0 (TID 20) (d952e2b2ede8, executor driver, partition 20, PROCESS_LOCAL, 4553 bytes) taskResourceAssignments Map()
[2022-06-07 06:16:12,616] {subprocess.py:92} INFO - 22/06/07 06:16:12 INFO TaskSetManager: Finished task 15.0 in stage 0.0 (TID 15) in 77 ms on d952e2b2ede8 (executor driver) (16/180)
[2022-06-07 06:16:12,618] {subprocess.py:92} INFO - 22/06/07 06:16:12 INFO Executor: Running task 20.0 in stage 0.0 (TID 20)
[2022-06-07 06:16:12,619] {subprocess.py:92} INFO - 22/06/07 06:16:12 INFO Executor: Finished task 17.0 in stage 0.0 (TID 17). 2646 bytes result sent to driver
[2022-06-07 06:16:12,623] {subprocess.py:92} INFO - 22/06/07 06:16:12 INFO Executor: Finished task 18.0 in stage 0.0 (TID 18). 2646 bytes result sent to driver
[2022-06-07 06:16:12,624] {subprocess.py:92} INFO - 22/06/07 06:16:12 INFO TaskSetManager: Starting task 21.0 in stage 0.0 (TID 21) (d952e2b2ede8, executor driver, partition 21, PROCESS_LOCAL, 4553 bytes) taskResourceAssignments Map()
[2022-06-07 06:16:12,626] {subprocess.py:92} INFO - 22/06/07 06:16:12 INFO TaskSetManager: Finished task 16.0 in stage 0.0 (TID 16) in 84 ms on d952e2b2ede8 (executor driver) (17/180)
[2022-06-07 06:16:12,627] {subprocess.py:92} INFO - 22/06/07 06:16:12 INFO TaskSetManager: Finished task 17.0 in stage 0.0 (TID 17) in 66 ms on d952e2b2ede8 (executor driver) (18/180)
[2022-06-07 06:16:12,633] {subprocess.py:92} INFO - 22/06/07 06:16:12 INFO Executor: Running task 21.0 in stage 0.0 (TID 21)
[2022-06-07 06:16:12,634] {subprocess.py:92} INFO - 22/06/07 06:16:12 INFO TaskSetManager: Starting task 22.0 in stage 0.0 (TID 22) (d952e2b2ede8, executor driver, partition 22, PROCESS_LOCAL, 4553 bytes) taskResourceAssignments Map()
[2022-06-07 06:16:12,635] {subprocess.py:92} INFO - 22/06/07 06:16:12 INFO TaskSetManager: Finished task 18.0 in stage 0.0 (TID 18) in 51 ms on d952e2b2ede8 (executor driver) (19/180)
[2022-06-07 06:16:12,638] {subprocess.py:92} INFO - 22/06/07 06:16:12 INFO Executor: Running task 22.0 in stage 0.0 (TID 22)
[2022-06-07 06:16:12,644] {subprocess.py:92} INFO - 22/06/07 06:16:12 INFO Executor: Finished task 19.0 in stage 0.0 (TID 19). 2646 bytes result sent to driver
[2022-06-07 06:16:12,657] {subprocess.py:92} INFO - 22/06/07 06:16:12 INFO TaskSetManager: Starting task 23.0 in stage 0.0 (TID 23) (d952e2b2ede8, executor driver, partition 23, PROCESS_LOCAL, 4553 bytes) taskResourceAssignments Map()
[2022-06-07 06:16:12,658] {subprocess.py:92} INFO - 22/06/07 06:16:12 INFO Executor: Running task 23.0 in stage 0.0 (TID 23)
[2022-06-07 06:16:12,660] {subprocess.py:92} INFO - 22/06/07 06:16:12 INFO TaskSetManager: Finished task 19.0 in stage 0.0 (TID 19) in 51 ms on d952e2b2ede8 (executor driver) (20/180)
[2022-06-07 06:16:12,681] {subprocess.py:92} INFO - 22/06/07 06:16:12 INFO Executor: Finished task 22.0 in stage 0.0 (TID 22). 2646 bytes result sent to driver
[2022-06-07 06:16:12,682] {subprocess.py:92} INFO - 22/06/07 06:16:12 INFO Executor: Finished task 20.0 in stage 0.0 (TID 20). 2646 bytes result sent to driver
[2022-06-07 06:16:12,683] {subprocess.py:92} INFO - 22/06/07 06:16:12 INFO Executor: Finished task 21.0 in stage 0.0 (TID 21). 2689 bytes result sent to driver
[2022-06-07 06:16:12,684] {subprocess.py:92} INFO - 22/06/07 06:16:12 INFO TaskSetManager: Starting task 24.0 in stage 0.0 (TID 24) (d952e2b2ede8, executor driver, partition 24, PROCESS_LOCAL, 4553 bytes) taskResourceAssignments Map()
[2022-06-07 06:16:12,685] {subprocess.py:92} INFO - 22/06/07 06:16:12 INFO Executor: Running task 24.0 in stage 0.0 (TID 24)
[2022-06-07 06:16:12,686] {subprocess.py:92} INFO - 22/06/07 06:16:12 INFO TaskSetManager: Starting task 25.0 in stage 0.0 (TID 25) (d952e2b2ede8, executor driver, partition 25, PROCESS_LOCAL, 4553 bytes) taskResourceAssignments Map()
[2022-06-07 06:16:12,687] {subprocess.py:92} INFO - 22/06/07 06:16:12 INFO TaskSetManager: Starting task 26.0 in stage 0.0 (TID 26) (d952e2b2ede8, executor driver, partition 26, PROCESS_LOCAL, 4553 bytes) taskResourceAssignments Map()
[2022-06-07 06:16:12,688] {subprocess.py:92} INFO - 22/06/07 06:16:12 INFO TaskSetManager: Finished task 22.0 in stage 0.0 (TID 22) in 55 ms on d952e2b2ede8 (executor driver) (21/180)
[2022-06-07 06:16:12,690] {subprocess.py:92} INFO - 22/06/07 06:16:12 INFO Executor: Running task 26.0 in stage 0.0 (TID 26)
[2022-06-07 06:16:12,691] {subprocess.py:92} INFO - 22/06/07 06:16:12 INFO TaskSetManager: Finished task 20.0 in stage 0.0 (TID 20) in 77 ms on d952e2b2ede8 (executor driver) (22/180)
[2022-06-07 06:16:12,693] {subprocess.py:92} INFO - 22/06/07 06:16:12 INFO TaskSetManager: Finished task 21.0 in stage 0.0 (TID 21) in 70 ms on d952e2b2ede8 (executor driver) (23/180)
[2022-06-07 06:16:12,696] {subprocess.py:92} INFO - 22/06/07 06:16:12 INFO Executor: Running task 25.0 in stage 0.0 (TID 25)
[2022-06-07 06:16:12,708] {subprocess.py:92} INFO - 22/06/07 06:16:12 INFO Executor: Finished task 26.0 in stage 0.0 (TID 26). 2646 bytes result sent to driver
[2022-06-07 06:16:12,710] {subprocess.py:92} INFO - 22/06/07 06:16:12 INFO Executor: Finished task 23.0 in stage 0.0 (TID 23). 2646 bytes result sent to driver
[2022-06-07 06:16:12,712] {subprocess.py:92} INFO - 22/06/07 06:16:12 INFO TaskSetManager: Starting task 27.0 in stage 0.0 (TID 27) (d952e2b2ede8, executor driver, partition 27, PROCESS_LOCAL, 4553 bytes) taskResourceAssignments Map()
[2022-06-07 06:16:12,714] {subprocess.py:92} INFO - 22/06/07 06:16:12 INFO TaskSetManager: Finished task 26.0 in stage 0.0 (TID 26) in 28 ms on d952e2b2ede8 (executor driver) (24/180)
[2022-06-07 06:16:12,718] {subprocess.py:92} INFO - 22/06/07 06:16:12 INFO Executor: Finished task 24.0 in stage 0.0 (TID 24). 2646 bytes result sent to driver
[2022-06-07 06:16:12,725] {subprocess.py:92} INFO - 22/06/07 06:16:12 INFO TaskSetManager: Starting task 28.0 in stage 0.0 (TID 28) (d952e2b2ede8, executor driver, partition 28, PROCESS_LOCAL, 4553 bytes) taskResourceAssignments Map()
[2022-06-07 06:16:12,727] {subprocess.py:92} INFO - 22/06/07 06:16:12 INFO TaskSetManager: Finished task 23.0 in stage 0.0 (TID 23) in 70 ms on d952e2b2ede8 (executor driver) (25/180)
[2022-06-07 06:16:12,729] {subprocess.py:92} INFO - 22/06/07 06:16:12 INFO Executor: Running task 27.0 in stage 0.0 (TID 27)
[2022-06-07 06:16:12,730] {subprocess.py:92} INFO - 22/06/07 06:16:12 INFO TaskSetManager: Starting task 29.0 in stage 0.0 (TID 29) (d952e2b2ede8, executor driver, partition 29, PROCESS_LOCAL, 4553 bytes) taskResourceAssignments Map()
[2022-06-07 06:16:12,732] {subprocess.py:92} INFO - 22/06/07 06:16:12 INFO Executor: Running task 28.0 in stage 0.0 (TID 28)
[2022-06-07 06:16:12,733] {subprocess.py:92} INFO - 22/06/07 06:16:12 INFO Executor: Running task 29.0 in stage 0.0 (TID 29)
[2022-06-07 06:16:12,735] {subprocess.py:92} INFO - 22/06/07 06:16:12 INFO TaskSetManager: Finished task 24.0 in stage 0.0 (TID 24) in 52 ms on d952e2b2ede8 (executor driver) (26/180)
[2022-06-07 06:16:12,747] {subprocess.py:92} INFO - 22/06/07 06:16:12 INFO Executor: Finished task 25.0 in stage 0.0 (TID 25). 2646 bytes result sent to driver
[2022-06-07 06:16:12,750] {subprocess.py:92} INFO - 22/06/07 06:16:12 INFO TaskSetManager: Starting task 30.0 in stage 0.0 (TID 30) (d952e2b2ede8, executor driver, partition 30, PROCESS_LOCAL, 4553 bytes) taskResourceAssignments Map()
[2022-06-07 06:16:12,758] {subprocess.py:92} INFO - 22/06/07 06:16:12 INFO TaskSetManager: Finished task 25.0 in stage 0.0 (TID 25) in 75 ms on d952e2b2ede8 (executor driver) (27/180)
[2022-06-07 06:16:12,760] {subprocess.py:92} INFO - 22/06/07 06:16:12 INFO Executor: Running task 30.0 in stage 0.0 (TID 30)
[2022-06-07 06:16:12,761] {subprocess.py:92} INFO - 22/06/07 06:16:12 INFO Executor: Finished task 27.0 in stage 0.0 (TID 27). 2646 bytes result sent to driver
[2022-06-07 06:16:12,763] {subprocess.py:92} INFO - 22/06/07 06:16:12 INFO TaskSetManager: Starting task 31.0 in stage 0.0 (TID 31) (d952e2b2ede8, executor driver, partition 31, PROCESS_LOCAL, 4553 bytes) taskResourceAssignments Map()
[2022-06-07 06:16:12,764] {subprocess.py:92} INFO - 22/06/07 06:16:12 INFO Executor: Running task 31.0 in stage 0.0 (TID 31)
[2022-06-07 06:16:12,765] {subprocess.py:92} INFO - 22/06/07 06:16:12 INFO TaskSetManager: Finished task 27.0 in stage 0.0 (TID 27) in 53 ms on d952e2b2ede8 (executor driver) (28/180)
[2022-06-07 06:16:12,768] {subprocess.py:92} INFO - 22/06/07 06:16:12 INFO Executor: Finished task 29.0 in stage 0.0 (TID 29). 2646 bytes result sent to driver
[2022-06-07 06:16:12,770] {subprocess.py:92} INFO - 22/06/07 06:16:12 INFO TaskSetManager: Starting task 32.0 in stage 0.0 (TID 32) (d952e2b2ede8, executor driver, partition 32, PROCESS_LOCAL, 4553 bytes) taskResourceAssignments Map()
[2022-06-07 06:16:12,771] {subprocess.py:92} INFO - 22/06/07 06:16:12 INFO TaskSetManager: Finished task 29.0 in stage 0.0 (TID 29) in 41 ms on d952e2b2ede8 (executor driver) (29/180)
[2022-06-07 06:16:12,780] {subprocess.py:92} INFO - 22/06/07 06:16:12 INFO Executor: Running task 32.0 in stage 0.0 (TID 32)
[2022-06-07 06:16:12,783] {subprocess.py:92} INFO - 22/06/07 06:16:12 INFO Executor: Finished task 28.0 in stage 0.0 (TID 28). 2646 bytes result sent to driver
[2022-06-07 06:16:12,785] {subprocess.py:92} INFO - 22/06/07 06:16:12 INFO Executor: Finished task 31.0 in stage 0.0 (TID 31). 2646 bytes result sent to driver
[2022-06-07 06:16:12,785] {subprocess.py:92} INFO - 22/06/07 06:16:12 INFO TaskSetManager: Starting task 33.0 in stage 0.0 (TID 33) (d952e2b2ede8, executor driver, partition 33, PROCESS_LOCAL, 4553 bytes) taskResourceAssignments Map()
[2022-06-07 06:16:12,786] {subprocess.py:92} INFO - 22/06/07 06:16:12 INFO TaskSetManager: Starting task 34.0 in stage 0.0 (TID 34) (d952e2b2ede8, executor driver, partition 34, PROCESS_LOCAL, 4553 bytes) taskResourceAssignments Map()
[2022-06-07 06:16:12,787] {subprocess.py:92} INFO - 22/06/07 06:16:12 INFO Executor: Running task 34.0 in stage 0.0 (TID 34)
[2022-06-07 06:16:12,793] {subprocess.py:92} INFO - 22/06/07 06:16:12 INFO TaskSetManager: Finished task 31.0 in stage 0.0 (TID 31) in 30 ms on d952e2b2ede8 (executor driver) (30/180)
[2022-06-07 06:16:12,794] {subprocess.py:92} INFO - 22/06/07 06:16:12 INFO TaskSetManager: Finished task 28.0 in stage 0.0 (TID 28) in 69 ms on d952e2b2ede8 (executor driver) (31/180)
[2022-06-07 06:16:12,795] {subprocess.py:92} INFO - 22/06/07 06:16:12 INFO Executor: Finished task 30.0 in stage 0.0 (TID 30). 2646 bytes result sent to driver
[2022-06-07 06:16:12,796] {subprocess.py:92} INFO - 22/06/07 06:16:12 INFO Executor: Running task 33.0 in stage 0.0 (TID 33)
[2022-06-07 06:16:12,798] {subprocess.py:92} INFO - 22/06/07 06:16:12 INFO TaskSetManager: Starting task 35.0 in stage 0.0 (TID 35) (d952e2b2ede8, executor driver, partition 35, PROCESS_LOCAL, 4553 bytes) taskResourceAssignments Map()
[2022-06-07 06:16:12,799] {subprocess.py:92} INFO - 22/06/07 06:16:12 INFO Executor: Running task 35.0 in stage 0.0 (TID 35)
[2022-06-07 06:16:12,800] {subprocess.py:92} INFO - 22/06/07 06:16:12 INFO TaskSetManager: Finished task 30.0 in stage 0.0 (TID 30) in 51 ms on d952e2b2ede8 (executor driver) (32/180)
[2022-06-07 06:16:12,809] {subprocess.py:92} INFO - 22/06/07 06:16:12 INFO Executor: Finished task 34.0 in stage 0.0 (TID 34). 2646 bytes result sent to driver
[2022-06-07 06:16:12,810] {subprocess.py:92} INFO - 22/06/07 06:16:12 INFO TaskSetManager: Starting task 36.0 in stage 0.0 (TID 36) (d952e2b2ede8, executor driver, partition 36, PROCESS_LOCAL, 4553 bytes) taskResourceAssignments Map()
[2022-06-07 06:16:12,811] {subprocess.py:92} INFO - 22/06/07 06:16:12 INFO Executor: Running task 36.0 in stage 0.0 (TID 36)
[2022-06-07 06:16:12,812] {subprocess.py:92} INFO - 22/06/07 06:16:12 INFO TaskSetManager: Finished task 34.0 in stage 0.0 (TID 34) in 26 ms on d952e2b2ede8 (executor driver) (33/180)
[2022-06-07 06:16:12,818] {subprocess.py:92} INFO - 22/06/07 06:16:12 INFO Executor: Finished task 35.0 in stage 0.0 (TID 35). 2646 bytes result sent to driver
[2022-06-07 06:16:12,819] {subprocess.py:92} INFO - 22/06/07 06:16:12 INFO TaskSetManager: Starting task 37.0 in stage 0.0 (TID 37) (d952e2b2ede8, executor driver, partition 37, PROCESS_LOCAL, 4553 bytes) taskResourceAssignments Map()
[2022-06-07 06:16:12,820] {subprocess.py:92} INFO - 22/06/07 06:16:12 INFO Executor: Running task 37.0 in stage 0.0 (TID 37)
[2022-06-07 06:16:12,833] {subprocess.py:92} INFO - 22/06/07 06:16:12 INFO TaskSetManager: Finished task 35.0 in stage 0.0 (TID 35) in 34 ms on d952e2b2ede8 (executor driver) (34/180)
[2022-06-07 06:16:12,845] {subprocess.py:92} INFO - 22/06/07 06:16:12 INFO Executor: Finished task 33.0 in stage 0.0 (TID 33). 2646 bytes result sent to driver
[2022-06-07 06:16:12,846] {subprocess.py:92} INFO - 22/06/07 06:16:12 INFO Executor: Finished task 37.0 in stage 0.0 (TID 37). 2646 bytes result sent to driver
[2022-06-07 06:16:12,847] {subprocess.py:92} INFO - 22/06/07 06:16:12 INFO Executor: Finished task 32.0 in stage 0.0 (TID 32). 2646 bytes result sent to driver
[2022-06-07 06:16:12,849] {subprocess.py:92} INFO - 22/06/07 06:16:12 INFO Executor: Finished task 36.0 in stage 0.0 (TID 36). 2646 bytes result sent to driver
[2022-06-07 06:16:12,851] {subprocess.py:92} INFO - 22/06/07 06:16:12 INFO TaskSetManager: Starting task 38.0 in stage 0.0 (TID 38) (d952e2b2ede8, executor driver, partition 38, PROCESS_LOCAL, 4553 bytes) taskResourceAssignments Map()
[2022-06-07 06:16:12,853] {subprocess.py:92} INFO - 22/06/07 06:16:12 INFO TaskSetManager: Finished task 33.0 in stage 0.0 (TID 33) in 69 ms on d952e2b2ede8 (executor driver) (35/180)
[2022-06-07 06:16:12,854] {subprocess.py:92} INFO - 22/06/07 06:16:12 INFO Executor: Running task 38.0 in stage 0.0 (TID 38)
[2022-06-07 06:16:12,855] {subprocess.py:92} INFO - 22/06/07 06:16:12 INFO TaskSetManager: Starting task 39.0 in stage 0.0 (TID 39) (d952e2b2ede8, executor driver, partition 39, PROCESS_LOCAL, 4553 bytes) taskResourceAssignments Map()
[2022-06-07 06:16:12,857] {subprocess.py:92} INFO - 22/06/07 06:16:12 INFO TaskSetManager: Starting task 40.0 in stage 0.0 (TID 40) (d952e2b2ede8, executor driver, partition 40, PROCESS_LOCAL, 4553 bytes) taskResourceAssignments Map()
[2022-06-07 06:16:12,858] {subprocess.py:92} INFO - 22/06/07 06:16:12 INFO TaskSetManager: Finished task 32.0 in stage 0.0 (TID 32) in 89 ms on d952e2b2ede8 (executor driver) (36/180)
[2022-06-07 06:16:12,859] {subprocess.py:92} INFO - 22/06/07 06:16:12 INFO Executor: Running task 40.0 in stage 0.0 (TID 40)
[2022-06-07 06:16:12,860] {subprocess.py:92} INFO - 22/06/07 06:16:12 INFO TaskSetManager: Starting task 41.0 in stage 0.0 (TID 41) (d952e2b2ede8, executor driver, partition 41, PROCESS_LOCAL, 4553 bytes) taskResourceAssignments Map()
[2022-06-07 06:16:12,860] {subprocess.py:92} INFO - 22/06/07 06:16:12 INFO TaskSetManager: Finished task 36.0 in stage 0.0 (TID 36) in 49 ms on d952e2b2ede8 (executor driver) (37/180)
[2022-06-07 06:16:12,861] {subprocess.py:92} INFO - 22/06/07 06:16:12 INFO TaskSetManager: Finished task 37.0 in stage 0.0 (TID 37) in 42 ms on d952e2b2ede8 (executor driver) (38/180)
[2022-06-07 06:16:12,862] {subprocess.py:92} INFO - 22/06/07 06:16:12 INFO Executor: Running task 39.0 in stage 0.0 (TID 39)
[2022-06-07 06:16:12,865] {subprocess.py:92} INFO - 22/06/07 06:16:12 INFO Executor: Running task 41.0 in stage 0.0 (TID 41)
[2022-06-07 06:16:12,882] {subprocess.py:92} INFO - 22/06/07 06:16:12 INFO Executor: Finished task 41.0 in stage 0.0 (TID 41). 2646 bytes result sent to driver
[2022-06-07 06:16:12,883] {subprocess.py:92} INFO - 22/06/07 06:16:12 INFO TaskSetManager: Starting task 42.0 in stage 0.0 (TID 42) (d952e2b2ede8, executor driver, partition 42, PROCESS_LOCAL, 4553 bytes) taskResourceAssignments Map()
[2022-06-07 06:16:12,885] {subprocess.py:92} INFO - 22/06/07 06:16:12 INFO TaskSetManager: Finished task 41.0 in stage 0.0 (TID 41) in 26 ms on d952e2b2ede8 (executor driver) (39/180)
[2022-06-07 06:16:12,888] {subprocess.py:92} INFO - 22/06/07 06:16:12 INFO Executor: Finished task 40.0 in stage 0.0 (TID 40). 2646 bytes result sent to driver
[2022-06-07 06:16:12,895] {subprocess.py:92} INFO - 22/06/07 06:16:12 INFO Executor: Finished task 38.0 in stage 0.0 (TID 38). 2646 bytes result sent to driver
[2022-06-07 06:16:12,896] {subprocess.py:92} INFO - 22/06/07 06:16:12 INFO Executor: Running task 42.0 in stage 0.0 (TID 42)
[2022-06-07 06:16:12,898] {subprocess.py:92} INFO - 22/06/07 06:16:12 INFO TaskSetManager: Starting task 43.0 in stage 0.0 (TID 43) (d952e2b2ede8, executor driver, partition 43, PROCESS_LOCAL, 4553 bytes) taskResourceAssignments Map()
[2022-06-07 06:16:12,899] {subprocess.py:92} INFO - 22/06/07 06:16:12 INFO Executor: Running task 43.0 in stage 0.0 (TID 43)
[2022-06-07 06:16:12,900] {subprocess.py:92} INFO - 22/06/07 06:16:12 INFO TaskSetManager: Starting task 44.0 in stage 0.0 (TID 44) (d952e2b2ede8, executor driver, partition 44, PROCESS_LOCAL, 4553 bytes) taskResourceAssignments Map()
[2022-06-07 06:16:12,901] {subprocess.py:92} INFO - 22/06/07 06:16:12 INFO TaskSetManager: Finished task 38.0 in stage 0.0 (TID 38) in 50 ms on d952e2b2ede8 (executor driver) (40/180)
[2022-06-07 06:16:12,902] {subprocess.py:92} INFO - 22/06/07 06:16:12 INFO TaskSetManager: Finished task 40.0 in stage 0.0 (TID 40) in 45 ms on d952e2b2ede8 (executor driver) (41/180)
[2022-06-07 06:16:12,903] {subprocess.py:92} INFO - 22/06/07 06:16:12 INFO Executor: Running task 44.0 in stage 0.0 (TID 44)
[2022-06-07 06:16:12,907] {subprocess.py:92} INFO - 22/06/07 06:16:12 INFO Executor: Finished task 39.0 in stage 0.0 (TID 39). 2646 bytes result sent to driver
[2022-06-07 06:16:12,909] {subprocess.py:92} INFO - 22/06/07 06:16:12 INFO TaskSetManager: Starting task 45.0 in stage 0.0 (TID 45) (d952e2b2ede8, executor driver, partition 45, PROCESS_LOCAL, 4553 bytes) taskResourceAssignments Map()
[2022-06-07 06:16:12,910] {subprocess.py:92} INFO - 22/06/07 06:16:12 INFO TaskSetManager: Finished task 39.0 in stage 0.0 (TID 39) in 55 ms on d952e2b2ede8 (executor driver) (42/180)
[2022-06-07 06:16:12,912] {subprocess.py:92} INFO - 22/06/07 06:16:12 INFO Executor: Running task 45.0 in stage 0.0 (TID 45)
[2022-06-07 06:16:12,928] {subprocess.py:92} INFO - 22/06/07 06:16:12 INFO Executor: Finished task 44.0 in stage 0.0 (TID 44). 2646 bytes result sent to driver
[2022-06-07 06:16:12,931] {subprocess.py:92} INFO - 22/06/07 06:16:12 INFO TaskSetManager: Starting task 46.0 in stage 0.0 (TID 46) (d952e2b2ede8, executor driver, partition 46, PROCESS_LOCAL, 4553 bytes) taskResourceAssignments Map()
[2022-06-07 06:16:12,932] {subprocess.py:92} INFO - 22/06/07 06:16:12 INFO TaskSetManager: Finished task 44.0 in stage 0.0 (TID 44) in 33 ms on d952e2b2ede8 (executor driver) (43/180)
[2022-06-07 06:16:12,933] {subprocess.py:92} INFO - 22/06/07 06:16:12 INFO Executor: Running task 46.0 in stage 0.0 (TID 46)
[2022-06-07 06:16:12,936] {subprocess.py:92} INFO - 22/06/07 06:16:12 INFO Executor: Finished task 42.0 in stage 0.0 (TID 42). 2646 bytes result sent to driver
[2022-06-07 06:16:12,938] {subprocess.py:92} INFO - 22/06/07 06:16:12 INFO TaskSetManager: Starting task 47.0 in stage 0.0 (TID 47) (d952e2b2ede8, executor driver, partition 47, PROCESS_LOCAL, 4553 bytes) taskResourceAssignments Map()
[2022-06-07 06:16:12,940] {subprocess.py:92} INFO - 22/06/07 06:16:12 INFO Executor: Running task 47.0 in stage 0.0 (TID 47)
[2022-06-07 06:16:12,941] {subprocess.py:92} INFO - 22/06/07 06:16:12 INFO TaskSetManager: Finished task 42.0 in stage 0.0 (TID 42) in 57 ms on d952e2b2ede8 (executor driver) (44/180)
[2022-06-07 06:16:12,942] {subprocess.py:92} INFO - 22/06/07 06:16:12 INFO Executor: Finished task 43.0 in stage 0.0 (TID 43). 2646 bytes result sent to driver
[2022-06-07 06:16:12,944] {subprocess.py:92} INFO - 22/06/07 06:16:12 INFO TaskSetManager: Starting task 48.0 in stage 0.0 (TID 48) (d952e2b2ede8, executor driver, partition 48, PROCESS_LOCAL, 4553 bytes) taskResourceAssignments Map()
[2022-06-07 06:16:12,945] {subprocess.py:92} INFO - 22/06/07 06:16:12 INFO TaskSetManager: Finished task 43.0 in stage 0.0 (TID 43) in 48 ms on d952e2b2ede8 (executor driver) (45/180)
[2022-06-07 06:16:12,947] {subprocess.py:92} INFO - 22/06/07 06:16:12 INFO Executor: Running task 48.0 in stage 0.0 (TID 48)
[2022-06-07 06:16:12,956] {subprocess.py:92} INFO - 22/06/07 06:16:12 INFO Executor: Finished task 47.0 in stage 0.0 (TID 47). 2646 bytes result sent to driver
[2022-06-07 06:16:12,958] {subprocess.py:92} INFO - 22/06/07 06:16:12 INFO TaskSetManager: Starting task 49.0 in stage 0.0 (TID 49) (d952e2b2ede8, executor driver, partition 49, PROCESS_LOCAL, 4553 bytes) taskResourceAssignments Map()
[2022-06-07 06:16:12,962] {subprocess.py:92} INFO - 22/06/07 06:16:12 INFO TaskSetManager: Finished task 47.0 in stage 0.0 (TID 47) in 20 ms on d952e2b2ede8 (executor driver) (46/180)
[2022-06-07 06:16:12,962] {subprocess.py:92} INFO - 22/06/07 06:16:12 INFO Executor: Running task 49.0 in stage 0.0 (TID 49)
[2022-06-07 06:16:12,989] {subprocess.py:92} INFO - 22/06/07 06:16:12 INFO Executor: Finished task 45.0 in stage 0.0 (TID 45). 2646 bytes result sent to driver
[2022-06-07 06:16:12,994] {subprocess.py:92} INFO - 22/06/07 06:16:12 INFO Executor: Finished task 46.0 in stage 0.0 (TID 46). 2646 bytes result sent to driver
[2022-06-07 06:16:12,996] {subprocess.py:92} INFO - 22/06/07 06:16:12 INFO TaskSetManager: Starting task 50.0 in stage 0.0 (TID 50) (d952e2b2ede8, executor driver, partition 50, PROCESS_LOCAL, 4553 bytes) taskResourceAssignments Map()
[2022-06-07 06:16:13,002] {subprocess.py:92} INFO - 22/06/07 06:16:12 INFO Executor: Finished task 48.0 in stage 0.0 (TID 48). 2646 bytes result sent to driver
[2022-06-07 06:16:13,003] {subprocess.py:92} INFO - 22/06/07 06:16:12 INFO Executor: Running task 50.0 in stage 0.0 (TID 50)
[2022-06-07 06:16:13,008] {subprocess.py:92} INFO - 22/06/07 06:16:12 INFO TaskSetManager: Finished task 45.0 in stage 0.0 (TID 45) in 82 ms on d952e2b2ede8 (executor driver) (47/180)
[2022-06-07 06:16:13,011] {subprocess.py:92} INFO - 22/06/07 06:16:12 INFO TaskSetManager: Starting task 51.0 in stage 0.0 (TID 51) (d952e2b2ede8, executor driver, partition 51, PROCESS_LOCAL, 4553 bytes) taskResourceAssignments Map()
[2022-06-07 06:16:13,014] {subprocess.py:92} INFO - 22/06/07 06:16:12 INFO Executor: Running task 51.0 in stage 0.0 (TID 51)
[2022-06-07 06:16:13,016] {subprocess.py:92} INFO - 22/06/07 06:16:12 INFO TaskSetManager: Finished task 48.0 in stage 0.0 (TID 48) in 51 ms on d952e2b2ede8 (executor driver) (48/180)
[2022-06-07 06:16:13,019] {subprocess.py:92} INFO - 22/06/07 06:16:12 INFO TaskSetManager: Starting task 52.0 in stage 0.0 (TID 52) (d952e2b2ede8, executor driver, partition 52, PROCESS_LOCAL, 4553 bytes) taskResourceAssignments Map()
[2022-06-07 06:16:13,022] {subprocess.py:92} INFO - 22/06/07 06:16:12 INFO TaskSetManager: Finished task 46.0 in stage 0.0 (TID 46) in 68 ms on d952e2b2ede8 (executor driver) (49/180)
[2022-06-07 06:16:13,024] {subprocess.py:92} INFO - 22/06/07 06:16:13 INFO Executor: Running task 52.0 in stage 0.0 (TID 52)
[2022-06-07 06:16:13,025] {subprocess.py:92} INFO - 22/06/07 06:16:13 INFO Executor: Finished task 49.0 in stage 0.0 (TID 49). 2646 bytes result sent to driver
[2022-06-07 06:16:13,026] {subprocess.py:92} INFO - 22/06/07 06:16:13 INFO TaskSetManager: Starting task 53.0 in stage 0.0 (TID 53) (d952e2b2ede8, executor driver, partition 53, PROCESS_LOCAL, 4553 bytes) taskResourceAssignments Map()
[2022-06-07 06:16:13,027] {subprocess.py:92} INFO - 22/06/07 06:16:13 INFO TaskSetManager: Finished task 49.0 in stage 0.0 (TID 49) in 45 ms on d952e2b2ede8 (executor driver) (50/180)
[2022-06-07 06:16:13,030] {subprocess.py:92} INFO - 22/06/07 06:16:13 INFO Executor: Running task 53.0 in stage 0.0 (TID 53)
[2022-06-07 06:16:13,031] {subprocess.py:92} INFO - 22/06/07 06:16:13 INFO Executor: Finished task 50.0 in stage 0.0 (TID 50). 2646 bytes result sent to driver
[2022-06-07 06:16:13,031] {subprocess.py:92} INFO - 22/06/07 06:16:13 INFO TaskSetManager: Starting task 54.0 in stage 0.0 (TID 54) (d952e2b2ede8, executor driver, partition 54, PROCESS_LOCAL, 4553 bytes) taskResourceAssignments Map()
[2022-06-07 06:16:13,032] {subprocess.py:92} INFO - 22/06/07 06:16:13 INFO TaskSetManager: Finished task 50.0 in stage 0.0 (TID 50) in 39 ms on d952e2b2ede8 (executor driver) (51/180)
[2022-06-07 06:16:13,035] {subprocess.py:92} INFO - 22/06/07 06:16:13 INFO Executor: Finished task 53.0 in stage 0.0 (TID 53). 2646 bytes result sent to driver
[2022-06-07 06:16:13,037] {subprocess.py:92} INFO - 22/06/07 06:16:13 INFO TaskSetManager: Starting task 55.0 in stage 0.0 (TID 55) (d952e2b2ede8, executor driver, partition 55, PROCESS_LOCAL, 4553 bytes) taskResourceAssignments Map()
[2022-06-07 06:16:13,038] {subprocess.py:92} INFO - 22/06/07 06:16:13 INFO TaskSetManager: Finished task 53.0 in stage 0.0 (TID 53) in 37 ms on d952e2b2ede8 (executor driver) (52/180)
[2022-06-07 06:16:13,041] {subprocess.py:92} INFO - 22/06/07 06:16:13 INFO Executor: Running task 54.0 in stage 0.0 (TID 54)
[2022-06-07 06:16:13,042] {subprocess.py:92} INFO - 22/06/07 06:16:13 INFO Executor: Running task 55.0 in stage 0.0 (TID 55)
[2022-06-07 06:16:13,068] {subprocess.py:92} INFO - 22/06/07 06:16:13 INFO Executor: Finished task 52.0 in stage 0.0 (TID 52). 2646 bytes result sent to driver
[2022-06-07 06:16:13,082] {subprocess.py:92} INFO - 22/06/07 06:16:13 INFO TaskSetManager: Starting task 56.0 in stage 0.0 (TID 56) (d952e2b2ede8, executor driver, partition 56, PROCESS_LOCAL, 4553 bytes) taskResourceAssignments Map()
[2022-06-07 06:16:13,084] {subprocess.py:92} INFO - 22/06/07 06:16:13 INFO TaskSetManager: Finished task 52.0 in stage 0.0 (TID 52) in 87 ms on d952e2b2ede8 (executor driver) (53/180)
[2022-06-07 06:16:13,085] {subprocess.py:92} INFO - 22/06/07 06:16:13 INFO Executor: Running task 56.0 in stage 0.0 (TID 56)
[2022-06-07 06:16:13,102] {subprocess.py:92} INFO - 22/06/07 06:16:13 INFO Executor: Finished task 54.0 in stage 0.0 (TID 54). 2646 bytes result sent to driver
[2022-06-07 06:16:13,104] {subprocess.py:92} INFO - 22/06/07 06:16:13 INFO Executor: Finished task 55.0 in stage 0.0 (TID 55). 2646 bytes result sent to driver
[2022-06-07 06:16:13,106] {subprocess.py:92} INFO - 22/06/07 06:16:13 INFO TaskSetManager: Starting task 57.0 in stage 0.0 (TID 57) (d952e2b2ede8, executor driver, partition 57, PROCESS_LOCAL, 4553 bytes) taskResourceAssignments Map()
[2022-06-07 06:16:13,109] {subprocess.py:92} INFO - 22/06/07 06:16:13 INFO Executor: Running task 57.0 in stage 0.0 (TID 57)
[2022-06-07 06:16:13,111] {subprocess.py:92} INFO - 22/06/07 06:16:13 INFO TaskSetManager: Starting task 58.0 in stage 0.0 (TID 58) (d952e2b2ede8, executor driver, partition 58, PROCESS_LOCAL, 4553 bytes) taskResourceAssignments Map()
[2022-06-07 06:16:13,112] {subprocess.py:92} INFO - 22/06/07 06:16:13 INFO TaskSetManager: Finished task 55.0 in stage 0.0 (TID 55) in 76 ms on d952e2b2ede8 (executor driver) (54/180)
[2022-06-07 06:16:13,115] {subprocess.py:92} INFO - 22/06/07 06:16:13 INFO Executor: Finished task 56.0 in stage 0.0 (TID 56). 2646 bytes result sent to driver
[2022-06-07 06:16:13,117] {subprocess.py:92} INFO - 22/06/07 06:16:13 INFO Executor: Finished task 51.0 in stage 0.0 (TID 51). 2646 bytes result sent to driver
[2022-06-07 06:16:13,117] {subprocess.py:92} INFO - 22/06/07 06:16:13 INFO TaskSetManager: Finished task 54.0 in stage 0.0 (TID 54) in 93 ms on d952e2b2ede8 (executor driver) (55/180)
[2022-06-07 06:16:13,118] {subprocess.py:92} INFO - 22/06/07 06:16:13 INFO Executor: Running task 58.0 in stage 0.0 (TID 58)
[2022-06-07 06:16:13,120] {subprocess.py:92} INFO - 22/06/07 06:16:13 INFO TaskSetManager: Starting task 59.0 in stage 0.0 (TID 59) (d952e2b2ede8, executor driver, partition 59, PROCESS_LOCAL, 4553 bytes) taskResourceAssignments Map()
[2022-06-07 06:16:13,123] {subprocess.py:92} INFO - 22/06/07 06:16:13 INFO TaskSetManager: Starting task 60.0 in stage 0.0 (TID 60) (d952e2b2ede8, executor driver, partition 60, PROCESS_LOCAL, 4553 bytes) taskResourceAssignments Map()
[2022-06-07 06:16:13,124] {subprocess.py:92} INFO - 22/06/07 06:16:13 INFO Executor: Running task 59.0 in stage 0.0 (TID 59)
[2022-06-07 06:16:13,126] {subprocess.py:92} INFO - 22/06/07 06:16:13 INFO Executor: Running task 60.0 in stage 0.0 (TID 60)
[2022-06-07 06:16:13,126] {subprocess.py:92} INFO - 22/06/07 06:16:13 INFO TaskSetManager: Finished task 56.0 in stage 0.0 (TID 56) in 44 ms on d952e2b2ede8 (executor driver) (56/180)
[2022-06-07 06:16:13,128] {subprocess.py:92} INFO - 22/06/07 06:16:13 INFO TaskSetManager: Finished task 51.0 in stage 0.0 (TID 51) in 134 ms on d952e2b2ede8 (executor driver) (57/180)
[2022-06-07 06:16:13,187] {subprocess.py:92} INFO - 22/06/07 06:16:13 INFO Executor: Finished task 57.0 in stage 0.0 (TID 57). 2689 bytes result sent to driver
[2022-06-07 06:16:13,188] {subprocess.py:92} INFO - 22/06/07 06:16:13 INFO TaskSetManager: Starting task 61.0 in stage 0.0 (TID 61) (d952e2b2ede8, executor driver, partition 61, PROCESS_LOCAL, 4553 bytes) taskResourceAssignments Map()
[2022-06-07 06:16:13,189] {subprocess.py:92} INFO - 22/06/07 06:16:13 INFO Executor: Running task 61.0 in stage 0.0 (TID 61)
[2022-06-07 06:16:13,197] {subprocess.py:92} INFO - 22/06/07 06:16:13 INFO TaskSetManager: Finished task 57.0 in stage 0.0 (TID 57) in 85 ms on d952e2b2ede8 (executor driver) (58/180)
[2022-06-07 06:16:13,205] {subprocess.py:92} INFO - 22/06/07 06:16:13 INFO Executor: Finished task 59.0 in stage 0.0 (TID 59). 2689 bytes result sent to driver
[2022-06-07 06:16:13,207] {subprocess.py:92} INFO - 22/06/07 06:16:13 INFO Executor: Finished task 58.0 in stage 0.0 (TID 58). 2689 bytes result sent to driver
[2022-06-07 06:16:13,216] {subprocess.py:92} INFO - 22/06/07 06:16:13 INFO TaskSetManager: Starting task 62.0 in stage 0.0 (TID 62) (d952e2b2ede8, executor driver, partition 62, PROCESS_LOCAL, 4553 bytes) taskResourceAssignments Map()
[2022-06-07 06:16:13,217] {subprocess.py:92} INFO - 22/06/07 06:16:13 INFO Executor: Finished task 60.0 in stage 0.0 (TID 60). 2689 bytes result sent to driver
[2022-06-07 06:16:13,217] {subprocess.py:92} INFO - 22/06/07 06:16:13 INFO Executor: Running task 62.0 in stage 0.0 (TID 62)
[2022-06-07 06:16:13,218] {subprocess.py:92} INFO - 22/06/07 06:16:13 INFO TaskSetManager: Starting task 63.0 in stage 0.0 (TID 63) (d952e2b2ede8, executor driver, partition 63, PROCESS_LOCAL, 4553 bytes) taskResourceAssignments Map()
[2022-06-07 06:16:13,219] {subprocess.py:92} INFO - 22/06/07 06:16:13 INFO TaskSetManager: Starting task 64.0 in stage 0.0 (TID 64) (d952e2b2ede8, executor driver, partition 64, PROCESS_LOCAL, 4553 bytes) taskResourceAssignments Map()
[2022-06-07 06:16:13,219] {subprocess.py:92} INFO - 22/06/07 06:16:13 INFO Executor: Running task 63.0 in stage 0.0 (TID 63)
[2022-06-07 06:16:13,220] {subprocess.py:92} INFO - 22/06/07 06:16:13 INFO Executor: Running task 64.0 in stage 0.0 (TID 64)
[2022-06-07 06:16:13,221] {subprocess.py:92} INFO - 22/06/07 06:16:13 INFO TaskSetManager: Finished task 59.0 in stage 0.0 (TID 59) in 91 ms on d952e2b2ede8 (executor driver) (59/180)
[2022-06-07 06:16:13,222] {subprocess.py:92} INFO - 22/06/07 06:16:13 INFO TaskSetManager: Finished task 58.0 in stage 0.0 (TID 58) in 100 ms on d952e2b2ede8 (executor driver) (60/180)
[2022-06-07 06:16:13,223] {subprocess.py:92} INFO - 22/06/07 06:16:13 INFO TaskSetManager: Finished task 60.0 in stage 0.0 (TID 60) in 89 ms on d952e2b2ede8 (executor driver) (61/180)
[2022-06-07 06:16:13,227] {subprocess.py:92} INFO - 22/06/07 06:16:13 INFO Executor: Finished task 63.0 in stage 0.0 (TID 63). 2646 bytes result sent to driver
[2022-06-07 06:16:13,231] {subprocess.py:92} INFO - 22/06/07 06:16:13 INFO Executor: Finished task 61.0 in stage 0.0 (TID 61). 2646 bytes result sent to driver
[2022-06-07 06:16:13,233] {subprocess.py:92} INFO - 22/06/07 06:16:13 INFO TaskSetManager: Starting task 65.0 in stage 0.0 (TID 65) (d952e2b2ede8, executor driver, partition 65, PROCESS_LOCAL, 4553 bytes) taskResourceAssignments Map()
[2022-06-07 06:16:13,235] {subprocess.py:92} INFO - 22/06/07 06:16:13 INFO Executor: Running task 65.0 in stage 0.0 (TID 65)
[2022-06-07 06:16:13,236] {subprocess.py:92} INFO - 22/06/07 06:16:13 INFO TaskSetManager: Starting task 66.0 in stage 0.0 (TID 66) (d952e2b2ede8, executor driver, partition 66, PROCESS_LOCAL, 4553 bytes) taskResourceAssignments Map()
[2022-06-07 06:16:13,237] {subprocess.py:92} INFO - 22/06/07 06:16:13 INFO Executor: Finished task 64.0 in stage 0.0 (TID 64). 2646 bytes result sent to driver
[2022-06-07 06:16:13,238] {subprocess.py:92} INFO - 22/06/07 06:16:13 INFO TaskSetManager: Finished task 63.0 in stage 0.0 (TID 63) in 29 ms on d952e2b2ede8 (executor driver) (62/180)
[2022-06-07 06:16:13,239] {subprocess.py:92} INFO - 22/06/07 06:16:13 INFO TaskSetManager: Finished task 61.0 in stage 0.0 (TID 61) in 51 ms on d952e2b2ede8 (executor driver) (63/180)
[2022-06-07 06:16:13,241] {subprocess.py:92} INFO - 22/06/07 06:16:13 INFO Executor: Finished task 62.0 in stage 0.0 (TID 62). 2646 bytes result sent to driver
[2022-06-07 06:16:13,242] {subprocess.py:92} INFO - 22/06/07 06:16:13 INFO Executor: Running task 66.0 in stage 0.0 (TID 66)
[2022-06-07 06:16:13,249] {subprocess.py:92} INFO - 22/06/07 06:16:13 INFO TaskSetManager: Starting task 67.0 in stage 0.0 (TID 67) (d952e2b2ede8, executor driver, partition 67, PROCESS_LOCAL, 4553 bytes) taskResourceAssignments Map()
[2022-06-07 06:16:13,251] {subprocess.py:92} INFO - 22/06/07 06:16:13 INFO TaskSetManager: Finished task 64.0 in stage 0.0 (TID 64) in 41 ms on d952e2b2ede8 (executor driver) (64/180)
[2022-06-07 06:16:13,252] {subprocess.py:92} INFO - 22/06/07 06:16:13 INFO Executor: Running task 67.0 in stage 0.0 (TID 67)
[2022-06-07 06:16:13,253] {subprocess.py:92} INFO - 22/06/07 06:16:13 INFO TaskSetManager: Finished task 62.0 in stage 0.0 (TID 62) in 47 ms on d952e2b2ede8 (executor driver) (65/180)
[2022-06-07 06:16:13,256] {subprocess.py:92} INFO - 22/06/07 06:16:13 INFO TaskSetManager: Starting task 68.0 in stage 0.0 (TID 68) (d952e2b2ede8, executor driver, partition 68, PROCESS_LOCAL, 4553 bytes) taskResourceAssignments Map()
[2022-06-07 06:16:13,257] {subprocess.py:92} INFO - 22/06/07 06:16:13 INFO Executor: Running task 68.0 in stage 0.0 (TID 68)
[2022-06-07 06:16:13,271] {subprocess.py:92} INFO - 22/06/07 06:16:13 INFO Executor: Finished task 68.0 in stage 0.0 (TID 68). 2646 bytes result sent to driver
[2022-06-07 06:16:13,272] {subprocess.py:92} INFO - 22/06/07 06:16:13 INFO Executor: Finished task 65.0 in stage 0.0 (TID 65). 2646 bytes result sent to driver
[2022-06-07 06:16:13,272] {subprocess.py:92} INFO - 22/06/07 06:16:13 INFO Executor: Finished task 66.0 in stage 0.0 (TID 66). 2646 bytes result sent to driver
[2022-06-07 06:16:13,273] {subprocess.py:92} INFO - 22/06/07 06:16:13 INFO TaskSetManager: Starting task 69.0 in stage 0.0 (TID 69) (d952e2b2ede8, executor driver, partition 69, PROCESS_LOCAL, 4553 bytes) taskResourceAssignments Map()
[2022-06-07 06:16:13,274] {subprocess.py:92} INFO - 22/06/07 06:16:13 INFO Executor: Running task 69.0 in stage 0.0 (TID 69)
[2022-06-07 06:16:13,275] {subprocess.py:92} INFO - 22/06/07 06:16:13 INFO TaskSetManager: Starting task 70.0 in stage 0.0 (TID 70) (d952e2b2ede8, executor driver, partition 70, PROCESS_LOCAL, 4553 bytes) taskResourceAssignments Map()
[2022-06-07 06:16:13,278] {subprocess.py:92} INFO - 22/06/07 06:16:13 INFO Executor: Finished task 67.0 in stage 0.0 (TID 67). 2646 bytes result sent to driver
[2022-06-07 06:16:13,280] {subprocess.py:92} INFO - 22/06/07 06:16:13 INFO Executor: Running task 70.0 in stage 0.0 (TID 70)
[2022-06-07 06:16:13,280] {subprocess.py:92} INFO - 22/06/07 06:16:13 INFO TaskSetManager: Starting task 71.0 in stage 0.0 (TID 71) (d952e2b2ede8, executor driver, partition 71, PROCESS_LOCAL, 4553 bytes) taskResourceAssignments Map()
[2022-06-07 06:16:13,281] {subprocess.py:92} INFO - 22/06/07 06:16:13 INFO Executor: Running task 71.0 in stage 0.0 (TID 71)
[2022-06-07 06:16:13,282] {subprocess.py:92} INFO - 22/06/07 06:16:13 INFO TaskSetManager: Finished task 68.0 in stage 0.0 (TID 68) in 25 ms on d952e2b2ede8 (executor driver) (66/180)
[2022-06-07 06:16:13,286] {subprocess.py:92} INFO - 22/06/07 06:16:13 INFO TaskSetManager: Starting task 72.0 in stage 0.0 (TID 72) (d952e2b2ede8, executor driver, partition 72, PROCESS_LOCAL, 4553 bytes) taskResourceAssignments Map()
[2022-06-07 06:16:13,287] {subprocess.py:92} INFO - 22/06/07 06:16:13 INFO TaskSetManager: Finished task 66.0 in stage 0.0 (TID 66) in 52 ms on d952e2b2ede8 (executor driver) (67/180)
[2022-06-07 06:16:13,288] {subprocess.py:92} INFO - 22/06/07 06:16:13 INFO TaskSetManager: Finished task 65.0 in stage 0.0 (TID 65) in 55 ms on d952e2b2ede8 (executor driver) (68/180)
[2022-06-07 06:16:13,289] {subprocess.py:92} INFO - 22/06/07 06:16:13 INFO TaskSetManager: Finished task 67.0 in stage 0.0 (TID 67) in 40 ms on d952e2b2ede8 (executor driver) (69/180)
[2022-06-07 06:16:13,292] {subprocess.py:92} INFO - 22/06/07 06:16:13 INFO Executor: Finished task 69.0 in stage 0.0 (TID 69). 2646 bytes result sent to driver
[2022-06-07 06:16:13,293] {subprocess.py:92} INFO - 22/06/07 06:16:13 INFO TaskSetManager: Starting task 73.0 in stage 0.0 (TID 73) (d952e2b2ede8, executor driver, partition 73, PROCESS_LOCAL, 4553 bytes) taskResourceAssignments Map()
[2022-06-07 06:16:13,294] {subprocess.py:92} INFO - 22/06/07 06:16:13 INFO Executor: Running task 73.0 in stage 0.0 (TID 73)
[2022-06-07 06:16:13,295] {subprocess.py:92} INFO - 22/06/07 06:16:13 INFO TaskSetManager: Finished task 69.0 in stage 0.0 (TID 69) in 23 ms on d952e2b2ede8 (executor driver) (70/180)
[2022-06-07 06:16:13,297] {subprocess.py:92} INFO - 22/06/07 06:16:13 INFO Executor: Running task 72.0 in stage 0.0 (TID 72)
[2022-06-07 06:16:13,302] {subprocess.py:92} INFO - 22/06/07 06:16:13 INFO Executor: Finished task 71.0 in stage 0.0 (TID 71). 2646 bytes result sent to driver
[2022-06-07 06:16:13,304] {subprocess.py:92} INFO - 22/06/07 06:16:13 INFO TaskSetManager: Starting task 74.0 in stage 0.0 (TID 74) (d952e2b2ede8, executor driver, partition 74, PROCESS_LOCAL, 4553 bytes) taskResourceAssignments Map()
[2022-06-07 06:16:13,305] {subprocess.py:92} INFO - 22/06/07 06:16:13 INFO Executor: Running task 74.0 in stage 0.0 (TID 74)
[2022-06-07 06:16:13,306] {subprocess.py:92} INFO - 22/06/07 06:16:13 INFO Executor: Finished task 73.0 in stage 0.0 (TID 73). 2646 bytes result sent to driver
[2022-06-07 06:16:13,308] {subprocess.py:92} INFO - 22/06/07 06:16:13 INFO TaskSetManager: Starting task 75.0 in stage 0.0 (TID 75) (d952e2b2ede8, executor driver, partition 75, PROCESS_LOCAL, 4553 bytes) taskResourceAssignments Map()
[2022-06-07 06:16:13,312] {subprocess.py:92} INFO - 22/06/07 06:16:13 INFO TaskSetManager: Finished task 73.0 in stage 0.0 (TID 73) in 15 ms on d952e2b2ede8 (executor driver) (71/180)
[2022-06-07 06:16:13,313] {subprocess.py:92} INFO - 22/06/07 06:16:13 INFO TaskSetManager: Finished task 71.0 in stage 0.0 (TID 71) in 30 ms on d952e2b2ede8 (executor driver) (72/180)
[2022-06-07 06:16:13,315] {subprocess.py:92} INFO - 22/06/07 06:16:13 INFO Executor: Running task 75.0 in stage 0.0 (TID 75)
[2022-06-07 06:16:13,316] {subprocess.py:92} INFO - 22/06/07 06:16:13 INFO Executor: Finished task 74.0 in stage 0.0 (TID 74). 2646 bytes result sent to driver
[2022-06-07 06:16:13,318] {subprocess.py:92} INFO - 22/06/07 06:16:13 INFO TaskSetManager: Starting task 76.0 in stage 0.0 (TID 76) (d952e2b2ede8, executor driver, partition 76, PROCESS_LOCAL, 4553 bytes) taskResourceAssignments Map()
[2022-06-07 06:16:13,319] {subprocess.py:92} INFO - 22/06/07 06:16:13 INFO Executor: Running task 76.0 in stage 0.0 (TID 76)
[2022-06-07 06:16:13,319] {subprocess.py:92} INFO - 22/06/07 06:16:13 INFO TaskSetManager: Finished task 74.0 in stage 0.0 (TID 74) in 15 ms on d952e2b2ede8 (executor driver) (73/180)
[2022-06-07 06:16:13,322] {subprocess.py:92} INFO - 22/06/07 06:16:13 INFO Executor: Finished task 75.0 in stage 0.0 (TID 75). 2646 bytes result sent to driver
[2022-06-07 06:16:13,324] {subprocess.py:92} INFO - 22/06/07 06:16:13 INFO TaskSetManager: Starting task 77.0 in stage 0.0 (TID 77) (d952e2b2ede8, executor driver, partition 77, PROCESS_LOCAL, 4553 bytes) taskResourceAssignments Map()
[2022-06-07 06:16:13,326] {subprocess.py:92} INFO - 22/06/07 06:16:13 INFO TaskSetManager: Finished task 75.0 in stage 0.0 (TID 75) in 18 ms on d952e2b2ede8 (executor driver) (74/180)
[2022-06-07 06:16:13,327] {subprocess.py:92} INFO - 22/06/07 06:16:13 INFO Executor: Running task 77.0 in stage 0.0 (TID 77)
[2022-06-07 06:16:13,329] {subprocess.py:92} INFO - 22/06/07 06:16:13 INFO Executor: Finished task 70.0 in stage 0.0 (TID 70). 2646 bytes result sent to driver
[2022-06-07 06:16:13,331] {subprocess.py:92} INFO - 22/06/07 06:16:13 INFO TaskSetManager: Starting task 78.0 in stage 0.0 (TID 78) (d952e2b2ede8, executor driver, partition 78, PROCESS_LOCAL, 4553 bytes) taskResourceAssignments Map()
[2022-06-07 06:16:13,332] {subprocess.py:92} INFO - 22/06/07 06:16:13 INFO TaskSetManager: Finished task 70.0 in stage 0.0 (TID 70) in 56 ms on d952e2b2ede8 (executor driver) (75/180)
[2022-06-07 06:16:13,334] {subprocess.py:92} INFO - 22/06/07 06:16:13 INFO Executor: Running task 78.0 in stage 0.0 (TID 78)
[2022-06-07 06:16:13,335] {subprocess.py:92} INFO - 22/06/07 06:16:13 INFO Executor: Finished task 76.0 in stage 0.0 (TID 76). 2646 bytes result sent to driver
[2022-06-07 06:16:13,338] {subprocess.py:92} INFO - 22/06/07 06:16:13 INFO TaskSetManager: Starting task 79.0 in stage 0.0 (TID 79) (d952e2b2ede8, executor driver, partition 79, PROCESS_LOCAL, 4553 bytes) taskResourceAssignments Map()
[2022-06-07 06:16:13,339] {subprocess.py:92} INFO - 22/06/07 06:16:13 INFO Executor: Finished task 72.0 in stage 0.0 (TID 72). 2646 bytes result sent to driver
[2022-06-07 06:16:13,341] {subprocess.py:92} INFO - 22/06/07 06:16:13 INFO Executor: Running task 79.0 in stage 0.0 (TID 79)
[2022-06-07 06:16:13,342] {subprocess.py:92} INFO - 22/06/07 06:16:13 INFO TaskSetManager: Finished task 76.0 in stage 0.0 (TID 76) in 22 ms on d952e2b2ede8 (executor driver) (76/180)
[2022-06-07 06:16:13,344] {subprocess.py:92} INFO - 22/06/07 06:16:13 INFO TaskSetManager: Starting task 80.0 in stage 0.0 (TID 80) (d952e2b2ede8, executor driver, partition 80, PROCESS_LOCAL, 4553 bytes) taskResourceAssignments Map()
[2022-06-07 06:16:13,346] {subprocess.py:92} INFO - 22/06/07 06:16:13 INFO TaskSetManager: Finished task 72.0 in stage 0.0 (TID 72) in 62 ms on d952e2b2ede8 (executor driver) (77/180)
[2022-06-07 06:16:13,347] {subprocess.py:92} INFO - 22/06/07 06:16:13 INFO Executor: Running task 80.0 in stage 0.0 (TID 80)
[2022-06-07 06:16:13,356] {subprocess.py:92} INFO - 22/06/07 06:16:13 INFO Executor: Finished task 79.0 in stage 0.0 (TID 79). 2646 bytes result sent to driver
[2022-06-07 06:16:13,357] {subprocess.py:92} INFO - 22/06/07 06:16:13 INFO TaskSetManager: Starting task 81.0 in stage 0.0 (TID 81) (d952e2b2ede8, executor driver, partition 81, PROCESS_LOCAL, 4553 bytes) taskResourceAssignments Map()
[2022-06-07 06:16:13,358] {subprocess.py:92} INFO - 22/06/07 06:16:13 INFO Executor: Finished task 77.0 in stage 0.0 (TID 77). 2646 bytes result sent to driver
[2022-06-07 06:16:13,361] {subprocess.py:92} INFO - 22/06/07 06:16:13 INFO TaskSetManager: Starting task 82.0 in stage 0.0 (TID 82) (d952e2b2ede8, executor driver, partition 82, PROCESS_LOCAL, 4553 bytes) taskResourceAssignments Map()
[2022-06-07 06:16:13,362] {subprocess.py:92} INFO - 22/06/07 06:16:13 INFO Executor: Running task 82.0 in stage 0.0 (TID 82)
[2022-06-07 06:16:13,364] {subprocess.py:92} INFO - 22/06/07 06:16:13 INFO TaskSetManager: Finished task 79.0 in stage 0.0 (TID 79) in 27 ms on d952e2b2ede8 (executor driver) (78/180)
[2022-06-07 06:16:13,365] {subprocess.py:92} INFO - 22/06/07 06:16:13 INFO TaskSetManager: Finished task 77.0 in stage 0.0 (TID 77) in 41 ms on d952e2b2ede8 (executor driver) (79/180)
[2022-06-07 06:16:13,366] {subprocess.py:92} INFO - 22/06/07 06:16:13 INFO Executor: Running task 81.0 in stage 0.0 (TID 81)
[2022-06-07 06:16:13,367] {subprocess.py:92} INFO - 22/06/07 06:16:13 INFO Executor: Finished task 80.0 in stage 0.0 (TID 80). 2646 bytes result sent to driver
[2022-06-07 06:16:13,368] {subprocess.py:92} INFO - 22/06/07 06:16:13 INFO TaskSetManager: Starting task 83.0 in stage 0.0 (TID 83) (d952e2b2ede8, executor driver, partition 83, PROCESS_LOCAL, 4553 bytes) taskResourceAssignments Map()
[2022-06-07 06:16:13,369] {subprocess.py:92} INFO - 22/06/07 06:16:13 INFO Executor: Running task 83.0 in stage 0.0 (TID 83)
[2022-06-07 06:16:13,370] {subprocess.py:92} INFO - 22/06/07 06:16:13 INFO TaskSetManager: Finished task 80.0 in stage 0.0 (TID 80) in 25 ms on d952e2b2ede8 (executor driver) (80/180)
[2022-06-07 06:16:13,372] {subprocess.py:92} INFO - 22/06/07 06:16:13 INFO Executor: Finished task 78.0 in stage 0.0 (TID 78). 2646 bytes result sent to driver
[2022-06-07 06:16:13,374] {subprocess.py:92} INFO - 22/06/07 06:16:13 INFO TaskSetManager: Starting task 84.0 in stage 0.0 (TID 84) (d952e2b2ede8, executor driver, partition 84, PROCESS_LOCAL, 4553 bytes) taskResourceAssignments Map()
[2022-06-07 06:16:13,376] {subprocess.py:92} INFO - 22/06/07 06:16:13 INFO Executor: Running task 84.0 in stage 0.0 (TID 84)
[2022-06-07 06:16:13,377] {subprocess.py:92} INFO - 22/06/07 06:16:13 INFO TaskSetManager: Finished task 78.0 in stage 0.0 (TID 78) in 46 ms on d952e2b2ede8 (executor driver) (81/180)
[2022-06-07 06:16:13,385] {subprocess.py:92} INFO - 22/06/07 06:16:13 INFO Executor: Finished task 82.0 in stage 0.0 (TID 82). 2646 bytes result sent to driver
[2022-06-07 06:16:13,386] {subprocess.py:92} INFO - 22/06/07 06:16:13 INFO Executor: Finished task 83.0 in stage 0.0 (TID 83). 2646 bytes result sent to driver
[2022-06-07 06:16:13,388] {subprocess.py:92} INFO - 22/06/07 06:16:13 INFO Executor: Finished task 84.0 in stage 0.0 (TID 84). 2646 bytes result sent to driver
[2022-06-07 06:16:13,389] {subprocess.py:92} INFO - 22/06/07 06:16:13 INFO TaskSetManager: Starting task 85.0 in stage 0.0 (TID 85) (d952e2b2ede8, executor driver, partition 85, PROCESS_LOCAL, 4553 bytes) taskResourceAssignments Map()
[2022-06-07 06:16:13,390] {subprocess.py:92} INFO - 22/06/07 06:16:13 INFO TaskSetManager: Finished task 82.0 in stage 0.0 (TID 82) in 30 ms on d952e2b2ede8 (executor driver) (82/180)
[2022-06-07 06:16:13,391] {subprocess.py:92} INFO - 22/06/07 06:16:13 INFO Executor: Running task 85.0 in stage 0.0 (TID 85)
[2022-06-07 06:16:13,392] {subprocess.py:92} INFO - 22/06/07 06:16:13 INFO Executor: Finished task 81.0 in stage 0.0 (TID 81). 2646 bytes result sent to driver
[2022-06-07 06:16:13,394] {subprocess.py:92} INFO - 22/06/07 06:16:13 INFO TaskSetManager: Starting task 86.0 in stage 0.0 (TID 86) (d952e2b2ede8, executor driver, partition 86, PROCESS_LOCAL, 4553 bytes) taskResourceAssignments Map()
[2022-06-07 06:16:13,395] {subprocess.py:92} INFO - 22/06/07 06:16:13 INFO Executor: Running task 86.0 in stage 0.0 (TID 86)
[2022-06-07 06:16:13,397] {subprocess.py:92} INFO - 22/06/07 06:16:13 INFO TaskSetManager: Starting task 87.0 in stage 0.0 (TID 87) (d952e2b2ede8, executor driver, partition 87, PROCESS_LOCAL, 4553 bytes) taskResourceAssignments Map()
[2022-06-07 06:16:13,399] {subprocess.py:92} INFO - 22/06/07 06:16:13 INFO Executor: Running task 87.0 in stage 0.0 (TID 87)
[2022-06-07 06:16:13,400] {subprocess.py:92} INFO - 22/06/07 06:16:13 INFO TaskSetManager: Starting task 88.0 in stage 0.0 (TID 88) (d952e2b2ede8, executor driver, partition 88, PROCESS_LOCAL, 4553 bytes) taskResourceAssignments Map()
[2022-06-07 06:16:13,401] {subprocess.py:92} INFO - 22/06/07 06:16:13 INFO TaskSetManager: Finished task 84.0 in stage 0.0 (TID 84) in 28 ms on d952e2b2ede8 (executor driver) (83/180)
[2022-06-07 06:16:13,402] {subprocess.py:92} INFO - 22/06/07 06:16:13 INFO TaskSetManager: Finished task 83.0 in stage 0.0 (TID 83) in 34 ms on d952e2b2ede8 (executor driver) (84/180)
[2022-06-07 06:16:13,403] {subprocess.py:92} INFO - 22/06/07 06:16:13 INFO TaskSetManager: Finished task 81.0 in stage 0.0 (TID 81) in 45 ms on d952e2b2ede8 (executor driver) (85/180)
[2022-06-07 06:16:13,404] {subprocess.py:92} INFO - 22/06/07 06:16:13 INFO Executor: Running task 88.0 in stage 0.0 (TID 88)
[2022-06-07 06:16:13,409] {subprocess.py:92} INFO - 22/06/07 06:16:13 INFO Executor: Finished task 87.0 in stage 0.0 (TID 87). 2646 bytes result sent to driver
[2022-06-07 06:16:13,411] {subprocess.py:92} INFO - 22/06/07 06:16:13 INFO Executor: Finished task 86.0 in stage 0.0 (TID 86). 2646 bytes result sent to driver
[2022-06-07 06:16:13,413] {subprocess.py:92} INFO - 22/06/07 06:16:13 INFO TaskSetManager: Starting task 89.0 in stage 0.0 (TID 89) (d952e2b2ede8, executor driver, partition 89, PROCESS_LOCAL, 4553 bytes) taskResourceAssignments Map()
[2022-06-07 06:16:13,414] {subprocess.py:92} INFO - 22/06/07 06:16:13 INFO Executor: Running task 89.0 in stage 0.0 (TID 89)
[2022-06-07 06:16:13,416] {subprocess.py:92} INFO - 22/06/07 06:16:13 INFO TaskSetManager: Starting task 90.0 in stage 0.0 (TID 90) (d952e2b2ede8, executor driver, partition 90, PROCESS_LOCAL, 4553 bytes) taskResourceAssignments Map()
[2022-06-07 06:16:13,417] {subprocess.py:92} INFO - 22/06/07 06:16:13 INFO TaskSetManager: Finished task 87.0 in stage 0.0 (TID 87) in 21 ms on d952e2b2ede8 (executor driver) (86/180)
[2022-06-07 06:16:13,418] {subprocess.py:92} INFO - 22/06/07 06:16:13 INFO Executor: Running task 90.0 in stage 0.0 (TID 90)
[2022-06-07 06:16:13,419] {subprocess.py:92} INFO - 22/06/07 06:16:13 INFO TaskSetManager: Finished task 86.0 in stage 0.0 (TID 86) in 27 ms on d952e2b2ede8 (executor driver) (87/180)
[2022-06-07 06:16:13,419] {subprocess.py:92} INFO - 22/06/07 06:16:13 INFO Executor: Finished task 88.0 in stage 0.0 (TID 88). 2689 bytes result sent to driver
[2022-06-07 06:16:13,426] {subprocess.py:92} INFO - 22/06/07 06:16:13 INFO TaskSetManager: Starting task 91.0 in stage 0.0 (TID 91) (d952e2b2ede8, executor driver, partition 91, PROCESS_LOCAL, 4553 bytes) taskResourceAssignments Map()
[2022-06-07 06:16:13,428] {subprocess.py:92} INFO - 22/06/07 06:16:13 INFO Executor: Running task 91.0 in stage 0.0 (TID 91)
[2022-06-07 06:16:13,429] {subprocess.py:92} INFO - 22/06/07 06:16:13 INFO TaskSetManager: Finished task 88.0 in stage 0.0 (TID 88) in 28 ms on d952e2b2ede8 (executor driver) (88/180)
[2022-06-07 06:16:13,429] {subprocess.py:92} INFO - 22/06/07 06:16:13 INFO Executor: Finished task 90.0 in stage 0.0 (TID 90). 2646 bytes result sent to driver
[2022-06-07 06:16:13,431] {subprocess.py:92} INFO - 22/06/07 06:16:13 INFO TaskSetManager: Starting task 92.0 in stage 0.0 (TID 92) (d952e2b2ede8, executor driver, partition 92, PROCESS_LOCAL, 4553 bytes) taskResourceAssignments Map()
[2022-06-07 06:16:13,433] {subprocess.py:92} INFO - 22/06/07 06:16:13 INFO TaskSetManager: Finished task 90.0 in stage 0.0 (TID 90) in 17 ms on d952e2b2ede8 (executor driver) (89/180)
[2022-06-07 06:16:13,434] {subprocess.py:92} INFO - 22/06/07 06:16:13 INFO Executor: Running task 92.0 in stage 0.0 (TID 92)
[2022-06-07 06:16:13,435] {subprocess.py:92} INFO - 22/06/07 06:16:13 INFO Executor: Finished task 85.0 in stage 0.0 (TID 85). 2646 bytes result sent to driver
[2022-06-07 06:16:13,436] {subprocess.py:92} INFO - 22/06/07 06:16:13 INFO TaskSetManager: Starting task 93.0 in stage 0.0 (TID 93) (d952e2b2ede8, executor driver, partition 93, PROCESS_LOCAL, 4553 bytes) taskResourceAssignments Map()
[2022-06-07 06:16:13,437] {subprocess.py:92} INFO - 22/06/07 06:16:13 INFO TaskSetManager: Finished task 85.0 in stage 0.0 (TID 85) in 49 ms on d952e2b2ede8 (executor driver) (90/180)
[2022-06-07 06:16:13,438] {subprocess.py:92} INFO - 22/06/07 06:16:13 INFO Executor: Running task 93.0 in stage 0.0 (TID 93)
[2022-06-07 06:16:13,445] {subprocess.py:92} INFO - 22/06/07 06:16:13 INFO Executor: Finished task 91.0 in stage 0.0 (TID 91). 2646 bytes result sent to driver
[2022-06-07 06:16:13,447] {subprocess.py:92} INFO - 22/06/07 06:16:13 INFO TaskSetManager: Starting task 94.0 in stage 0.0 (TID 94) (d952e2b2ede8, executor driver, partition 94, PROCESS_LOCAL, 4553 bytes) taskResourceAssignments Map()
[2022-06-07 06:16:13,449] {subprocess.py:92} INFO - 22/06/07 06:16:13 INFO Executor: Running task 94.0 in stage 0.0 (TID 94)
[2022-06-07 06:16:13,449] {subprocess.py:92} INFO - 22/06/07 06:16:13 INFO TaskSetManager: Finished task 91.0 in stage 0.0 (TID 91) in 23 ms on d952e2b2ede8 (executor driver) (91/180)
[2022-06-07 06:16:13,455] {subprocess.py:92} INFO - 22/06/07 06:16:13 INFO Executor: Finished task 89.0 in stage 0.0 (TID 89). 2646 bytes result sent to driver
[2022-06-07 06:16:13,456] {subprocess.py:92} INFO - 22/06/07 06:16:13 INFO Executor: Finished task 93.0 in stage 0.0 (TID 93). 2646 bytes result sent to driver
[2022-06-07 06:16:13,457] {subprocess.py:92} INFO - 22/06/07 06:16:13 INFO TaskSetManager: Starting task 95.0 in stage 0.0 (TID 95) (d952e2b2ede8, executor driver, partition 95, PROCESS_LOCAL, 4553 bytes) taskResourceAssignments Map()
[2022-06-07 06:16:13,458] {subprocess.py:92} INFO - 22/06/07 06:16:13 INFO Executor: Running task 95.0 in stage 0.0 (TID 95)
[2022-06-07 06:16:13,458] {subprocess.py:92} INFO - 22/06/07 06:16:13 INFO TaskSetManager: Starting task 96.0 in stage 0.0 (TID 96) (d952e2b2ede8, executor driver, partition 96, PROCESS_LOCAL, 4553 bytes) taskResourceAssignments Map()
[2022-06-07 06:16:13,459] {subprocess.py:92} INFO - 22/06/07 06:16:13 INFO TaskSetManager: Finished task 93.0 in stage 0.0 (TID 93) in 22 ms on d952e2b2ede8 (executor driver) (92/180)
[2022-06-07 06:16:13,460] {subprocess.py:92} INFO - 22/06/07 06:16:13 INFO Executor: Running task 96.0 in stage 0.0 (TID 96)
[2022-06-07 06:16:13,461] {subprocess.py:92} INFO - 22/06/07 06:16:13 INFO TaskSetManager: Finished task 89.0 in stage 0.0 (TID 89) in 47 ms on d952e2b2ede8 (executor driver) (93/180)
[2022-06-07 06:16:13,465] {subprocess.py:92} INFO - 22/06/07 06:16:13 INFO Executor: Finished task 92.0 in stage 0.0 (TID 92). 2646 bytes result sent to driver
[2022-06-07 06:16:13,475] {subprocess.py:92} INFO - 22/06/07 06:16:13 INFO Executor: Finished task 94.0 in stage 0.0 (TID 94). 2646 bytes result sent to driver
[2022-06-07 06:16:13,478] {subprocess.py:92} INFO - 22/06/07 06:16:13 INFO TaskSetManager: Starting task 97.0 in stage 0.0 (TID 97) (d952e2b2ede8, executor driver, partition 97, PROCESS_LOCAL, 4553 bytes) taskResourceAssignments Map()
[2022-06-07 06:16:13,479] {subprocess.py:92} INFO - 22/06/07 06:16:13 INFO Executor: Finished task 95.0 in stage 0.0 (TID 95). 2646 bytes result sent to driver
[2022-06-07 06:16:13,480] {subprocess.py:92} INFO - 22/06/07 06:16:13 INFO Executor: Running task 97.0 in stage 0.0 (TID 97)
[2022-06-07 06:16:13,482] {subprocess.py:92} INFO - 22/06/07 06:16:13 INFO TaskSetManager: Starting task 98.0 in stage 0.0 (TID 98) (d952e2b2ede8, executor driver, partition 98, PROCESS_LOCAL, 4553 bytes) taskResourceAssignments Map()
[2022-06-07 06:16:13,484] {subprocess.py:92} INFO - 22/06/07 06:16:13 INFO Executor: Running task 98.0 in stage 0.0 (TID 98)
[2022-06-07 06:16:13,485] {subprocess.py:92} INFO - 22/06/07 06:16:13 INFO TaskSetManager: Starting task 99.0 in stage 0.0 (TID 99) (d952e2b2ede8, executor driver, partition 99, PROCESS_LOCAL, 4553 bytes) taskResourceAssignments Map()
[2022-06-07 06:16:13,487] {subprocess.py:92} INFO - 22/06/07 06:16:13 INFO TaskSetManager: Finished task 94.0 in stage 0.0 (TID 94) in 40 ms on d952e2b2ede8 (executor driver) (94/180)
[2022-06-07 06:16:13,490] {subprocess.py:92} INFO - 22/06/07 06:16:13 INFO Executor: Running task 99.0 in stage 0.0 (TID 99)
[2022-06-07 06:16:13,491] {subprocess.py:92} INFO - 22/06/07 06:16:13 INFO TaskSetManager: Finished task 92.0 in stage 0.0 (TID 92) in 56 ms on d952e2b2ede8 (executor driver) (95/180)
[2022-06-07 06:16:13,492] {subprocess.py:92} INFO - 22/06/07 06:16:13 INFO TaskSetManager: Finished task 95.0 in stage 0.0 (TID 95) in 32 ms on d952e2b2ede8 (executor driver) (96/180)
[2022-06-07 06:16:13,493] {subprocess.py:92} INFO - 22/06/07 06:16:13 INFO Executor: Finished task 96.0 in stage 0.0 (TID 96). 2689 bytes result sent to driver
[2022-06-07 06:16:13,497] {subprocess.py:92} INFO - 22/06/07 06:16:13 INFO TaskSetManager: Finished task 96.0 in stage 0.0 (TID 96) in 39 ms on d952e2b2ede8 (executor driver) (97/180)
[2022-06-07 06:16:13,500] {subprocess.py:92} INFO - 22/06/07 06:16:13 INFO TaskSetManager: Starting task 100.0 in stage 0.0 (TID 100) (d952e2b2ede8, executor driver, partition 100, PROCESS_LOCAL, 4553 bytes) taskResourceAssignments Map()
[2022-06-07 06:16:13,503] {subprocess.py:92} INFO - 22/06/07 06:16:13 INFO Executor: Finished task 98.0 in stage 0.0 (TID 98). 2646 bytes result sent to driver
[2022-06-07 06:16:13,507] {subprocess.py:92} INFO - 22/06/07 06:16:13 INFO Executor: Running task 100.0 in stage 0.0 (TID 100)
[2022-06-07 06:16:13,508] {subprocess.py:92} INFO - 22/06/07 06:16:13 INFO TaskSetManager: Starting task 101.0 in stage 0.0 (TID 101) (d952e2b2ede8, executor driver, partition 101, PROCESS_LOCAL, 4553 bytes) taskResourceAssignments Map()
[2022-06-07 06:16:13,509] {subprocess.py:92} INFO - 22/06/07 06:16:13 INFO Executor: Running task 101.0 in stage 0.0 (TID 101)
[2022-06-07 06:16:13,510] {subprocess.py:92} INFO - 22/06/07 06:16:13 INFO TaskSetManager: Finished task 98.0 in stage 0.0 (TID 98) in 25 ms on d952e2b2ede8 (executor driver) (98/180)
[2022-06-07 06:16:13,511] {subprocess.py:92} INFO - 22/06/07 06:16:13 INFO Executor: Finished task 97.0 in stage 0.0 (TID 97). 2646 bytes result sent to driver
[2022-06-07 06:16:13,512] {subprocess.py:92} INFO - 22/06/07 06:16:13 INFO Executor: Finished task 99.0 in stage 0.0 (TID 99). 2646 bytes result sent to driver
[2022-06-07 06:16:13,514] {subprocess.py:92} INFO - 22/06/07 06:16:13 INFO TaskSetManager: Starting task 102.0 in stage 0.0 (TID 102) (d952e2b2ede8, executor driver, partition 102, PROCESS_LOCAL, 4553 bytes) taskResourceAssignments Map()
[2022-06-07 06:16:13,514] {subprocess.py:92} INFO - 22/06/07 06:16:13 INFO Executor: Running task 102.0 in stage 0.0 (TID 102)
[2022-06-07 06:16:13,518] {subprocess.py:92} INFO - 22/06/07 06:16:13 INFO TaskSetManager: Finished task 97.0 in stage 0.0 (TID 97) in 38 ms on d952e2b2ede8 (executor driver) (99/180)
[2022-06-07 06:16:13,519] {subprocess.py:92} INFO - 22/06/07 06:16:13 INFO TaskSetManager: Starting task 103.0 in stage 0.0 (TID 103) (d952e2b2ede8, executor driver, partition 103, PROCESS_LOCAL, 4553 bytes) taskResourceAssignments Map()
[2022-06-07 06:16:13,520] {subprocess.py:92} INFO - 22/06/07 06:16:13 INFO TaskSetManager: Finished task 99.0 in stage 0.0 (TID 99) in 36 ms on d952e2b2ede8 (executor driver) (100/180)
[2022-06-07 06:16:13,522] {subprocess.py:92} INFO - 22/06/07 06:16:13 INFO Executor: Running task 103.0 in stage 0.0 (TID 103)
[2022-06-07 06:16:13,536] {subprocess.py:92} INFO - 22/06/07 06:16:13 INFO Executor: Finished task 100.0 in stage 0.0 (TID 100). 2646 bytes result sent to driver
[2022-06-07 06:16:13,538] {subprocess.py:92} INFO - 22/06/07 06:16:13 INFO Executor: Finished task 102.0 in stage 0.0 (TID 102). 2646 bytes result sent to driver
[2022-06-07 06:16:13,542] {subprocess.py:92} INFO - 22/06/07 06:16:13 INFO TaskSetManager: Starting task 104.0 in stage 0.0 (TID 104) (d952e2b2ede8, executor driver, partition 104, PROCESS_LOCAL, 4553 bytes) taskResourceAssignments Map()
[2022-06-07 06:16:13,543] {subprocess.py:92} INFO - 22/06/07 06:16:13 INFO Executor: Finished task 101.0 in stage 0.0 (TID 101). 2646 bytes result sent to driver
[2022-06-07 06:16:13,544] {subprocess.py:92} INFO - 22/06/07 06:16:13 INFO TaskSetManager: Finished task 100.0 in stage 0.0 (TID 100) in 46 ms on d952e2b2ede8 (executor driver) (101/180)
[2022-06-07 06:16:13,546] {subprocess.py:92} INFO - 22/06/07 06:16:13 INFO Executor: Running task 104.0 in stage 0.0 (TID 104)
[2022-06-07 06:16:13,548] {subprocess.py:92} INFO - 22/06/07 06:16:13 INFO TaskSetManager: Starting task 105.0 in stage 0.0 (TID 105) (d952e2b2ede8, executor driver, partition 105, PROCESS_LOCAL, 4553 bytes) taskResourceAssignments Map()
[2022-06-07 06:16:13,550] {subprocess.py:92} INFO - 22/06/07 06:16:13 INFO TaskSetManager: Finished task 102.0 in stage 0.0 (TID 102) in 35 ms on d952e2b2ede8 (executor driver) (102/180)
[2022-06-07 06:16:13,550] {subprocess.py:92} INFO - 22/06/07 06:16:13 INFO Executor: Running task 105.0 in stage 0.0 (TID 105)
[2022-06-07 06:16:13,551] {subprocess.py:92} INFO - 22/06/07 06:16:13 INFO TaskSetManager: Starting task 106.0 in stage 0.0 (TID 106) (d952e2b2ede8, executor driver, partition 106, PROCESS_LOCAL, 4553 bytes) taskResourceAssignments Map()
[2022-06-07 06:16:13,552] {subprocess.py:92} INFO - 22/06/07 06:16:13 INFO Executor: Finished task 103.0 in stage 0.0 (TID 103). 2646 bytes result sent to driver
[2022-06-07 06:16:13,553] {subprocess.py:92} INFO - 22/06/07 06:16:13 INFO TaskSetManager: Finished task 101.0 in stage 0.0 (TID 101) in 46 ms on d952e2b2ede8 (executor driver) (103/180)
[2022-06-07 06:16:13,554] {subprocess.py:92} INFO - 22/06/07 06:16:13 INFO Executor: Running task 106.0 in stage 0.0 (TID 106)
[2022-06-07 06:16:13,560] {subprocess.py:92} INFO - 22/06/07 06:16:13 INFO TaskSetManager: Starting task 107.0 in stage 0.0 (TID 107) (d952e2b2ede8, executor driver, partition 107, PROCESS_LOCAL, 4553 bytes) taskResourceAssignments Map()
[2022-06-07 06:16:13,562] {subprocess.py:92} INFO - 22/06/07 06:16:13 INFO TaskSetManager: Finished task 103.0 in stage 0.0 (TID 103) in 45 ms on d952e2b2ede8 (executor driver) (104/180)
[2022-06-07 06:16:13,563] {subprocess.py:92} INFO - 22/06/07 06:16:13 INFO Executor: Running task 107.0 in stage 0.0 (TID 107)
[2022-06-07 06:16:13,572] {subprocess.py:92} INFO - 22/06/07 06:16:13 INFO Executor: Finished task 106.0 in stage 0.0 (TID 106). 2646 bytes result sent to driver
[2022-06-07 06:16:13,574] {subprocess.py:92} INFO - 22/06/07 06:16:13 INFO TaskSetManager: Starting task 108.0 in stage 0.0 (TID 108) (d952e2b2ede8, executor driver, partition 108, PROCESS_LOCAL, 4553 bytes) taskResourceAssignments Map()
[2022-06-07 06:16:13,575] {subprocess.py:92} INFO - 22/06/07 06:16:13 INFO Executor: Running task 108.0 in stage 0.0 (TID 108)
[2022-06-07 06:16:13,578] {subprocess.py:92} INFO - 22/06/07 06:16:13 INFO TaskSetManager: Finished task 106.0 in stage 0.0 (TID 106) in 29 ms on d952e2b2ede8 (executor driver) (105/180)
[2022-06-07 06:16:13,581] {subprocess.py:92} INFO - 22/06/07 06:16:13 INFO Executor: Finished task 105.0 in stage 0.0 (TID 105). 2646 bytes result sent to driver
[2022-06-07 06:16:13,583] {subprocess.py:92} INFO - 22/06/07 06:16:13 INFO Executor: Finished task 104.0 in stage 0.0 (TID 104). 2646 bytes result sent to driver
[2022-06-07 06:16:13,590] {subprocess.py:92} INFO - 22/06/07 06:16:13 INFO TaskSetManager: Starting task 109.0 in stage 0.0 (TID 109) (d952e2b2ede8, executor driver, partition 109, PROCESS_LOCAL, 4553 bytes) taskResourceAssignments Map()
[2022-06-07 06:16:13,591] {subprocess.py:92} INFO - 22/06/07 06:16:13 INFO Executor: Running task 109.0 in stage 0.0 (TID 109)
[2022-06-07 06:16:13,592] {subprocess.py:92} INFO - 22/06/07 06:16:13 INFO TaskSetManager: Finished task 105.0 in stage 0.0 (TID 105) in 44 ms on d952e2b2ede8 (executor driver) (106/180)
[2022-06-07 06:16:13,596] {subprocess.py:92} INFO - 22/06/07 06:16:13 INFO Executor: Finished task 108.0 in stage 0.0 (TID 108). 2646 bytes result sent to driver
[2022-06-07 06:16:13,597] {subprocess.py:92} INFO - 22/06/07 06:16:13 INFO TaskSetManager: Starting task 110.0 in stage 0.0 (TID 110) (d952e2b2ede8, executor driver, partition 110, PROCESS_LOCAL, 4553 bytes) taskResourceAssignments Map()
[2022-06-07 06:16:13,599] {subprocess.py:92} INFO - 22/06/07 06:16:13 INFO Executor: Running task 110.0 in stage 0.0 (TID 110)
[2022-06-07 06:16:13,600] {subprocess.py:92} INFO - 22/06/07 06:16:13 INFO TaskSetManager: Starting task 111.0 in stage 0.0 (TID 111) (d952e2b2ede8, executor driver, partition 111, PROCESS_LOCAL, 4553 bytes) taskResourceAssignments Map()
[2022-06-07 06:16:13,601] {subprocess.py:92} INFO - 22/06/07 06:16:13 INFO TaskSetManager: Finished task 104.0 in stage 0.0 (TID 104) in 60 ms on d952e2b2ede8 (executor driver) (107/180)
[2022-06-07 06:16:13,602] {subprocess.py:92} INFO - 22/06/07 06:16:13 INFO TaskSetManager: Finished task 108.0 in stage 0.0 (TID 108) in 29 ms on d952e2b2ede8 (executor driver) (108/180)
[2022-06-07 06:16:13,603] {subprocess.py:92} INFO - 22/06/07 06:16:13 INFO Executor: Finished task 107.0 in stage 0.0 (TID 107). 2646 bytes result sent to driver
[2022-06-07 06:16:13,603] {subprocess.py:92} INFO - 22/06/07 06:16:13 INFO Executor: Running task 111.0 in stage 0.0 (TID 111)
[2022-06-07 06:16:13,610] {subprocess.py:92} INFO - 22/06/07 06:16:13 INFO TaskSetManager: Starting task 112.0 in stage 0.0 (TID 112) (d952e2b2ede8, executor driver, partition 112, PROCESS_LOCAL, 4553 bytes) taskResourceAssignments Map()
[2022-06-07 06:16:13,612] {subprocess.py:92} INFO - 22/06/07 06:16:13 INFO Executor: Finished task 110.0 in stage 0.0 (TID 110). 2646 bytes result sent to driver
[2022-06-07 06:16:13,613] {subprocess.py:92} INFO - 22/06/07 06:16:13 INFO TaskSetManager: Finished task 107.0 in stage 0.0 (TID 107) in 52 ms on d952e2b2ede8 (executor driver) (109/180)
[2022-06-07 06:16:13,614] {subprocess.py:92} INFO - 22/06/07 06:16:13 INFO TaskSetManager: Starting task 113.0 in stage 0.0 (TID 113) (d952e2b2ede8, executor driver, partition 113, PROCESS_LOCAL, 4553 bytes) taskResourceAssignments Map()
[2022-06-07 06:16:13,616] {subprocess.py:92} INFO - 22/06/07 06:16:13 INFO Executor: Running task 112.0 in stage 0.0 (TID 112)
[2022-06-07 06:16:13,617] {subprocess.py:92} INFO - 22/06/07 06:16:13 INFO TaskSetManager: Finished task 110.0 in stage 0.0 (TID 110) in 18 ms on d952e2b2ede8 (executor driver) (110/180)
[2022-06-07 06:16:13,617] {subprocess.py:92} INFO - 22/06/07 06:16:13 INFO Executor: Running task 113.0 in stage 0.0 (TID 113)
[2022-06-07 06:16:13,618] {subprocess.py:92} INFO - 22/06/07 06:16:13 INFO Executor: Finished task 111.0 in stage 0.0 (TID 111). 2646 bytes result sent to driver
[2022-06-07 06:16:13,625] {subprocess.py:92} INFO - 22/06/07 06:16:13 INFO TaskSetManager: Starting task 114.0 in stage 0.0 (TID 114) (d952e2b2ede8, executor driver, partition 114, PROCESS_LOCAL, 4553 bytes) taskResourceAssignments Map()
[2022-06-07 06:16:13,627] {subprocess.py:92} INFO - 22/06/07 06:16:13 INFO Executor: Finished task 109.0 in stage 0.0 (TID 109). 2646 bytes result sent to driver
[2022-06-07 06:16:13,627] {subprocess.py:92} INFO - 22/06/07 06:16:13 INFO TaskSetManager: Finished task 111.0 in stage 0.0 (TID 111) in 26 ms on d952e2b2ede8 (executor driver) (111/180)
[2022-06-07 06:16:13,628] {subprocess.py:92} INFO - 22/06/07 06:16:13 INFO TaskSetManager: Starting task 115.0 in stage 0.0 (TID 115) (d952e2b2ede8, executor driver, partition 115, PROCESS_LOCAL, 4553 bytes) taskResourceAssignments Map()
[2022-06-07 06:16:13,629] {subprocess.py:92} INFO - 22/06/07 06:16:13 INFO Executor: Running task 114.0 in stage 0.0 (TID 114)
[2022-06-07 06:16:13,630] {subprocess.py:92} INFO - 22/06/07 06:16:13 INFO Executor: Finished task 113.0 in stage 0.0 (TID 113). 2646 bytes result sent to driver
[2022-06-07 06:16:13,631] {subprocess.py:92} INFO - 22/06/07 06:16:13 INFO TaskSetManager: Finished task 109.0 in stage 0.0 (TID 109) in 43 ms on d952e2b2ede8 (executor driver) (112/180)
[2022-06-07 06:16:13,631] {subprocess.py:92} INFO - 22/06/07 06:16:13 INFO TaskSetManager: Starting task 116.0 in stage 0.0 (TID 116) (d952e2b2ede8, executor driver, partition 116, PROCESS_LOCAL, 4553 bytes) taskResourceAssignments Map()
[2022-06-07 06:16:13,632] {subprocess.py:92} INFO - 22/06/07 06:16:13 INFO Executor: Running task 116.0 in stage 0.0 (TID 116)
[2022-06-07 06:16:13,633] {subprocess.py:92} INFO - 22/06/07 06:16:13 INFO TaskSetManager: Finished task 113.0 in stage 0.0 (TID 113) in 19 ms on d952e2b2ede8 (executor driver) (113/180)
[2022-06-07 06:16:13,635] {subprocess.py:92} INFO - 22/06/07 06:16:13 INFO Executor: Running task 115.0 in stage 0.0 (TID 115)
[2022-06-07 06:16:13,639] {subprocess.py:92} INFO - 22/06/07 06:16:13 INFO Executor: Finished task 112.0 in stage 0.0 (TID 112). 2646 bytes result sent to driver
[2022-06-07 06:16:13,643] {subprocess.py:92} INFO - 22/06/07 06:16:13 INFO TaskSetManager: Starting task 117.0 in stage 0.0 (TID 117) (d952e2b2ede8, executor driver, partition 117, PROCESS_LOCAL, 4553 bytes) taskResourceAssignments Map()
[2022-06-07 06:16:13,645] {subprocess.py:92} INFO - 22/06/07 06:16:13 INFO TaskSetManager: Finished task 112.0 in stage 0.0 (TID 112) in 36 ms on d952e2b2ede8 (executor driver) (114/180)
[2022-06-07 06:16:13,646] {subprocess.py:92} INFO - 22/06/07 06:16:13 INFO Executor: Running task 117.0 in stage 0.0 (TID 117)
[2022-06-07 06:16:13,649] {subprocess.py:92} INFO - 22/06/07 06:16:13 INFO Executor: Finished task 116.0 in stage 0.0 (TID 116). 2646 bytes result sent to driver
[2022-06-07 06:16:13,651] {subprocess.py:92} INFO - 22/06/07 06:16:13 INFO TaskSetManager: Starting task 118.0 in stage 0.0 (TID 118) (d952e2b2ede8, executor driver, partition 118, PROCESS_LOCAL, 4553 bytes) taskResourceAssignments Map()
[2022-06-07 06:16:13,652] {subprocess.py:92} INFO - 22/06/07 06:16:13 INFO TaskSetManager: Finished task 116.0 in stage 0.0 (TID 116) in 21 ms on d952e2b2ede8 (executor driver) (115/180)
[2022-06-07 06:16:13,653] {subprocess.py:92} INFO - 22/06/07 06:16:13 INFO Executor: Running task 118.0 in stage 0.0 (TID 118)
[2022-06-07 06:16:13,654] {subprocess.py:92} INFO - 22/06/07 06:16:13 INFO Executor: Finished task 115.0 in stage 0.0 (TID 115). 2646 bytes result sent to driver
[2022-06-07 06:16:13,656] {subprocess.py:92} INFO - 22/06/07 06:16:13 INFO TaskSetManager: Starting task 119.0 in stage 0.0 (TID 119) (d952e2b2ede8, executor driver, partition 119, PROCESS_LOCAL, 4553 bytes) taskResourceAssignments Map()
[2022-06-07 06:16:13,657] {subprocess.py:92} INFO - 22/06/07 06:16:13 INFO Executor: Finished task 114.0 in stage 0.0 (TID 114). 2646 bytes result sent to driver
[2022-06-07 06:16:13,658] {subprocess.py:92} INFO - 22/06/07 06:16:13 INFO Executor: Running task 119.0 in stage 0.0 (TID 119)
[2022-06-07 06:16:13,659] {subprocess.py:92} INFO - 22/06/07 06:16:13 INFO TaskSetManager: Finished task 115.0 in stage 0.0 (TID 115) in 30 ms on d952e2b2ede8 (executor driver) (116/180)
[2022-06-07 06:16:13,660] {subprocess.py:92} INFO - 22/06/07 06:16:13 INFO TaskSetManager: Starting task 120.0 in stage 0.0 (TID 120) (d952e2b2ede8, executor driver, partition 120, PROCESS_LOCAL, 4553 bytes) taskResourceAssignments Map()
[2022-06-07 06:16:13,661] {subprocess.py:92} INFO - 22/06/07 06:16:13 INFO Executor: Running task 120.0 in stage 0.0 (TID 120)
[2022-06-07 06:16:13,664] {subprocess.py:92} INFO - 22/06/07 06:16:13 INFO TaskSetManager: Finished task 114.0 in stage 0.0 (TID 114) in 39 ms on d952e2b2ede8 (executor driver) (117/180)
[2022-06-07 06:16:13,670] {subprocess.py:92} INFO - 22/06/07 06:16:13 INFO Executor: Finished task 117.0 in stage 0.0 (TID 117). 2646 bytes result sent to driver
[2022-06-07 06:16:13,673] {subprocess.py:92} INFO - 22/06/07 06:16:13 INFO Executor: Finished task 118.0 in stage 0.0 (TID 118). 2646 bytes result sent to driver
[2022-06-07 06:16:13,675] {subprocess.py:92} INFO - 22/06/07 06:16:13 INFO TaskSetManager: Starting task 121.0 in stage 0.0 (TID 121) (d952e2b2ede8, executor driver, partition 121, PROCESS_LOCAL, 4553 bytes) taskResourceAssignments Map()
[2022-06-07 06:16:13,676] {subprocess.py:92} INFO - 22/06/07 06:16:13 INFO TaskSetManager: Finished task 117.0 in stage 0.0 (TID 117) in 36 ms on d952e2b2ede8 (executor driver) (118/180)
[2022-06-07 06:16:13,676] {subprocess.py:92} INFO - 22/06/07 06:16:13 INFO Executor: Running task 121.0 in stage 0.0 (TID 121)
[2022-06-07 06:16:13,677] {subprocess.py:92} INFO - 22/06/07 06:16:13 INFO Executor: Finished task 119.0 in stage 0.0 (TID 119). 2646 bytes result sent to driver
[2022-06-07 06:16:13,679] {subprocess.py:92} INFO - 22/06/07 06:16:13 INFO TaskSetManager: Starting task 122.0 in stage 0.0 (TID 122) (d952e2b2ede8, executor driver, partition 122, PROCESS_LOCAL, 4553 bytes) taskResourceAssignments Map()
[2022-06-07 06:16:13,680] {subprocess.py:92} INFO - 22/06/07 06:16:13 INFO Executor: Running task 122.0 in stage 0.0 (TID 122)
[2022-06-07 06:16:13,680] {subprocess.py:92} INFO - 22/06/07 06:16:13 INFO TaskSetManager: Finished task 119.0 in stage 0.0 (TID 119) in 24 ms on d952e2b2ede8 (executor driver) (119/180)
[2022-06-07 06:16:13,687] {subprocess.py:92} INFO - 22/06/07 06:16:13 INFO TaskSetManager: Starting task 123.0 in stage 0.0 (TID 123) (d952e2b2ede8, executor driver, partition 123, PROCESS_LOCAL, 4553 bytes) taskResourceAssignments Map()
[2022-06-07 06:16:13,688] {subprocess.py:92} INFO - 22/06/07 06:16:13 INFO TaskSetManager: Finished task 118.0 in stage 0.0 (TID 118) in 37 ms on d952e2b2ede8 (executor driver) (120/180)
[2022-06-07 06:16:13,689] {subprocess.py:92} INFO - 22/06/07 06:16:13 INFO Executor: Running task 123.0 in stage 0.0 (TID 123)
[2022-06-07 06:16:13,693] {subprocess.py:92} INFO - 22/06/07 06:16:13 INFO Executor: Finished task 122.0 in stage 0.0 (TID 122). 2646 bytes result sent to driver
[2022-06-07 06:16:13,694] {subprocess.py:92} INFO - 22/06/07 06:16:13 INFO Executor: Finished task 120.0 in stage 0.0 (TID 120). 2646 bytes result sent to driver
[2022-06-07 06:16:13,695] {subprocess.py:92} INFO - 22/06/07 06:16:13 INFO TaskSetManager: Starting task 124.0 in stage 0.0 (TID 124) (d952e2b2ede8, executor driver, partition 124, PROCESS_LOCAL, 4553 bytes) taskResourceAssignments Map()
[2022-06-07 06:16:13,696] {subprocess.py:92} INFO - 22/06/07 06:16:13 INFO TaskSetManager: Finished task 122.0 in stage 0.0 (TID 122) in 17 ms on d952e2b2ede8 (executor driver) (121/180)
[2022-06-07 06:16:13,697] {subprocess.py:92} INFO - 22/06/07 06:16:13 INFO Executor: Running task 124.0 in stage 0.0 (TID 124)
[2022-06-07 06:16:13,697] {subprocess.py:92} INFO - 22/06/07 06:16:13 INFO TaskSetManager: Finished task 120.0 in stage 0.0 (TID 120) in 37 ms on d952e2b2ede8 (executor driver) (122/180)
[2022-06-07 06:16:13,698] {subprocess.py:92} INFO - 22/06/07 06:16:13 INFO TaskSetManager: Starting task 125.0 in stage 0.0 (TID 125) (d952e2b2ede8, executor driver, partition 125, PROCESS_LOCAL, 4553 bytes) taskResourceAssignments Map()
[2022-06-07 06:16:13,700] {subprocess.py:92} INFO - 22/06/07 06:16:13 INFO Executor: Running task 125.0 in stage 0.0 (TID 125)
[2022-06-07 06:16:13,701] {subprocess.py:92} INFO - 22/06/07 06:16:13 INFO Executor: Finished task 121.0 in stage 0.0 (TID 121). 2646 bytes result sent to driver
[2022-06-07 06:16:13,702] {subprocess.py:92} INFO - 22/06/07 06:16:13 INFO TaskSetManager: Finished task 121.0 in stage 0.0 (TID 121) in 28 ms on d952e2b2ede8 (executor driver) (123/180)
[2022-06-07 06:16:13,709] {subprocess.py:92} INFO - 22/06/07 06:16:13 INFO TaskSetManager: Starting task 126.0 in stage 0.0 (TID 126) (d952e2b2ede8, executor driver, partition 126, PROCESS_LOCAL, 4553 bytes) taskResourceAssignments Map()
[2022-06-07 06:16:13,710] {subprocess.py:92} INFO - 22/06/07 06:16:13 INFO Executor: Running task 126.0 in stage 0.0 (TID 126)
[2022-06-07 06:16:13,719] {subprocess.py:92} INFO - 22/06/07 06:16:13 INFO Executor: Finished task 126.0 in stage 0.0 (TID 126). 2646 bytes result sent to driver
[2022-06-07 06:16:13,720] {subprocess.py:92} INFO - 22/06/07 06:16:13 INFO TaskSetManager: Starting task 127.0 in stage 0.0 (TID 127) (d952e2b2ede8, executor driver, partition 127, PROCESS_LOCAL, 4553 bytes) taskResourceAssignments Map()
[2022-06-07 06:16:13,722] {subprocess.py:92} INFO - 22/06/07 06:16:13 INFO Executor: Running task 127.0 in stage 0.0 (TID 127)
[2022-06-07 06:16:13,724] {subprocess.py:92} INFO - 22/06/07 06:16:13 INFO TaskSetManager: Finished task 126.0 in stage 0.0 (TID 126) in 13 ms on d952e2b2ede8 (executor driver) (124/180)
