[2022-06-08 05:21:41,000] {taskinstance.py:1159} INFO - Dependencies all met for <TaskInstance: hands_on_test.generate_sql_requirement scheduled__2022-06-07T00:00:00+00:00 [queued]>
[2022-06-08 05:21:41,019] {taskinstance.py:1159} INFO - Dependencies all met for <TaskInstance: hands_on_test.generate_sql_requirement scheduled__2022-06-07T00:00:00+00:00 [queued]>
[2022-06-08 05:21:41,020] {taskinstance.py:1356} INFO - 
--------------------------------------------------------------------------------
[2022-06-08 05:21:41,020] {taskinstance.py:1357} INFO - Starting attempt 1 of 2
[2022-06-08 05:21:41,021] {taskinstance.py:1358} INFO - 
--------------------------------------------------------------------------------
[2022-06-08 05:21:41,040] {taskinstance.py:1377} INFO - Executing <Task(BashOperator): generate_sql_requirement> on 2022-06-07 00:00:00+00:00
[2022-06-08 05:21:41,047] {standard_task_runner.py:52} INFO - Started process 11397 to run task
[2022-06-08 05:21:41,052] {standard_task_runner.py:79} INFO - Running: ['***', 'tasks', 'run', 'hands_on_test', 'generate_sql_requirement', 'scheduled__2022-06-07T00:00:00+00:00', '--job-id', '161', '--raw', '--subdir', 'DAGS_FOLDER/dag.py', '--cfg-path', '/tmp/tmpwqs7f50o', '--error-file', '/tmp/tmpyp_3cdcb']
[2022-06-08 05:21:41,055] {standard_task_runner.py:80} INFO - Job 161: Subtask generate_sql_requirement
[2022-06-08 05:21:41,159] {task_command.py:369} INFO - Running <TaskInstance: hands_on_test.generate_sql_requirement scheduled__2022-06-07T00:00:00+00:00 [running]> on host b79bd65fcc57
[2022-06-08 05:21:41,269] {taskinstance.py:1571} INFO - Exporting the following env vars:
AIRFLOW_CTX_DAG_OWNER=***
AIRFLOW_CTX_DAG_ID=hands_on_test
AIRFLOW_CTX_TASK_ID=generate_sql_requirement
AIRFLOW_CTX_EXECUTION_DATE=2022-06-07T00:00:00+00:00
AIRFLOW_CTX_TRY_NUMBER=1
AIRFLOW_CTX_DAG_RUN_ID=scheduled__2022-06-07T00:00:00+00:00
[2022-06-08 05:21:41,272] {subprocess.py:62} INFO - Tmp dir root location: 
 /tmp
[2022-06-08 05:21:41,273] {subprocess.py:74} INFO - Running command: ['bash', '-c', 'docker exec spark-master /spark/bin/spark-submit --master local[*] --name spark_create_restaurant_detail_new /home/script/sql_requirement.py ']
[2022-06-08 05:21:41,286] {subprocess.py:85} INFO - Output:
[2022-06-08 05:21:44,177] {subprocess.py:92} INFO - 22/06/08 05:21:44 WARN NativeCodeLoader: Unable to load native-hadoop library for your platform... using builtin-java classes where applicable
[2022-06-08 05:21:45,013] {subprocess.py:92} INFO - Using Spark's default log4j profile: org/apache/spark/log4j-defaults.properties
[2022-06-08 05:21:45,033] {subprocess.py:92} INFO - 22/06/08 05:21:45 INFO SparkContext: Running Spark version 3.1.1
[2022-06-08 05:21:45,089] {subprocess.py:92} INFO - 22/06/08 05:21:45 INFO ResourceUtils: ==============================================================
[2022-06-08 05:21:45,090] {subprocess.py:92} INFO - 22/06/08 05:21:45 INFO ResourceUtils: No custom resources configured for spark.driver.
[2022-06-08 05:21:45,091] {subprocess.py:92} INFO - 22/06/08 05:21:45 INFO ResourceUtils: ==============================================================
[2022-06-08 05:21:45,092] {subprocess.py:92} INFO - 22/06/08 05:21:45 INFO SparkContext: Submitted application: spark_create_restaurant_detail_new
[2022-06-08 05:21:45,124] {subprocess.py:92} INFO - 22/06/08 05:21:45 INFO ResourceProfile: Default ResourceProfile created, executor resources: Map(cores -> name: cores, amount: 1, script: , vendor: , memory -> name: memory, amount: 1024, script: , vendor: , offHeap -> name: offHeap, amount: 0, script: , vendor: ), task resources: Map(cpus -> name: cpus, amount: 1.0)
[2022-06-08 05:21:45,146] {subprocess.py:92} INFO - 22/06/08 05:21:45 INFO ResourceProfile: Limiting resource is cpu
[2022-06-08 05:21:45,148] {subprocess.py:92} INFO - 22/06/08 05:21:45 INFO ResourceProfileManager: Added ResourceProfile id: 0
[2022-06-08 05:21:45,211] {subprocess.py:92} INFO - 22/06/08 05:21:45 INFO SecurityManager: Changing view acls to: root
[2022-06-08 05:21:45,213] {subprocess.py:92} INFO - 22/06/08 05:21:45 INFO SecurityManager: Changing modify acls to: root
[2022-06-08 05:21:45,214] {subprocess.py:92} INFO - 22/06/08 05:21:45 INFO SecurityManager: Changing view acls groups to:
[2022-06-08 05:21:45,215] {subprocess.py:92} INFO - 22/06/08 05:21:45 INFO SecurityManager: Changing modify acls groups to:
[2022-06-08 05:21:45,215] {subprocess.py:92} INFO - 22/06/08 05:21:45 INFO SecurityManager: SecurityManager: authentication disabled; ui acls disabled; users  with view permissions: Set(root); groups with view permissions: Set(); users  with modify permissions: Set(root); groups with modify permissions: Set()
[2022-06-08 05:21:45,501] {subprocess.py:92} INFO - 22/06/08 05:21:45 INFO Utils: Successfully started service 'sparkDriver' on port 42489.
[2022-06-08 05:21:45,540] {subprocess.py:92} INFO - 22/06/08 05:21:45 INFO SparkEnv: Registering MapOutputTracker
[2022-06-08 05:21:45,598] {subprocess.py:92} INFO - 22/06/08 05:21:45 INFO SparkEnv: Registering BlockManagerMaster
[2022-06-08 05:21:45,623] {subprocess.py:92} INFO - 22/06/08 05:21:45 INFO BlockManagerMasterEndpoint: Using org.apache.spark.storage.DefaultTopologyMapper for getting topology information
[2022-06-08 05:21:45,624] {subprocess.py:92} INFO - 22/06/08 05:21:45 INFO BlockManagerMasterEndpoint: BlockManagerMasterEndpoint up
[2022-06-08 05:21:45,629] {subprocess.py:92} INFO - 22/06/08 05:21:45 INFO SparkEnv: Registering BlockManagerMasterHeartbeat
[2022-06-08 05:21:45,648] {subprocess.py:92} INFO - 22/06/08 05:21:45 INFO DiskBlockManager: Created local directory at /tmp/blockmgr-f3f8a0ab-17ef-4265-9531-c8e3cbf17fcc
[2022-06-08 05:21:45,680] {subprocess.py:92} INFO - 22/06/08 05:21:45 INFO MemoryStore: MemoryStore started with capacity 366.3 MiB
[2022-06-08 05:21:45,702] {subprocess.py:92} INFO - 22/06/08 05:21:45 INFO SparkEnv: Registering OutputCommitCoordinator
[2022-06-08 05:21:46,038] {subprocess.py:92} INFO - 22/06/08 05:21:46 INFO Utils: Successfully started service 'SparkUI' on port 4040.
[2022-06-08 05:21:46,123] {subprocess.py:92} INFO - 22/06/08 05:21:46 INFO SparkUI: Bound SparkUI to 0.0.0.0, and started at http://1e082e99bba9:4040
[2022-06-08 05:21:46,448] {subprocess.py:92} INFO - 22/06/08 05:21:46 INFO Executor: Starting executor ID driver on host 1e082e99bba9
[2022-06-08 05:21:46,498] {subprocess.py:92} INFO - 22/06/08 05:21:46 INFO Utils: Successfully started service 'org.apache.spark.network.netty.NettyBlockTransferService' on port 45725.
[2022-06-08 05:21:46,499] {subprocess.py:92} INFO - 22/06/08 05:21:46 INFO NettyBlockTransferService: Server created on 1e082e99bba9:45725
[2022-06-08 05:21:46,500] {subprocess.py:92} INFO - 22/06/08 05:21:46 INFO BlockManager: Using org.apache.spark.storage.RandomBlockReplicationPolicy for block replication policy
[2022-06-08 05:21:46,508] {subprocess.py:92} INFO - 22/06/08 05:21:46 INFO BlockManagerMaster: Registering BlockManager BlockManagerId(driver, 1e082e99bba9, 45725, None)
[2022-06-08 05:21:46,523] {subprocess.py:92} INFO - 22/06/08 05:21:46 INFO BlockManagerMasterEndpoint: Registering block manager 1e082e99bba9:45725 with 366.3 MiB RAM, BlockManagerId(driver, 1e082e99bba9, 45725, None)
[2022-06-08 05:21:46,532] {subprocess.py:92} INFO - 22/06/08 05:21:46 INFO BlockManagerMaster: Registered BlockManager BlockManagerId(driver, 1e082e99bba9, 45725, None)
[2022-06-08 05:21:46,534] {subprocess.py:92} INFO - 22/06/08 05:21:46 INFO BlockManager: Initialized BlockManager: BlockManagerId(driver, 1e082e99bba9, 45725, None)
[2022-06-08 05:21:47,150] {subprocess.py:92} INFO - 22/06/08 05:21:47 INFO SharedState: Setting hive.metastore.warehouse.dir ('null') to the value of spark.sql.warehouse.dir ('file:/spark-warehouse').
[2022-06-08 05:21:47,151] {subprocess.py:92} INFO - 22/06/08 05:21:47 INFO SharedState: Warehouse path is 'file:/spark-warehouse'.
[2022-06-08 05:21:48,959] {subprocess.py:92} INFO - 22/06/08 05:21:48 INFO HadoopFSUtils: Listing leaf files and directories in parallel under 180 paths. The first several paths are: hdfs://hive-namenode:8020/user/spark/order_detail_new/dt=20190101, hdfs://hive-namenode:8020/user/spark/order_detail_new/dt=20190102, hdfs://hive-namenode:8020/user/spark/order_detail_new/dt=20190103, hdfs://hive-namenode:8020/user/spark/order_detail_new/dt=20190104, hdfs://hive-namenode:8020/user/spark/order_detail_new/dt=20190105, hdfs://hive-namenode:8020/user/spark/order_detail_new/dt=20190106, hdfs://hive-namenode:8020/user/spark/order_detail_new/dt=20190107, hdfs://hive-namenode:8020/user/spark/order_detail_new/dt=20190108, hdfs://hive-namenode:8020/user/spark/order_detail_new/dt=20190109, hdfs://hive-namenode:8020/user/spark/order_detail_new/dt=20190110.
[2022-06-08 05:21:49,580] {subprocess.py:92} INFO - 22/06/08 05:21:49 INFO SparkContext: Starting job: parquet at NativeMethodAccessorImpl.java:0
[2022-06-08 05:21:49,612] {subprocess.py:92} INFO - 22/06/08 05:21:49 INFO DAGScheduler: Got job 0 (parquet at NativeMethodAccessorImpl.java:0) with 180 output partitions
[2022-06-08 05:21:49,614] {subprocess.py:92} INFO - 22/06/08 05:21:49 INFO DAGScheduler: Final stage: ResultStage 0 (parquet at NativeMethodAccessorImpl.java:0)
[2022-06-08 05:21:49,615] {subprocess.py:92} INFO - 22/06/08 05:21:49 INFO DAGScheduler: Parents of final stage: List()
[2022-06-08 05:21:49,619] {subprocess.py:92} INFO - 22/06/08 05:21:49 INFO DAGScheduler: Missing parents: List()
[2022-06-08 05:21:49,637] {subprocess.py:92} INFO - 22/06/08 05:21:49 INFO DAGScheduler: Submitting ResultStage 0 (MapPartitionsRDD[2] at parquet at NativeMethodAccessorImpl.java:0), which has no missing parents
[2022-06-08 05:21:49,767] {subprocess.py:92} INFO - 22/06/08 05:21:49 INFO MemoryStore: Block broadcast_0 stored as values in memory (estimated size 83.6 KiB, free 366.2 MiB)
[2022-06-08 05:21:49,810] {subprocess.py:92} INFO - 22/06/08 05:21:49 INFO MemoryStore: Block broadcast_0_piece0 stored as bytes in memory (estimated size 29.5 KiB, free 366.2 MiB)
[2022-06-08 05:21:49,824] {subprocess.py:92} INFO - 22/06/08 05:21:49 INFO BlockManagerInfo: Added broadcast_0_piece0 in memory on 1e082e99bba9:45725 (size: 29.5 KiB, free: 366.3 MiB)
[2022-06-08 05:21:49,831] {subprocess.py:92} INFO - 22/06/08 05:21:49 INFO SparkContext: Created broadcast 0 from broadcast at DAGScheduler.scala:1383
[2022-06-08 05:21:49,859] {subprocess.py:92} INFO - 22/06/08 05:21:49 INFO DAGScheduler: Submitting 180 missing tasks from ResultStage 0 (MapPartitionsRDD[2] at parquet at NativeMethodAccessorImpl.java:0) (first 15 tasks are for partitions Vector(0, 1, 2, 3, 4, 5, 6, 7, 8, 9, 10, 11, 12, 13, 14))
[2022-06-08 05:21:49,861] {subprocess.py:92} INFO - 22/06/08 05:21:49 INFO TaskSchedulerImpl: Adding task set 0.0 with 180 tasks resource profile 0
[2022-06-08 05:21:49,969] {subprocess.py:92} INFO - 22/06/08 05:21:49 INFO TaskSetManager: Starting task 0.0 in stage 0.0 (TID 0) (1e082e99bba9, executor driver, partition 0, PROCESS_LOCAL, 4545 bytes) taskResourceAssignments Map()
[2022-06-08 05:21:49,986] {subprocess.py:92} INFO - 22/06/08 05:21:49 INFO TaskSetManager: Starting task 1.0 in stage 0.0 (TID 1) (1e082e99bba9, executor driver, partition 1, PROCESS_LOCAL, 4545 bytes) taskResourceAssignments Map()
[2022-06-08 05:21:49,987] {subprocess.py:92} INFO - 22/06/08 05:21:49 INFO TaskSetManager: Starting task 2.0 in stage 0.0 (TID 2) (1e082e99bba9, executor driver, partition 2, PROCESS_LOCAL, 4545 bytes) taskResourceAssignments Map()
[2022-06-08 05:21:49,989] {subprocess.py:92} INFO - 22/06/08 05:21:49 INFO TaskSetManager: Starting task 3.0 in stage 0.0 (TID 3) (1e082e99bba9, executor driver, partition 3, PROCESS_LOCAL, 4545 bytes) taskResourceAssignments Map()
[2022-06-08 05:21:50,012] {subprocess.py:92} INFO - 22/06/08 05:21:50 INFO Executor: Running task 1.0 in stage 0.0 (TID 1)
[2022-06-08 05:21:50,013] {subprocess.py:92} INFO - 22/06/08 05:21:50 INFO Executor: Running task 0.0 in stage 0.0 (TID 0)
[2022-06-08 05:21:50,014] {subprocess.py:92} INFO - 22/06/08 05:21:50 INFO Executor: Running task 2.0 in stage 0.0 (TID 2)
[2022-06-08 05:21:50,014] {subprocess.py:92} INFO - 22/06/08 05:21:50 INFO Executor: Running task 3.0 in stage 0.0 (TID 3)
[2022-06-08 05:21:50,659] {subprocess.py:92} INFO - 22/06/08 05:21:50 INFO Executor: Finished task 2.0 in stage 0.0 (TID 2). 2453 bytes result sent to driver
[2022-06-08 05:21:50,661] {subprocess.py:92} INFO - 22/06/08 05:21:50 INFO Executor: Finished task 1.0 in stage 0.0 (TID 1). 2453 bytes result sent to driver
[2022-06-08 05:21:50,662] {subprocess.py:92} INFO - 22/06/08 05:21:50 INFO Executor: Finished task 0.0 in stage 0.0 (TID 0). 2692 bytes result sent to driver
[2022-06-08 05:21:50,666] {subprocess.py:92} INFO - 22/06/08 05:21:50 INFO TaskSetManager: Starting task 4.0 in stage 0.0 (TID 4) (1e082e99bba9, executor driver, partition 4, PROCESS_LOCAL, 4545 bytes) taskResourceAssignments Map()
[2022-06-08 05:21:50,668] {subprocess.py:92} INFO - 22/06/08 05:21:50 INFO Executor: Running task 4.0 in stage 0.0 (TID 4)
[2022-06-08 05:21:50,672] {subprocess.py:92} INFO - 22/06/08 05:21:50 INFO TaskSetManager: Starting task 5.0 in stage 0.0 (TID 5) (1e082e99bba9, executor driver, partition 5, PROCESS_LOCAL, 4545 bytes) taskResourceAssignments Map()
[2022-06-08 05:21:50,673] {subprocess.py:92} INFO - 22/06/08 05:21:50 INFO Executor: Running task 5.0 in stage 0.0 (TID 5)
[2022-06-08 05:21:50,679] {subprocess.py:92} INFO - 22/06/08 05:21:50 INFO TaskSetManager: Starting task 6.0 in stage 0.0 (TID 6) (1e082e99bba9, executor driver, partition 6, PROCESS_LOCAL, 4545 bytes) taskResourceAssignments Map()
[2022-06-08 05:21:50,681] {subprocess.py:92} INFO - 22/06/08 05:21:50 INFO Executor: Finished task 3.0 in stage 0.0 (TID 3). 2692 bytes result sent to driver
[2022-06-08 05:21:50,682] {subprocess.py:92} INFO - 22/06/08 05:21:50 INFO Executor: Running task 6.0 in stage 0.0 (TID 6)
[2022-06-08 05:21:50,695] {subprocess.py:92} INFO - 22/06/08 05:21:50 INFO TaskSetManager: Starting task 7.0 in stage 0.0 (TID 7) (1e082e99bba9, executor driver, partition 7, PROCESS_LOCAL, 4545 bytes) taskResourceAssignments Map()
[2022-06-08 05:21:50,697] {subprocess.py:92} INFO - 22/06/08 05:21:50 INFO Executor: Running task 7.0 in stage 0.0 (TID 7)
[2022-06-08 05:21:50,700] {subprocess.py:92} INFO - 22/06/08 05:21:50 INFO Executor: Finished task 5.0 in stage 0.0 (TID 5). 2606 bytes result sent to driver
[2022-06-08 05:21:50,707] {subprocess.py:92} INFO - 22/06/08 05:21:50 INFO Executor: Finished task 4.0 in stage 0.0 (TID 4). 2606 bytes result sent to driver
[2022-06-08 05:21:50,708] {subprocess.py:92} INFO - 22/06/08 05:21:50 INFO TaskSetManager: Starting task 8.0 in stage 0.0 (TID 8) (1e082e99bba9, executor driver, partition 8, PROCESS_LOCAL, 4545 bytes) taskResourceAssignments Map()
[2022-06-08 05:21:50,711] {subprocess.py:92} INFO - 22/06/08 05:21:50 INFO TaskSetManager: Starting task 9.0 in stage 0.0 (TID 9) (1e082e99bba9, executor driver, partition 9, PROCESS_LOCAL, 4545 bytes) taskResourceAssignments Map()
[2022-06-08 05:21:50,714] {subprocess.py:92} INFO - 22/06/08 05:21:50 INFO Executor: Running task 8.0 in stage 0.0 (TID 8)
[2022-06-08 05:21:50,715] {subprocess.py:92} INFO - 22/06/08 05:21:50 INFO TaskSetManager: Finished task 1.0 in stage 0.0 (TID 1) in 728 ms on 1e082e99bba9 (executor driver) (1/180)
[2022-06-08 05:21:50,717] {subprocess.py:92} INFO - 22/06/08 05:21:50 INFO TaskSetManager: Finished task 5.0 in stage 0.0 (TID 5) in 46 ms on 1e082e99bba9 (executor driver) (2/180)
[2022-06-08 05:21:50,720] {subprocess.py:92} INFO - 22/06/08 05:21:50 INFO Executor: Finished task 6.0 in stage 0.0 (TID 6). 2367 bytes result sent to driver
[2022-06-08 05:21:50,723] {subprocess.py:92} INFO - 22/06/08 05:21:50 INFO Executor: Running task 9.0 in stage 0.0 (TID 9)
[2022-06-08 05:21:50,726] {subprocess.py:92} INFO - 22/06/08 05:21:50 INFO Executor: Finished task 7.0 in stage 0.0 (TID 7). 2367 bytes result sent to driver
[2022-06-08 05:21:50,727] {subprocess.py:92} INFO - 22/06/08 05:21:50 INFO TaskSetManager: Finished task 0.0 in stage 0.0 (TID 0) in 805 ms on 1e082e99bba9 (executor driver) (3/180)
[2022-06-08 05:21:50,730] {subprocess.py:92} INFO - 22/06/08 05:21:50 INFO TaskSetManager: Starting task 10.0 in stage 0.0 (TID 10) (1e082e99bba9, executor driver, partition 10, PROCESS_LOCAL, 4545 bytes) taskResourceAssignments Map()
[2022-06-08 05:21:50,732] {subprocess.py:92} INFO - 22/06/08 05:21:50 INFO TaskSetManager: Finished task 2.0 in stage 0.0 (TID 2) in 745 ms on 1e082e99bba9 (executor driver) (4/180)
[2022-06-08 05:21:50,733] {subprocess.py:92} INFO - 22/06/08 05:21:50 INFO Executor: Running task 10.0 in stage 0.0 (TID 10)
[2022-06-08 05:21:50,733] {subprocess.py:92} INFO - 22/06/08 05:21:50 INFO TaskSetManager: Finished task 7.0 in stage 0.0 (TID 7) in 38 ms on 1e082e99bba9 (executor driver) (5/180)
[2022-06-08 05:21:50,734] {subprocess.py:92} INFO - 22/06/08 05:21:50 INFO TaskSetManager: Finished task 3.0 in stage 0.0 (TID 3) in 745 ms on 1e082e99bba9 (executor driver) (6/180)
[2022-06-08 05:21:50,735] {subprocess.py:92} INFO - 22/06/08 05:21:50 INFO TaskSetManager: Finished task 4.0 in stage 0.0 (TID 4) in 69 ms on 1e082e99bba9 (executor driver) (7/180)
[2022-06-08 05:21:50,735] {subprocess.py:92} INFO - 22/06/08 05:21:50 INFO TaskSetManager: Finished task 6.0 in stage 0.0 (TID 6) in 56 ms on 1e082e99bba9 (executor driver) (8/180)
[2022-06-08 05:21:50,738] {subprocess.py:92} INFO - 22/06/08 05:21:50 INFO TaskSetManager: Starting task 11.0 in stage 0.0 (TID 11) (1e082e99bba9, executor driver, partition 11, PROCESS_LOCAL, 4545 bytes) taskResourceAssignments Map()
[2022-06-08 05:21:50,742] {subprocess.py:92} INFO - 22/06/08 05:21:50 INFO Executor: Running task 11.0 in stage 0.0 (TID 11)
[2022-06-08 05:21:50,753] {subprocess.py:92} INFO - 22/06/08 05:21:50 INFO Executor: Finished task 8.0 in stage 0.0 (TID 8). 2367 bytes result sent to driver
[2022-06-08 05:21:50,754] {subprocess.py:92} INFO - 22/06/08 05:21:50 INFO TaskSetManager: Starting task 12.0 in stage 0.0 (TID 12) (1e082e99bba9, executor driver, partition 12, PROCESS_LOCAL, 4545 bytes) taskResourceAssignments Map()
[2022-06-08 05:21:50,755] {subprocess.py:92} INFO - 22/06/08 05:21:50 INFO TaskSetManager: Finished task 8.0 in stage 0.0 (TID 8) in 52 ms on 1e082e99bba9 (executor driver) (9/180)
[2022-06-08 05:21:50,756] {subprocess.py:92} INFO - 22/06/08 05:21:50 INFO Executor: Running task 12.0 in stage 0.0 (TID 12)
[2022-06-08 05:21:50,766] {subprocess.py:92} INFO - 22/06/08 05:21:50 INFO Executor: Finished task 9.0 in stage 0.0 (TID 9). 2367 bytes result sent to driver
[2022-06-08 05:21:50,767] {subprocess.py:92} INFO - 22/06/08 05:21:50 INFO TaskSetManager: Starting task 13.0 in stage 0.0 (TID 13) (1e082e99bba9, executor driver, partition 13, PROCESS_LOCAL, 4545 bytes) taskResourceAssignments Map()
[2022-06-08 05:21:50,769] {subprocess.py:92} INFO - 22/06/08 05:21:50 INFO TaskSetManager: Finished task 9.0 in stage 0.0 (TID 9) in 58 ms on 1e082e99bba9 (executor driver) (10/180)
[2022-06-08 05:21:50,770] {subprocess.py:92} INFO - 22/06/08 05:21:50 INFO Executor: Running task 13.0 in stage 0.0 (TID 13)
[2022-06-08 05:21:50,796] {subprocess.py:92} INFO - 22/06/08 05:21:50 INFO Executor: Finished task 12.0 in stage 0.0 (TID 12). 2606 bytes result sent to driver
[2022-06-08 05:21:50,798] {subprocess.py:92} INFO - 22/06/08 05:21:50 INFO TaskSetManager: Starting task 14.0 in stage 0.0 (TID 14) (1e082e99bba9, executor driver, partition 14, PROCESS_LOCAL, 4545 bytes) taskResourceAssignments Map()
[2022-06-08 05:21:50,799] {subprocess.py:92} INFO - 22/06/08 05:21:50 INFO TaskSetManager: Finished task 12.0 in stage 0.0 (TID 12) in 46 ms on 1e082e99bba9 (executor driver) (11/180)
[2022-06-08 05:21:50,800] {subprocess.py:92} INFO - 22/06/08 05:21:50 INFO Executor: Running task 14.0 in stage 0.0 (TID 14)
[2022-06-08 05:21:50,803] {subprocess.py:92} INFO - 22/06/08 05:21:50 INFO Executor: Finished task 11.0 in stage 0.0 (TID 11). 2367 bytes result sent to driver
[2022-06-08 05:21:50,806] {subprocess.py:92} INFO - 22/06/08 05:21:50 INFO TaskSetManager: Starting task 15.0 in stage 0.0 (TID 15) (1e082e99bba9, executor driver, partition 15, PROCESS_LOCAL, 4545 bytes) taskResourceAssignments Map()
[2022-06-08 05:21:50,807] {subprocess.py:92} INFO - 22/06/08 05:21:50 INFO TaskSetManager: Finished task 11.0 in stage 0.0 (TID 11) in 71 ms on 1e082e99bba9 (executor driver) (12/180)
[2022-06-08 05:21:50,809] {subprocess.py:92} INFO - 22/06/08 05:21:50 INFO Executor: Finished task 13.0 in stage 0.0 (TID 13). 2367 bytes result sent to driver
[2022-06-08 05:21:50,811] {subprocess.py:92} INFO - 22/06/08 05:21:50 INFO Executor: Finished task 10.0 in stage 0.0 (TID 10). 2367 bytes result sent to driver
[2022-06-08 05:21:50,815] {subprocess.py:92} INFO - 22/06/08 05:21:50 INFO TaskSetManager: Starting task 16.0 in stage 0.0 (TID 16) (1e082e99bba9, executor driver, partition 16, PROCESS_LOCAL, 4545 bytes) taskResourceAssignments Map()
[2022-06-08 05:21:50,820] {subprocess.py:92} INFO - 22/06/08 05:21:50 INFO Executor: Running task 15.0 in stage 0.0 (TID 15)
[2022-06-08 05:21:50,826] {subprocess.py:92} INFO - 22/06/08 05:21:50 INFO Executor: Running task 16.0 in stage 0.0 (TID 16)
[2022-06-08 05:21:50,827] {subprocess.py:92} INFO - 22/06/08 05:21:50 INFO TaskSetManager: Starting task 17.0 in stage 0.0 (TID 17) (1e082e99bba9, executor driver, partition 17, PROCESS_LOCAL, 4545 bytes) taskResourceAssignments Map()
[2022-06-08 05:21:50,828] {subprocess.py:92} INFO - 22/06/08 05:21:50 INFO TaskSetManager: Finished task 10.0 in stage 0.0 (TID 10) in 92 ms on 1e082e99bba9 (executor driver) (13/180)
[2022-06-08 05:21:50,829] {subprocess.py:92} INFO - 22/06/08 05:21:50 INFO TaskSetManager: Finished task 13.0 in stage 0.0 (TID 13) in 54 ms on 1e082e99bba9 (executor driver) (14/180)
[2022-06-08 05:21:50,830] {subprocess.py:92} INFO - 22/06/08 05:21:50 INFO Executor: Running task 17.0 in stage 0.0 (TID 17)
[2022-06-08 05:21:50,837] {subprocess.py:92} INFO - 22/06/08 05:21:50 INFO Executor: Finished task 14.0 in stage 0.0 (TID 14). 2606 bytes result sent to driver
[2022-06-08 05:21:50,847] {subprocess.py:92} INFO - 22/06/08 05:21:50 INFO TaskSetManager: Starting task 18.0 in stage 0.0 (TID 18) (1e082e99bba9, executor driver, partition 18, PROCESS_LOCAL, 4545 bytes) taskResourceAssignments Map()
[2022-06-08 05:21:50,848] {subprocess.py:92} INFO - 22/06/08 05:21:50 INFO TaskSetManager: Finished task 14.0 in stage 0.0 (TID 14) in 51 ms on 1e082e99bba9 (executor driver) (15/180)
[2022-06-08 05:21:50,854] {subprocess.py:92} INFO - 22/06/08 05:21:50 INFO Executor: Running task 18.0 in stage 0.0 (TID 18)
[2022-06-08 05:21:50,863] {subprocess.py:92} INFO - 22/06/08 05:21:50 INFO Executor: Finished task 17.0 in stage 0.0 (TID 17). 2606 bytes result sent to driver
[2022-06-08 05:21:50,865] {subprocess.py:92} INFO - 22/06/08 05:21:50 INFO Executor: Finished task 15.0 in stage 0.0 (TID 15). 2367 bytes result sent to driver
[2022-06-08 05:21:50,866] {subprocess.py:92} INFO - 22/06/08 05:21:50 INFO Executor: Finished task 16.0 in stage 0.0 (TID 16). 2367 bytes result sent to driver
[2022-06-08 05:21:50,868] {subprocess.py:92} INFO - 22/06/08 05:21:50 INFO TaskSetManager: Starting task 19.0 in stage 0.0 (TID 19) (1e082e99bba9, executor driver, partition 19, PROCESS_LOCAL, 4545 bytes) taskResourceAssignments Map()
[2022-06-08 05:21:50,871] {subprocess.py:92} INFO - 22/06/08 05:21:50 INFO TaskSetManager: Starting task 20.0 in stage 0.0 (TID 20) (1e082e99bba9, executor driver, partition 20, PROCESS_LOCAL, 4545 bytes) taskResourceAssignments Map()
[2022-06-08 05:21:50,876] {subprocess.py:92} INFO - 22/06/08 05:21:50 INFO Executor: Running task 19.0 in stage 0.0 (TID 19)
[2022-06-08 05:21:50,877] {subprocess.py:92} INFO - 22/06/08 05:21:50 INFO TaskSetManager: Starting task 21.0 in stage 0.0 (TID 21) (1e082e99bba9, executor driver, partition 21, PROCESS_LOCAL, 4545 bytes) taskResourceAssignments Map()
[2022-06-08 05:21:50,877] {subprocess.py:92} INFO - 22/06/08 05:21:50 INFO Executor: Running task 20.0 in stage 0.0 (TID 20)
[2022-06-08 05:21:50,878] {subprocess.py:92} INFO - 22/06/08 05:21:50 INFO Executor: Running task 21.0 in stage 0.0 (TID 21)
[2022-06-08 05:21:50,883] {subprocess.py:92} INFO - 22/06/08 05:21:50 INFO TaskSetManager: Finished task 17.0 in stage 0.0 (TID 17) in 62 ms on 1e082e99bba9 (executor driver) (16/180)
[2022-06-08 05:21:50,896] {subprocess.py:92} INFO - 22/06/08 05:21:50 INFO Executor: Finished task 18.0 in stage 0.0 (TID 18). 2367 bytes result sent to driver
[2022-06-08 05:21:50,899] {subprocess.py:92} INFO - 22/06/08 05:21:50 INFO TaskSetManager: Finished task 15.0 in stage 0.0 (TID 15) in 86 ms on 1e082e99bba9 (executor driver) (17/180)
[2022-06-08 05:21:50,900] {subprocess.py:92} INFO - 22/06/08 05:21:50 INFO TaskSetManager: Finished task 16.0 in stage 0.0 (TID 16) in 81 ms on 1e082e99bba9 (executor driver) (18/180)
[2022-06-08 05:21:50,900] {subprocess.py:92} INFO - 22/06/08 05:21:50 INFO TaskSetManager: Starting task 22.0 in stage 0.0 (TID 22) (1e082e99bba9, executor driver, partition 22, PROCESS_LOCAL, 4545 bytes) taskResourceAssignments Map()
[2022-06-08 05:21:50,901] {subprocess.py:92} INFO - 22/06/08 05:21:50 INFO Executor: Running task 22.0 in stage 0.0 (TID 22)
[2022-06-08 05:21:50,903] {subprocess.py:92} INFO - 22/06/08 05:21:50 INFO TaskSetManager: Finished task 18.0 in stage 0.0 (TID 18) in 54 ms on 1e082e99bba9 (executor driver) (19/180)
[2022-06-08 05:21:50,908] {subprocess.py:92} INFO - 22/06/08 05:21:50 INFO Executor: Finished task 20.0 in stage 0.0 (TID 20). 2606 bytes result sent to driver
[2022-06-08 05:21:50,918] {subprocess.py:92} INFO - 22/06/08 05:21:50 INFO TaskSetManager: Starting task 23.0 in stage 0.0 (TID 23) (1e082e99bba9, executor driver, partition 23, PROCESS_LOCAL, 4545 bytes) taskResourceAssignments Map()
[2022-06-08 05:21:50,919] {subprocess.py:92} INFO - 22/06/08 05:21:50 INFO Executor: Finished task 21.0 in stage 0.0 (TID 21). 2606 bytes result sent to driver
[2022-06-08 05:21:50,920] {subprocess.py:92} INFO - 22/06/08 05:21:50 INFO Executor: Running task 23.0 in stage 0.0 (TID 23)
[2022-06-08 05:21:50,921] {subprocess.py:92} INFO - 22/06/08 05:21:50 INFO TaskSetManager: Starting task 24.0 in stage 0.0 (TID 24) (1e082e99bba9, executor driver, partition 24, PROCESS_LOCAL, 4545 bytes) taskResourceAssignments Map()
[2022-06-08 05:21:50,922] {subprocess.py:92} INFO - 22/06/08 05:21:50 INFO TaskSetManager: Finished task 20.0 in stage 0.0 (TID 20) in 53 ms on 1e082e99bba9 (executor driver) (20/180)
[2022-06-08 05:21:50,923] {subprocess.py:92} INFO - 22/06/08 05:21:50 INFO TaskSetManager: Finished task 21.0 in stage 0.0 (TID 21) in 50 ms on 1e082e99bba9 (executor driver) (21/180)
[2022-06-08 05:21:50,924] {subprocess.py:92} INFO - 22/06/08 05:21:50 INFO Executor: Running task 24.0 in stage 0.0 (TID 24)
[2022-06-08 05:21:50,938] {subprocess.py:92} INFO - 22/06/08 05:21:50 INFO Executor: Finished task 22.0 in stage 0.0 (TID 22). 2606 bytes result sent to driver
[2022-06-08 05:21:50,940] {subprocess.py:92} INFO - 22/06/08 05:21:50 INFO TaskSetManager: Starting task 25.0 in stage 0.0 (TID 25) (1e082e99bba9, executor driver, partition 25, PROCESS_LOCAL, 4545 bytes) taskResourceAssignments Map()
[2022-06-08 05:21:50,942] {subprocess.py:92} INFO - 22/06/08 05:21:50 INFO Executor: Running task 25.0 in stage 0.0 (TID 25)
[2022-06-08 05:21:50,943] {subprocess.py:92} INFO - 22/06/08 05:21:50 INFO TaskSetManager: Finished task 22.0 in stage 0.0 (TID 22) in 44 ms on 1e082e99bba9 (executor driver) (22/180)
[2022-06-08 05:21:50,947] {subprocess.py:92} INFO - 22/06/08 05:21:50 INFO Executor: Finished task 19.0 in stage 0.0 (TID 19). 2606 bytes result sent to driver
[2022-06-08 05:21:50,952] {subprocess.py:92} INFO - 22/06/08 05:21:50 INFO TaskSetManager: Starting task 26.0 in stage 0.0 (TID 26) (1e082e99bba9, executor driver, partition 26, PROCESS_LOCAL, 4545 bytes) taskResourceAssignments Map()
[2022-06-08 05:21:50,955] {subprocess.py:92} INFO - 22/06/08 05:21:50 INFO Executor: Finished task 23.0 in stage 0.0 (TID 23). 2606 bytes result sent to driver
[2022-06-08 05:21:50,958] {subprocess.py:92} INFO - 22/06/08 05:21:50 INFO TaskSetManager: Starting task 27.0 in stage 0.0 (TID 27) (1e082e99bba9, executor driver, partition 27, PROCESS_LOCAL, 4545 bytes) taskResourceAssignments Map()
[2022-06-08 05:21:50,959] {subprocess.py:92} INFO - 22/06/08 05:21:50 INFO Executor: Finished task 24.0 in stage 0.0 (TID 24). 2606 bytes result sent to driver
[2022-06-08 05:21:50,960] {subprocess.py:92} INFO - 22/06/08 05:21:50 INFO Executor: Running task 27.0 in stage 0.0 (TID 27)
[2022-06-08 05:21:50,961] {subprocess.py:92} INFO - 22/06/08 05:21:50 INFO TaskSetManager: Starting task 28.0 in stage 0.0 (TID 28) (1e082e99bba9, executor driver, partition 28, PROCESS_LOCAL, 4545 bytes) taskResourceAssignments Map()
[2022-06-08 05:21:50,962] {subprocess.py:92} INFO - 22/06/08 05:21:50 INFO TaskSetManager: Finished task 23.0 in stage 0.0 (TID 23) in 44 ms on 1e082e99bba9 (executor driver) (23/180)
[2022-06-08 05:21:50,966] {subprocess.py:92} INFO - 22/06/08 05:21:50 INFO Executor: Running task 28.0 in stage 0.0 (TID 28)
[2022-06-08 05:21:50,967] {subprocess.py:92} INFO - 22/06/08 05:21:50 INFO TaskSetManager: Finished task 24.0 in stage 0.0 (TID 24) in 42 ms on 1e082e99bba9 (executor driver) (24/180)
[2022-06-08 05:21:50,969] {subprocess.py:92} INFO - 22/06/08 05:21:50 INFO TaskSetManager: Finished task 19.0 in stage 0.0 (TID 19) in 101 ms on 1e082e99bba9 (executor driver) (25/180)
[2022-06-08 05:21:50,969] {subprocess.py:92} INFO - 22/06/08 05:21:50 INFO Executor: Running task 26.0 in stage 0.0 (TID 26)
[2022-06-08 05:21:50,983] {subprocess.py:92} INFO - 22/06/08 05:21:50 INFO Executor: Finished task 27.0 in stage 0.0 (TID 27). 2367 bytes result sent to driver
[2022-06-08 05:21:50,985] {subprocess.py:92} INFO - 22/06/08 05:21:50 INFO TaskSetManager: Starting task 29.0 in stage 0.0 (TID 29) (1e082e99bba9, executor driver, partition 29, PROCESS_LOCAL, 4545 bytes) taskResourceAssignments Map()
[2022-06-08 05:21:50,987] {subprocess.py:92} INFO - 22/06/08 05:21:50 INFO TaskSetManager: Finished task 27.0 in stage 0.0 (TID 27) in 30 ms on 1e082e99bba9 (executor driver) (26/180)
[2022-06-08 05:21:50,989] {subprocess.py:92} INFO - 22/06/08 05:21:50 INFO Executor: Running task 29.0 in stage 0.0 (TID 29)
[2022-06-08 05:21:50,994] {subprocess.py:92} INFO - 22/06/08 05:21:50 INFO Executor: Finished task 25.0 in stage 0.0 (TID 25). 2606 bytes result sent to driver
[2022-06-08 05:21:50,998] {subprocess.py:92} INFO - 22/06/08 05:21:50 INFO Executor: Finished task 26.0 in stage 0.0 (TID 26). 2367 bytes result sent to driver
[2022-06-08 05:21:51,000] {subprocess.py:92} INFO - 22/06/08 05:21:50 INFO TaskSetManager: Starting task 30.0 in stage 0.0 (TID 30) (1e082e99bba9, executor driver, partition 30, PROCESS_LOCAL, 4545 bytes) taskResourceAssignments Map()
[2022-06-08 05:21:51,001] {subprocess.py:92} INFO - 22/06/08 05:21:51 INFO TaskSetManager: Finished task 25.0 in stage 0.0 (TID 25) in 61 ms on 1e082e99bba9 (executor driver) (27/180)
[2022-06-08 05:21:51,002] {subprocess.py:92} INFO - 22/06/08 05:21:51 INFO Executor: Running task 30.0 in stage 0.0 (TID 30)
[2022-06-08 05:21:51,003] {subprocess.py:92} INFO - 22/06/08 05:21:51 INFO TaskSetManager: Finished task 26.0 in stage 0.0 (TID 26) in 50 ms on 1e082e99bba9 (executor driver) (28/180)
[2022-06-08 05:21:51,005] {subprocess.py:92} INFO - 22/06/08 05:21:51 INFO TaskSetManager: Starting task 31.0 in stage 0.0 (TID 31) (1e082e99bba9, executor driver, partition 31, PROCESS_LOCAL, 4545 bytes) taskResourceAssignments Map()
[2022-06-08 05:21:51,007] {subprocess.py:92} INFO - 22/06/08 05:21:51 INFO Executor: Running task 31.0 in stage 0.0 (TID 31)
[2022-06-08 05:21:51,008] {subprocess.py:92} INFO - 22/06/08 05:21:51 INFO Executor: Finished task 28.0 in stage 0.0 (TID 28). 2649 bytes result sent to driver
[2022-06-08 05:21:51,010] {subprocess.py:92} INFO - 22/06/08 05:21:51 INFO TaskSetManager: Starting task 32.0 in stage 0.0 (TID 32) (1e082e99bba9, executor driver, partition 32, PROCESS_LOCAL, 4545 bytes) taskResourceAssignments Map()
[2022-06-08 05:21:51,011] {subprocess.py:92} INFO - 22/06/08 05:21:51 INFO Executor: Running task 32.0 in stage 0.0 (TID 32)
[2022-06-08 05:21:51,012] {subprocess.py:92} INFO - 22/06/08 05:21:51 INFO TaskSetManager: Finished task 28.0 in stage 0.0 (TID 28) in 51 ms on 1e082e99bba9 (executor driver) (29/180)
[2022-06-08 05:21:51,014] {subprocess.py:92} INFO - 22/06/08 05:21:51 INFO Executor: Finished task 29.0 in stage 0.0 (TID 29). 2128 bytes result sent to driver
[2022-06-08 05:21:51,019] {subprocess.py:92} INFO - 22/06/08 05:21:51 INFO TaskSetManager: Starting task 33.0 in stage 0.0 (TID 33) (1e082e99bba9, executor driver, partition 33, PROCESS_LOCAL, 4545 bytes) taskResourceAssignments Map()
[2022-06-08 05:21:51,021] {subprocess.py:92} INFO - 22/06/08 05:21:51 INFO TaskSetManager: Finished task 29.0 in stage 0.0 (TID 29) in 36 ms on 1e082e99bba9 (executor driver) (30/180)
[2022-06-08 05:21:51,023] {subprocess.py:92} INFO - 22/06/08 05:21:51 INFO Executor: Running task 33.0 in stage 0.0 (TID 33)
[2022-06-08 05:21:51,031] {subprocess.py:92} INFO - 22/06/08 05:21:51 INFO Executor: Finished task 31.0 in stage 0.0 (TID 31). 2367 bytes result sent to driver
[2022-06-08 05:21:51,032] {subprocess.py:92} INFO - 22/06/08 05:21:51 INFO TaskSetManager: Starting task 34.0 in stage 0.0 (TID 34) (1e082e99bba9, executor driver, partition 34, PROCESS_LOCAL, 4545 bytes) taskResourceAssignments Map()
[2022-06-08 05:21:51,033] {subprocess.py:92} INFO - 22/06/08 05:21:51 INFO Executor: Running task 34.0 in stage 0.0 (TID 34)
[2022-06-08 05:21:51,034] {subprocess.py:92} INFO - 22/06/08 05:21:51 INFO TaskSetManager: Finished task 31.0 in stage 0.0 (TID 31) in 30 ms on 1e082e99bba9 (executor driver) (31/180)
[2022-06-08 05:21:51,043] {subprocess.py:92} INFO - 22/06/08 05:21:51 INFO Executor: Finished task 30.0 in stage 0.0 (TID 30). 2128 bytes result sent to driver
[2022-06-08 05:21:51,048] {subprocess.py:92} INFO - 22/06/08 05:21:51 INFO TaskSetManager: Starting task 35.0 in stage 0.0 (TID 35) (1e082e99bba9, executor driver, partition 35, PROCESS_LOCAL, 4545 bytes) taskResourceAssignments Map()
[2022-06-08 05:21:51,049] {subprocess.py:92} INFO - 22/06/08 05:21:51 INFO Executor: Finished task 32.0 in stage 0.0 (TID 32). 2367 bytes result sent to driver
[2022-06-08 05:21:51,050] {subprocess.py:92} INFO - 22/06/08 05:21:51 INFO Executor: Running task 35.0 in stage 0.0 (TID 35)
[2022-06-08 05:21:51,051] {subprocess.py:92} INFO - 22/06/08 05:21:51 INFO TaskSetManager: Starting task 36.0 in stage 0.0 (TID 36) (1e082e99bba9, executor driver, partition 36, PROCESS_LOCAL, 4545 bytes) taskResourceAssignments Map()
[2022-06-08 05:21:51,052] {subprocess.py:92} INFO - 22/06/08 05:21:51 INFO TaskSetManager: Finished task 32.0 in stage 0.0 (TID 32) in 42 ms on 1e082e99bba9 (executor driver) (32/180)
[2022-06-08 05:21:51,053] {subprocess.py:92} INFO - 22/06/08 05:21:51 INFO Executor: Running task 36.0 in stage 0.0 (TID 36)
[2022-06-08 05:21:51,054] {subprocess.py:92} INFO - 22/06/08 05:21:51 INFO TaskSetManager: Finished task 30.0 in stage 0.0 (TID 30) in 53 ms on 1e082e99bba9 (executor driver) (33/180)
[2022-06-08 05:21:51,056] {subprocess.py:92} INFO - 22/06/08 05:21:51 INFO Executor: Finished task 33.0 in stage 0.0 (TID 33). 2128 bytes result sent to driver
[2022-06-08 05:21:51,058] {subprocess.py:92} INFO - 22/06/08 05:21:51 INFO TaskSetManager: Starting task 37.0 in stage 0.0 (TID 37) (1e082e99bba9, executor driver, partition 37, PROCESS_LOCAL, 4545 bytes) taskResourceAssignments Map()
[2022-06-08 05:21:51,059] {subprocess.py:92} INFO - 22/06/08 05:21:51 INFO TaskSetManager: Finished task 33.0 in stage 0.0 (TID 33) in 40 ms on 1e082e99bba9 (executor driver) (34/180)
[2022-06-08 05:21:51,060] {subprocess.py:92} INFO - 22/06/08 05:21:51 INFO Executor: Running task 37.0 in stage 0.0 (TID 37)
[2022-06-08 05:21:51,067] {subprocess.py:92} INFO - 22/06/08 05:21:51 INFO Executor: Finished task 34.0 in stage 0.0 (TID 34). 2128 bytes result sent to driver
[2022-06-08 05:21:51,069] {subprocess.py:92} INFO - 22/06/08 05:21:51 INFO TaskSetManager: Starting task 38.0 in stage 0.0 (TID 38) (1e082e99bba9, executor driver, partition 38, PROCESS_LOCAL, 4545 bytes) taskResourceAssignments Map()
[2022-06-08 05:21:51,070] {subprocess.py:92} INFO - 22/06/08 05:21:51 INFO TaskSetManager: Finished task 34.0 in stage 0.0 (TID 34) in 37 ms on 1e082e99bba9 (executor driver) (35/180)
[2022-06-08 05:21:51,071] {subprocess.py:92} INFO - 22/06/08 05:21:51 INFO Executor: Running task 38.0 in stage 0.0 (TID 38)
[2022-06-08 05:21:51,088] {subprocess.py:92} INFO - 22/06/08 05:21:51 INFO Executor: Finished task 37.0 in stage 0.0 (TID 37). 2367 bytes result sent to driver
[2022-06-08 05:21:51,090] {subprocess.py:92} INFO - 22/06/08 05:21:51 INFO TaskSetManager: Starting task 39.0 in stage 0.0 (TID 39) (1e082e99bba9, executor driver, partition 39, PROCESS_LOCAL, 4545 bytes) taskResourceAssignments Map()
[2022-06-08 05:21:51,092] {subprocess.py:92} INFO - 22/06/08 05:21:51 INFO TaskSetManager: Finished task 37.0 in stage 0.0 (TID 37) in 35 ms on 1e082e99bba9 (executor driver) (36/180)
[2022-06-08 05:21:51,093] {subprocess.py:92} INFO - 22/06/08 05:21:51 INFO Executor: Running task 39.0 in stage 0.0 (TID 39)
[2022-06-08 05:21:51,094] {subprocess.py:92} INFO - 22/06/08 05:21:51 INFO Executor: Finished task 38.0 in stage 0.0 (TID 38). 2367 bytes result sent to driver
[2022-06-08 05:21:51,096] {subprocess.py:92} INFO - 22/06/08 05:21:51 INFO TaskSetManager: Starting task 40.0 in stage 0.0 (TID 40) (1e082e99bba9, executor driver, partition 40, PROCESS_LOCAL, 4545 bytes) taskResourceAssignments Map()
[2022-06-08 05:21:51,099] {subprocess.py:92} INFO - 22/06/08 05:21:51 INFO TaskSetManager: Finished task 38.0 in stage 0.0 (TID 38) in 30 ms on 1e082e99bba9 (executor driver) (37/180)
[2022-06-08 05:21:51,100] {subprocess.py:92} INFO - 22/06/08 05:21:51 INFO Executor: Running task 40.0 in stage 0.0 (TID 40)
[2022-06-08 05:21:51,102] {subprocess.py:92} INFO - 22/06/08 05:21:51 INFO Executor: Finished task 36.0 in stage 0.0 (TID 36). 2128 bytes result sent to driver
[2022-06-08 05:21:51,107] {subprocess.py:92} INFO - 22/06/08 05:21:51 INFO Executor: Finished task 35.0 in stage 0.0 (TID 35). 2128 bytes result sent to driver
[2022-06-08 05:21:51,109] {subprocess.py:92} INFO - 22/06/08 05:21:51 INFO TaskSetManager: Starting task 41.0 in stage 0.0 (TID 41) (1e082e99bba9, executor driver, partition 41, PROCESS_LOCAL, 4545 bytes) taskResourceAssignments Map()
[2022-06-08 05:21:51,111] {subprocess.py:92} INFO - 22/06/08 05:21:51 INFO Executor: Running task 41.0 in stage 0.0 (TID 41)
[2022-06-08 05:21:51,116] {subprocess.py:92} INFO - 22/06/08 05:21:51 INFO TaskSetManager: Starting task 42.0 in stage 0.0 (TID 42) (1e082e99bba9, executor driver, partition 42, PROCESS_LOCAL, 4545 bytes) taskResourceAssignments Map()
[2022-06-08 05:21:51,117] {subprocess.py:92} INFO - 22/06/08 05:21:51 INFO TaskSetManager: Finished task 36.0 in stage 0.0 (TID 36) in 63 ms on 1e082e99bba9 (executor driver) (38/180)
[2022-06-08 05:21:51,118] {subprocess.py:92} INFO - 22/06/08 05:21:51 INFO TaskSetManager: Finished task 35.0 in stage 0.0 (TID 35) in 69 ms on 1e082e99bba9 (executor driver) (39/180)
[2022-06-08 05:21:51,118] {subprocess.py:92} INFO - 22/06/08 05:21:51 INFO Executor: Running task 42.0 in stage 0.0 (TID 42)
[2022-06-08 05:21:51,119] {subprocess.py:92} INFO - 22/06/08 05:21:51 INFO Executor: Finished task 39.0 in stage 0.0 (TID 39). 2367 bytes result sent to driver
[2022-06-08 05:21:51,120] {subprocess.py:92} INFO - 22/06/08 05:21:51 INFO TaskSetManager: Starting task 43.0 in stage 0.0 (TID 43) (1e082e99bba9, executor driver, partition 43, PROCESS_LOCAL, 4545 bytes) taskResourceAssignments Map()
[2022-06-08 05:21:51,121] {subprocess.py:92} INFO - 22/06/08 05:21:51 INFO TaskSetManager: Finished task 39.0 in stage 0.0 (TID 39) in 32 ms on 1e082e99bba9 (executor driver) (40/180)
[2022-06-08 05:21:51,123] {subprocess.py:92} INFO - 22/06/08 05:21:51 INFO Executor: Running task 43.0 in stage 0.0 (TID 43)
[2022-06-08 05:21:51,131] {subprocess.py:92} INFO - 22/06/08 05:21:51 INFO Executor: Finished task 40.0 in stage 0.0 (TID 40). 2128 bytes result sent to driver
[2022-06-08 05:21:51,133] {subprocess.py:92} INFO - 22/06/08 05:21:51 INFO Executor: Finished task 42.0 in stage 0.0 (TID 42). 2367 bytes result sent to driver
[2022-06-08 05:21:51,136] {subprocess.py:92} INFO - 22/06/08 05:21:51 INFO TaskSetManager: Starting task 44.0 in stage 0.0 (TID 44) (1e082e99bba9, executor driver, partition 44, PROCESS_LOCAL, 4545 bytes) taskResourceAssignments Map()
[2022-06-08 05:21:51,138] {subprocess.py:92} INFO - 22/06/08 05:21:51 INFO Executor: Running task 44.0 in stage 0.0 (TID 44)
[2022-06-08 05:21:51,141] {subprocess.py:92} INFO - 22/06/08 05:21:51 INFO Executor: Finished task 43.0 in stage 0.0 (TID 43). 2606 bytes result sent to driver
[2022-06-08 05:21:51,142] {subprocess.py:92} INFO - 22/06/08 05:21:51 INFO TaskSetManager: Starting task 45.0 in stage 0.0 (TID 45) (1e082e99bba9, executor driver, partition 45, PROCESS_LOCAL, 4545 bytes) taskResourceAssignments Map()
[2022-06-08 05:21:51,143] {subprocess.py:92} INFO - 22/06/08 05:21:51 INFO Executor: Finished task 41.0 in stage 0.0 (TID 41). 2367 bytes result sent to driver
[2022-06-08 05:21:51,144] {subprocess.py:92} INFO - 22/06/08 05:21:51 INFO TaskSetManager: Finished task 40.0 in stage 0.0 (TID 40) in 46 ms on 1e082e99bba9 (executor driver) (41/180)
[2022-06-08 05:21:51,145] {subprocess.py:92} INFO - 22/06/08 05:21:51 INFO TaskSetManager: Finished task 42.0 in stage 0.0 (TID 42) in 31 ms on 1e082e99bba9 (executor driver) (42/180)
[2022-06-08 05:21:51,145] {subprocess.py:92} INFO - 22/06/08 05:21:51 INFO Executor: Running task 45.0 in stage 0.0 (TID 45)
[2022-06-08 05:21:51,151] {subprocess.py:92} INFO - 22/06/08 05:21:51 INFO TaskSetManager: Starting task 46.0 in stage 0.0 (TID 46) (1e082e99bba9, executor driver, partition 46, PROCESS_LOCAL, 4545 bytes) taskResourceAssignments Map()
[2022-06-08 05:21:51,153] {subprocess.py:92} INFO - 22/06/08 05:21:51 INFO TaskSetManager: Starting task 47.0 in stage 0.0 (TID 47) (1e082e99bba9, executor driver, partition 47, PROCESS_LOCAL, 4545 bytes) taskResourceAssignments Map()
[2022-06-08 05:21:51,155] {subprocess.py:92} INFO - 22/06/08 05:21:51 INFO TaskSetManager: Finished task 41.0 in stage 0.0 (TID 41) in 46 ms on 1e082e99bba9 (executor driver) (43/180)
[2022-06-08 05:21:51,157] {subprocess.py:92} INFO - 22/06/08 05:21:51 INFO TaskSetManager: Finished task 43.0 in stage 0.0 (TID 43) in 35 ms on 1e082e99bba9 (executor driver) (44/180)
[2022-06-08 05:21:51,158] {subprocess.py:92} INFO - 22/06/08 05:21:51 INFO Executor: Running task 47.0 in stage 0.0 (TID 47)
[2022-06-08 05:21:51,162] {subprocess.py:92} INFO - 22/06/08 05:21:51 INFO Executor: Running task 46.0 in stage 0.0 (TID 46)
[2022-06-08 05:21:51,176] {subprocess.py:92} INFO - 22/06/08 05:21:51 INFO Executor: Finished task 47.0 in stage 0.0 (TID 47). 2128 bytes result sent to driver
[2022-06-08 05:21:51,180] {subprocess.py:92} INFO - 22/06/08 05:21:51 INFO Executor: Finished task 44.0 in stage 0.0 (TID 44). 2128 bytes result sent to driver
[2022-06-08 05:21:51,181] {subprocess.py:92} INFO - 22/06/08 05:21:51 INFO TaskSetManager: Starting task 48.0 in stage 0.0 (TID 48) (1e082e99bba9, executor driver, partition 48, PROCESS_LOCAL, 4545 bytes) taskResourceAssignments Map()
[2022-06-08 05:21:51,182] {subprocess.py:92} INFO - 22/06/08 05:21:51 INFO Executor: Running task 48.0 in stage 0.0 (TID 48)
[2022-06-08 05:21:51,183] {subprocess.py:92} INFO - 22/06/08 05:21:51 INFO TaskSetManager: Finished task 47.0 in stage 0.0 (TID 47) in 30 ms on 1e082e99bba9 (executor driver) (45/180)
[2022-06-08 05:21:51,186] {subprocess.py:92} INFO - 22/06/08 05:21:51 INFO TaskSetManager: Starting task 49.0 in stage 0.0 (TID 49) (1e082e99bba9, executor driver, partition 49, PROCESS_LOCAL, 4545 bytes) taskResourceAssignments Map()
[2022-06-08 05:21:51,187] {subprocess.py:92} INFO - 22/06/08 05:21:51 INFO Executor: Running task 49.0 in stage 0.0 (TID 49)
[2022-06-08 05:21:51,189] {subprocess.py:92} INFO - 22/06/08 05:21:51 INFO TaskSetManager: Finished task 44.0 in stage 0.0 (TID 44) in 52 ms on 1e082e99bba9 (executor driver) (46/180)
[2022-06-08 05:21:51,191] {subprocess.py:92} INFO - 22/06/08 05:21:51 INFO Executor: Finished task 46.0 in stage 0.0 (TID 46). 2367 bytes result sent to driver
[2022-06-08 05:21:51,192] {subprocess.py:92} INFO - 22/06/08 05:21:51 INFO TaskSetManager: Starting task 50.0 in stage 0.0 (TID 50) (1e082e99bba9, executor driver, partition 50, PROCESS_LOCAL, 4545 bytes) taskResourceAssignments Map()
[2022-06-08 05:21:51,193] {subprocess.py:92} INFO - 22/06/08 05:21:51 INFO TaskSetManager: Finished task 46.0 in stage 0.0 (TID 46) in 40 ms on 1e082e99bba9 (executor driver) (47/180)
[2022-06-08 05:21:51,195] {subprocess.py:92} INFO - 22/06/08 05:21:51 INFO Executor: Running task 50.0 in stage 0.0 (TID 50)
[2022-06-08 05:21:51,198] {subprocess.py:92} INFO - 22/06/08 05:21:51 INFO Executor: Finished task 45.0 in stage 0.0 (TID 45). 2367 bytes result sent to driver
[2022-06-08 05:21:51,200] {subprocess.py:92} INFO - 22/06/08 05:21:51 INFO TaskSetManager: Starting task 51.0 in stage 0.0 (TID 51) (1e082e99bba9, executor driver, partition 51, PROCESS_LOCAL, 4545 bytes) taskResourceAssignments Map()
[2022-06-08 05:21:51,201] {subprocess.py:92} INFO - 22/06/08 05:21:51 INFO TaskSetManager: Finished task 45.0 in stage 0.0 (TID 45) in 60 ms on 1e082e99bba9 (executor driver) (48/180)
[2022-06-08 05:21:51,202] {subprocess.py:92} INFO - 22/06/08 05:21:51 INFO Executor: Running task 51.0 in stage 0.0 (TID 51)
[2022-06-08 05:21:51,206] {subprocess.py:92} INFO - 22/06/08 05:21:51 INFO Executor: Finished task 49.0 in stage 0.0 (TID 49). 2367 bytes result sent to driver
[2022-06-08 05:21:51,209] {subprocess.py:92} INFO - 22/06/08 05:21:51 INFO TaskSetManager: Starting task 52.0 in stage 0.0 (TID 52) (1e082e99bba9, executor driver, partition 52, PROCESS_LOCAL, 4545 bytes) taskResourceAssignments Map()
[2022-06-08 05:21:51,210] {subprocess.py:92} INFO - 22/06/08 05:21:51 INFO Executor: Finished task 48.0 in stage 0.0 (TID 48). 2367 bytes result sent to driver
[2022-06-08 05:21:51,210] {subprocess.py:92} INFO - 22/06/08 05:21:51 INFO Executor: Running task 52.0 in stage 0.0 (TID 52)
[2022-06-08 05:21:51,211] {subprocess.py:92} INFO - 22/06/08 05:21:51 INFO TaskSetManager: Starting task 53.0 in stage 0.0 (TID 53) (1e082e99bba9, executor driver, partition 53, PROCESS_LOCAL, 4545 bytes) taskResourceAssignments Map()
[2022-06-08 05:21:51,213] {subprocess.py:92} INFO - 22/06/08 05:21:51 INFO Executor: Running task 53.0 in stage 0.0 (TID 53)
[2022-06-08 05:21:51,214] {subprocess.py:92} INFO - 22/06/08 05:21:51 INFO TaskSetManager: Finished task 48.0 in stage 0.0 (TID 48) in 36 ms on 1e082e99bba9 (executor driver) (49/180)
[2022-06-08 05:21:51,215] {subprocess.py:92} INFO - 22/06/08 05:21:51 INFO TaskSetManager: Finished task 49.0 in stage 0.0 (TID 49) in 28 ms on 1e082e99bba9 (executor driver) (50/180)
[2022-06-08 05:21:51,218] {subprocess.py:92} INFO - 22/06/08 05:21:51 INFO Executor: Finished task 50.0 in stage 0.0 (TID 50). 2128 bytes result sent to driver
[2022-06-08 05:21:51,220] {subprocess.py:92} INFO - 22/06/08 05:21:51 INFO TaskSetManager: Starting task 54.0 in stage 0.0 (TID 54) (1e082e99bba9, executor driver, partition 54, PROCESS_LOCAL, 4545 bytes) taskResourceAssignments Map()
[2022-06-08 05:21:51,221] {subprocess.py:92} INFO - 22/06/08 05:21:51 INFO TaskSetManager: Finished task 50.0 in stage 0.0 (TID 50) in 32 ms on 1e082e99bba9 (executor driver) (51/180)
[2022-06-08 05:21:51,225] {subprocess.py:92} INFO - 22/06/08 05:21:51 INFO Executor: Running task 54.0 in stage 0.0 (TID 54)
[2022-06-08 05:21:51,228] {subprocess.py:92} INFO - 22/06/08 05:21:51 INFO Executor: Finished task 51.0 in stage 0.0 (TID 51). 2128 bytes result sent to driver
[2022-06-08 05:21:51,229] {subprocess.py:92} INFO - 22/06/08 05:21:51 INFO TaskSetManager: Starting task 55.0 in stage 0.0 (TID 55) (1e082e99bba9, executor driver, partition 55, PROCESS_LOCAL, 4545 bytes) taskResourceAssignments Map()
[2022-06-08 05:21:51,230] {subprocess.py:92} INFO - 22/06/08 05:21:51 INFO TaskSetManager: Finished task 51.0 in stage 0.0 (TID 51) in 32 ms on 1e082e99bba9 (executor driver) (52/180)
[2022-06-08 05:21:51,231] {subprocess.py:92} INFO - 22/06/08 05:21:51 INFO Executor: Running task 55.0 in stage 0.0 (TID 55)
[2022-06-08 05:21:51,245] {subprocess.py:92} INFO - 22/06/08 05:21:51 INFO Executor: Finished task 53.0 in stage 0.0 (TID 53). 2367 bytes result sent to driver
[2022-06-08 05:21:51,246] {subprocess.py:92} INFO - 22/06/08 05:21:51 INFO Executor: Finished task 52.0 in stage 0.0 (TID 52). 2367 bytes result sent to driver
[2022-06-08 05:21:51,285] {subprocess.py:92} INFO - 22/06/08 05:21:51 INFO Executor: Finished task 54.0 in stage 0.0 (TID 54). 2410 bytes result sent to driver
[2022-06-08 05:21:51,294] {subprocess.py:92} INFO - 22/06/08 05:21:51 INFO TaskSetManager: Starting task 56.0 in stage 0.0 (TID 56) (1e082e99bba9, executor driver, partition 56, PROCESS_LOCAL, 4545 bytes) taskResourceAssignments Map()
[2022-06-08 05:21:51,296] {subprocess.py:92} INFO - 22/06/08 05:21:51 INFO Executor: Running task 56.0 in stage 0.0 (TID 56)
[2022-06-08 05:21:51,297] {subprocess.py:92} INFO - 22/06/08 05:21:51 INFO TaskSetManager: Starting task 57.0 in stage 0.0 (TID 57) (1e082e99bba9, executor driver, partition 57, PROCESS_LOCAL, 4545 bytes) taskResourceAssignments Map()
[2022-06-08 05:21:51,298] {subprocess.py:92} INFO - 22/06/08 05:21:51 INFO Executor: Running task 57.0 in stage 0.0 (TID 57)
[2022-06-08 05:21:51,300] {subprocess.py:92} INFO - 22/06/08 05:21:51 INFO TaskSetManager: Starting task 58.0 in stage 0.0 (TID 58) (1e082e99bba9, executor driver, partition 58, PROCESS_LOCAL, 4545 bytes) taskResourceAssignments Map()
[2022-06-08 05:21:51,301] {subprocess.py:92} INFO - 22/06/08 05:21:51 INFO TaskSetManager: Finished task 53.0 in stage 0.0 (TID 53) in 90 ms on 1e082e99bba9 (executor driver) (53/180)
[2022-06-08 05:21:51,302] {subprocess.py:92} INFO - 22/06/08 05:21:51 INFO TaskSetManager: Finished task 54.0 in stage 0.0 (TID 54) in 82 ms on 1e082e99bba9 (executor driver) (54/180)
[2022-06-08 05:21:51,302] {subprocess.py:92} INFO - 22/06/08 05:21:51 INFO TaskSetManager: Finished task 52.0 in stage 0.0 (TID 52) in 94 ms on 1e082e99bba9 (executor driver) (55/180)
[2022-06-08 05:21:51,304] {subprocess.py:92} INFO - 22/06/08 05:21:51 INFO Executor: Running task 58.0 in stage 0.0 (TID 58)
[2022-06-08 05:21:51,314] {subprocess.py:92} INFO - 22/06/08 05:21:51 INFO Executor: Finished task 55.0 in stage 0.0 (TID 55). 2171 bytes result sent to driver
[2022-06-08 05:21:51,315] {subprocess.py:92} INFO - 22/06/08 05:21:51 INFO TaskSetManager: Starting task 59.0 in stage 0.0 (TID 59) (1e082e99bba9, executor driver, partition 59, PROCESS_LOCAL, 4545 bytes) taskResourceAssignments Map()
[2022-06-08 05:21:51,316] {subprocess.py:92} INFO - 22/06/08 05:21:51 INFO Executor: Running task 59.0 in stage 0.0 (TID 59)
[2022-06-08 05:21:51,317] {subprocess.py:92} INFO - 22/06/08 05:21:51 INFO TaskSetManager: Finished task 55.0 in stage 0.0 (TID 55) in 88 ms on 1e082e99bba9 (executor driver) (56/180)
[2022-06-08 05:21:51,324] {subprocess.py:92} INFO - 22/06/08 05:21:51 INFO Executor: Finished task 57.0 in stage 0.0 (TID 57). 2128 bytes result sent to driver
[2022-06-08 05:21:51,326] {subprocess.py:92} INFO - 22/06/08 05:21:51 INFO TaskSetManager: Starting task 60.0 in stage 0.0 (TID 60) (1e082e99bba9, executor driver, partition 60, PROCESS_LOCAL, 4545 bytes) taskResourceAssignments Map()
[2022-06-08 05:21:51,327] {subprocess.py:92} INFO - 22/06/08 05:21:51 INFO TaskSetManager: Finished task 57.0 in stage 0.0 (TID 57) in 30 ms on 1e082e99bba9 (executor driver) (57/180)
[2022-06-08 05:21:51,328] {subprocess.py:92} INFO - 22/06/08 05:21:51 INFO Executor: Running task 60.0 in stage 0.0 (TID 60)
[2022-06-08 05:21:51,343] {subprocess.py:92} INFO - 22/06/08 05:21:51 INFO Executor: Finished task 58.0 in stage 0.0 (TID 58). 2128 bytes result sent to driver
[2022-06-08 05:21:51,345] {subprocess.py:92} INFO - 22/06/08 05:21:51 INFO TaskSetManager: Starting task 61.0 in stage 0.0 (TID 61) (1e082e99bba9, executor driver, partition 61, PROCESS_LOCAL, 4545 bytes) taskResourceAssignments Map()
[2022-06-08 05:21:51,347] {subprocess.py:92} INFO - 22/06/08 05:21:51 INFO Executor: Finished task 60.0 in stage 0.0 (TID 60). 2367 bytes result sent to driver
[2022-06-08 05:21:51,348] {subprocess.py:92} INFO - 22/06/08 05:21:51 INFO TaskSetManager: Finished task 58.0 in stage 0.0 (TID 58) in 49 ms on 1e082e99bba9 (executor driver) (58/180)
[2022-06-08 05:21:51,349] {subprocess.py:92} INFO - 22/06/08 05:21:51 INFO Executor: Running task 61.0 in stage 0.0 (TID 61)
[2022-06-08 05:21:51,350] {subprocess.py:92} INFO - 22/06/08 05:21:51 INFO TaskSetManager: Finished task 60.0 in stage 0.0 (TID 60) in 23 ms on 1e082e99bba9 (executor driver) (59/180)
[2022-06-08 05:21:51,354] {subprocess.py:92} INFO - 22/06/08 05:21:51 INFO TaskSetManager: Starting task 62.0 in stage 0.0 (TID 62) (1e082e99bba9, executor driver, partition 62, PROCESS_LOCAL, 4545 bytes) taskResourceAssignments Map()
[2022-06-08 05:21:51,355] {subprocess.py:92} INFO - 22/06/08 05:21:51 INFO Executor: Finished task 56.0 in stage 0.0 (TID 56). 2171 bytes result sent to driver
[2022-06-08 05:21:51,356] {subprocess.py:92} INFO - 22/06/08 05:21:51 INFO Executor: Running task 62.0 in stage 0.0 (TID 62)
[2022-06-08 05:21:51,357] {subprocess.py:92} INFO - 22/06/08 05:21:51 INFO Executor: Finished task 59.0 in stage 0.0 (TID 59). 2367 bytes result sent to driver
[2022-06-08 05:21:51,366] {subprocess.py:92} INFO - 22/06/08 05:21:51 INFO TaskSetManager: Starting task 63.0 in stage 0.0 (TID 63) (1e082e99bba9, executor driver, partition 63, PROCESS_LOCAL, 4545 bytes) taskResourceAssignments Map()
[2022-06-08 05:21:51,367] {subprocess.py:92} INFO - 22/06/08 05:21:51 INFO Executor: Running task 63.0 in stage 0.0 (TID 63)
[2022-06-08 05:21:51,369] {subprocess.py:92} INFO - 22/06/08 05:21:51 INFO TaskSetManager: Finished task 59.0 in stage 0.0 (TID 59) in 52 ms on 1e082e99bba9 (executor driver) (60/180)
[2022-06-08 05:21:51,383] {subprocess.py:92} INFO - 22/06/08 05:21:51 INFO TaskSetManager: Starting task 64.0 in stage 0.0 (TID 64) (1e082e99bba9, executor driver, partition 64, PROCESS_LOCAL, 4545 bytes) taskResourceAssignments Map()
[2022-06-08 05:21:51,386] {subprocess.py:92} INFO - 22/06/08 05:21:51 INFO Executor: Finished task 62.0 in stage 0.0 (TID 62). 2367 bytes result sent to driver
[2022-06-08 05:21:51,387] {subprocess.py:92} INFO - 22/06/08 05:21:51 INFO Executor: Finished task 61.0 in stage 0.0 (TID 61). 2606 bytes result sent to driver
[2022-06-08 05:21:51,388] {subprocess.py:92} INFO - 22/06/08 05:21:51 INFO Executor: Running task 64.0 in stage 0.0 (TID 64)
[2022-06-08 05:21:51,389] {subprocess.py:92} INFO - 22/06/08 05:21:51 INFO TaskSetManager: Finished task 56.0 in stage 0.0 (TID 56) in 137 ms on 1e082e99bba9 (executor driver) (61/180)
[2022-06-08 05:21:51,391] {subprocess.py:92} INFO - 22/06/08 05:21:51 INFO TaskSetManager: Starting task 65.0 in stage 0.0 (TID 65) (1e082e99bba9, executor driver, partition 65, PROCESS_LOCAL, 4545 bytes) taskResourceAssignments Map()
[2022-06-08 05:21:51,393] {subprocess.py:92} INFO - 22/06/08 05:21:51 INFO Executor: Running task 65.0 in stage 0.0 (TID 65)
[2022-06-08 05:21:51,394] {subprocess.py:92} INFO - 22/06/08 05:21:51 INFO TaskSetManager: Starting task 66.0 in stage 0.0 (TID 66) (1e082e99bba9, executor driver, partition 66, PROCESS_LOCAL, 4545 bytes) taskResourceAssignments Map()
[2022-06-08 05:21:51,396] {subprocess.py:92} INFO - 22/06/08 05:21:51 INFO TaskSetManager: Finished task 61.0 in stage 0.0 (TID 61) in 51 ms on 1e082e99bba9 (executor driver) (62/180)
[2022-06-08 05:21:51,397] {subprocess.py:92} INFO - 22/06/08 05:21:51 INFO TaskSetManager: Finished task 62.0 in stage 0.0 (TID 62) in 46 ms on 1e082e99bba9 (executor driver) (63/180)
[2022-06-08 05:21:51,399] {subprocess.py:92} INFO - 22/06/08 05:21:51 INFO Executor: Running task 66.0 in stage 0.0 (TID 66)
[2022-06-08 05:21:51,409] {subprocess.py:92} INFO - 22/06/08 05:21:51 INFO Executor: Finished task 63.0 in stage 0.0 (TID 63). 2367 bytes result sent to driver
[2022-06-08 05:21:51,410] {subprocess.py:92} INFO - 22/06/08 05:21:51 INFO TaskSetManager: Starting task 67.0 in stage 0.0 (TID 67) (1e082e99bba9, executor driver, partition 67, PROCESS_LOCAL, 4545 bytes) taskResourceAssignments Map()
[2022-06-08 05:21:51,411] {subprocess.py:92} INFO - 22/06/08 05:21:51 INFO Executor: Running task 67.0 in stage 0.0 (TID 67)
[2022-06-08 05:21:51,412] {subprocess.py:92} INFO - 22/06/08 05:21:51 INFO TaskSetManager: Finished task 63.0 in stage 0.0 (TID 63) in 53 ms on 1e082e99bba9 (executor driver) (64/180)
[2022-06-08 05:21:51,420] {subprocess.py:92} INFO - 22/06/08 05:21:51 INFO Executor: Finished task 65.0 in stage 0.0 (TID 65). 2367 bytes result sent to driver
[2022-06-08 05:21:51,421] {subprocess.py:92} INFO - 22/06/08 05:21:51 INFO TaskSetManager: Starting task 68.0 in stage 0.0 (TID 68) (1e082e99bba9, executor driver, partition 68, PROCESS_LOCAL, 4545 bytes) taskResourceAssignments Map()
[2022-06-08 05:21:51,423] {subprocess.py:92} INFO - 22/06/08 05:21:51 INFO Executor: Running task 68.0 in stage 0.0 (TID 68)
[2022-06-08 05:21:51,424] {subprocess.py:92} INFO - 22/06/08 05:21:51 INFO TaskSetManager: Finished task 65.0 in stage 0.0 (TID 65) in 35 ms on 1e082e99bba9 (executor driver) (65/180)
[2022-06-08 05:21:51,429] {subprocess.py:92} INFO - 22/06/08 05:21:51 INFO Executor: Finished task 67.0 in stage 0.0 (TID 67). 2606 bytes result sent to driver
[2022-06-08 05:21:51,430] {subprocess.py:92} INFO - 22/06/08 05:21:51 INFO TaskSetManager: Starting task 69.0 in stage 0.0 (TID 69) (1e082e99bba9, executor driver, partition 69, PROCESS_LOCAL, 4545 bytes) taskResourceAssignments Map()
[2022-06-08 05:21:51,431] {subprocess.py:92} INFO - 22/06/08 05:21:51 INFO Executor: Running task 69.0 in stage 0.0 (TID 69)
[2022-06-08 05:21:51,432] {subprocess.py:92} INFO - 22/06/08 05:21:51 INFO TaskSetManager: Finished task 67.0 in stage 0.0 (TID 67) in 22 ms on 1e082e99bba9 (executor driver) (66/180)
[2022-06-08 05:21:51,435] {subprocess.py:92} INFO - 22/06/08 05:21:51 INFO Executor: Finished task 64.0 in stage 0.0 (TID 64). 2367 bytes result sent to driver
[2022-06-08 05:21:51,437] {subprocess.py:92} INFO - 22/06/08 05:21:51 INFO TaskSetManager: Starting task 70.0 in stage 0.0 (TID 70) (1e082e99bba9, executor driver, partition 70, PROCESS_LOCAL, 4545 bytes) taskResourceAssignments Map()
[2022-06-08 05:21:51,437] {subprocess.py:92} INFO - 22/06/08 05:21:51 INFO TaskSetManager: Finished task 64.0 in stage 0.0 (TID 64) in 63 ms on 1e082e99bba9 (executor driver) (67/180)
[2022-06-08 05:21:51,438] {subprocess.py:92} INFO - 22/06/08 05:21:51 INFO Executor: Running task 70.0 in stage 0.0 (TID 70)
[2022-06-08 05:21:51,443] {subprocess.py:92} INFO - 22/06/08 05:21:51 INFO Executor: Finished task 66.0 in stage 0.0 (TID 66). 2606 bytes result sent to driver
[2022-06-08 05:21:51,446] {subprocess.py:92} INFO - 22/06/08 05:21:51 INFO TaskSetManager: Starting task 71.0 in stage 0.0 (TID 71) (1e082e99bba9, executor driver, partition 71, PROCESS_LOCAL, 4545 bytes) taskResourceAssignments Map()
[2022-06-08 05:21:51,447] {subprocess.py:92} INFO - 22/06/08 05:21:51 INFO TaskSetManager: Finished task 66.0 in stage 0.0 (TID 66) in 55 ms on 1e082e99bba9 (executor driver) (68/180)
[2022-06-08 05:21:51,449] {subprocess.py:92} INFO - 22/06/08 05:21:51 INFO Executor: Running task 71.0 in stage 0.0 (TID 71)
[2022-06-08 05:21:51,454] {subprocess.py:92} INFO - 22/06/08 05:21:51 INFO Executor: Finished task 68.0 in stage 0.0 (TID 68). 2367 bytes result sent to driver
[2022-06-08 05:21:51,457] {subprocess.py:92} INFO - 22/06/08 05:21:51 INFO TaskSetManager: Starting task 72.0 in stage 0.0 (TID 72) (1e082e99bba9, executor driver, partition 72, PROCESS_LOCAL, 4545 bytes) taskResourceAssignments Map()
[2022-06-08 05:21:51,459] {subprocess.py:92} INFO - 22/06/08 05:21:51 INFO Executor: Running task 72.0 in stage 0.0 (TID 72)
[2022-06-08 05:21:51,460] {subprocess.py:92} INFO - 22/06/08 05:21:51 INFO TaskSetManager: Finished task 68.0 in stage 0.0 (TID 68) in 39 ms on 1e082e99bba9 (executor driver) (69/180)
[2022-06-08 05:21:51,464] {subprocess.py:92} INFO - 22/06/08 05:21:51 INFO Executor: Finished task 70.0 in stage 0.0 (TID 70). 2606 bytes result sent to driver
[2022-06-08 05:21:51,466] {subprocess.py:92} INFO - 22/06/08 05:21:51 INFO TaskSetManager: Starting task 73.0 in stage 0.0 (TID 73) (1e082e99bba9, executor driver, partition 73, PROCESS_LOCAL, 4545 bytes) taskResourceAssignments Map()
[2022-06-08 05:21:51,467] {subprocess.py:92} INFO - 22/06/08 05:21:51 INFO TaskSetManager: Finished task 70.0 in stage 0.0 (TID 70) in 30 ms on 1e082e99bba9 (executor driver) (70/180)
[2022-06-08 05:21:51,469] {subprocess.py:92} INFO - 22/06/08 05:21:51 INFO Executor: Running task 73.0 in stage 0.0 (TID 73)
[2022-06-08 05:21:51,471] {subprocess.py:92} INFO - 22/06/08 05:21:51 INFO Executor: Finished task 69.0 in stage 0.0 (TID 69). 2367 bytes result sent to driver
[2022-06-08 05:21:51,473] {subprocess.py:92} INFO - 22/06/08 05:21:51 INFO TaskSetManager: Starting task 74.0 in stage 0.0 (TID 74) (1e082e99bba9, executor driver, partition 74, PROCESS_LOCAL, 4545 bytes) taskResourceAssignments Map()
[2022-06-08 05:21:51,474] {subprocess.py:92} INFO - 22/06/08 05:21:51 INFO TaskSetManager: Finished task 69.0 in stage 0.0 (TID 69) in 45 ms on 1e082e99bba9 (executor driver) (71/180)
[2022-06-08 05:21:51,475] {subprocess.py:92} INFO - 22/06/08 05:21:51 INFO Executor: Running task 74.0 in stage 0.0 (TID 74)
[2022-06-08 05:21:51,478] {subprocess.py:92} INFO - 22/06/08 05:21:51 INFO Executor: Finished task 71.0 in stage 0.0 (TID 71). 2367 bytes result sent to driver
[2022-06-08 05:21:51,481] {subprocess.py:92} INFO - 22/06/08 05:21:51 INFO TaskSetManager: Starting task 75.0 in stage 0.0 (TID 75) (1e082e99bba9, executor driver, partition 75, PROCESS_LOCAL, 4545 bytes) taskResourceAssignments Map()
[2022-06-08 05:21:51,482] {subprocess.py:92} INFO - 22/06/08 05:21:51 INFO TaskSetManager: Finished task 71.0 in stage 0.0 (TID 71) in 37 ms on 1e082e99bba9 (executor driver) (72/180)
[2022-06-08 05:21:51,484] {subprocess.py:92} INFO - 22/06/08 05:21:51 INFO Executor: Running task 75.0 in stage 0.0 (TID 75)
[2022-06-08 05:21:51,487] {subprocess.py:92} INFO - 22/06/08 05:21:51 INFO Executor: Finished task 72.0 in stage 0.0 (TID 72). 2367 bytes result sent to driver
[2022-06-08 05:21:51,489] {subprocess.py:92} INFO - 22/06/08 05:21:51 INFO TaskSetManager: Starting task 76.0 in stage 0.0 (TID 76) (1e082e99bba9, executor driver, partition 76, PROCESS_LOCAL, 4545 bytes) taskResourceAssignments Map()
[2022-06-08 05:21:51,490] {subprocess.py:92} INFO - 22/06/08 05:21:51 INFO Executor: Running task 76.0 in stage 0.0 (TID 76)
[2022-06-08 05:21:51,492] {subprocess.py:92} INFO - 22/06/08 05:21:51 INFO TaskSetManager: Finished task 72.0 in stage 0.0 (TID 72) in 36 ms on 1e082e99bba9 (executor driver) (73/180)
[2022-06-08 05:21:51,499] {subprocess.py:92} INFO - 22/06/08 05:21:51 INFO Executor: Finished task 73.0 in stage 0.0 (TID 73). 2367 bytes result sent to driver
[2022-06-08 05:21:51,501] {subprocess.py:92} INFO - 22/06/08 05:21:51 INFO TaskSetManager: Starting task 77.0 in stage 0.0 (TID 77) (1e082e99bba9, executor driver, partition 77, PROCESS_LOCAL, 4545 bytes) taskResourceAssignments Map()
[2022-06-08 05:21:51,503] {subprocess.py:92} INFO - 22/06/08 05:21:51 INFO Executor: Finished task 75.0 in stage 0.0 (TID 75). 2367 bytes result sent to driver
[2022-06-08 05:21:51,504] {subprocess.py:92} INFO - 22/06/08 05:21:51 INFO Executor: Running task 77.0 in stage 0.0 (TID 77)
[2022-06-08 05:21:51,504] {subprocess.py:92} INFO - 22/06/08 05:21:51 INFO TaskSetManager: Starting task 78.0 in stage 0.0 (TID 78) (1e082e99bba9, executor driver, partition 78, PROCESS_LOCAL, 4545 bytes) taskResourceAssignments Map()
[2022-06-08 05:21:51,507] {subprocess.py:92} INFO - 22/06/08 05:21:51 INFO Executor: Finished task 76.0 in stage 0.0 (TID 76). 2367 bytes result sent to driver
[2022-06-08 05:21:51,508] {subprocess.py:92} INFO - 22/06/08 05:21:51 INFO Executor: Running task 78.0 in stage 0.0 (TID 78)
[2022-06-08 05:21:51,509] {subprocess.py:92} INFO - 22/06/08 05:21:51 INFO TaskSetManager: Finished task 73.0 in stage 0.0 (TID 73) in 40 ms on 1e082e99bba9 (executor driver) (74/180)
[2022-06-08 05:21:51,510] {subprocess.py:92} INFO - 22/06/08 05:21:51 INFO TaskSetManager: Starting task 79.0 in stage 0.0 (TID 79) (1e082e99bba9, executor driver, partition 79, PROCESS_LOCAL, 4545 bytes) taskResourceAssignments Map()
[2022-06-08 05:21:51,512] {subprocess.py:92} INFO - 22/06/08 05:21:51 INFO TaskSetManager: Finished task 75.0 in stage 0.0 (TID 75) in 31 ms on 1e082e99bba9 (executor driver) (75/180)
[2022-06-08 05:21:51,513] {subprocess.py:92} INFO - 22/06/08 05:21:51 INFO Executor: Running task 79.0 in stage 0.0 (TID 79)
[2022-06-08 05:21:51,514] {subprocess.py:92} INFO - 22/06/08 05:21:51 INFO TaskSetManager: Finished task 76.0 in stage 0.0 (TID 76) in 24 ms on 1e082e99bba9 (executor driver) (76/180)
[2022-06-08 05:21:51,523] {subprocess.py:92} INFO - 22/06/08 05:21:51 INFO Executor: Finished task 74.0 in stage 0.0 (TID 74). 2606 bytes result sent to driver
[2022-06-08 05:21:51,525] {subprocess.py:92} INFO - 22/06/08 05:21:51 INFO TaskSetManager: Starting task 80.0 in stage 0.0 (TID 80) (1e082e99bba9, executor driver, partition 80, PROCESS_LOCAL, 4545 bytes) taskResourceAssignments Map()
[2022-06-08 05:21:51,526] {subprocess.py:92} INFO - 22/06/08 05:21:51 INFO Executor: Finished task 78.0 in stage 0.0 (TID 78). 2367 bytes result sent to driver
[2022-06-08 05:21:51,527] {subprocess.py:92} INFO - 22/06/08 05:21:51 INFO TaskSetManager: Starting task 81.0 in stage 0.0 (TID 81) (1e082e99bba9, executor driver, partition 81, PROCESS_LOCAL, 4545 bytes) taskResourceAssignments Map()
[2022-06-08 05:21:51,528] {subprocess.py:92} INFO - 22/06/08 05:21:51 INFO Executor: Running task 80.0 in stage 0.0 (TID 80)
[2022-06-08 05:21:51,529] {subprocess.py:92} INFO - 22/06/08 05:21:51 INFO TaskSetManager: Finished task 74.0 in stage 0.0 (TID 74) in 55 ms on 1e082e99bba9 (executor driver) (77/180)
[2022-06-08 05:21:51,530] {subprocess.py:92} INFO - 22/06/08 05:21:51 INFO Executor: Running task 81.0 in stage 0.0 (TID 81)
[2022-06-08 05:21:51,531] {subprocess.py:92} INFO - 22/06/08 05:21:51 INFO TaskSetManager: Finished task 78.0 in stage 0.0 (TID 78) in 26 ms on 1e082e99bba9 (executor driver) (78/180)
[2022-06-08 05:21:51,534] {subprocess.py:92} INFO - 22/06/08 05:21:51 INFO Executor: Finished task 79.0 in stage 0.0 (TID 79). 2606 bytes result sent to driver
[2022-06-08 05:21:51,535] {subprocess.py:92} INFO - 22/06/08 05:21:51 INFO TaskSetManager: Finished task 79.0 in stage 0.0 (TID 79) in 26 ms on 1e082e99bba9 (executor driver) (79/180)
[2022-06-08 05:21:51,537] {subprocess.py:92} INFO - 22/06/08 05:21:51 INFO TaskSetManager: Starting task 82.0 in stage 0.0 (TID 82) (1e082e99bba9, executor driver, partition 82, PROCESS_LOCAL, 4545 bytes) taskResourceAssignments Map()
[2022-06-08 05:21:51,540] {subprocess.py:92} INFO - 22/06/08 05:21:51 INFO Executor: Running task 82.0 in stage 0.0 (TID 82)
[2022-06-08 05:21:51,543] {subprocess.py:92} INFO - 22/06/08 05:21:51 INFO Executor: Finished task 77.0 in stage 0.0 (TID 77). 2367 bytes result sent to driver
[2022-06-08 05:21:51,546] {subprocess.py:92} INFO - 22/06/08 05:21:51 INFO TaskSetManager: Starting task 83.0 in stage 0.0 (TID 83) (1e082e99bba9, executor driver, partition 83, PROCESS_LOCAL, 4545 bytes) taskResourceAssignments Map()
[2022-06-08 05:21:51,547] {subprocess.py:92} INFO - 22/06/08 05:21:51 INFO Executor: Running task 83.0 in stage 0.0 (TID 83)
[2022-06-08 05:21:51,548] {subprocess.py:92} INFO - 22/06/08 05:21:51 INFO TaskSetManager: Finished task 77.0 in stage 0.0 (TID 77) in 46 ms on 1e082e99bba9 (executor driver) (80/180)
[2022-06-08 05:21:51,556] {subprocess.py:92} INFO - 22/06/08 05:21:51 INFO Executor: Finished task 80.0 in stage 0.0 (TID 80). 2606 bytes result sent to driver
[2022-06-08 05:21:51,557] {subprocess.py:92} INFO - 22/06/08 05:21:51 INFO TaskSetManager: Starting task 84.0 in stage 0.0 (TID 84) (1e082e99bba9, executor driver, partition 84, PROCESS_LOCAL, 4545 bytes) taskResourceAssignments Map()
[2022-06-08 05:21:51,559] {subprocess.py:92} INFO - 22/06/08 05:21:51 INFO TaskSetManager: Finished task 80.0 in stage 0.0 (TID 80) in 34 ms on 1e082e99bba9 (executor driver) (81/180)
[2022-06-08 05:21:51,560] {subprocess.py:92} INFO - 22/06/08 05:21:51 INFO Executor: Finished task 81.0 in stage 0.0 (TID 81). 2367 bytes result sent to driver
[2022-06-08 05:21:51,560] {subprocess.py:92} INFO - 22/06/08 05:21:51 INFO Executor: Running task 84.0 in stage 0.0 (TID 84)
[2022-06-08 05:21:51,562] {subprocess.py:92} INFO - 22/06/08 05:21:51 INFO TaskSetManager: Starting task 85.0 in stage 0.0 (TID 85) (1e082e99bba9, executor driver, partition 85, PROCESS_LOCAL, 4545 bytes) taskResourceAssignments Map()
[2022-06-08 05:21:51,563] {subprocess.py:92} INFO - 22/06/08 05:21:51 INFO TaskSetManager: Finished task 81.0 in stage 0.0 (TID 81) in 36 ms on 1e082e99bba9 (executor driver) (82/180)
[2022-06-08 05:21:51,565] {subprocess.py:92} INFO - 22/06/08 05:21:51 INFO Executor: Running task 85.0 in stage 0.0 (TID 85)
[2022-06-08 05:21:51,565] {subprocess.py:92} INFO - 22/06/08 05:21:51 INFO Executor: Finished task 82.0 in stage 0.0 (TID 82). 2606 bytes result sent to driver
[2022-06-08 05:21:51,567] {subprocess.py:92} INFO - 22/06/08 05:21:51 INFO TaskSetManager: Starting task 86.0 in stage 0.0 (TID 86) (1e082e99bba9, executor driver, partition 86, PROCESS_LOCAL, 4545 bytes) taskResourceAssignments Map()
[2022-06-08 05:21:51,568] {subprocess.py:92} INFO - 22/06/08 05:21:51 INFO Executor: Running task 86.0 in stage 0.0 (TID 86)
[2022-06-08 05:21:51,569] {subprocess.py:92} INFO - 22/06/08 05:21:51 INFO TaskSetManager: Finished task 82.0 in stage 0.0 (TID 82) in 31 ms on 1e082e99bba9 (executor driver) (83/180)
[2022-06-08 05:21:51,570] {subprocess.py:92} INFO - 22/06/08 05:21:51 INFO Executor: Finished task 83.0 in stage 0.0 (TID 83). 2367 bytes result sent to driver
[2022-06-08 05:21:51,572] {subprocess.py:92} INFO - 22/06/08 05:21:51 INFO TaskSetManager: Starting task 87.0 in stage 0.0 (TID 87) (1e082e99bba9, executor driver, partition 87, PROCESS_LOCAL, 4545 bytes) taskResourceAssignments Map()
[2022-06-08 05:21:51,574] {subprocess.py:92} INFO - 22/06/08 05:21:51 INFO TaskSetManager: Finished task 83.0 in stage 0.0 (TID 83) in 28 ms on 1e082e99bba9 (executor driver) (84/180)
[2022-06-08 05:21:51,574] {subprocess.py:92} INFO - 22/06/08 05:21:51 INFO Executor: Running task 87.0 in stage 0.0 (TID 87)
[2022-06-08 05:21:51,583] {subprocess.py:92} INFO - 22/06/08 05:21:51 INFO Executor: Finished task 84.0 in stage 0.0 (TID 84). 2367 bytes result sent to driver
[2022-06-08 05:21:51,585] {subprocess.py:92} INFO - 22/06/08 05:21:51 INFO TaskSetManager: Starting task 88.0 in stage 0.0 (TID 88) (1e082e99bba9, executor driver, partition 88, PROCESS_LOCAL, 4545 bytes) taskResourceAssignments Map()
[2022-06-08 05:21:51,587] {subprocess.py:92} INFO - 22/06/08 05:21:51 INFO TaskSetManager: Finished task 84.0 in stage 0.0 (TID 84) in 30 ms on 1e082e99bba9 (executor driver) (85/180)
[2022-06-08 05:21:51,588] {subprocess.py:92} INFO - 22/06/08 05:21:51 INFO Executor: Running task 88.0 in stage 0.0 (TID 88)
[2022-06-08 05:21:51,591] {subprocess.py:92} INFO - 22/06/08 05:21:51 INFO Executor: Finished task 85.0 in stage 0.0 (TID 85). 2367 bytes result sent to driver
[2022-06-08 05:21:51,592] {subprocess.py:92} INFO - 22/06/08 05:21:51 INFO TaskSetManager: Starting task 89.0 in stage 0.0 (TID 89) (1e082e99bba9, executor driver, partition 89, PROCESS_LOCAL, 4545 bytes) taskResourceAssignments Map()
[2022-06-08 05:21:51,593] {subprocess.py:92} INFO - 22/06/08 05:21:51 INFO Executor: Running task 89.0 in stage 0.0 (TID 89)
[2022-06-08 05:21:51,594] {subprocess.py:92} INFO - 22/06/08 05:21:51 INFO TaskSetManager: Finished task 85.0 in stage 0.0 (TID 85) in 32 ms on 1e082e99bba9 (executor driver) (86/180)
[2022-06-08 05:21:51,595] {subprocess.py:92} INFO - 22/06/08 05:21:51 INFO Executor: Finished task 87.0 in stage 0.0 (TID 87). 2410 bytes result sent to driver
[2022-06-08 05:21:51,596] {subprocess.py:92} INFO - 22/06/08 05:21:51 INFO Executor: Finished task 86.0 in stage 0.0 (TID 86). 2367 bytes result sent to driver
[2022-06-08 05:21:51,598] {subprocess.py:92} INFO - 22/06/08 05:21:51 INFO TaskSetManager: Starting task 90.0 in stage 0.0 (TID 90) (1e082e99bba9, executor driver, partition 90, PROCESS_LOCAL, 4545 bytes) taskResourceAssignments Map()
[2022-06-08 05:21:51,599] {subprocess.py:92} INFO - 22/06/08 05:21:51 INFO Executor: Running task 90.0 in stage 0.0 (TID 90)
[2022-06-08 05:21:51,603] {subprocess.py:92} INFO - 22/06/08 05:21:51 INFO TaskSetManager: Starting task 91.0 in stage 0.0 (TID 91) (1e082e99bba9, executor driver, partition 91, PROCESS_LOCAL, 4545 bytes) taskResourceAssignments Map()
[2022-06-08 05:21:51,604] {subprocess.py:92} INFO - 22/06/08 05:21:51 INFO Executor: Running task 91.0 in stage 0.0 (TID 91)
[2022-06-08 05:21:51,607] {subprocess.py:92} INFO - 22/06/08 05:21:51 INFO TaskSetManager: Finished task 86.0 in stage 0.0 (TID 86) in 35 ms on 1e082e99bba9 (executor driver) (87/180)
[2022-06-08 05:21:51,607] {subprocess.py:92} INFO - 22/06/08 05:21:51 INFO TaskSetManager: Finished task 87.0 in stage 0.0 (TID 87) in 30 ms on 1e082e99bba9 (executor driver) (88/180)
[2022-06-08 05:21:51,614] {subprocess.py:92} INFO - 22/06/08 05:21:51 INFO Executor: Finished task 88.0 in stage 0.0 (TID 88). 2606 bytes result sent to driver
[2022-06-08 05:21:51,616] {subprocess.py:92} INFO - 22/06/08 05:21:51 INFO TaskSetManager: Starting task 92.0 in stage 0.0 (TID 92) (1e082e99bba9, executor driver, partition 92, PROCESS_LOCAL, 4545 bytes) taskResourceAssignments Map()
[2022-06-08 05:21:51,617] {subprocess.py:92} INFO - 22/06/08 05:21:51 INFO TaskSetManager: Finished task 88.0 in stage 0.0 (TID 88) in 33 ms on 1e082e99bba9 (executor driver) (89/180)
[2022-06-08 05:21:51,618] {subprocess.py:92} INFO - 22/06/08 05:21:51 INFO Executor: Running task 92.0 in stage 0.0 (TID 92)
[2022-06-08 05:21:51,620] {subprocess.py:92} INFO - 22/06/08 05:21:51 INFO Executor: Finished task 91.0 in stage 0.0 (TID 91). 2367 bytes result sent to driver
[2022-06-08 05:21:51,622] {subprocess.py:92} INFO - 22/06/08 05:21:51 INFO TaskSetManager: Starting task 93.0 in stage 0.0 (TID 93) (1e082e99bba9, executor driver, partition 93, PROCESS_LOCAL, 4545 bytes) taskResourceAssignments Map()
[2022-06-08 05:21:51,625] {subprocess.py:92} INFO - 22/06/08 05:21:51 INFO TaskSetManager: Finished task 91.0 in stage 0.0 (TID 91) in 23 ms on 1e082e99bba9 (executor driver) (90/180)
[2022-06-08 05:21:51,627] {subprocess.py:92} INFO - 22/06/08 05:21:51 INFO Executor: Running task 93.0 in stage 0.0 (TID 93)
[2022-06-08 05:21:51,628] {subprocess.py:92} INFO - 22/06/08 05:21:51 INFO Executor: Finished task 90.0 in stage 0.0 (TID 90). 2367 bytes result sent to driver
[2022-06-08 05:21:51,628] {subprocess.py:92} INFO - 22/06/08 05:21:51 INFO Executor: Finished task 89.0 in stage 0.0 (TID 89). 2367 bytes result sent to driver
[2022-06-08 05:21:51,629] {subprocess.py:92} INFO - 22/06/08 05:21:51 INFO TaskSetManager: Starting task 94.0 in stage 0.0 (TID 94) (1e082e99bba9, executor driver, partition 94, PROCESS_LOCAL, 4545 bytes) taskResourceAssignments Map()
[2022-06-08 05:21:51,630] {subprocess.py:92} INFO - 22/06/08 05:21:51 INFO Executor: Running task 94.0 in stage 0.0 (TID 94)
[2022-06-08 05:21:51,631] {subprocess.py:92} INFO - 22/06/08 05:21:51 INFO TaskSetManager: Finished task 90.0 in stage 0.0 (TID 90) in 30 ms on 1e082e99bba9 (executor driver) (91/180)
[2022-06-08 05:21:51,638] {subprocess.py:92} INFO - 22/06/08 05:21:51 INFO TaskSetManager: Starting task 95.0 in stage 0.0 (TID 95) (1e082e99bba9, executor driver, partition 95, PROCESS_LOCAL, 4545 bytes) taskResourceAssignments Map()
[2022-06-08 05:21:51,639] {subprocess.py:92} INFO - 22/06/08 05:21:51 INFO Executor: Finished task 92.0 in stage 0.0 (TID 92). 2606 bytes result sent to driver
[2022-06-08 05:21:51,640] {subprocess.py:92} INFO - 22/06/08 05:21:51 INFO TaskSetManager: Finished task 89.0 in stage 0.0 (TID 89) in 48 ms on 1e082e99bba9 (executor driver) (92/180)
[2022-06-08 05:21:51,642] {subprocess.py:92} INFO - 22/06/08 05:21:51 INFO Executor: Running task 95.0 in stage 0.0 (TID 95)
[2022-06-08 05:21:51,643] {subprocess.py:92} INFO - 22/06/08 05:21:51 INFO Executor: Finished task 93.0 in stage 0.0 (TID 93). 2606 bytes result sent to driver
[2022-06-08 05:21:51,645] {subprocess.py:92} INFO - 22/06/08 05:21:51 INFO Executor: Finished task 94.0 in stage 0.0 (TID 94). 2367 bytes result sent to driver
[2022-06-08 05:21:51,646] {subprocess.py:92} INFO - 22/06/08 05:21:51 INFO TaskSetManager: Starting task 96.0 in stage 0.0 (TID 96) (1e082e99bba9, executor driver, partition 96, PROCESS_LOCAL, 4545 bytes) taskResourceAssignments Map()
[2022-06-08 05:21:51,647] {subprocess.py:92} INFO - 22/06/08 05:21:51 INFO Executor: Running task 96.0 in stage 0.0 (TID 96)
[2022-06-08 05:21:51,649] {subprocess.py:92} INFO - 22/06/08 05:21:51 INFO TaskSetManager: Starting task 97.0 in stage 0.0 (TID 97) (1e082e99bba9, executor driver, partition 97, PROCESS_LOCAL, 4545 bytes) taskResourceAssignments Map()
[2022-06-08 05:21:51,651] {subprocess.py:92} INFO - 22/06/08 05:21:51 INFO TaskSetManager: Starting task 98.0 in stage 0.0 (TID 98) (1e082e99bba9, executor driver, partition 98, PROCESS_LOCAL, 4545 bytes) taskResourceAssignments Map()
[2022-06-08 05:21:51,652] {subprocess.py:92} INFO - 22/06/08 05:21:51 INFO TaskSetManager: Finished task 93.0 in stage 0.0 (TID 93) in 30 ms on 1e082e99bba9 (executor driver) (93/180)
[2022-06-08 05:21:51,653] {subprocess.py:92} INFO - 22/06/08 05:21:51 INFO TaskSetManager: Finished task 94.0 in stage 0.0 (TID 94) in 26 ms on 1e082e99bba9 (executor driver) (94/180)
[2022-06-08 05:21:51,654] {subprocess.py:92} INFO - 22/06/08 05:21:51 INFO TaskSetManager: Finished task 92.0 in stage 0.0 (TID 92) in 39 ms on 1e082e99bba9 (executor driver) (95/180)
[2022-06-08 05:21:51,655] {subprocess.py:92} INFO - 22/06/08 05:21:51 INFO Executor: Running task 98.0 in stage 0.0 (TID 98)
[2022-06-08 05:21:51,659] {subprocess.py:92} INFO - 22/06/08 05:21:51 INFO Executor: Running task 97.0 in stage 0.0 (TID 97)
[2022-06-08 05:21:51,661] {subprocess.py:92} INFO - 22/06/08 05:21:51 INFO Executor: Finished task 95.0 in stage 0.0 (TID 95). 2367 bytes result sent to driver
[2022-06-08 05:21:51,662] {subprocess.py:92} INFO - 22/06/08 05:21:51 INFO TaskSetManager: Starting task 99.0 in stage 0.0 (TID 99) (1e082e99bba9, executor driver, partition 99, PROCESS_LOCAL, 4545 bytes) taskResourceAssignments Map()
[2022-06-08 05:21:51,663] {subprocess.py:92} INFO - 22/06/08 05:21:51 INFO TaskSetManager: Finished task 95.0 in stage 0.0 (TID 95) in 26 ms on 1e082e99bba9 (executor driver) (96/180)
[2022-06-08 05:21:51,664] {subprocess.py:92} INFO - 22/06/08 05:21:51 INFO Executor: Running task 99.0 in stage 0.0 (TID 99)
[2022-06-08 05:21:51,668] {subprocess.py:92} INFO - 22/06/08 05:21:51 INFO Executor: Finished task 96.0 in stage 0.0 (TID 96). 2367 bytes result sent to driver
[2022-06-08 05:21:51,670] {subprocess.py:92} INFO - 22/06/08 05:21:51 INFO TaskSetManager: Starting task 100.0 in stage 0.0 (TID 100) (1e082e99bba9, executor driver, partition 100, PROCESS_LOCAL, 4545 bytes) taskResourceAssignments Map()
[2022-06-08 05:21:51,671] {subprocess.py:92} INFO - 22/06/08 05:21:51 INFO TaskSetManager: Finished task 96.0 in stage 0.0 (TID 96) in 24 ms on 1e082e99bba9 (executor driver) (97/180)
[2022-06-08 05:21:51,672] {subprocess.py:92} INFO - 22/06/08 05:21:51 INFO Executor: Running task 100.0 in stage 0.0 (TID 100)
[2022-06-08 05:21:51,675] {subprocess.py:92} INFO - 22/06/08 05:21:51 INFO Executor: Finished task 98.0 in stage 0.0 (TID 98). 2367 bytes result sent to driver
[2022-06-08 05:21:51,678] {subprocess.py:92} INFO - 22/06/08 05:21:51 INFO TaskSetManager: Starting task 101.0 in stage 0.0 (TID 101) (1e082e99bba9, executor driver, partition 101, PROCESS_LOCAL, 4545 bytes) taskResourceAssignments Map()
[2022-06-08 05:21:51,679] {subprocess.py:92} INFO - 22/06/08 05:21:51 INFO Executor: Running task 101.0 in stage 0.0 (TID 101)
[2022-06-08 05:21:51,680] {subprocess.py:92} INFO - 22/06/08 05:21:51 INFO TaskSetManager: Finished task 98.0 in stage 0.0 (TID 98) in 29 ms on 1e082e99bba9 (executor driver) (98/180)
[2022-06-08 05:21:51,683] {subprocess.py:92} INFO - 22/06/08 05:21:51 INFO Executor: Finished task 97.0 in stage 0.0 (TID 97). 2606 bytes result sent to driver
[2022-06-08 05:21:51,685] {subprocess.py:92} INFO - 22/06/08 05:21:51 INFO TaskSetManager: Starting task 102.0 in stage 0.0 (TID 102) (1e082e99bba9, executor driver, partition 102, PROCESS_LOCAL, 4545 bytes) taskResourceAssignments Map()
[2022-06-08 05:21:51,686] {subprocess.py:92} INFO - 22/06/08 05:21:51 INFO TaskSetManager: Finished task 97.0 in stage 0.0 (TID 97) in 38 ms on 1e082e99bba9 (executor driver) (99/180)
[2022-06-08 05:21:51,687] {subprocess.py:92} INFO - 22/06/08 05:21:51 INFO Executor: Running task 102.0 in stage 0.0 (TID 102)
[2022-06-08 05:21:51,690] {subprocess.py:92} INFO - 22/06/08 05:21:51 INFO Executor: Finished task 100.0 in stage 0.0 (TID 100). 2128 bytes result sent to driver
[2022-06-08 05:21:51,691] {subprocess.py:92} INFO - 22/06/08 05:21:51 INFO TaskSetManager: Starting task 103.0 in stage 0.0 (TID 103) (1e082e99bba9, executor driver, partition 103, PROCESS_LOCAL, 4545 bytes) taskResourceAssignments Map()
[2022-06-08 05:21:51,693] {subprocess.py:92} INFO - 22/06/08 05:21:51 INFO TaskSetManager: Finished task 100.0 in stage 0.0 (TID 100) in 23 ms on 1e082e99bba9 (executor driver) (100/180)
[2022-06-08 05:21:51,693] {subprocess.py:92} INFO - 22/06/08 05:21:51 INFO Executor: Running task 103.0 in stage 0.0 (TID 103)
[2022-06-08 05:21:51,705] {subprocess.py:92} INFO - 22/06/08 05:21:51 INFO Executor: Finished task 103.0 in stage 0.0 (TID 103). 2367 bytes result sent to driver
[2022-06-08 05:21:51,707] {subprocess.py:92} INFO - 22/06/08 05:21:51 INFO TaskSetManager: Starting task 104.0 in stage 0.0 (TID 104) (1e082e99bba9, executor driver, partition 104, PROCESS_LOCAL, 4545 bytes) taskResourceAssignments Map()
[2022-06-08 05:21:51,708] {subprocess.py:92} INFO - 22/06/08 05:21:51 INFO Executor: Running task 104.0 in stage 0.0 (TID 104)
[2022-06-08 05:21:51,709] {subprocess.py:92} INFO - 22/06/08 05:21:51 INFO TaskSetManager: Finished task 103.0 in stage 0.0 (TID 103) in 18 ms on 1e082e99bba9 (executor driver) (101/180)
[2022-06-08 05:21:51,710] {subprocess.py:92} INFO - 22/06/08 05:21:51 INFO Executor: Finished task 101.0 in stage 0.0 (TID 101). 2128 bytes result sent to driver
[2022-06-08 05:21:51,710] {subprocess.py:92} INFO - 22/06/08 05:21:51 INFO Executor: Finished task 99.0 in stage 0.0 (TID 99). 2367 bytes result sent to driver
[2022-06-08 05:21:51,711] {subprocess.py:92} INFO - 22/06/08 05:21:51 INFO Executor: Finished task 102.0 in stage 0.0 (TID 102). 2367 bytes result sent to driver
[2022-06-08 05:21:51,712] {subprocess.py:92} INFO - 22/06/08 05:21:51 INFO TaskSetManager: Starting task 105.0 in stage 0.0 (TID 105) (1e082e99bba9, executor driver, partition 105, PROCESS_LOCAL, 4545 bytes) taskResourceAssignments Map()
[2022-06-08 05:21:51,713] {subprocess.py:92} INFO - 22/06/08 05:21:51 INFO TaskSetManager: Finished task 101.0 in stage 0.0 (TID 101) in 36 ms on 1e082e99bba9 (executor driver) (102/180)
[2022-06-08 05:21:51,714] {subprocess.py:92} INFO - 22/06/08 05:21:51 INFO Executor: Running task 105.0 in stage 0.0 (TID 105)
[2022-06-08 05:21:51,715] {subprocess.py:92} INFO - 22/06/08 05:21:51 INFO TaskSetManager: Starting task 106.0 in stage 0.0 (TID 106) (1e082e99bba9, executor driver, partition 106, PROCESS_LOCAL, 4545 bytes) taskResourceAssignments Map()
[2022-06-08 05:21:51,716] {subprocess.py:92} INFO - 22/06/08 05:21:51 INFO Executor: Running task 106.0 in stage 0.0 (TID 106)
[2022-06-08 05:21:51,717] {subprocess.py:92} INFO - 22/06/08 05:21:51 INFO TaskSetManager: Finished task 99.0 in stage 0.0 (TID 99) in 55 ms on 1e082e99bba9 (executor driver) (103/180)
[2022-06-08 05:21:51,718] {subprocess.py:92} INFO - 22/06/08 05:21:51 INFO TaskSetManager: Finished task 102.0 in stage 0.0 (TID 102) in 33 ms on 1e082e99bba9 (executor driver) (104/180)
[2022-06-08 05:21:51,719] {subprocess.py:92} INFO - 22/06/08 05:21:51 INFO TaskSetManager: Starting task 107.0 in stage 0.0 (TID 107) (1e082e99bba9, executor driver, partition 107, PROCESS_LOCAL, 4545 bytes) taskResourceAssignments Map()
[2022-06-08 05:21:51,720] {subprocess.py:92} INFO - 22/06/08 05:21:51 INFO Executor: Running task 107.0 in stage 0.0 (TID 107)
[2022-06-08 05:21:51,729] {subprocess.py:92} INFO - 22/06/08 05:21:51 INFO Executor: Finished task 104.0 in stage 0.0 (TID 104). 2367 bytes result sent to driver
[2022-06-08 05:21:51,730] {subprocess.py:92} INFO - 22/06/08 05:21:51 INFO TaskSetManager: Starting task 108.0 in stage 0.0 (TID 108) (1e082e99bba9, executor driver, partition 108, PROCESS_LOCAL, 4545 bytes) taskResourceAssignments Map()
[2022-06-08 05:21:51,731] {subprocess.py:92} INFO - 22/06/08 05:21:51 INFO TaskSetManager: Finished task 104.0 in stage 0.0 (TID 104) in 25 ms on 1e082e99bba9 (executor driver) (105/180)
[2022-06-08 05:21:51,733] {subprocess.py:92} INFO - 22/06/08 05:21:51 INFO Executor: Running task 108.0 in stage 0.0 (TID 108)
[2022-06-08 05:21:51,738] {subprocess.py:92} INFO - 22/06/08 05:21:51 INFO Executor: Finished task 105.0 in stage 0.0 (TID 105). 2367 bytes result sent to driver
[2022-06-08 05:21:51,740] {subprocess.py:92} INFO - 22/06/08 05:21:51 INFO Executor: Finished task 107.0 in stage 0.0 (TID 107). 1886 bytes result sent to driver
[2022-06-08 05:21:51,741] {subprocess.py:92} INFO - 22/06/08 05:21:51 INFO Executor: Finished task 106.0 in stage 0.0 (TID 106). 2128 bytes result sent to driver
[2022-06-08 05:21:51,742] {subprocess.py:92} INFO - 22/06/08 05:21:51 INFO TaskSetManager: Starting task 109.0 in stage 0.0 (TID 109) (1e082e99bba9, executor driver, partition 109, PROCESS_LOCAL, 4545 bytes) taskResourceAssignments Map()
[2022-06-08 05:21:51,744] {subprocess.py:92} INFO - 22/06/08 05:21:51 INFO TaskSetManager: Finished task 105.0 in stage 0.0 (TID 105) in 32 ms on 1e082e99bba9 (executor driver) (106/180)
[2022-06-08 05:21:51,745] {subprocess.py:92} INFO - 22/06/08 05:21:51 INFO Executor: Running task 109.0 in stage 0.0 (TID 109)
[2022-06-08 05:21:51,746] {subprocess.py:92} INFO - 22/06/08 05:21:51 INFO TaskSetManager: Starting task 110.0 in stage 0.0 (TID 110) (1e082e99bba9, executor driver, partition 110, PROCESS_LOCAL, 4545 bytes) taskResourceAssignments Map()
[2022-06-08 05:21:51,747] {subprocess.py:92} INFO - 22/06/08 05:21:51 INFO Executor: Running task 110.0 in stage 0.0 (TID 110)
[2022-06-08 05:21:51,748] {subprocess.py:92} INFO - 22/06/08 05:21:51 INFO TaskSetManager: Starting task 111.0 in stage 0.0 (TID 111) (1e082e99bba9, executor driver, partition 111, PROCESS_LOCAL, 4545 bytes) taskResourceAssignments Map()
[2022-06-08 05:21:51,749] {subprocess.py:92} INFO - 22/06/08 05:21:51 INFO TaskSetManager: Finished task 106.0 in stage 0.0 (TID 106) in 35 ms on 1e082e99bba9 (executor driver) (107/180)
[2022-06-08 05:21:51,750] {subprocess.py:92} INFO - 22/06/08 05:21:51 INFO TaskSetManager: Finished task 107.0 in stage 0.0 (TID 107) in 31 ms on 1e082e99bba9 (executor driver) (108/180)
[2022-06-08 05:21:51,751] {subprocess.py:92} INFO - 22/06/08 05:21:51 INFO Executor: Running task 111.0 in stage 0.0 (TID 111)
[2022-06-08 05:21:51,753] {subprocess.py:92} INFO - 22/06/08 05:21:51 INFO Executor: Finished task 108.0 in stage 0.0 (TID 108). 1886 bytes result sent to driver
[2022-06-08 05:21:51,754] {subprocess.py:92} INFO - 22/06/08 05:21:51 INFO TaskSetManager: Starting task 112.0 in stage 0.0 (TID 112) (1e082e99bba9, executor driver, partition 112, PROCESS_LOCAL, 4545 bytes) taskResourceAssignments Map()
[2022-06-08 05:21:51,755] {subprocess.py:92} INFO - 22/06/08 05:21:51 INFO TaskSetManager: Finished task 108.0 in stage 0.0 (TID 108) in 25 ms on 1e082e99bba9 (executor driver) (109/180)
[2022-06-08 05:21:51,756] {subprocess.py:92} INFO - 22/06/08 05:21:51 INFO Executor: Running task 112.0 in stage 0.0 (TID 112)
[2022-06-08 05:21:51,766] {subprocess.py:92} INFO - 22/06/08 05:21:51 INFO Executor: Finished task 112.0 in stage 0.0 (TID 112). 2367 bytes result sent to driver
[2022-06-08 05:21:51,767] {subprocess.py:92} INFO - 22/06/08 05:21:51 INFO TaskSetManager: Finished task 112.0 in stage 0.0 (TID 112) in 14 ms on 1e082e99bba9 (executor driver) (110/180)
[2022-06-08 05:21:51,769] {subprocess.py:92} INFO - 22/06/08 05:21:51 INFO Executor: Finished task 110.0 in stage 0.0 (TID 110). 2128 bytes result sent to driver
[2022-06-08 05:21:51,771] {subprocess.py:92} INFO - 22/06/08 05:21:51 INFO TaskSetManager: Starting task 113.0 in stage 0.0 (TID 113) (1e082e99bba9, executor driver, partition 113, PROCESS_LOCAL, 4545 bytes) taskResourceAssignments Map()
[2022-06-08 05:21:51,773] {subprocess.py:92} INFO - 22/06/08 05:21:51 INFO Executor: Running task 113.0 in stage 0.0 (TID 113)
[2022-06-08 05:21:51,774] {subprocess.py:92} INFO - 22/06/08 05:21:51 INFO TaskSetManager: Starting task 114.0 in stage 0.0 (TID 114) (1e082e99bba9, executor driver, partition 114, PROCESS_LOCAL, 4545 bytes) taskResourceAssignments Map()
[2022-06-08 05:21:51,776] {subprocess.py:92} INFO - 22/06/08 05:21:51 INFO TaskSetManager: Finished task 110.0 in stage 0.0 (TID 110) in 30 ms on 1e082e99bba9 (executor driver) (111/180)
[2022-06-08 05:21:51,777] {subprocess.py:92} INFO - 22/06/08 05:21:51 INFO Executor: Running task 114.0 in stage 0.0 (TID 114)
[2022-06-08 05:21:51,778] {subprocess.py:92} INFO - 22/06/08 05:21:51 INFO Executor: Finished task 111.0 in stage 0.0 (TID 111). 2606 bytes result sent to driver
[2022-06-08 05:21:51,779] {subprocess.py:92} INFO - 22/06/08 05:21:51 INFO TaskSetManager: Starting task 115.0 in stage 0.0 (TID 115) (1e082e99bba9, executor driver, partition 115, PROCESS_LOCAL, 4545 bytes) taskResourceAssignments Map()
[2022-06-08 05:21:51,780] {subprocess.py:92} INFO - 22/06/08 05:21:51 INFO TaskSetManager: Finished task 111.0 in stage 0.0 (TID 111) in 32 ms on 1e082e99bba9 (executor driver) (112/180)
[2022-06-08 05:21:51,780] {subprocess.py:92} INFO - 22/06/08 05:21:51 INFO Executor: Running task 115.0 in stage 0.0 (TID 115)
[2022-06-08 05:21:51,782] {subprocess.py:92} INFO - 22/06/08 05:21:51 INFO Executor: Finished task 109.0 in stage 0.0 (TID 109). 2128 bytes result sent to driver
[2022-06-08 05:21:51,783] {subprocess.py:92} INFO - 22/06/08 05:21:51 INFO TaskSetManager: Starting task 116.0 in stage 0.0 (TID 116) (1e082e99bba9, executor driver, partition 116, PROCESS_LOCAL, 4545 bytes) taskResourceAssignments Map()
[2022-06-08 05:21:51,785] {subprocess.py:92} INFO - 22/06/08 05:21:51 INFO TaskSetManager: Finished task 109.0 in stage 0.0 (TID 109) in 41 ms on 1e082e99bba9 (executor driver) (113/180)
[2022-06-08 05:21:51,785] {subprocess.py:92} INFO - 22/06/08 05:21:51 INFO Executor: Running task 116.0 in stage 0.0 (TID 116)
[2022-06-08 05:21:51,792] {subprocess.py:92} INFO - 22/06/08 05:21:51 INFO Executor: Finished task 114.0 in stage 0.0 (TID 114). 2128 bytes result sent to driver
[2022-06-08 05:21:51,793] {subprocess.py:92} INFO - 22/06/08 05:21:51 INFO TaskSetManager: Starting task 117.0 in stage 0.0 (TID 117) (1e082e99bba9, executor driver, partition 117, PROCESS_LOCAL, 4545 bytes) taskResourceAssignments Map()
[2022-06-08 05:21:51,795] {subprocess.py:92} INFO - 22/06/08 05:21:51 INFO TaskSetManager: Finished task 114.0 in stage 0.0 (TID 114) in 21 ms on 1e082e99bba9 (executor driver) (114/180)
[2022-06-08 05:21:51,796] {subprocess.py:92} INFO - 22/06/08 05:21:51 INFO Executor: Running task 117.0 in stage 0.0 (TID 117)
[2022-06-08 05:21:51,806] {subprocess.py:92} INFO - 22/06/08 05:21:51 INFO Executor: Finished task 115.0 in stage 0.0 (TID 115). 2128 bytes result sent to driver
[2022-06-08 05:21:51,808] {subprocess.py:92} INFO - 22/06/08 05:21:51 INFO TaskSetManager: Starting task 118.0 in stage 0.0 (TID 118) (1e082e99bba9, executor driver, partition 118, PROCESS_LOCAL, 4545 bytes) taskResourceAssignments Map()
[2022-06-08 05:21:51,809] {subprocess.py:92} INFO - 22/06/08 05:21:51 INFO TaskSetManager: Finished task 115.0 in stage 0.0 (TID 115) in 32 ms on 1e082e99bba9 (executor driver) (115/180)
[2022-06-08 05:21:51,811] {subprocess.py:92} INFO - 22/06/08 05:21:51 INFO Executor: Finished task 113.0 in stage 0.0 (TID 113). 2606 bytes result sent to driver
[2022-06-08 05:21:51,812] {subprocess.py:92} INFO - 22/06/08 05:21:51 INFO Executor: Running task 118.0 in stage 0.0 (TID 118)
[2022-06-08 05:21:51,812] {subprocess.py:92} INFO - 22/06/08 05:21:51 INFO TaskSetManager: Starting task 119.0 in stage 0.0 (TID 119) (1e082e99bba9, executor driver, partition 119, PROCESS_LOCAL, 4545 bytes) taskResourceAssignments Map()
[2022-06-08 05:21:51,814] {subprocess.py:92} INFO - 22/06/08 05:21:51 INFO TaskSetManager: Finished task 113.0 in stage 0.0 (TID 113) in 45 ms on 1e082e99bba9 (executor driver) (116/180)
[2022-06-08 05:21:51,815] {subprocess.py:92} INFO - 22/06/08 05:21:51 INFO Executor: Running task 119.0 in stage 0.0 (TID 119)
[2022-06-08 05:21:51,815] {subprocess.py:92} INFO - 22/06/08 05:21:51 INFO Executor: Finished task 117.0 in stage 0.0 (TID 117). 2128 bytes result sent to driver
[2022-06-08 05:21:51,816] {subprocess.py:92} INFO - 22/06/08 05:21:51 INFO TaskSetManager: Starting task 120.0 in stage 0.0 (TID 120) (1e082e99bba9, executor driver, partition 120, PROCESS_LOCAL, 4545 bytes) taskResourceAssignments Map()
[2022-06-08 05:21:51,818] {subprocess.py:92} INFO - 22/06/08 05:21:51 INFO Executor: Running task 120.0 in stage 0.0 (TID 120)
[2022-06-08 05:21:51,819] {subprocess.py:92} INFO - 22/06/08 05:21:51 INFO TaskSetManager: Finished task 117.0 in stage 0.0 (TID 117) in 26 ms on 1e082e99bba9 (executor driver) (117/180)
[2022-06-08 05:21:51,820] {subprocess.py:92} INFO - 22/06/08 05:21:51 INFO Executor: Finished task 116.0 in stage 0.0 (TID 116). 2367 bytes result sent to driver
[2022-06-08 05:21:51,828] {subprocess.py:92} INFO - 22/06/08 05:21:51 INFO TaskSetManager: Starting task 121.0 in stage 0.0 (TID 121) (1e082e99bba9, executor driver, partition 121, PROCESS_LOCAL, 4545 bytes) taskResourceAssignments Map()
[2022-06-08 05:21:51,829] {subprocess.py:92} INFO - 22/06/08 05:21:51 INFO Executor: Finished task 120.0 in stage 0.0 (TID 120). 2367 bytes result sent to driver
[2022-06-08 05:21:51,829] {subprocess.py:92} INFO - 22/06/08 05:21:51 INFO TaskSetManager: Finished task 116.0 in stage 0.0 (TID 116) in 46 ms on 1e082e99bba9 (executor driver) (118/180)
[2022-06-08 05:21:51,830] {subprocess.py:92} INFO - 22/06/08 05:21:51 INFO Executor: Running task 121.0 in stage 0.0 (TID 121)
[2022-06-08 05:21:51,831] {subprocess.py:92} INFO - 22/06/08 05:21:51 INFO TaskSetManager: Starting task 122.0 in stage 0.0 (TID 122) (1e082e99bba9, executor driver, partition 122, PROCESS_LOCAL, 4545 bytes) taskResourceAssignments Map()
[2022-06-08 05:21:51,832] {subprocess.py:92} INFO - 22/06/08 05:21:51 INFO TaskSetManager: Finished task 120.0 in stage 0.0 (TID 120) in 16 ms on 1e082e99bba9 (executor driver) (119/180)
[2022-06-08 05:21:51,833] {subprocess.py:92} INFO - 22/06/08 05:21:51 INFO Executor: Running task 122.0 in stage 0.0 (TID 122)
[2022-06-08 05:21:51,836] {subprocess.py:92} INFO - 22/06/08 05:21:51 INFO Executor: Finished task 118.0 in stage 0.0 (TID 118). 2128 bytes result sent to driver
[2022-06-08 05:21:51,838] {subprocess.py:92} INFO - 22/06/08 05:21:51 INFO Executor: Finished task 119.0 in stage 0.0 (TID 119). 2367 bytes result sent to driver
[2022-06-08 05:21:51,839] {subprocess.py:92} INFO - 22/06/08 05:21:51 INFO TaskSetManager: Starting task 123.0 in stage 0.0 (TID 123) (1e082e99bba9, executor driver, partition 123, PROCESS_LOCAL, 4545 bytes) taskResourceAssignments Map()
[2022-06-08 05:21:51,841] {subprocess.py:92} INFO - 22/06/08 05:21:51 INFO TaskSetManager: Finished task 118.0 in stage 0.0 (TID 118) in 32 ms on 1e082e99bba9 (executor driver) (120/180)
[2022-06-08 05:21:51,842] {subprocess.py:92} INFO - 22/06/08 05:21:51 INFO Executor: Running task 123.0 in stage 0.0 (TID 123)
[2022-06-08 05:21:51,843] {subprocess.py:92} INFO - 22/06/08 05:21:51 INFO TaskSetManager: Starting task 124.0 in stage 0.0 (TID 124) (1e082e99bba9, executor driver, partition 124, PROCESS_LOCAL, 4545 bytes) taskResourceAssignments Map()
[2022-06-08 05:21:51,845] {subprocess.py:92} INFO - 22/06/08 05:21:51 INFO TaskSetManager: Finished task 119.0 in stage 0.0 (TID 119) in 32 ms on 1e082e99bba9 (executor driver) (121/180)
[2022-06-08 05:21:51,846] {subprocess.py:92} INFO - 22/06/08 05:21:51 INFO Executor: Running task 124.0 in stage 0.0 (TID 124)
[2022-06-08 05:21:51,853] {subprocess.py:92} INFO - 22/06/08 05:21:51 INFO Executor: Finished task 122.0 in stage 0.0 (TID 122). 2367 bytes result sent to driver
[2022-06-08 05:21:51,854] {subprocess.py:92} INFO - 22/06/08 05:21:51 INFO TaskSetManager: Finished task 122.0 in stage 0.0 (TID 122) in 24 ms on 1e082e99bba9 (executor driver) (122/180)
[2022-06-08 05:21:51,855] {subprocess.py:92} INFO - 22/06/08 05:21:51 INFO TaskSetManager: Starting task 125.0 in stage 0.0 (TID 125) (1e082e99bba9, executor driver, partition 125, PROCESS_LOCAL, 4545 bytes) taskResourceAssignments Map()
[2022-06-08 05:21:51,857] {subprocess.py:92} INFO - 22/06/08 05:21:51 INFO Executor: Running task 125.0 in stage 0.0 (TID 125)
[2022-06-08 05:21:51,859] {subprocess.py:92} INFO - 22/06/08 05:21:51 INFO Executor: Finished task 121.0 in stage 0.0 (TID 121). 2367 bytes result sent to driver
[2022-06-08 05:21:51,860] {subprocess.py:92} INFO - 22/06/08 05:21:51 INFO TaskSetManager: Starting task 126.0 in stage 0.0 (TID 126) (1e082e99bba9, executor driver, partition 126, PROCESS_LOCAL, 4545 bytes) taskResourceAssignments Map()
[2022-06-08 05:21:51,862] {subprocess.py:92} INFO - 22/06/08 05:21:51 INFO TaskSetManager: Finished task 121.0 in stage 0.0 (TID 121) in 34 ms on 1e082e99bba9 (executor driver) (123/180)
[2022-06-08 05:21:51,862] {subprocess.py:92} INFO - 22/06/08 05:21:51 INFO Executor: Running task 126.0 in stage 0.0 (TID 126)
[2022-06-08 05:21:51,863] {subprocess.py:92} INFO - 22/06/08 05:21:51 INFO Executor: Finished task 124.0 in stage 0.0 (TID 124). 2367 bytes result sent to driver
[2022-06-08 05:21:51,865] {subprocess.py:92} INFO - 22/06/08 05:21:51 INFO TaskSetManager: Starting task 127.0 in stage 0.0 (TID 127) (1e082e99bba9, executor driver, partition 127, PROCESS_LOCAL, 4545 bytes) taskResourceAssignments Map()
[2022-06-08 05:21:51,866] {subprocess.py:92} INFO - 22/06/08 05:21:51 INFO TaskSetManager: Finished task 124.0 in stage 0.0 (TID 124) in 24 ms on 1e082e99bba9 (executor driver) (124/180)
[2022-06-08 05:21:51,867] {subprocess.py:92} INFO - 22/06/08 05:21:51 INFO Executor: Running task 127.0 in stage 0.0 (TID 127)
[2022-06-08 05:21:51,869] {subprocess.py:92} INFO - 22/06/08 05:21:51 INFO Executor: Finished task 123.0 in stage 0.0 (TID 123). 2128 bytes result sent to driver
